File: experimental/Instron/DYN1_cyclic_temperature_600MPa.is_trelax_RawData/Specimen_RawData_4.csv
Test : Start of hold value,"100.00000",MPa

Time,Extension,Load,Temperature: Chamber 3119-600 1 1,Tensile strain (Extension),Tensile stress
(s),(mm),(N),(C),(mm/mm),(MPa)
"0.00000","1.99937","0.45540","29.40417","0.00000","3.99445"
"5.30000","2.04261","0.57787","29.51067","0.00042","5.06867"
"10.60000","2.08692","0.77696","29.62662","0.00086","6.81489"
"15.90000","2.13097","1.38911","29.55261","0.00129","12.18415"
"21.20000","2.17523","1.66552","29.60588","0.00172","14.60863"
"26.50000","2.21924","1.81095","29.69459","0.00216","15.88423"
"31.80000","2.26366","2.27810","29.71525","0.00259","19.98175"
"37.10000","2.30764","2.75490","29.70443","0.00302","24.16382"
"42.40000","2.35204","3.09228","29.73033","0.00346","27.12308"
"47.70000","2.39598","3.13048","29.73640","0.00389","27.45815"
"53.00000","2.44030","3.75781","29.66686","0.00432","32.96064"
"58.30000","2.48423","4.17388","29.65439","0.00475","36.61000"
"63.60000","2.52852","4.31372","29.76945","0.00519","37.83660"
"68.90000","2.57264","4.60278","29.80513","0.00562","40.37205"
"74.20000","2.61692","5.24343","29.73916","0.00605","45.99127"
"79.50000","2.66099","5.41261","29.74672","0.00649","47.47517"
"84.80000","2.70521","5.57370","29.80941","0.00692","48.88817"
"90.10000","2.74934","6.19735","29.73794","0.00735","54.35836"
"95.40000","2.79351","6.51739","29.75427","0.00779","57.16544"
"100.70000","2.83772","6.57482","29.83471","0.00822","57.66923"
"106.00000","2.88188","7.03712","29.75397","0.00865","61.72415"
"111.30000","2.92609","7.57315","29.80213","0.00909","66.42580"
"116.60000","2.97013","7.67739","29.82431","0.00952","67.34013"
"121.90000","3.01434","7.93365","29.79746","0.00995","69.58781"
"127.20000","3.05841","8.49955","29.82482","0.01038","74.55145"
"132.50000","3.10278","8.75447","29.85130","0.01082","76.78738"
"137.80000","3.14684","8.88362","29.95895","0.01125","77.92018"
"143.10000","3.19114","9.42771","29.91375","0.01168","82.69257"
"148.40000","3.23511","9.83955","29.97921","0.01211","86.30493"
"153.70000","3.27943","9.88532","30.08366","0.01255","86.70636"
"159.00000","3.32350","10.24066","30.05958","0.01298","89.82315"
"164.30000","3.36784","10.81098","30.03449","0.01342","94.82549"
"169.60000","3.41188","11.00865","30.10014","0.01385","96.55930"
"174.90000","3.45609","11.15360","30.16762","0.01428","97.83072"
"180.00700","3.48801","11.51487","30.15251","0.01459","100.99948"
"185.30700","3.49123","11.46749","30.13502","0.01463","100.58392"
"190.60700","3.49291","11.19670","30.22842","0.01464","98.20872"
"195.90700","3.49506","11.15343","30.26254","0.01466","97.82925"
"201.20700","3.50447","11.49736","30.21979","0.01476","100.84593"
"206.50700","3.54324","11.93254","30.24516","0.01514","104.66295"
"211.80700","3.54320","11.73171","30.25421","0.01514","102.90149"
"217.10700","3.54309","11.72887","30.28400","0.01513","102.87651"
"222.40700","3.54296","11.76319","30.32886","0.01513","103.17760"
"227.70700","3.54285","11.43652","30.37147","0.01513","100.31226"
"233.00700","3.54275","11.32915","30.41996","0.01513","99.37054"
"238.30700","3.54263","11.55074","30.38084","0.01513","101.31409"
"243.60700","3.54247","11.67231","30.37632","0.01513","102.38046"
"248.90700","3.54233","11.60249","30.40439","0.01513","101.76801"
"254.20700","3.54218","11.69719","30.43151","0.01513","102.59870"
"259.50700","3.54200","11.78314","30.39681","0.01512","103.35256"
"264.80700","3.54180","11.56596","30.43683","0.01512","101.44766"
"270.10700","3.54167","11.29573","30.49055","0.01512","99.07738"
"275.40700","3.54153","11.25229","30.48693","0.01512","98.69637"
"280.70700","3.54137","11.45705","30.45371","0.01512","100.49234"
"286.00700","3.54121","11.45116","30.51270","0.01512","100.44064"
"291.30700","3.54112","11.32947","30.51995","0.01511","99.37335"
"296.60700","3.54109","11.43657","30.48267","0.01511","100.31274"
"301.90700","3.54104","11.63863","30.45475","0.01511","102.08505"
"307.20700","3.54103","11.56109","30.39051","0.01511","101.40494"
"312.50700","3.54104","11.29472","30.43613","0.01511","99.06855"
"317.80700","3.54106","11.23710","30.37371","0.01511","98.56309"
"323.10700","3.54107","11.41398","30.31130","0.01511","100.11456"
"328.40700","3.54109","11.31767","30.32884","0.01511","99.26982"
"333.70700","3.54112","11.14639","30.29440","0.01511","97.76749"
"339.00700","3.54117","11.20514","30.21528","0.01512","98.28275"
"344.30700","3.54121","11.42022","30.10326","0.01512","100.16931"
"349.60700","3.54126","11.38966","30.07481","0.01512","99.90125"
"354.90700","3.54133","11.17562","30.05530","0.01512","98.02383"
"360.20700","3.54143","11.23300","29.94700","0.01512","98.52711"
"365.50700","3.54152","11.39075","29.87715","0.01512","99.91086"
"370.80700","3.54162","11.15253","29.90516","0.01512","97.82137"
"376.10700","3.54180","10.92590","29.83635","0.01512","95.83353"
"381.40700","3.54197","11.20271","29.70166","0.01512","98.26150"
"386.70700","3.54216","11.17731","29.68033","0.01513","98.03869"
"392.00700","3.54256","11.02803","29.68578","0.01513","96.72933"
"397.30700","3.54361","11.21576","29.61214","0.01514","98.37598"
"402.60700","3.57722","11.95102","29.52071","0.01547","104.82504"
"407.90700","3.57995","11.63802","29.52552","0.01550","102.07968"
"413.20700","3.57992","11.35206","29.54584","0.01550","99.57142"
"418.50700","3.57986","11.56762","29.42952","0.01549","101.46217"
"423.80700","3.57978","11.55087","29.38415","0.01549","101.31525"
"429.10700","3.57971","11.38208","29.43102","0.01549","99.83479"
"434.40700","3.57963","11.71076","29.45886","0.01549","102.71769"
"439.70700","3.57948","11.97395","29.63498","0.01549","105.02623"
"445.00700","3.57926","11.99158","29.88751","0.01549","105.18079"
"450.30700","3.57744","11.94416","30.17255","0.01547","104.76491"
"455.60700","3.55034","11.49886","30.53077","0.01521","100.85904"
"460.90700","3.53283","11.17623","30.79258","0.01503","98.02924"
"466.20700","3.53294","11.24629","31.20805","0.01503","98.64371"
"471.50700","3.53304","11.12886","31.63991","0.01504","97.61369"
"476.80700","3.53304","11.42191","31.91723","0.01504","100.18413"
"482.10700","3.53307","11.28126","32.34170","0.01504","98.95048"
"487.40700","3.53303","11.60590","32.56138","0.01504","101.79792"
"492.70700","3.53294","11.60838","32.96641","0.01503","101.81966"
"498.00700","3.53283","11.63330","33.39438","0.01503","102.03825"
"503.30700","3.53262","11.61634","33.72764","0.01503","101.88956"
"508.60700","3.48286","10.91310","34.12716","0.01454","95.72127"
"513.90700","3.48310","10.97072","34.58427","0.01455","96.22662"
"519.20700","3.48329","11.11988","35.12899","0.01455","97.53500"
"524.50700","3.48336","11.33008","35.83289","0.01455","99.37871"
"529.80700","3.48329","11.45732","36.54806","0.01455","100.49474"
"535.10700","3.48309","11.68595","37.47252","0.01455","102.50011"
"540.40700","3.47282","11.89792","38.47407","0.01445","104.35933"
"545.70700","3.39396","11.00601","39.43995","0.01367","96.53619"
"551.00700","3.39383","11.07055","40.51704","0.01367","97.10223"
"556.30700","3.39497","11.24864","41.54638","0.01368","98.66436"
"561.60700","3.39530","11.30160","42.54511","0.01369","99.12889"
"566.90700","3.39532","11.51752","43.60004","0.01369","101.02272"
"572.20700","3.39520","11.58731","44.60387","0.01368","101.63493"
"577.50700","3.39497","11.63677","45.46535","0.01368","102.06867"
"582.80700","3.39319","11.86883","46.36569","0.01366","104.10419"
"588.10700","3.34374","11.21120","47.16077","0.01318","98.33592"
"593.40700","3.33821","11.30173","47.90483","0.01313","99.13001"
"598.70700","3.33827","11.38031","48.67539","0.01313","99.81923"
"604.00700","3.33821","11.54367","49.44254","0.01313","101.25214"
"609.30700","3.33793","11.68272","50.15419","0.01312","102.47173"
"614.60700","3.28432","11.02207","50.89806","0.01260","96.67707"
"619.90700","3.28442","11.12908","51.53188","0.01260","97.61569"
"625.20700","3.28471","11.28348","52.26310","0.01260","98.96989"
"630.50700","3.28479","11.39397","53.02688","0.01260","99.93906"
"635.80700","3.28471","11.52406","53.73494","0.01260","101.08008"
"641.10700","3.28434","11.69553","54.47004","0.01260","102.58409"
"646.40700","3.26731","11.53771","55.18974","0.01243","101.19986"
"651.70700","3.20956","10.92603","55.98665","0.01186","95.83468"
"657.00700","3.20931","11.13514","56.70855","0.01186","97.66877"
"662.30700","3.20941","11.38673","57.52229","0.01186","99.87557"
"667.60700","3.20939","11.47946","58.32534","0.01186","100.68894"
"672.90700","3.20924","11.73011","59.07076","0.01186","102.88739"
"678.20700","3.20831","11.79474","59.92000","0.01185","103.45434"
"683.50700","3.15236","11.29886","60.67257","0.01130","99.10485"
"688.80700","3.15236","11.44756","61.45349","0.01130","100.40910"
"694.10700","3.15231","11.63164","62.22707","0.01130","102.02374"
"699.40700","3.15216","11.73851","62.88474","0.01130","102.96111"
"704.70700","3.11965","11.48816","63.68062","0.01098","100.76521"
"710.00700","3.00147","10.24884","64.35301","0.00982","89.89484"
"715.30700","3.00036","10.47604","65.13796","0.00981","91.88773"
"720.60700","3.00732","10.76050","65.93616","0.00988","94.38276"
"725.90700","3.05267","11.49203","66.62276","0.01033","100.79919"
"731.20700","3.07575","11.96342","67.34039","0.01055","104.93380"
"736.50700","3.07529","12.13713","68.03288","0.01055","106.45748"
"741.80700","3.06545","12.33311","68.69038","0.01045","108.17648"
"747.10700","2.99763","11.68151","69.46281","0.00979","102.46117"
"752.40700","2.94331","11.37616","70.21562","0.00925","99.78288"
"757.70700","2.90966","11.29248","70.93783","0.00892","99.04883"
"763.00700","2.90898","11.60609","71.70735","0.00892","101.79965"
"768.30700","2.81804","10.82545","72.38927","0.00803","94.95247"
"773.60700","2.74926","10.70164","73.10504","0.00735","93.86650"
"778.90700","2.75031","11.11970","73.88505","0.00736","97.53340"
"784.20700","2.75044","11.59418","74.57283","0.00736","101.69515"
"789.50700","2.75015","11.96858","75.37130","0.00736","104.97908"
"794.80700","2.72058","12.09821","76.14559","0.00707","106.11607"
"800.10700","2.57084","11.14020","76.80447","0.00560","97.71323"
"805.40700","2.55838","11.41685","77.51293","0.00548","100.13976"
"810.70700","2.47475","11.24815","78.16447","0.00466","98.66000"
"816.00700","2.41804","11.38077","78.88235","0.00410","99.82330"
"821.30700","2.36549","11.61913","79.55803","0.00359","101.91398"
"826.60700","2.27142","11.41636","80.28663","0.00267","100.13549"
"831.90700","2.19382","11.57398","81.02313","0.00191","101.51794"
"837.20700","2.10673","11.43152","81.70547","0.00105","100.26841"
"842.50700","2.00221","11.40387","82.45983","0.00003","100.02587"
"847.80700","1.87681","11.40758","83.15931","-0.00120","100.05841"
"853.10700","1.75396","11.30813","83.98512","-0.00241","99.18613"
"858.40700","1.63191","11.41319","84.69028","-0.00360","100.10764"
"863.70700","1.47206","11.19245","85.34464","-0.00517","98.17148"
"869.00700","1.30885","11.24479","86.12762","-0.00677","98.63058"
"874.30700","1.17787","11.56686","86.78938","-0.00805","101.45549"
"879.60700","0.97582","11.33288","87.53996","-0.01004","99.40324"
"884.90700","0.83554","11.96778","88.30620","-0.01141","104.97207"
"890.20700","0.43457","10.93393","88.99149","-0.01534","95.90392"
"895.50700","0.20133","11.44169","89.73425","-0.01763","100.35763"
"900.80700","-0.02771","11.31169","90.39130","-0.01987","99.21740"
"906.10700","-0.29000","11.52302","91.04491","-0.02245","101.07098"
"911.40700","-0.63030","11.31762","91.80626","-0.02578","99.26936"
"916.70700","-0.89906","11.60477","92.42551","-0.02842","101.78806"
"922.00700","-1.18132","11.40821","93.18546","-0.03118","100.06394"
"927.30700","-1.50918","11.45287","93.88799","-0.03440","100.45569"
"932.60700","-1.82186","11.16193","94.62951","-0.03746","97.90377"
"937.90700","-2.03478","11.44801","95.26774","-0.03955","100.41309"
"943.20700","-2.23563","11.15596","96.02176","-0.04152","97.85138"
"948.50700","-2.40860","11.41642","96.72578","-0.04322","100.13596"
"953.80700","-2.61225","11.36746","97.50332","-0.04521","99.70650"
"959.10700","-2.79938","11.31723","98.32847","-0.04705","99.26598"
"964.40700","-2.93016","11.57035","98.92695","-0.04833","101.48617"
"969.70700","-3.07471","11.40090","99.61157","-0.04975","99.99985"
"975.00700","-3.21092","11.59600","100.25574","-0.05108","101.71113"
"980.30700","-3.36236","11.34256","101.04403","-0.05257","99.48817"
"985.60700","-3.49269","11.19158","101.78281","-0.05384","98.16383"
"990.90700","-3.60150","11.35954","102.42679","-0.05491","99.63709"
"996.20700","-3.74062","11.24955","103.12980","-0.05628","98.67227"
"1001.50700","-3.83613","11.32367","103.83994","-0.05721","99.32243"
"1006.80700","-3.95092","11.35927","104.50842","-0.05834","99.63467"
"1012.10700","-4.05376","11.34406","105.23040","-0.05935","99.50130"
"1017.40700","-4.15506","11.35660","105.98148","-0.06034","99.61124"
"1022.70700","-4.16377","12.14286","106.65081","-0.06042","106.50773"
"1028.00700","-4.31175","11.54309","107.39424","-0.06187","101.24702"
"1033.30700","-4.57815","10.56287","108.07851","-0.06449","92.64929"
"1038.60700","-4.65411","11.03705","108.84181","-0.06523","96.80847"
"1043.90700","-4.65435","11.85009","109.48193","-0.06523","103.93981"
"1049.20700","-4.79721","11.28944","110.13882","-0.06663","99.02225"
"1054.50700","-4.89538","11.55012","110.88433","-0.06760","101.30865"
"1059.80700","-5.03034","11.37942","111.63107","-0.06892","99.81142"
"1065.10700","-5.18415","11.25608","112.38788","-0.07043","98.72958"
"1070.40700","-5.26135","11.39598","113.14307","-0.07118","99.95672"
"1075.70700","-5.32361","11.47333","113.76349","-0.07179","100.63515"
"1081.00700","-5.41200","11.23287","114.48383","-0.07266","98.52604"
"1086.30700","-5.43629","11.63033","115.12145","-0.07290","102.01222"
"1091.60700","-5.54427","11.31259","115.88530","-0.07396","99.22522"
"1096.90700","-5.62013","11.38633","116.59446","-0.07470","99.87202"
"1102.20700","-5.67108","11.47419","117.26676","-0.07520","100.64271"
"1107.50700","-5.75291","11.46031","117.92537","-0.07600","100.52097"
"1112.80700","-5.81684","11.51951","118.50615","-0.07663","101.04022"
"1118.10700","-5.87658","11.31296","119.23447","-0.07722","99.22849"
"1123.40700","-5.95603","11.34662","119.98622","-0.07799","99.52374"
"1128.70700","-6.00398","11.41823","120.71862","-0.07847","100.15189"
"1134.00700","-6.03733","11.35678","121.40192","-0.07879","99.61282"
"1139.30700","-6.09981","11.21813","122.02980","-0.07940","98.39674"
"1144.60700","-6.13255","11.47840","122.74905","-0.07973","100.67966"
"1149.90700","-6.20867","11.34906","123.46648","-0.08047","99.54513"
"1155.20700","-6.23734","11.32610","124.14909","-0.08075","99.34373"
"1160.50700","-6.26371","11.38529","124.85213","-0.08101","99.86291"
"1165.80700","-6.28687","11.33699","125.33512","-0.08124","99.43929"
"1171.10700","-6.28702","11.51019","125.67415","-0.08124","100.95847"
"1176.40700","-6.28728","11.44428","125.77588","-0.08124","100.38030"
"1181.70700","-6.28729","11.49302","125.72032","-0.08124","100.80782"
"1187.00700","-6.28723","11.20506","125.63237","-0.08124","98.28208"
"1192.30700","-6.28714","11.34577","125.47011","-0.08124","99.51626"
"1197.60700","-6.28701","11.25252","125.27473","-0.08124","98.69839"
"1202.90700","-6.28683","11.11302","125.07277","-0.08124","97.47482"
"1208.20700","-6.28643","11.13274","124.91856","-0.08123","97.64777"
"1213.50700","-6.28572","10.96713","124.72004","-0.08123","96.19514"
"1218.80700","-6.28347","10.92258","124.43509","-0.08121","95.80437"
"1224.10700","-6.19893","12.12016","124.06943","-0.08038","106.30863"
"1229.40700","-6.18618","11.96337","123.59131","-0.08025","104.93340"
"1234.70700","-6.18640","11.56850","123.08130","-0.08025","101.46992"
"1240.00700","-6.18659","11.44255","122.42516","-0.08026","100.36514"
"1245.30700","-6.18651","11.21051","121.67259","-0.08025","98.32987"
"1250.60700","-6.18624","10.81271","121.03149","-0.08025","94.84072"
"1255.90700","-6.17167","10.84065","120.28292","-0.08011","95.08580"
"1261.20700","-6.08552","11.80995","119.42365","-0.07926","103.58774"
"1266.50700","-6.08557","11.41312","118.70798","-0.07926","100.10699"
"1271.80700","-6.08550","11.13562","117.94032","-0.07926","97.67304"
"1277.10700","-6.07303","11.21525","117.24861","-0.07914","98.37143"
"1282.40700","-6.00757","11.73706","116.48165","-0.07850","102.94838"
"1287.70700","-6.00767","11.44626","115.78529","-0.07850","100.39768"
"1293.00700","-6.00766","11.35749","115.11558","-0.07850","99.61907"
"1298.30700","-6.00750","10.99549","114.41736","-0.07850","96.44389"
"1303.60700","-5.96770","11.44430","113.85729","-0.07811","100.38055"
"1308.90700","-5.92029","11.71662","113.22771","-0.07764","102.76907"
"1314.20700","-5.92032","11.43352","112.62450","-0.07764","100.28597"
"1319.50700","-5.92028","11.24413","112.09220","-0.07764","98.62476"
"1324.80700","-5.90709","11.16830","111.48502","-0.07752","97.95965"
"1330.10700","-5.84590","11.76246","110.83923","-0.07692","103.17117"
"1335.40700","-5.83824","11.49046","110.26273","-0.07684","100.78542"
"1340.70700","-5.83816","11.29318","109.63894","-0.07684","99.05497"
"1346.00700","-5.81274","11.34784","109.06340","-0.07659","99.53441"
"1351.30700","-5.79710","11.33007","108.52055","-0.07644","99.37862"
"1356.60700","-5.75855","11.62796","107.95550","-0.07606","101.99148"
"1361.90700","-5.74063","11.49705","107.45840","-0.07588","100.84317"
"1367.20700","-5.74001","11.26338","106.89644","-0.07588","98.79366"
"1372.50700","-5.70881","11.45349","106.35739","-0.07557","100.46111"
"1377.80700","-5.70223","11.26334","105.90854","-0.07551","98.79327"
"1383.10700","-5.67111","11.47147","105.38129","-0.07520","100.61885"
"1388.40700","-5.63700","11.56089","104.84406","-0.07487","101.40320"
"1393.70700","-5.63699","11.37319","104.36138","-0.07487","99.75679"
"1399.00700","-5.62431","11.28557","103.88770","-0.07474","98.98827"
"1404.30700","-5.59279","11.44075","103.44477","-0.07443","100.34936"
"1409.60700","-5.55703","11.46478","102.98101","-0.07408","100.56013"
"1414.90700","-5.55693","11.36163","102.49658","-0.07408","99.65536"
"1420.20700","-5.53631","11.34160","102.07560","-0.07388","99.47967"
"1425.50700","-5.50869","11.27492","101.63408","-0.07361","98.89486"
"1430.80700","-5.49351","11.20062","101.15109","-0.07346","98.24317"
"1436.10700","-5.44994","11.64763","100.74666","-0.07303","102.16399"
"1441.40700","-5.44991","11.38158","100.27008","-0.07303","99.83041"
"1446.70700","-5.42830","11.46201","99.88125","-0.07282","100.53582"
"1452.00700","-5.40332","11.40073","99.40316","-0.07258","99.99832"
"1457.30700","-5.36101","11.53836","98.95702","-0.07216","101.20557"
"1462.60700","-5.34645","11.35349","98.51455","-0.07202","99.58399"
"1467.90700","-5.32945","11.17981","98.08331","-0.07185","98.06062"
"1473.20700","-5.30462","11.33014","97.66727","-0.07161","99.37917"
"1478.50700","-5.24093","11.86217","97.14677","-0.07098","104.04579"
"1483.80700","-5.23280","11.49931","96.68085","-0.07090","100.86298"
"1489.10700","-5.22991","11.22449","96.20934","-0.07088","98.45248"
"1494.40700","-5.16945","11.74094","95.69402","-0.07028","102.98238"
"1499.70700","-5.16213","11.30597","95.28542","-0.07021","99.16723"
"1505.00700","-5.12614","11.37592","94.92348","-0.06986","99.78076"
"1510.30700","-5.08035","11.50062","94.42624","-0.06941","100.87454"
"1515.60700","-5.06251","11.30772","94.02293","-0.06923","99.18253"
"1520.90700","-5.02276","11.51096","93.57861","-0.06885","100.96519"
"1526.20700","-5.01564","11.30035","93.21456","-0.06878","99.11792"
"1531.50700","-4.93814","11.67026","92.75021","-0.06802","102.36242"
"1536.80700","-4.92931","11.36242","92.29434","-0.06793","99.66230"
"1542.10700","-4.91872","11.10373","91.88766","-0.06783","97.39328"
"1547.40700","-4.83820","11.66987","91.47521","-0.06704","102.35902"
"1552.70700","-4.83122","11.31133","91.04367","-0.06697","99.21424"
"1558.00700","-4.80125","11.33646","90.65519","-0.06667","99.43463"
"1563.30700","-4.72831","11.63285","90.20786","-0.06596","102.03433"
"1568.60700","-4.72609","11.34285","89.90835","-0.06594","99.49072"
"1573.90700","-4.65799","11.36161","89.50073","-0.06527","99.65524"
"1579.20700","-4.56748","11.67178","89.00898","-0.06438","102.37581"
"1584.50700","-4.54812","11.35523","88.56781","-0.06419","99.59926"
"1589.80700","-4.52734","11.14537","88.08526","-0.06399","97.75854"
"1595.10700","-4.43527","11.42526","87.60947","-0.06309","100.21350"
"1600.40700","-4.37600","11.23108","87.15244","-0.06250","98.51031"
"1605.70700","-4.37133","10.89396","86.50391","-0.06246","95.55334"
"1611.00700","-4.26185","11.52935","86.05943","-0.06139","101.12647"
"1616.30700","-4.14808","11.55625","85.45601","-0.06027","101.36243"
"1621.60700","-4.12196","11.37179","84.97309","-0.06001","99.74454"
"1626.90700","-3.86240","11.88268","84.56600","-0.05747","104.22564"
"1632.20700","-3.86205","11.29015","83.95772","-0.05747","99.02840"
"1637.50700","-3.85153","10.94118","83.41129","-0.05736","95.96751"
"1642.80700","-3.68098","11.42364","82.81552","-0.05569","100.19933"
"1648.10700","-3.60357","11.42506","82.24224","-0.05493","100.21177"
"1653.40700","-3.45738","11.42020","81.67878","-0.05350","100.16914"
"1658.70700","-3.32695","11.53196","81.07985","-0.05222","101.14936"
"1664.00700","-3.17510","11.47843","80.50279","-0.05073","100.67987"
"1669.30700","-3.02786","11.45590","80.02670","-0.04929","100.48231"
"1674.60700","-2.89850","11.26383","79.58139","-0.04802","98.79761"
"1679.90700","-2.73054","11.47904","79.07298","-0.04637","100.68520"
"1685.20700","-2.51630","11.37027","78.43140","-0.04427","99.73116"
"1690.50700","-2.25542","11.42014","77.86829","-0.04171","100.16862"
"1695.80700","-1.99753","11.71095","77.31865","-0.03919","102.71939"
"1701.10700","-1.82553","11.29993","76.82262","-0.03750","99.11425"
"1706.40700","-1.62590","11.39757","76.24126","-0.03554","99.97060"
"1711.70700","-1.41366","11.30369","75.79810","-0.03346","99.14720"
"1717.00700","-1.17475","11.37804","75.27001","-0.03112","99.79933"
"1722.30700","-0.95660","11.27648","74.76746","-0.02898","98.90856"
"1727.60700","-0.70375","11.42673","74.22621","-0.02650","100.22641"
"1732.90700","-0.32042","11.45443","73.71880","-0.02274","100.46937"
"1738.20700","-0.01826","11.35283","73.15703","-0.01978","99.57822"
"1743.50700","0.24482","11.18018","72.56256","-0.01720","98.06390"
"1748.80700","0.67761","11.70920","71.73085","-0.01296","102.70402"
"1754.10700","0.98112","11.63227","70.83563","-0.00998","102.02928"
"1759.40700","1.05841","11.39408","70.10412","-0.00923","99.93998"
"1764.70700","1.15392","11.40425","69.60760","-0.00829","100.02918"
"1770.00700","1.25508","11.35148","69.06750","-0.00730","99.56638"
"1775.30700","1.32506","11.47818","68.59266","-0.00661","100.67772"
"1780.60700","1.37494","11.33832","68.18316","-0.00612","99.45094"
"1785.90700","1.47730","11.54258","67.79136","-0.00512","101.24254"
"1791.20700","1.58581","11.39633","67.35605","-0.00405","99.95973"
"1796.50700","1.72081","11.13097","66.75864","-0.00273","97.63221"
"1801.80700","1.94538","11.13911","66.10219","-0.00053","97.70363"
"1807.10700","2.16109","11.58090","65.37682","0.00159","101.57868"
"1812.40700","2.23790","11.44103","64.69337","0.00234","100.35187"
"1817.70700","2.31904","11.47127","63.94949","0.00313","100.61707"
"1823.00700","2.39671","11.47329","63.35718","0.00390","100.63481"
"1828.30700","2.46244","11.10680","62.69019","0.00454","97.42024"
"1833.60700","2.58205","11.75909","61.94952","0.00571","103.14158"
"1838.90700","2.59771","11.40070","61.30711","0.00587","99.99812"
"1844.20700","2.63423","11.20058","60.81289","0.00622","98.24275"
"1849.50700","2.72746","11.60349","60.21818","0.00714","101.77679"
"1854.80700","2.74443","11.42925","59.76916","0.00730","100.24847"
"1860.10700","2.79308","11.18497","59.34081","0.00778","98.10583"
"1865.40700","2.84774","11.45528","58.81528","0.00832","100.47684"
"1870.70700","2.86315","11.40520","58.50809","0.00847","100.03756"
"1876.00700","2.86336","11.01074","58.27454","0.00847","96.57762"
"1881.30700","2.91997","11.46602","57.80931","0.00903","100.57101"
"1886.60700","2.96906","11.56871","57.40470","0.00951","101.47178"
"1891.90700","2.99524","11.41288","57.05845","0.00976","100.10491"
"1897.20700","3.02718","11.55790","56.72861","0.01008","101.37695"
"1902.50700","3.02897","11.32976","56.45438","0.01009","99.37586"
"1907.80700","3.03311","11.20152","56.15758","0.01013","98.25103"
"1913.10700","3.06200","11.36727","55.94647","0.01042","99.70489"
"1918.40700","3.08687","11.36857","55.70972","0.01066","99.71626"
"1923.70700","3.15737","11.14735","55.34185","0.01135","97.77590"
"1929.00700","3.26878","11.47512","54.49820","0.01244","100.65085"
"1934.30700","3.30197","11.02800","53.68102","0.01277","96.72903"
"1939.60700","3.39880","11.47038","52.75075","0.01372","100.60929"
"1944.90700","3.40750","11.24748","52.00531","0.01380","98.65417"
"1950.20700","3.49271","11.43069","51.36470","0.01464","100.26114"
"1955.50700","3.49365","11.29584","50.65821","0.01465","99.07832"
"1960.80700","3.57423","11.83518","49.84548","0.01544","103.80897"
"1966.10700","3.58397","11.44558","49.34470","0.01554","100.39173"
"1971.40700","3.58419","11.14076","48.72923","0.01554","97.71810"
"1976.70700","3.65103","11.47923","47.96071","0.01619","100.68689"
"1982.00700","3.69337","11.40470","47.20927","0.01661","100.03316"
"1987.30700","3.69352","11.36432","46.61562","0.01661","99.67896"
"1992.60700","3.72687","12.02670","46.12523","0.01694","105.48889"
"1997.90700","3.79305","11.98844","46.02729","0.01758","105.15328"
"2003.20700","3.79168","12.01738","45.91261","0.01757","105.40715"
"2008.50700","3.77710","12.18374","45.76212","0.01743","106.86629"
"2013.80700","3.72503","10.71743","45.85862","0.01692","94.00495"
"2019.10700","3.72518","10.73186","45.89463","0.01692","94.13157"
"2024.40700","3.72546","11.13720","45.89009","0.01692","97.68688"
"2029.70700","3.72623","11.53938","45.67517","0.01693","101.21452"
"2035.00700","3.74137","11.23992","45.63696","0.01708","98.58782"
"2040.30700","3.76118","11.37023","45.56007","0.01727","99.73080"
"2045.60700","3.77099","11.28571","45.61171","0.01737","98.98945"
"2050.90700","3.77081","11.45753","45.84631","0.01737","100.49660"
"2056.20700","3.77060","11.22310","45.94450","0.01736","98.44034"
"2061.50700","3.77022","11.42860","46.08100","0.01736","100.24278"
"2066.80700","3.76955","11.87066","46.04785","0.01735","104.12021"
"2072.10700","3.76537","11.99720","46.16211","0.01731","105.23016"
"2077.40700","3.73484","11.23621","46.31569","0.01701","98.55534"
"2082.70700","3.73410","11.04656","46.57486","0.01701","96.89186"
"2088.00700","3.73431","10.97365","46.64375","0.01701","96.25231"
"2093.30700","3.73438","11.56585","46.67616","0.01701","101.44668"
"2098.60700","3.73437","11.63356","46.92345","0.01701","102.04051"
"2103.90700","3.73442","11.29264","47.32293","0.01701","99.05029"
"2109.20700","3.73439","11.43248","47.49114","0.01701","100.27681"
"2114.50700","3.73417","12.02814","47.79104","0.01701","105.50153"
"2119.80700","3.73392","11.79619","48.05859","0.01701","103.46706"
"2125.10700","3.69704","11.05744","48.45995","0.01664","96.98730"
"2130.40700","3.67757","11.14390","48.77578","0.01645","97.74563"
"2135.70700","3.67775","11.41630","49.06190","0.01645","100.13493"
"2141.00700","3.67791","11.49829","49.44391","0.01646","100.85412"
"2146.30700","3.67803","11.26335","49.86459","0.01646","98.79337"
"2151.60700","3.67809","11.32371","50.30618","0.01646","99.32277"
"2156.90700","3.67804","11.25732","50.70360","0.01646","98.74046"
"2162.20700","3.67791","11.39791","51.05571","0.01646","99.97363"
"2167.50700","3.67759","11.82737","51.37958","0.01645","103.74050"
"2172.80700","3.67461","11.98548","51.63866","0.01642","105.12732"
"2178.10700","3.66927","11.83071","52.08195","0.01637","103.76981"
"2183.40700","3.58133","10.94201","52.54829","0.01551","95.97482"
"2188.70700","3.58138","10.84218","52.85675","0.01551","95.09920"
"2194.00700","3.58162","11.05405","53.24267","0.01551","96.95756"
"2199.30700","3.58189","11.05668","53.72088","0.01551","96.98062"
"2204.60700","3.58226","11.10965","54.11654","0.01552","97.44524"
"2209.90700","3.58267","11.22353","54.40693","0.01552","98.44409"
"2215.20700","3.58299","11.39176","54.76155","0.01553","99.91969"
"2220.50700","3.58300","11.58792","55.24038","0.01553","101.64020"
"2225.80700","3.58290","11.79991","55.71191","0.01552","103.49967"
"2231.10700","3.58262","12.10419","56.39722","0.01552","106.16856"
"2236.40700","3.58173","12.37110","57.05384","0.01551","108.50967"
"2241.70700","3.38537","10.27042","57.92316","0.01359","90.08418"
"2247.00700","3.34330","10.14181","58.87800","0.01318","88.95608"
"2252.30700","3.42994","11.66273","59.76784","0.01402","102.29645"
"2257.60700","3.45193","12.22486","60.79192","0.01424","107.22699"
"2262.90700","3.39620","11.84393","61.91425","0.01369","103.88574"
"2268.20700","3.27456","10.99668","62.86713","0.01250","96.45433"
"2273.50700","3.27347","11.41256","63.94461","0.01249","100.10213"
"2278.80700","3.27335","11.63827","64.99848","0.01249","102.08190"
"2284.10700","3.23436","11.57641","65.88410","0.01211","101.53924"
"2289.40700","3.16941","11.23127","66.82982","0.01147","98.51200"
"2294.70700","3.16920","11.51061","67.64182","0.01147","100.96210"
"2300.00700","3.14958","11.68836","68.48032","0.01128","102.52125"
"2305.30700","3.09611","11.46744","69.25972","0.01075","100.58350"
"2310.60700","3.05352","11.34250","69.95252","0.01033","99.48758"
"2315.90700","3.03304","11.55591","70.67615","0.01013","101.35948"
"2321.20700","2.99796","11.60070","71.32150","0.00979","101.75237"
"2326.50700","2.94936","11.53195","72.03745","0.00931","101.14933"
"2331.80700","2.89470","11.48732","72.69744","0.00878","100.75787"
"2337.10700","2.82912","11.32073","73.41421","0.00813","99.29668"
"2342.40700","2.67394","10.40103","74.11475","0.00661","91.22977"
"2347.70700","2.66866","10.99420","74.80116","0.00656","96.43260"
"2353.00700","2.66869","11.70271","75.55987","0.00656","102.64708"
"2358.30700","2.64726","11.97122","76.26823","0.00635","105.00227"
"2363.60700","2.46125","11.06248","77.05404","0.00453","97.03147"
"2368.90700","2.38574","11.39668","77.83748","0.00379","99.96279"
"2374.20700","2.33048","11.75069","78.55251","0.00325","103.06797"
"2379.50700","2.18034","11.43067","79.35712","0.00177","100.26099"
"2384.80700","2.08041","11.43176","80.20040","0.00079","100.27052"
"2390.10700","1.97833","11.61533","80.96175","-0.00021","101.88063"
"2395.40700","1.81671","11.30591","81.80249","-0.00179","99.16666"
"2400.70700","1.70080","11.30007","82.53333","-0.00293","99.11548"
"2406.00700","1.54137","11.47049","83.30297","-0.00449","100.61023"
"2411.30700","1.37302","11.41273","84.11619","-0.00614","100.10360"
"2416.60700","1.22390","11.54353","84.77649","-0.00760","101.25091"
"2421.90700","1.05408","11.47736","85.55271","-0.00927","100.67045"
"2427.20700","0.82001","11.35703","86.31332","-0.01156","99.61501"
"2432.50700","0.73295","11.86055","87.03536","-0.01242","104.03151"
"2437.80700","0.32086","11.06619","87.74592","-0.01646","97.06399"
"2443.10700","0.05485","11.28535","88.49547","-0.01906","98.98634"
"2448.40700","-0.18858","11.26795","89.14445","-0.02145","98.83375"
"2453.70700","-0.44106","11.33144","89.84051","-0.02393","99.39055"
"2459.00700","-0.78693","11.51018","90.61086","-0.02732","100.95837"
"2464.30700","-1.06568","11.43935","91.35681","-0.03005","100.33708"
"2469.60700","-1.39602","11.12740","92.14592","-0.03329","97.60089"
"2474.90700","-1.67955","11.17810","92.85024","-0.03607","98.04561"
"2480.20700","-1.90611","11.36673","93.52459","-0.03829","99.70015"
"2485.50700","-2.10389","11.38831","94.26475","-0.04023","99.88941"
"2490.80700","-2.31233","11.39360","94.97137","-0.04227","99.93582"
"2496.10700","-2.52606","11.33026","95.71191","-0.04437","99.38023"
"2501.40700","-2.70337","11.30133","96.45623","-0.04611","99.12651"
"2506.70700","-2.85875","11.43946","97.11295","-0.04763","100.33808"
"2512.00700","-2.98690","11.52870","97.87245","-0.04889","101.12078"
"2517.30700","-3.15167","11.31131","98.57759","-0.05050","99.21406"
"2522.60700","-3.29520","11.48960","99.34943","-0.05191","100.77785"
"2527.90700","-3.46612","11.34259","100.06010","-0.05358","99.48841"
"2533.20700","-3.59306","11.29560","100.84856","-0.05483","99.07626"
"2538.50700","-3.69288","11.41531","101.55416","-0.05581","100.12621"
"2543.80700","-3.78550","11.45026","102.24145","-0.05672","100.43280"
"2549.10700","-3.90335","11.32287","102.98947","-0.05787","99.31544"
"2554.40700","-4.01288","11.34449","103.65257","-0.05894","99.50507"
"2559.70700","-4.11682","11.31626","104.33542","-0.05996","99.25748"
"2565.00700","-4.25898","11.27640","105.08334","-0.06136","98.90779"
"2570.30700","-4.36080","11.53503","105.80705","-0.06236","101.17632"
"2575.60700","-4.49978","11.44890","106.49451","-0.06372","100.42082"
"2580.90700","-4.62275","11.37480","107.23223","-0.06492","99.77095"
"2586.20700","-4.69736","11.49430","107.90305","-0.06565","100.81905"
"2591.50700","-4.79495","11.48249","108.63486","-0.06661","100.71548"
"2596.80700","-4.88441","11.32224","109.30272","-0.06749","99.30994"
"2602.10700","-4.95871","11.59874","110.01991","-0.06822","101.73512"
"2607.40700","-5.06630","11.30483","110.84029","-0.06927","99.15718"
"2612.70700","-5.13629","11.58998","111.49345","-0.06996","101.65826"
"2618.00700","-5.22640","11.35184","112.27384","-0.07084","99.56951"
"2623.30700","-5.28518","11.37000","113.00017","-0.07142","99.72878"
"2628.60700","-5.36763","11.13529","113.64252","-0.07223","97.67011"
"2633.90700","-5.41434","11.46539","114.28262","-0.07268","100.56546"
"2639.20700","-5.47130","11.54028","114.92272","-0.07324","101.22238"
"2644.50700","-5.54429","11.45412","115.65303","-0.07396","100.46666"
"2649.80700","-5.58110","11.51464","116.34383","-0.07432","100.99747"
"2655.10700","-5.65766","11.45233","116.98327","-0.07507","100.45091"
"2660.40700","-5.71835","11.43579","117.77948","-0.07566","100.30583"
"2665.70700","-5.75345","11.42146","118.52897","-0.07601","100.18019"
"2671.00700","-5.81797","11.47849","119.30463","-0.07664","100.68043"
"2676.30700","-5.85982","11.55111","120.07890","-0.07705","101.31734"
"2681.60700","-5.90888","11.57973","120.77438","-0.07753","101.56838"
"2686.90700","-5.96497","11.40161","121.54870","-0.07808","100.00610"
"2692.20700","-6.00652","11.62684","122.34921","-0.07849","101.98161"
"2697.50700","-6.05775","11.48728","122.93328","-0.07899","100.75748"
"2702.80700","-6.10008","11.36362","123.66286","-0.07941","99.67288"
"2708.10700","-6.11578","11.54335","124.22232","-0.07956","101.24931"
"2713.40700","-6.17155","11.12176","124.81554","-0.08011","97.55141"
"2718.70700","-6.18178","11.13242","125.10110","-0.08021","97.64495"
"2724.00700","-6.18162","11.18238","125.33548","-0.08021","98.08314"
"2729.30700","-6.18150","11.21441","125.43509","-0.08021","98.36407"
"2734.60700","-6.18133","11.15167","125.46867","-0.08020","97.81382"
"2739.90700","-6.18105","11.02989","125.38921","-0.08020","96.74565"
"2745.20700","-6.18051","11.01239","125.20715","-0.08020","96.59212"
"2750.50700","-6.17926","11.02311","125.03859","-0.08018","96.68620"
"2755.80700","-6.10312","12.16555","124.87099","-0.07944","106.70674"
"2761.10700","-6.09762","12.05959","124.68279","-0.07938","105.77735"
"2766.40700","-6.09830","12.10153","124.48348","-0.07939","106.14520"
"2771.70700","-6.10029","11.92112","124.15903","-0.07941","104.56283"
"2777.00700","-6.14700","10.99009","123.83332","-0.07987","96.39650"
"2782.30700","-6.14674","10.84480","123.47969","-0.07986","95.12216"
"2787.60700","-6.14618","10.63189","122.96020","-0.07986","93.25472"
"2792.90700","-6.13435","10.46053","122.45003","-0.07974","91.75163"
"2798.20700","-6.03099","11.93979","121.79625","-0.07873","104.72659"
"2803.50700","-6.03082","11.67908","121.15069","-0.07873","102.43980"
"2808.80700","-6.03080","11.20236","120.35374","-0.07873","98.25840"
"2814.10700","-6.03057","10.92987","119.68112","-0.07873","95.86829"
"2819.40700","-5.99097","11.32344","118.90553","-0.07834","99.32047"
"2824.70700","-5.94429","11.79578","118.18423","-0.07788","103.46339"
"2830.00700","-5.94387","11.52604","117.52949","-0.07788","101.09751"
"2835.30700","-5.94383","11.39041","116.80660","-0.07788","99.90781"
"2840.60700","-5.92942","11.17772","116.10262","-0.07773","98.04228"
"2845.90700","-5.89479","11.51110","115.46043","-0.07739","100.96644"
"2851.20700","-5.89382","11.12131","114.76727","-0.07739","97.54749"
"2856.50700","-5.83733","11.79834","114.16144","-0.07683","103.48589"
"2861.80700","-5.83710","11.43827","113.54408","-0.07683","100.32762"
"2867.10700","-5.83707","11.27638","112.93568","-0.07683","98.90768"
"2872.40700","-5.82277","11.26727","112.37012","-0.07669","98.82774"
"2877.70700","-5.79929","11.29630","111.81764","-0.07646","99.08233"
"2883.00700","-5.78037","11.30093","111.33049","-0.07627","99.12302"
"2888.30700","-5.73919","11.55837","110.73195","-0.07587","101.38106"
"2893.60700","-5.73917","11.43169","110.18029","-0.07587","100.26992"
"2898.90700","-5.73911","11.27537","109.73523","-0.07587","98.89879"
"2904.20700","-5.71142","11.54013","109.19193","-0.07560","101.22102"
"2909.50700","-5.70185","11.31011","108.75537","-0.07550","99.20349"
"2914.80700","-5.65995","11.68496","108.25944","-0.07509","102.49142"
"2920.10700","-5.65147","11.58414","107.75567","-0.07501","101.60706"
"2925.40700","-5.65142","11.30744","107.32951","-0.07501","99.18005"
"2930.70700","-5.63636","11.21889","106.84423","-0.07486","98.40341"
"2936.00700","-5.60455","11.43232","106.39996","-0.07455","100.27544"
"2941.30700","-5.60441","11.17944","105.94111","-0.07455","98.05733"
"2946.60700","-5.54973","11.89992","105.49247","-0.07401","104.37682"
"2951.90700","-5.54803","11.53448","105.06480","-0.07399","101.17147"
"2957.20700","-5.54797","11.30304","104.62611","-0.07399","99.14147"
"2962.50700","-5.53689","11.12587","104.19379","-0.07389","97.58746"
"2967.80700","-5.49749","11.32739","103.77443","-0.07350","99.35510"
"2973.10700","-5.49085","11.18454","103.34390","-0.07343","98.10213"
"2978.40700","-5.45055","11.49656","102.91339","-0.07304","100.83891"
"2983.70700","-5.45011","11.22923","102.44208","-0.07303","98.49409"
"2989.00700","-5.41620","11.48014","101.99503","-0.07270","100.69485"
"2994.30700","-5.41049","11.21038","101.57533","-0.07265","98.32873"
"2999.60700","-5.35444","11.65707","101.06699","-0.07210","102.24680"
"3004.90700","-5.35396","11.27661","100.61758","-0.07209","98.90970"
"3010.20700","-5.31912","11.54985","100.13018","-0.07175","101.30629"
"3015.50700","-5.31459","11.18865","99.66757","-0.07171","98.13816"
"3020.80700","-5.25252","11.77773","99.18240","-0.07110","103.30508"
"3026.10700","-5.23060","11.62803","98.76250","-0.07088","101.99204"
"3031.40700","-5.23057","11.43669","98.26079","-0.07088","100.31377"
"3036.70700","-5.22911","11.08578","97.80527","-0.07087","97.23586"
"3042.00700","-5.18381","11.39770","97.43491","-0.07042","99.97180"
"3047.30700","-5.13500","11.61752","96.97955","-0.06995","101.89989"
"3052.60700","-5.13263","11.26667","96.67766","-0.06992","98.82246"
"3057.90700","-5.12129","11.09597","96.24654","-0.06981","97.32524"
"3063.20700","-5.06556","11.51507","95.81823","-0.06926","101.00130"
"3068.50700","-5.03292","11.69343","95.44052","-0.06894","102.56570"
"3073.80700","-5.03186","11.30765","94.98026","-0.06893","99.18192"
"3079.10700","-5.01326","11.23553","94.54289","-0.06875","98.54932"
"3084.40700","-4.93381","11.53380","94.09856","-0.06797","101.16552"
"3089.70700","-4.92924","11.29129","93.65187","-0.06793","99.03841"
"3095.00700","-4.90609","11.24823","93.27269","-0.06770","98.66076"
"3100.30700","-4.82631","11.61139","92.77472","-0.06692","101.84605"
"3105.60700","-4.81813","11.31637","92.27090","-0.06684","99.25838"
"3110.90700","-4.74749","11.58639","91.87768","-0.06615","101.62682"
"3116.20700","-4.72540","11.33113","91.39709","-0.06593","99.38789"
"3121.50700","-4.66429","11.53455","90.92242","-0.06533","101.17211"
"3126.80700","-4.63020","11.46407","90.53615","-0.06500","100.55391"
"3132.10700","-4.60538","11.32850","90.03329","-0.06475","99.36480"
"3137.40700","-4.53171","11.51123","89.62769","-0.06403","100.96756"
"3142.70700","-4.49541","11.39013","89.12851","-0.06368","99.90540"
"3148.00700","-4.42204","11.14389","88.53237","-0.06296","97.74553"
"3153.30700","-4.33196","11.55107","87.93057","-0.06207","101.31702"
"3158.60700","-4.27294","11.41364","87.31532","-0.06149","100.11159"
"3163.90700","-4.23095","11.17762","86.73684","-0.06108","98.04137"
"3169.20700","-4.10977","11.58517","86.19270","-0.05989","101.61608"
"3174.50700","-4.04717","11.57725","85.58396","-0.05928","101.54665"
"3179.80700","-4.00792","11.38904","85.06686","-0.05890","99.89581"
"3185.10700","-3.91927","11.57545","84.59941","-0.05803","101.53089"
"3190.40700","-3.85905","11.43050","84.16895","-0.05744","100.25949"
"3195.70700","-3.77223","11.32172","83.71772","-0.05658","99.30537"
"3201.00700","-3.69215","11.32528","83.13718","-0.05580","99.33660"
"3206.30700","-3.63170","11.27237","82.54947","-0.05521","98.87245"
"3211.60700","-3.54427","11.04555","82.13968","-0.05435","96.88297"
"3216.90700","-3.36284","11.35010","81.59081","-0.05257","99.55423"
"3222.20700","-3.20247","11.63682","81.13001","-0.05100","102.06916"
"3227.50700","-3.07571","11.37448","80.50680","-0.04976","99.76810"
"3232.80700","-2.99386","11.21839","79.96497","-0.04895","98.39902"
"3238.10700","-2.79218","11.36053","79.52901","-0.04698","99.64578"
"3243.40700","-2.57780","11.33690","78.97357","-0.04487","99.43848"
"3248.70700","-2.42119","11.48639","78.49459","-0.04334","100.74966"
"3254.00700","-2.26850","11.27018","78.00281","-0.04184","98.85325"
"3259.30700","-1.99819","11.33767","77.38713","-0.03919","99.44522"
"3264.60700","-1.68329","11.79418","76.78823","-0.03611","103.44940"
"3269.90700","-1.52618","11.42451","76.25839","-0.03456","100.20695"
"3275.20700","-1.38168","11.52217","75.73936","-0.03315","101.06355"
"3280.50700","-1.28196","11.27589","75.35087","-0.03217","98.90336"
"3285.80700","-1.14606","11.42100","75.01527","-0.03084","100.17616"
"3291.10700","-1.01485","11.21371","74.70210","-0.02955","98.35793"
"3296.40700","-0.89431","11.20348","74.35360","-0.02837","98.26821"
"3301.70700","-0.72527","11.41493","73.98592","-0.02671","100.12286"
"3307.00700","-0.44629","11.58225","73.53135","-0.02398","101.59048"
"3312.30700","-0.25729","11.44182","73.03106","-0.02212","100.35880"
"3317.60700","-0.09256","11.40540","72.49812","-0.02051","100.03928"
"3322.90700","0.04093","11.19266","72.13493","-0.01920","98.17333"
"3328.20700","0.21013","11.61753","71.72691","-0.01754","101.89998"
"3333.50700","0.32666","11.44975","71.47890","-0.01640","100.42830"
"3338.80700","0.41167","10.30704","71.14139","-0.01557","90.40533"
"3344.10700","0.91818","11.69681","70.43096","-0.01060","102.59535"
"3349.40700","1.43553","12.04145","69.63346","-0.00553","105.61826"
"3354.70700","1.47149","11.04370","69.08595","-0.00518","96.86679"
"3360.00700","1.62074","11.28904","68.28056","-0.00371","99.01872"
"3365.30700","1.84677","11.65018","67.29961","-0.00150","102.18637"
"3370.60700","2.02690","11.86214","66.38714","0.00027","104.04549"
"3375.90700","2.04510","11.18432","65.58067","0.00045","98.10017"
"3381.20700","2.16084","11.49161","64.81807","0.00158","100.79544"
"3386.50700","2.25226","11.60452","64.14906","0.00248","101.78582"
"3391.80700","2.32397","10.95576","63.58519","0.00318","96.09544"
"3397.10700","2.48753","11.88264","62.88721","0.00479","104.22529"
"3402.40700","2.49435","11.28039","62.35326","0.00485","98.94281"
"3407.70700","2.52734","11.37031","61.82791","0.00518","99.73155"
"3413.00700","2.58871","11.73362","61.19555","0.00578","102.91821"
"3418.30700","2.62225","11.44019","60.79845","0.00611","100.34446"
"3423.60700","2.62245","10.99963","60.39636","0.00611","96.48024"
"3428.90700","2.71046","11.56549","59.94843","0.00697","101.44345"
"3434.20700","2.76134","11.33847","59.33829","0.00747","99.45223"
"3439.50700","2.81695","11.48850","58.90462","0.00802","100.76824"
"3444.80700","2.82677","11.28733","58.46072","0.00811","99.00372"
"3450.10700","2.86336","11.02320","57.98149","0.00847","96.68693"
"3455.40700","2.92514","11.30518","57.48302","0.00908","99.16026"
"3460.70700","3.01749","11.24905","56.76642","0.00998","98.66789"
"3466.00700","3.11804","11.33779","56.04467","0.01097","99.44630"
"3471.30700","3.17741","11.52149","55.34142","0.01155","101.05758"
"3476.60700","3.21629","11.61320","54.59026","0.01193","101.86196"
"3481.90700","3.22939","11.20040","54.08516","0.01206","98.24117"
"3487.20700","3.27024","10.92397","53.40424","0.01246","95.81661"
"3492.50700","3.30886","11.49429","52.73625","0.01284","100.81896"
"3497.80700","3.35813","11.46705","52.30122","0.01332","100.58004"
"3503.10700","3.38855","11.59483","51.69202","0.01362","101.70084"
"3508.40700","3.38894","11.39114","51.57592","0.01362","99.91425"
"3513.70700","3.43832","11.45228","51.25555","0.01411","100.45050"
"3519.00700","3.48741","11.82071","50.68926","0.01459","103.68210"
"3524.30700","3.48738","11.28461","50.17631","0.01459","98.97987"
"3529.60700","3.48764","10.94297","49.51473","0.01459","95.98327"
"3534.90700","3.55644","11.59504","49.12490","0.01527","101.70265"
"3540.20700","3.58108","11.63134","48.57293","0.01551","102.02113"
"3545.50700","3.58097","12.24676","48.23976","0.01551","107.41904"
"3550.80700","3.58095","11.28967","48.37930","0.01551","99.02421"
"3556.10700","3.58092","12.06376","48.02526","0.01551","105.81396"
"3561.40700","3.58092","11.11485","48.29476","0.01551","97.49083"
"3566.70700","3.58092","11.66868","48.20465","0.01551","102.34859"
"3572.00700","3.58102","10.96848","48.29008","0.01551","96.20699"
"3577.30700","3.58105","11.15557","48.22532","0.01551","97.84798"
"3582.60700","3.60067","11.10694","47.86730","0.01570","97.42146"
"3587.90700","3.61559","11.22427","47.74249","0.01584","98.45061"
"3593.20700","3.65936","12.04223","47.63068","0.01627","105.62509"
"3598.50700","3.65921","12.07882","47.43589","0.01627","105.94608"
"3603.80700","3.65910","12.05383","47.32341","0.01627","105.72681"
"3609.10700","3.65891","12.02018","47.28773","0.01627","105.43166"
"3614.40700","3.65858","11.93449","47.40747","0.01627","104.68006"
"3619.70700","3.65777","12.01146","47.62385","0.01626","105.35519"
"3625.00700","3.60283","11.33647","47.90245","0.01572","99.43468"
"3630.30700","3.54186","10.61185","48.02812","0.01512","93.07887"
"3635.60700","3.58294","11.33752","48.13885","0.01552","99.44389"
"3640.90700","3.58621","11.13239","48.30421","0.01556","97.64471"
"3646.20700","3.64421","11.75709","48.62097","0.01613","103.12406"
"3651.50700","3.64436","11.57560","48.75230","0.01613","101.53217"
"3656.80700","3.64428","11.41470","48.85207","0.01613","100.12089"
"3662.10700","3.64411","12.01286","48.78303","0.01612","105.36745"
"3667.40700","3.64381","11.99392","48.98837","0.01612","105.20136"
"3672.70700","3.64327","11.65975","49.39795","0.01612","102.27023"
"3678.00700","3.63917","11.88394","49.59591","0.01608","104.23670"
"3683.30700","3.58059","11.55453","49.74895","0.01550","101.34740"
"3688.60700","3.53017","10.49847","50.08545","0.01501","92.08443"
"3693.90700","3.53118","10.39722","50.44869","0.01502","91.19633"
"3699.20700","3.53327","10.90407","50.79662","0.01504","95.64204"
"3704.50700","3.53374","11.24122","51.05507","0.01504","98.59924"
"3709.80700","3.55188","11.38302","51.41298","0.01522","99.84300"
"3715.10700","3.57397","11.60847","51.81282","0.01544","101.82050"
"3720.40700","3.57388","11.59957","52.17048","0.01544","101.74240"
"3725.70700","3.57366","11.68687","52.64955","0.01543","102.50815"
"3731.00700","3.57322","11.87538","53.01699","0.01543","104.16158"
"3736.30700","3.57079","12.27223","53.41719","0.01541","107.64243"
"3741.60700","3.49975","11.33376","53.74572","0.01471","99.41090"
"3746.90700","3.39135","9.79585","54.10746","0.01365","85.92161"
"3752.20700","3.47046","11.24951","54.61600","0.01442","98.67194"
"3757.50700","3.53589","12.15659","54.93579","0.01506","106.62820"
"3762.80700","3.53547","12.22787","55.40979","0.01506","107.25335"
"3768.10700","3.53254","12.34823","55.86283","0.01503","108.30912"
"3773.40700","3.34233","9.86951","56.28241","0.01317","86.56772"
"3778.70700","3.35710","10.31602","56.65031","0.01331","90.48410"
"3784.00700","3.48286","12.03667","57.01587","0.01454","105.57636"
"3789.30700","3.48420","12.10498","57.33170","0.01456","106.17551"
"3794.60700","3.43472","11.78582","57.84512","0.01407","103.37609"
"3799.90700","3.34484","10.99640","58.43318","0.01319","96.45190"
"3805.20700","3.34509","11.37418","59.14270","0.01319","99.76551"
"3810.50700","3.34497","11.67200","59.91503","0.01319","102.37775"
"3815.80700","3.31195","11.64125","60.89890","0.01287","102.10803"
"3821.10700","3.22545","11.09602","61.85413","0.01202","97.32565"
"3826.40700","3.21678","11.54811","62.86646","0.01194","101.29105"
"3831.70700","3.19685","11.66970","63.85986","0.01174","102.35755"
"3837.00700","3.15106","11.57135","64.96625","0.01129","101.49493"
"3842.30700","3.10248","11.56978","66.02642","0.01081","101.48116"
"3847.60700","3.04343","11.40435","66.91079","0.01024","100.03007"
"3852.90700","3.00760","11.49490","67.93178","0.00988","100.82431"
"3858.20700","2.98167","11.53256","68.89069","0.00963","101.15465"
"3863.50700","2.90439","11.19528","69.67884","0.00887","98.19632"
"3868.80700","2.88734","11.48656","70.55303","0.00871","100.75123"
"3873.76600","2.81434","11.14964","71.24918","0.00799","97.79600"