File: experimental/Instron/DYN1_cyclic_temperature_600MPa.is_trelax_RawData/Specimen_RawData_3.csv
Test : Start of hold value,"200.00000",MPa

Time,Extension,Load,Temperature: Chamber 3119-600 1 1,Tensile strain (Extension),Tensile stress
(s),(mm),(N),(C),(mm/mm),(MPa)
"0.00000","2.79207","0.59023","30.04600","0.00000","5.17701"
"6.90000","2.84884","0.88059","30.12883","0.00055","7.72387"
"13.80000","2.90633","1.76001","30.07318","0.00111","15.43748"
"20.70000","2.96388","2.52431","30.05709","0.00167","22.14128"
"27.60000","3.02147","2.95766","30.13519","0.00223","25.94233"
"34.50000","3.07891","3.77288","30.06411","0.00279","33.09280"
"41.40000","3.13638","4.47407","30.04151","0.00335","39.24306"
"48.30000","3.19376","4.90881","30.05632","0.00391","43.05630"
"55.20000","3.25129","5.65382","30.02032","0.00447","49.59092"
"62.10000","3.30880","6.28978","29.99926","0.00503","55.16911"
"69.00000","3.36634","6.65903","30.03568","0.00559","58.40785"
"75.90000","3.42392","7.33783","30.00469","0.00615","64.36174"
"82.80000","3.48145","8.05117","29.99292","0.00671","70.61858"
"89.70000","3.53891","8.33762","30.03562","0.00727","73.13114"
"96.60000","3.59634","9.04152","29.98442","0.00782","79.30515"
"103.50000","3.65377","9.65998","29.98437","0.00838","84.72984"
"110.40000","3.71132","9.91776","30.03516","0.00894","86.99085"
"117.30000","3.76885","10.63402","29.98167","0.00950","93.27334"
"124.20000","3.82633","11.29824","29.96517","0.01006","99.09941"
"131.10000","3.88387","11.46171","30.01242","0.01062","100.53322"
"138.00000","3.94148","12.17467","29.97460","0.01118","106.78675"
"144.90000","3.99894","12.89111","29.98112","0.01174","113.07084"
"151.80000","4.05631","13.14065","30.02323","0.01230","115.25960"
"158.70000","4.11379","13.69298","29.94305","0.01286","120.10419"
"165.60000","4.17125","14.22748","29.93679","0.01342","124.79237"
"172.50000","4.22883","14.53662","30.01328","0.01398","127.50392"
"179.40000","4.28636","15.21816","29.96390","0.01454","133.48186"
"186.30000","4.34403","15.77300","29.95886","0.01510","138.34851"
"193.20000","4.40152","16.14740","29.96884","0.01566","141.63246"
"200.10000","4.45887","16.87428","29.91538","0.01622","148.00807"
"207.00000","4.51627","17.40228","29.97178","0.01677","152.63928"
"213.90000","4.57382","17.73887","30.02718","0.01733","155.59158"
"220.80000","4.63129","18.39028","29.94133","0.01789","161.30525"
"227.70000","4.68881","18.97395","29.95795","0.01845","166.42473"
"234.60000","4.74634","19.30334","30.01192","0.01901","169.31392"
"241.50000","4.80399","19.99270","29.91639","0.01957","175.36041"
"248.40000","4.86146","20.56256","29.93171","0.02013","180.35878"
"255.30000","4.91888","20.88652","29.99022","0.02069","183.20038"
"262.20000","4.97635","21.58158","29.95858","0.02125","189.29688"
"269.10000","5.03379","22.14431","29.91863","0.02181","194.23273"
"276.00000","5.09125","22.46337","29.96251","0.02237","197.03125"
"282.72400","5.24294","24.18686","29.92869","0.02384","212.14835"
"289.62400","5.22145","23.52798","29.95269","0.02363","206.36919"
"296.52400","5.13724","22.18097","30.04568","0.02281","194.55420"
"303.42400","5.13853","22.33652","30.16351","0.02283","195.91862"
"310.32400","5.18275","23.13711","30.29914","0.02326","202.94080"
"317.22400","5.18822","23.00855","30.52426","0.02331","201.81317"
"324.12400","5.18776","23.17068","30.79776","0.02331","203.23524"
"331.02400","5.18579","23.20906","31.11646","0.02329","203.57190"
"337.92400","5.13735","22.26613","31.41022","0.02282","195.30121"
"344.82400","5.13771","22.68246","31.83103","0.02282","198.95290"
"351.72400","5.13803","22.52091","32.44319","0.02282","197.53592"
"358.62400","5.13814","22.71655","33.26226","0.02282","199.25192"
"365.52400","5.13800","23.15807","34.25191","0.02282","203.12457"
"372.42400","5.13761","23.18032","35.40051","0.02282","203.31975"
"379.32400","5.08819","22.73442","36.63623","0.02234","199.40871"
"386.22400","5.08235","22.65728","37.98672","0.02228","198.73204"
"393.12400","5.08239","22.96202","39.16563","0.02228","201.40501"
"400.02400","5.08227","22.85026","40.44156","0.02228","200.42476"
"406.92400","5.05581","22.70031","41.51037","0.02202","199.10953"
"413.82400","5.03821","22.58843","42.59839","0.02185","198.12814"
"420.72400","5.03843","22.52805","43.58131","0.02185","197.59859"
"427.62400","5.03856","22.87701","44.55017","0.02185","200.65939"
"434.52400","5.03856","22.76411","45.44572","0.02185","199.66910"
"441.42400","5.03845","23.08710","46.33209","0.02185","202.50211"
"448.32400","5.03818","22.96394","47.15021","0.02185","201.42188"
"455.22400","5.02150","23.04723","48.07607","0.02169","202.15242"
"462.12400","4.99245","22.62214","48.95336","0.02141","198.42386"
"469.02400","4.99253","22.71080","49.90312","0.02141","199.20148"
"475.92400","4.99248","22.85915","50.81658","0.02141","200.50272"
"482.82400","4.99230","22.96566","51.75181","0.02140","201.43692"
"489.72400","4.94607","22.44346","52.71179","0.02095","196.85658"
"496.62400","4.94431","22.66703","53.68198","0.02094","198.81755"
"503.52400","4.94440","22.74688","54.68188","0.02094","199.51793"
"510.42400","4.94434","22.92677","55.63309","0.02094","201.09579"
"517.32400","4.94415","23.00756","56.64654","0.02094","201.80446"
"524.22400","4.91578","22.73034","57.59298","0.02066","199.37291"
"531.12400","4.89587","22.74007","58.56953","0.02047","199.45824"
"538.02400","4.89588","22.87108","59.48927","0.02047","200.60733"
"544.92400","4.89575","22.88025","60.45499","0.02047","200.68784"
"551.82400","4.85173","22.50947","61.35732","0.02004","197.43561"
"558.72400","4.84569","22.56175","62.34116","0.01998","197.89413"
"565.62400","4.84574","22.79329","63.26616","0.01998","199.92503"
"572.52400","4.84565","22.99764","64.23682","0.01998","201.71744"
"579.42400","4.83821","23.09100","65.06978","0.01991","202.53629"
"586.32400","4.79536","22.56748","66.02278","0.01949","197.94444"
"593.22400","4.79349","22.92319","66.94124","0.01947","201.06444"
"600.12400","4.77266","22.80121","67.91851","0.01927","199.99451"
"607.02400","4.74532","22.74543","68.81097","0.01900","199.50528"
"613.92400","4.74518","23.02403","69.77293","0.01900","201.94890"
"620.82400","4.71135","22.82789","70.73484","0.01867","200.22852"
"627.72400","4.68637","22.81781","71.66660","0.01843","200.14014"
"634.62400","4.64673","22.66532","72.57596","0.01804","198.80255"
"641.52400","4.64261","23.00084","73.54527","0.01800","201.74556"
"648.42400","4.58759","22.83557","74.51885","0.01747","200.29590"
"655.32400","4.54156","22.71565","75.38396","0.01702","199.24405"
"662.22400","4.50608","22.92419","76.34163","0.01667","201.07317"
"669.12400","4.44930","22.79787","77.22424","0.01612","199.96523"
"676.02400","4.39127","22.63126","78.21768","0.01556","198.50380"
"682.92400","4.34822","22.90660","79.05939","0.01514","200.91887"
"689.82400","4.25106","22.47132","79.97256","0.01419","197.10101"
"696.72400","4.21752","22.85975","80.95508","0.01387","200.50801"
"703.62400","4.14431","22.81827","81.88987","0.01315","200.14413"
"710.52400","4.06211","22.72387","82.86691","0.01236","199.31618"
"717.42400","3.99659","22.84439","83.81249","0.01172","200.37325"
"724.32400","3.91697","22.89402","84.68692","0.01094","200.80858"
"731.22400","3.85474","23.00877","85.53028","0.01034","201.81508"
"738.12400","3.76637","22.85977","86.43774","0.00948","200.50818"
"745.02400","3.66354","22.93276","87.37157","0.00848","201.14835"
"751.92400","3.47210","21.89366","88.28979","0.00662","192.03416"
"758.82400","3.34734","22.32605","89.27635","0.00540","195.82674"
"765.72400","3.34732","23.21960","90.19327","0.00540","203.66432"
"772.62400","3.21255","22.88772","91.16589","0.00409","200.75330"
"779.52400","3.10715","23.33607","92.13872","0.00307","204.68588"
"786.42400","2.83068","21.98368","93.12038","0.00038","192.82378"
"793.32400","2.73426","22.92419","93.95271","-0.00056","201.07323"
"800.22400","2.65000","23.07061","94.89333","-0.00138","202.35748"
"807.12400","2.44325","22.76112","95.73336","-0.00339","199.64284"
"814.02400","2.28267","22.83264","96.65891","-0.00496","200.27017"
"820.92400","2.09766","22.96413","97.63031","-0.00676","201.42349"
"827.82400","1.87115","22.75714","98.40772","-0.00896","199.60797"
"834.72400","1.69340","22.84551","99.39763","-0.01069","200.38304"
"841.62400","1.41398","22.64335","100.25005","-0.01341","198.60988"
"848.52400","1.21253","22.66197","101.20646","-0.01537","198.77324"
"855.42400","0.97427","22.70515","102.09705","-0.01768","199.15196"
"862.32400","0.72868","22.76539","103.13417","-0.02007","199.68033"
"869.22400","0.55326","22.77258","104.10747","-0.02178","199.74336"
"876.12400","0.35290","22.97970","105.04560","-0.02373","201.56009"
"883.02400","0.08258","22.47874","105.98920","-0.02636","197.16603"
"889.92400","-0.07713","22.82795","106.90088","-0.02791","200.22903"
"896.82400","-0.24121","22.69342","107.73796","-0.02951","199.04909"
"903.72400","-0.34771","22.95575","108.64792","-0.03055","201.35005"
"910.62400","-0.53361","22.79355","109.52985","-0.03235","199.92737"
"917.52400","-0.69222","22.68430","110.37460","-0.03390","198.96910"
"924.42400","-0.79592","22.85579","111.28564","-0.03491","200.47327"
"931.32400","-0.89730","22.95676","112.24737","-0.03589","201.35892"
"938.22400","-1.07593","22.55635","113.14843","-0.03763","197.84683"
"945.12400","-1.19522","22.89731","114.19179","-0.03879","200.83742"
"952.02400","-1.30299","22.67937","115.13170","-0.03984","198.92583"
"958.92400","-1.39939","22.79044","116.10817","-0.04078","199.90002"
"965.82400","-1.50922","22.89154","116.91904","-0.04184","200.78680"
"972.72400","-1.61540","22.85293","117.85757","-0.04288","200.44818"
"979.62400","-1.70178","22.84556","118.76784","-0.04372","200.38351"
"986.52400","-1.78260","22.89963","119.70180","-0.04450","200.85776"
"993.42400","-1.88847","22.91270","120.68392","-0.04553","200.97244"
"1000.32400","-1.93288","23.26924","121.47791","-0.04597","204.09972"
"1007.22400","-2.04422","22.72788","122.29456","-0.04705","199.35133"
"1014.12400","-2.24814","21.90951","123.15741","-0.04903","192.17320"
"1021.02400","-2.26457","22.54711","124.04984","-0.04919","197.76578"
"1027.92400","-2.26444","22.61257","124.76055","-0.04919","198.33989"
"1034.82400","-2.26438","22.71516","125.21580","-0.04919","199.23976"
"1041.72400","-2.26442","22.84867","125.62666","-0.04919","200.41081"
"1048.62400","-2.26439","22.74229","125.73058","-0.04919","199.47774"
"1055.52400","-2.26420","22.49375","125.66280","-0.04919","197.29768"
"1062.42400","-2.26359","22.39958","125.41847","-0.04918","196.47169"
"1069.32400","-2.21442","22.88292","125.18214","-0.04871","200.71117"
"1076.22400","-2.16743","23.22632","124.86277","-0.04825","203.72327"
"1083.12400","-2.16759","22.97805","124.56638","-0.04825","201.54561"
"1090.02400","-2.16760","22.53614","124.19947","-0.04825","197.66956"
"1096.92400","-2.16731","22.15741","123.65711","-0.04825","194.34763"
"1103.82400","-2.03674","23.27635","122.94216","-0.04698","204.16203"
"1110.72400","-2.02284","22.86727","122.04183","-0.04684","200.57391"
"1117.62400","-2.01828","22.40331","121.17371","-0.04680","196.50449"
"1124.52400","-1.91954","22.81966","120.14500","-0.04584","200.15637"
"1131.42400","-1.88753","22.43607","119.10419","-0.04553","196.79179"
"1138.32400","-1.77334","23.15468","118.05359","-0.04441","203.09489"
"1145.22400","-1.69374","23.44888","117.07084","-0.04364","205.67540"
"1152.12400","-1.69388","22.90473","116.09859","-0.04364","200.90253"
"1159.02400","-1.69364","22.36340","115.20795","-0.04364","196.15434"
"1165.92400","-1.60089","22.96610","114.42806","-0.04274","201.44081"
"1172.82400","-1.56396","22.62729","113.55045","-0.04238","198.46906"
"1179.72400","-1.49281","22.94593","112.80809","-0.04169","201.26390"
"1186.62400","-1.44868","22.89466","111.99725","-0.04126","200.81416"
"1193.52400","-1.39489","22.77209","111.25095","-0.04073","199.73911"
"1200.42400","-1.34010","22.63147","110.36140","-0.04020","198.50566"
"1207.32400","-1.24899","22.89185","109.60125","-0.03931","200.78954"
"1214.22400","-1.18507","23.01052","108.72292","-0.03869","201.83043"
"1221.12400","-1.10199","22.84168","107.96001","-0.03788","200.34952"
"1228.02400","-1.06334","22.84418","107.15302","-0.03751","200.37138"
"1234.92400","-0.99369","22.99019","106.41314","-0.03683","201.65210"
"1241.82400","-0.92581","22.64435","105.65737","-0.03617","198.61862"
"1248.72400","-0.86114","22.76773","104.90682","-0.03554","199.70082"
"1255.62400","-0.79776","22.83124","104.20370","-0.03492","200.25792"
"1262.52400","-0.71186","22.85449","103.48602","-0.03409","200.46188"
"1269.42400","-0.65175","22.62146","102.86690","-0.03350","198.41788"
"1276.32400","-0.56508","22.84420","102.17071","-0.03266","200.37155"
"1283.22400","-0.51005","22.76188","101.51112","-0.03212","199.64957"
"1290.12400","-0.42663","22.71446","100.96385","-0.03131","199.23364"
"1297.02400","-0.37419","22.83586","100.31782","-0.03080","200.29840"
"1303.92400","-0.30250","22.91986","99.76981","-0.03011","201.03522"
"1310.82400","-0.21938","22.85677","99.10225","-0.02930","200.48186"
"1317.72400","-0.15154","22.80832","98.49995","-0.02864","200.05692"
"1324.62400","-0.07728","22.64938","97.95953","-0.02791","198.66281"
"1331.52400","0.02972","22.68532","97.41330","-0.02687","198.97800"
"1338.42400","0.11661","22.79300","96.76318","-0.02603","199.92245"
"1345.32400","0.22717","22.86032","96.20767","-0.02495","200.51297"
"1352.22400","0.30966","22.74044","95.60366","-0.02415","199.46150"
"1359.12400","0.40540","22.75977","95.04233","-0.02322","199.63103"
"1366.02400","0.52031","22.71236","94.38217","-0.02210","199.21523"
"1372.92400","0.65653","22.74038","93.71451","-0.02078","199.46094"
"1379.82400","0.79010","22.76579","93.02262","-0.01948","199.68379"
"1386.72400","1.03355","23.15779","92.38702","-0.01711","203.12219"
"1393.62400","1.13429","22.75372","91.64516","-0.01613","199.57796"
"1400.52400","1.24218","22.66264","90.90821","-0.01508","198.77910"
"1407.42400","1.42305","22.87584","90.20644","-0.01332","200.64914"
"1414.32400","1.57145","22.73254","89.53674","-0.01187","199.39215"
"1421.22400","1.77677","22.52749","88.70059","-0.00988","197.59363"
"1428.12400","2.04467","22.95390","87.80818","-0.00727","201.33376"
"1435.02400","2.17311","22.49983","86.94851","-0.00602","197.35104"
"1441.92400","2.39160","23.12161","86.08459","-0.00390","202.80484"
"1448.82400","2.61396","22.58824","85.07330","-0.00173","198.12651"
"1455.72400","2.95042","23.08637","83.85689","0.00154","202.49568"
"1462.62400","3.02684","22.28892","82.52187","0.00228","195.50108"
"1469.52400","3.32854","23.01575","81.24598","0.00522","201.87628"
"1476.42400","3.45358","22.88110","80.07220","0.00644","200.69525"
"1483.32400","3.51767","22.32156","78.98435","0.00706","195.78737"
"1490.22400","3.72900","23.16456","77.88697","0.00911","203.18155"
"1497.12400","3.92666","23.40842","76.74603","0.01104","205.32050"
"1504.02400","3.94918","21.74375","75.53508","0.01126","190.71928"
"1510.92400","4.24585","22.56738","74.03524","0.01414","197.94351"
"1517.82400","4.36332","22.78165","72.38345","0.01529","199.82297"
"1524.72400","4.49641","22.75590","70.65170","0.01658","199.59708"
"1531.62400","4.61399","22.46326","69.12941","0.01772","197.03030"
"1538.52400","4.74187","23.18149","67.39259","0.01897","203.33003"
"1545.42400","4.76005","21.61995","65.83739","0.01915","189.63339"
"1552.32400","5.00175","23.53204","63.67355","0.02150","206.40482"
"1559.22400","4.99990","23.31390","62.65172","0.02148","204.49141"
"1566.12400","4.96876","22.82223","61.60622","0.02118","200.17885"
"1573.02400","4.94264","22.22552","61.02473","0.02092","194.94498"
"1579.92400","4.95955","21.89357","60.12830","0.02109","192.03343"
"1586.82400","5.19440","23.34769","58.93548","0.02337","204.78784"
"1593.72400","5.22694","23.91115","57.37536","0.02369","209.73003"
"1600.62400","5.22684","22.72757","56.12043","0.02369","199.34859"
"1607.52400","5.22702","23.01743","55.06395","0.02369","201.89104"
"1614.42400","5.28326","22.69649","54.28313","0.02424","199.07594"
"1621.32400","5.33289","22.70644","53.61213","0.02472","199.16327"
"1628.22400","5.34391","22.54712","52.27865","0.02483","197.76579"
"1635.12400","5.40380","22.22371","51.43054","0.02541","194.92915"
"1642.02400","5.51820","24.14162","49.59414","0.02652","211.75154"
"1648.92400","5.51740","23.43019","48.55963","0.02651","205.51143"
"1655.82400","5.51642","23.46408","47.63287","0.02650","205.80870"
"1662.72400","5.50743","23.24152","47.05988","0.02642","203.85655"
"1669.62400","5.50010","22.85351","46.11764","0.02634","200.45325"
"1676.52400","5.52056","23.00732","45.40876","0.02654","201.80232"
"1683.42400","5.62726","23.85645","44.55734","0.02758","209.25031"
"1690.32400","5.62690","22.89705","43.48283","0.02758","200.83510"
"1697.22400","5.62560","22.68140","42.73110","0.02757","198.94363"
"1704.12400","5.62198","22.73346","42.31152","0.02753","199.40027"
"1711.02400","5.61292","22.18703","41.82575","0.02744","194.60739"
"1717.92400","5.61424","22.56455","40.91704","0.02745","197.91875"
"1724.82400","5.70429","23.03052","39.70242","0.02833","202.00581"
"1731.72400","5.72010","22.92590","39.37315","0.02848","201.08820"
"1738.62400","5.71609","23.70195","37.92374","0.02845","207.89507"
"1745.52400","5.70947","22.45898","36.99932","0.02838","196.99274"
"1752.42400","5.70948","22.33764","36.81049","0.02838","195.92844"
"1759.32400","5.71099","22.15099","35.67422","0.02840","194.29132"
"1766.22400","5.72995","22.42747","34.73831","0.02858","196.71635"
"1773.12400","5.79317","23.39145","34.06709","0.02920","205.17163"
"1780.02400","5.78944","23.25663","34.16348","0.02916","203.98911"
"1786.92400","5.73244","22.47457","33.67414","0.02860","197.12946"
"1793.82400","5.72514","22.53890","33.92196","0.02853","197.69374"
"1800.72400","5.72936","21.92609","33.44634","0.02857","192.31868"
"1807.62400","5.82532","23.17448","31.81069","0.02951","203.26859"
"1814.52400","5.82466","23.68417","30.83168","0.02950","207.73912"
"1821.42400","5.82427","23.57754","29.80022","0.02950","206.80383"
"1828.32400","5.80422","23.08727","30.19716","0.02930","202.50362"
"1835.22400","5.78954","22.67161","30.39836","0.02916","198.85774"
"1842.12400","5.78976","22.21874","30.15228","0.02916","194.88551"
"1849.02400","5.79130","22.28098","29.39719","0.02918","195.43149"
"1855.92400","5.79162","22.94487","29.59379","0.02918","201.25456"
"1862.82400","5.79159","23.10265","30.17961","0.02918","202.63849"
"1869.72400","5.79148","22.63871","30.75547","0.02918","198.56917"
"1876.62400","5.79106","23.29423","31.24497","0.02918","204.31888"
"1883.52400","5.78785","23.53381","31.91488","0.02914","206.42027"
"1890.42400","5.72586","21.99938","32.58809","0.02854","192.96150"
"1897.32400","5.72662","22.48893","33.19468","0.02855","197.25542"
"1904.22400","5.72859","22.70183","33.67099","0.02857","199.12279"
"1911.12400","5.73564","22.54824","34.35513","0.02864","197.77565"
"1918.02400","5.74310","23.32095","34.92421","0.02871","204.55327"
"1924.92400","5.74259","23.00950","35.83244","0.02870","201.82146"
"1931.82400","5.72581","23.15049","36.48246","0.02854","203.05815"
"1938.72400","5.69598","22.84799","37.16484","0.02825","200.40483"
"1945.62400","5.68684","22.98140","37.67023","0.02816","201.57500"
"1952.52400","5.68660","23.01326","38.37947","0.02816","201.85446"
"1959.42400","5.67827","22.97941","39.03746","0.02808","201.55754"
"1966.32400","5.65042","22.68903","39.92431","0.02781","199.01056"
"1973.22400","5.64533","22.55965","40.32513","0.02776","197.87573"
"1980.12400","5.64543","22.79576","41.09401","0.02776","199.94675"
"1987.02400","5.64542","22.88242","41.72924","0.02776","200.70683"
"1993.92400","5.64528","23.02490","42.33043","0.02776","201.95654"
"2000.82400","5.64300","23.14543","42.99968","0.02773","203.01373"
"2007.72400","5.60474","22.74007","43.71616","0.02736","199.45821"
"2014.62400","5.58740","22.85530","44.70407","0.02719","200.46895"
"2021.52400","5.57190","22.89508","45.74212","0.02704","200.81790"
"2028.42400","5.55818","22.93911","46.96169","0.02691","201.20403"
"2035.32400","5.51763","22.66673","48.15935","0.02652","198.81499"
"2042.22400","5.51762","22.99723","49.57355","0.02652","201.71387"
"2049.12400","5.49400","22.84997","50.90052","0.02629","200.42218"
"2056.02400","5.44909","22.55491","52.36606","0.02585","197.83420"
"2062.92400","5.44915","22.79662","53.58512","0.02585","199.95428"
"2069.82400","5.44899","23.09340","54.86829","0.02585","202.55742"
"2076.72400","5.41821","22.85640","55.88426","0.02555","200.47861"
"2083.62400","5.38337","22.58538","57.01831","0.02521","198.10146"
"2090.52400","5.38135","22.78579","57.96593","0.02519","199.85922"
"2097.42400","5.38117","23.00669","59.02755","0.02519","201.79684"
"2104.32400","5.32667","22.48109","59.93494","0.02466","197.18671"
"2111.22400","5.32615","22.79783","60.93792","0.02465","199.96486"
"2118.12400","5.32603","23.08571","61.83138","0.02465","202.48990"
"2125.02400","5.27843","22.66505","62.76712","0.02419","198.80020"
"2131.92400","5.27373","23.02475","63.74352","0.02414","201.95522"
"2138.82400","5.22819","22.72498","64.75595","0.02370","199.32584"
"2145.72400","5.22799","23.09587","65.74985","0.02370","202.57899"
"2152.62400","5.17029","22.59831","66.82137","0.02314","198.21480"
"2159.52400","5.14394","22.67593","67.76451","0.02288","198.89563"
"2166.42400","5.13887","23.09358","68.83134","0.02283","202.55898"
"2173.32400","5.07159","22.74159","69.79588","0.02218","199.47156"
"2180.22400","5.04063","22.85620","70.81911","0.02187","200.47681"
"2187.12400","4.99658","22.81240","71.79365","0.02145","200.09264"
"2194.02400","4.94187","22.80728","72.84857","0.02091","200.04776"
"2200.92400","4.90278","22.84834","73.76549","0.02053","200.40794"
"2207.82400","4.82203","22.71845","74.74806","0.01975","199.26862"
"2214.72400","4.78862","23.00827","75.67819","0.01942","201.81065"
"2221.62400","4.70818","22.76904","76.66190","0.01864","199.71230"
"2228.52400","4.63968","22.71506","77.59760","0.01797","199.23889"
"2235.42400","4.55131","22.72835","78.61720","0.01711","199.35544"
"2242.32400","4.50381","22.84923","79.56374","0.01665","200.41571"
"2249.22400","4.41649","22.76009","80.46341","0.01580","199.63385"
"2256.12400","4.35328","22.80121","81.40553","0.01519","199.99451"
"2263.02400","4.25874","22.79285","82.34892","0.01427","199.92119"
"2269.92400","4.16041","22.63493","83.34018","0.01331","198.53604"
"2276.82400","4.08787","22.87193","84.27470","0.01261","200.61481"
"2283.72400","3.98025","22.63580","85.20466","0.01156","198.54366"
"2290.62400","3.90521","22.97953","86.19191","0.01083","201.55862"
"2297.52400","3.80949","22.84480","87.13488","0.00990","200.37688"
"2304.42400","3.68139","22.86844","87.99740","0.00865","200.58417"
"2311.32400","3.56276","22.77718","88.92541","0.00750","199.78371"
"2318.22400","3.44133","22.89505","89.86230","0.00632","200.81763"
"2325.12400","3.27840","22.69924","90.89709","0.00473","199.10013"
"2332.02400","3.16796","22.94937","91.80656","0.00366","201.29408"
"2338.92400","3.01697","22.83043","92.81175","0.00219","200.25076"
"2345.82400","2.82229","22.75206","93.72581","0.00029","199.56337"
"2352.72400","2.68818","22.80879","94.69805","-0.00101","200.06097"
"2359.62400","2.51796","22.72028","95.60614","-0.00267","199.28468"
"2366.52400","2.34392","22.96055","96.49413","-0.00436","201.39209"
"2373.42400","2.12060","22.78969","97.44616","-0.00653","199.89345"
"2380.32400","1.86978","22.57380","98.37898","-0.00897","197.99982"
"2387.22400","1.70850","22.94144","99.30259","-0.01054","201.22450"
"2394.12400","1.43775","22.53946","100.25300","-0.01318","197.69864"
"2401.02400","1.23418","22.72944","101.16918","-0.01516","199.36504"
"2407.92400","1.02398","22.75543","102.02010","-0.01720","199.59299"
"2414.82400","0.76457","22.81463","102.93194","-0.01972","200.11223"
"2421.72400","0.59373","22.80676","103.81918","-0.02139","200.04323"
"2428.62400","0.41286","22.94208","104.82255","-0.02315","201.23015"
"2435.52400","0.18481","22.77495","105.77355","-0.02536","199.76419"
"2442.42400","-0.04253","22.69587","106.69193","-0.02758","199.07056"
"2449.32400","-0.21888","22.68959","107.54089","-0.02929","199.01550"
"2456.22400","-0.35829","23.01954","108.50179","-0.03065","201.90950"
"2463.12400","-0.53598","22.74889","109.36635","-0.03238","199.53558"
"2470.02400","-0.68856","22.69028","110.24964","-0.03386","199.02151"
"2476.92400","-0.82130","22.82189","111.23692","-0.03515","200.17589"
"2483.82400","-0.93914","23.05370","112.13309","-0.03630","202.20914"
"2490.72400","-1.11557","22.79984","113.10556","-0.03802","199.98253"
"2497.62400","-1.17199","23.11829","114.04134","-0.03856","202.77571"
"2504.52400","-1.35962","22.68863","114.93469","-0.04039","199.00702"
"2511.42400","-1.46843","22.76357","115.94624","-0.04145","199.66437"
"2518.32400","-1.56763","22.79706","116.92704","-0.04241","199.95811"
"2525.22400","-1.64844","22.80253","117.81343","-0.04320","200.00612"
"2532.12400","-1.74433","22.76914","118.79346","-0.04413","199.71323"
"2539.02400","-1.83945","22.62548","119.62376","-0.04506","198.45311"
"2545.92400","-1.91491","22.78222","120.52297","-0.04579","199.82790"
"2552.82400","-1.98091","22.91997","121.49725","-0.04643","201.03619"
"2559.72400","-2.08605","22.70241","122.38731","-0.04746","199.12788"
"2566.62400","-2.13577","22.86403","123.34745","-0.04794","200.54555"
"2573.52400","-2.18719","22.69518","124.06434","-0.04844","199.06447"
"2580.42400","-2.22841","22.60352","124.68754","-0.04884","198.26056"
"2587.32400","-2.22839","22.88070","125.15871","-0.04884","200.69177"
"2594.22400","-2.22840","22.91794","125.46554","-0.04884","201.01839"
"2601.12400","-2.22832","22.73370","125.57205","-0.04884","199.40239"
"2608.02400","-2.22819","22.50448","125.47820","-0.04884","197.39183"
"2614.92400","-2.22778","22.26248","125.33195","-0.04884","195.26923"
"2621.82400","-2.22544","22.27722","125.08567","-0.04881","195.39850"
"2628.72400","-2.11985","23.31168","124.75954","-0.04779","204.47195"
"2635.62400","-2.11949","23.04994","124.46166","-0.04778","202.17615"
"2642.52400","-2.11968","22.79184","124.10876","-0.04778","199.91234"
"2649.42400","-2.11954","22.40352","123.53267","-0.04778","196.50629"
"2656.32400","-2.10107","22.09110","122.83303","-0.04760","193.76595"
"2663.22400","-1.92749","23.54935","121.88834","-0.04591","206.55664"
"2670.12400","-1.92793","22.77771","120.96095","-0.04592","199.78838"
"2677.02400","-1.92773","22.38891","119.95310","-0.04592","196.37817"
"2683.92400","-1.86385","22.54329","118.96170","-0.04529","197.73227"
"2690.82400","-1.74068","23.16777","117.98560","-0.04410","203.20972"
"2697.72400","-1.74069","22.54316","116.94527","-0.04410","197.73112"
"2704.62400","-1.70230","22.57530","115.93571","-0.04372","198.01300"
"2711.52400","-1.62869","22.68058","115.03448","-0.04301","198.93643"
"2718.42400","-1.54526","23.06790","114.16110","-0.04220","202.33372"
"2725.32400","-1.54052","22.48857","113.39706","-0.04215","197.25232"
"2732.22400","-1.46350","22.96296","112.55859","-0.04140","201.41324"
"2739.12400","-1.44305","22.58811","111.90576","-0.04120","198.12534"
"2746.02400","-1.36604","22.92244","111.11859","-0.04045","201.05782"
"2752.92400","-1.34140","22.61989","110.32555","-0.04021","198.40411"
"2759.82400","-1.25045","22.89001","109.63264","-0.03933","200.77341"
"2766.72400","-1.23580","22.71015","108.84772","-0.03918","199.19579"
"2773.62400","-1.14400","22.84376","108.24966","-0.03829","200.36775"
"2780.52400","-1.09655","23.07284","107.50753","-0.03783","202.37708"
"2787.42400","-1.06247","22.65174","106.90103","-0.03750","198.68350"
"2794.32400","-1.02181","22.77011","106.27275","-0.03710","199.72169"
"2801.22400","-0.94638","22.88984","105.66414","-0.03637","200.77190"
"2808.12400","-0.90156","22.76130","105.06945","-0.03593","199.64444"
"2815.02400","-0.83982","22.84296","104.44868","-0.03533","200.36070"
"2821.92400","-0.76996","22.88774","103.87629","-0.03465","200.75346"
"2828.82400","-0.70899","22.86516","103.33482","-0.03406","200.55545"
"2835.72400","-0.66239","22.80120","102.74440","-0.03361","199.99440"
"2842.62400","-0.58228","22.90656","102.17799","-0.03283","200.91853"
"2849.52400","-0.52146","22.89610","101.57169","-0.03224","200.82680"
"2856.42400","-0.47099","22.81605","101.00970","-0.03174","200.12465"
"2863.32400","-0.41377","22.76363","100.42400","-0.03119","199.66487"
"2870.22400","-0.30599","22.68115","99.88946","-0.03014","198.94147"
"2877.12400","-0.21617","22.82923","99.26514","-0.02927","200.24030"
"2884.02400","-0.14295","22.92066","98.61653","-0.02855","201.04225"
"2890.92400","-0.06668","22.50392","97.99100","-0.02781","197.38695"
"2897.82400","0.05506","22.73818","97.32751","-0.02663","199.44168"
"2904.72400","0.19161","22.86588","96.64453","-0.02530","200.56175"
"2911.62400","0.32139","22.95253","95.99911","-0.02404","201.32179"
"2918.52400","0.40315","22.72523","95.30274","-0.02324","199.32808"
"2925.42400","0.52396","22.74213","94.71777","-0.02207","199.47635"
"2932.32400","0.70846","22.89527","93.94377","-0.02027","200.81956"
"2939.22400","0.86751","22.91800","93.25058","-0.01872","201.01886"
"2946.12400","1.04359","22.69516","92.35000","-0.01701","199.06436"
"2953.02400","1.28535","22.80085","91.44902","-0.01466","199.99136"
"2959.92400","1.47731","22.94171","90.61045","-0.01279","201.22685"
"2966.82400","1.67508","22.45716","89.77640","-0.01087","196.97679"
"2973.72400","1.98342","22.89424","88.60209","-0.00787","200.81047"
"2980.62400","2.36205","23.19483","87.43076","-0.00418","203.44701"
"2987.52400","2.52252","22.86258","86.17654","-0.00262","200.53278"
"2994.42400","2.68365","22.48969","85.12826","-0.00105","197.26205"
"3001.32400","2.88158","22.92709","84.00488","0.00087","201.09860"
"3008.22400","2.98108","22.36377","83.00620","0.00184","196.15762"
"3015.12400","3.12843","22.35315","81.86939","0.00327","196.06448"
"3022.02400","3.47318","23.23227","80.71240","0.00663","203.77547"
"3028.92400","3.79237","22.88076","79.09875","0.00973","200.69228"
"3035.82400","3.87116","22.92875","77.63131","0.01050","201.11319"
"3042.72400","4.12494","23.11465","76.23961","0.01297","202.74373"
"3049.62400","4.18284","22.34846","74.34600","0.01353","196.02330"
"3056.52400","4.36372","23.18122","72.74298","0.01529","203.32762"
"3063.42400","4.40679","22.43740","71.17386","0.01571","196.80345"
"3070.32400","4.51084","23.45790","69.94125","0.01672","205.75447"
"3077.22400","4.51060","23.15596","69.47095","0.01672","203.10614"
"3084.12400","4.51021","22.81503","69.16184","0.01671","200.11572"
"3091.02400","4.51074","21.81009","68.35253","0.01672","191.30116"
"3097.92400","4.78836","23.47919","66.91028","0.01942","205.94121"
"3104.82400","4.82739","22.71725","65.39526","0.01980","199.25810"
"3111.72400","4.92280","23.13269","64.33199","0.02073","202.90198"
"3118.62400","4.95414","22.76874","63.05031","0.02103","199.70972"
"3125.52400","4.97837","23.11457","62.55482","0.02127","202.74303"
"3132.42400","4.98819","22.69064","61.58744","0.02136","199.02467"
"3139.32400","5.03518","22.93634","60.98905","0.02182","201.17975"
"3146.22400","5.03510","23.01642","60.80051","0.02182","201.88214"
"3153.12400","5.03508","22.78478","60.58249","0.02182","199.85042"
"3160.02400","5.05028","22.22922","59.83872","0.02197","194.97742"
"3166.92400","5.25408","23.13158","58.46923","0.02395","202.89227"
"3173.82400","5.33247","22.59985","56.21457","0.02471","198.22833"
"3180.72400","5.43040","22.77896","54.05902","0.02567","199.79939"
"3187.62400","5.48130","22.70517","51.78048","0.02616","199.15211"
"3194.52400","5.52705","23.27422","50.34187","0.02661","204.14336"
"3201.42400","5.52711","22.74391","48.76711","0.02661","199.49196"
"3208.32400","5.52747","21.66093","47.75607","0.02661","189.99289"
"3215.22400","5.60565","23.38524","46.63370","0.02737","205.11720"
"3222.12400","5.59613","23.01181","46.40459","0.02728","201.84175"
"3229.02400","5.58739","22.80631","45.22830","0.02719","200.03926"
"3235.92400","5.58974","21.90251","44.29173","0.02722","192.11185"
"3242.82400","5.61539","22.11416","43.65048","0.02747","193.96822"
"3249.72400","5.69396","23.18352","43.04455","0.02823","203.34782"
"3256.62400","5.69342","23.74719","41.86964","0.02823","208.29193"
"3263.52400","5.69354","22.37941","40.67498","0.02823","196.29477"
"3270.42400","5.69363","22.26187","40.20623","0.02823","195.26387"
"3277.32400","5.69419","22.26718","39.79162","0.02823","195.31038"
"3284.22400","5.77695","23.40264","38.34536","0.02904","205.26978"
"3291.12400","5.77659","22.41194","37.37636","0.02903","196.58012"
"3298.02400","5.77647","22.62554","36.43022","0.02903","198.45370"
"3304.92400","5.77642","22.83389","35.86021","0.02903","200.28116"
"3311.82400","5.77670","22.91934","34.78197","0.02904","201.03064"
"3318.72400","5.80876","22.54036","34.03687","0.02935","197.70653"
"3325.62400","5.84918","22.87411","33.41031","0.02974","200.63390"
"3332.52400","5.84906","23.74422","31.63160","0.02974","208.26590"
"3339.42400","5.84891","22.81861","31.08939","0.02974","200.14716"
"3346.32400","5.84849","23.22129","30.81529","0.02973","203.67917"
"3353.22400","5.83995","23.44484","30.95896","0.02965","205.63994"
"3360.12400","5.80978","22.96783","30.90113","0.02936","201.45595"
"3367.02400","5.81066","22.64036","30.59132","0.02937","198.58369"
"3373.92400","5.81812","22.55523","30.52597","0.02944","197.83694"
"3380.82400","5.83376","22.53510","30.51806","0.02959","197.66035"
"3387.72400","5.84113","22.54379","30.45177","0.02966","197.73657"
"3394.62400","5.84099","23.30045","30.08757","0.02966","204.37343"
"3401.52400","5.84103","22.91911","29.87927","0.02966","201.02859"
"3408.42400","5.84081","23.45150","30.27259","0.02966","205.69835"
"3415.32400","5.84019","22.83358","30.90472","0.02965","200.27841"
"3422.22400","5.80959","23.04062","31.36628","0.02936","202.09442"
"3429.12400","5.79035","22.80712","32.28063","0.02917","200.04633"
"3436.02400","5.78994","22.46990","33.00351","0.02916","197.08855"
"3442.92400","5.78986","22.90887","33.53800","0.02916","200.93886"
"3449.82400","5.78979","23.12889","33.99352","0.02916","202.86864"
"3456.72400","5.75818","22.19611","34.51876","0.02886","194.68706"
"3463.62400","5.75567","22.91728","35.04963","0.02883","201.01256"
"3470.52400","5.75564","22.89229","35.89124","0.02883","200.79340"
"3477.42400","5.75285","22.56172","36.62469","0.02880","197.89386"
"3484.32400","5.72442","22.73265","37.06133","0.02853","199.39314"
"3491.22400","5.71965","22.53109","37.74997","0.02848","197.62520"
"3498.12400","5.71975","22.64756","38.55387","0.02848","198.64682"
"3505.02400","5.71966","23.06378","39.11080","0.02848","202.29755"
"3511.92400","5.71933","23.21195","39.83743","0.02848","203.59724"
"3518.82400","5.68345","22.90447","40.52824","0.02813","200.90025"
"3525.72400","5.67872","22.76336","41.08794","0.02808","199.66252"
"3532.62400","5.67862","22.72318","42.02814","0.02808","199.31004"
"3539.52400","5.67855","22.96443","42.45541","0.02808","201.42615"
"3546.42400","5.62840","22.34273","43.23053","0.02759","195.97310"
"3553.32400","5.62336","22.48433","43.81375","0.02754","197.21504"
"3560.22400","5.62417","22.55080","44.44255","0.02755","197.79811"
"3567.12400","5.62462","22.79518","45.07373","0.02756","199.94157"
"3574.02400","5.62459","22.95256","45.91808","0.02756","201.32205"
"3580.92400","5.62429","23.27011","46.74622","0.02755","204.10736"
"3587.82400","5.61668","23.34792","47.83899","0.02748","204.78983"
"3594.72400","5.52366","22.40339","48.97361","0.02657","196.50510"
"3601.62400","5.52383","22.71086","50.34182","0.02658","199.20201"
"3608.52400","5.52378","22.96352","51.58925","0.02657","201.41818"
"3615.42400","5.50896","23.09541","53.03358","0.02643","202.57503"
"3622.32400","5.43717","22.34156","54.37104","0.02573","195.96280"
"3629.22400","5.43738","22.67980","55.57177","0.02573","198.92961"
"3636.12400","5.43739","22.90261","56.65416","0.02573","200.88387"
"3643.02400","5.43704","23.23313","57.87966","0.02573","203.78294"
"3649.92400","5.37666","22.60966","58.99497","0.02514","198.31439"
"3656.82400","5.37134","22.81359","59.96456","0.02509","200.10313"
"3663.72400","5.37124","23.04997","60.96359","0.02509","202.17647"
"3670.62400","5.32209","22.50561","61.83620","0.02461","197.40173"
"3677.52400","5.32206","22.93388","62.80387","0.02461","201.15822"
"3684.42400","5.29766","22.79142","63.65773","0.02438","199.90866"
"3691.32400","5.27424","22.93048","64.58585","0.02415","201.12836"
"3698.22400","5.22725","22.57595","65.59953","0.02369","198.01874"
"3705.12400","5.22685","22.97399","66.54033","0.02369","201.50998"
"3712.02400","5.16827","22.61688","67.61217","0.02312","198.37769"
"3718.92400","5.13843","22.78872","68.56737","0.02283","199.88496"
"3725.82400","5.13289","23.13652","69.61875","0.02277","202.93558"
"3732.72400","5.04703","22.54040","70.69167","0.02194","197.70686"
"3739.62400","5.03159","23.08324","71.66200","0.02179","202.46829"
"3746.52400","4.95785","22.74827","72.75089","0.02107","199.53018"
"3753.42400","4.92336","23.00261","73.67966","0.02073","201.76102"
"3760.32400","4.83548","22.62052","74.71940","0.01988","198.40962"
"3767.22400","4.79590","22.87482","75.62813","0.01949","200.64020"
"3774.12400","4.72801","22.73200","76.60830","0.01883","199.38750"
"3781.02400","4.65647","22.85358","77.54249","0.01814","200.45384"
"3787.92400","4.59411","22.95848","78.50101","0.01753","201.37395"
"3794.82400","4.51551","22.73784","79.39912","0.01677","199.43872"
"3801.72400","4.43865","22.86732","80.37025","0.01602","200.57436"
"3808.62400","4.35366","22.65215","81.28329","0.01519","198.68706"
"3815.52400","4.27808","22.79095","82.24838","0.01446","199.90456"
"3822.42400","4.18302","22.76784","83.17599","0.01353","199.70183"
"3829.32400","4.10304","22.94408","84.23374","0.01275","201.24762"
"3836.22400","3.99266","22.76059","85.14500","0.01168","199.63826"
"3843.12400","3.90315","22.95238","86.14384","0.01081","201.32048"
"3850.02400","3.79052","22.70506","87.14302","0.00971","199.15114"
"3856.92400","3.67679","22.65022","88.06694","0.00861","198.67012"
"3863.82400","3.58009","22.85917","88.95786","0.00767","200.50288"
"3870.72400","3.43249","22.70513","89.83447","0.00623","199.15178"
"3877.62400","3.31365","22.68599","90.80120","0.00507","198.98389"
"3884.52400","3.19858","22.82254","91.68691","0.00395","200.18161"
"3891.42400","3.05290","22.95904","92.66082","0.00254","201.37891"
"3898.32400","2.90969","22.69709","93.54349","0.00114","199.08122"
"3905.22400","2.59440","22.26707","94.48159","-0.00192","195.30943"
"3912.12400","2.54948","23.04631","95.35809","-0.00236","202.14435"
"3919.02400","2.36975","22.93140","96.36362","-0.00411","201.13640"
"3925.92400","2.15679","22.88193","97.23960","-0.00618","200.70255"
"3932.82400","1.97418","23.02699","98.14475","-0.00796","201.97490"
"3939.72400","1.64297","22.61152","99.07814","-0.01118","198.33067"
"3946.62400","1.46574","22.97643","100.01243","-0.01290","201.53136"
"3953.52400","1.23149","22.85001","101.00913","-0.01518","200.42258"
"3960.42400","1.01397","22.69620","101.97245","-0.01730","199.07347"
"3967.32400","0.74643","22.62494","102.96371","-0.01990","198.44836"
"3974.22400","0.58818","22.91134","103.86773","-0.02144","200.96051"
"3981.12400","0.36905","22.73436","104.73925","-0.02357","199.40816"
"3988.02400","0.18913","22.83678","105.68497","-0.02532","200.30652"
"3994.92400","-0.04689","22.72332","106.63610","-0.02762","199.31131"
"4001.82400","-0.22685","22.68608","107.58627","-0.02937","198.98471"
"4008.72400","-0.36667","22.78308","108.49007","-0.03073","199.83548"
"4015.62400","-0.54052","22.77514","109.38943","-0.03242","199.76582"
"4022.52400","-0.67868","22.77386","110.24300","-0.03376","199.75462"
"4029.42400","-0.79762","23.01247","111.14379","-0.03492","201.84753"
"4036.32400","-0.92718","22.90720","112.10287","-0.03618","200.92416"
"4043.22400","-1.08262","22.81621","112.96749","-0.03769","200.12610"
"4050.12400","-1.19326","22.85882","113.98366","-0.03877","200.49980"
"4057.02400","-1.32698","22.76692","114.89597","-0.04007","199.69379"
"4063.92400","-1.44975","22.69308","115.83762","-0.04127","199.04608"
"4070.82400","-1.52256","22.94629","116.74800","-0.04197","201.26704"
"4077.72400","-1.65593","22.77446","117.76445","-0.04327","199.75984"
"4084.62400","-1.72775","22.81927","118.58002","-0.04397","200.15297"
"4091.52400","-1.83431","22.80256","119.59236","-0.04501","200.00630"
"4098.42400","-1.88989","23.04247","120.44465","-0.04555","202.11061"
"4105.32400","-1.99587","22.60123","121.46880","-0.04658","198.24043"
"4112.22400","-2.03831","22.92561","122.35132","-0.04699","201.08563"
"4119.12400","-2.14437","22.51236","123.25108","-0.04802","197.46092"
"4126.02400","-2.17085","22.91997","124.13595","-0.04828","201.03618"
"4132.92400","-2.21999","22.73137","124.72437","-0.04876","199.38197"
"4139.82400","-2.22955","22.78217","125.30926","-0.04885","199.82747"
"4146.72400","-2.22945","22.52583","125.58238","-0.04885","197.57912"
"4153.62400","-2.22919","22.49765","125.56407","-0.04885","197.33191"
"4160.52400","-2.22812","22.24115","125.49450","-0.04884","195.08206"
"4167.42400","-2.14146","23.37394","125.26099","-0.04800","205.01807"
"4174.32400","-2.12693","23.22284","125.04368","-0.04785","203.69273"
"4181.22400","-2.12733","23.10119","124.68933","-0.04786","202.62567"
"4188.12400","-2.12756","22.78442","124.36048","-0.04786","199.84727"
"4195.02400","-2.12747","22.47390","123.94341","-0.04786","197.12363"
"4201.92400","-2.12685","22.19687","123.41675","-0.04785","194.69371"
"4208.82400","-1.97336","23.49100","122.73829","-0.04636","206.04485"
"4215.72400","-1.96905","22.93572","122.01459","-0.04632","201.17430"
"4222.62400","-1.96888","22.40981","121.05161","-0.04632","196.56148"
"4229.52400","-1.86179","22.96801","120.13708","-0.04527","201.45755"
"4236.42400","-1.83320","22.73117","119.12296","-0.04500","199.38017"
"4243.32400","-1.76700","22.90428","118.16911","-0.04435","200.89853"
"4250.22400","-1.72572","22.74876","117.10145","-0.04395","199.53448"
"4257.12400","-1.68487","22.85804","116.26762","-0.04355","200.49298"
"4264.02400","-1.63530","22.83611","115.30318","-0.04307","200.30067"
"4270.92400","-1.56399","23.04599","114.45654","-0.04238","202.14151"
"4277.82400","-1.54114","22.59537","113.65211","-0.04216","198.18907"
"4284.72400","-1.47097","22.84198","112.85960","-0.04147","200.35214"
"4291.62400","-1.43468","22.67396","112.08810","-0.04112","198.87839"
"4298.52400","-1.35961","22.99995","111.26331","-0.04039","201.73769"
"4305.42400","-1.35372","22.75871","110.56113","-0.04033","199.62178"
"4312.32400","-1.27883","22.87542","109.85609","-0.03960","200.64543"
"4319.22400","-1.24848","22.61402","109.18597","-0.03931","198.35265"
"4326.12400","-1.15043","23.03733","108.48666","-0.03835","202.06557"
"4333.02400","-1.14230","22.77574","107.87122","-0.03828","199.77109"
"4339.92400","-1.06410","23.08257","107.24953","-0.03751","202.46239"
"4346.82400","-1.04286","22.67399","106.62711","-0.03731","198.87863"
"4353.72400","-0.96451","22.90172","106.00060","-0.03655","200.87608"
"4360.62400","-0.94044","22.69951","105.36850","-0.03631","199.10246"
"4367.52400","-0.86890","22.73556","104.81485","-0.03562","199.41864"
"4374.42400","-0.78599","22.96983","104.19690","-0.03481","201.47354"
"4381.32400","-0.75443","22.75908","103.61839","-0.03450","199.62502"
"4388.22400","-0.69436","22.85082","103.09573","-0.03392","200.42966"
"4395.12400","-0.62038","22.92360","102.54761","-0.03320","201.06801"
"4402.02400","-0.56242","22.71093","101.91512","-0.03263","199.20268"
"4408.92400","-0.48377","22.78181","101.36591","-0.03187","199.82436"
"4415.82400","-0.44095","22.78997","100.78301","-0.03145","199.89597"
"4422.72400","-0.33437","22.90497","100.18810","-0.03042","200.90462"
"4429.62400","-0.27222","22.72475","99.59372","-0.02981","199.32388"
"4436.52400","-0.17218","22.79095","98.99375","-0.02884","199.90448"
"4443.42400","-0.08207","22.59218","98.37923","-0.02796","198.16109"
"4450.32400","0.04126","22.75234","97.61720","-0.02676","199.56583"
"4457.22400","0.14345","22.68332","96.95752","-0.02577","198.96043"
"4464.12400","0.30031","23.07475","96.20247","-0.02424","202.39378"
"4471.02400","0.37600","22.73019","95.61367","-0.02350","199.37157"
"4477.92400","0.50722","22.63092","94.83403","-0.02223","198.50084"
"4484.82400","0.73114","22.82086","94.10930","-0.02005","200.16682"
"4491.72400","0.97057","23.05254","93.16058","-0.01772","202.19896"
"4498.62400","1.12084","22.68913","92.15429","-0.01626","199.01140"
"4505.52400","1.27927","22.64452","91.37715","-0.01472","198.62013"
"4512.42400","1.52839","22.79551","90.43080","-0.01229","199.94452"
"4519.32400","1.76258","22.75706","89.48278","-0.01002","199.60728"
"4526.22400","2.03900","22.85482","88.47775","-0.00733","200.46477"
"4533.12400","2.22325","22.86847","87.32931","-0.00553","200.58444"
"4540.02400","2.29111","22.56281","86.64898","-0.00487","197.90341"
"4546.92400","2.53033","23.00885","85.68359","-0.00255","201.81578"
"4553.82400","2.67540","22.74967","84.78393","-0.00114","199.54247"
"4560.72400","2.80910","22.92411","83.86975","0.00017","201.07248"
"4567.62400","2.87126","22.40843","83.17636","0.00077","196.54933"
"4574.52400","3.05880","22.84768","82.24722","0.00259","200.40215"
"4581.42400","3.31072","22.55889","81.30753","0.00505","197.86905"
"4588.32400","3.53883","22.78639","80.05778","0.00726","199.86456"
"4595.22400","3.89058","23.88573","78.59414","0.01069","209.50705"
"4602.12400","3.89119","22.62812","77.30417","0.01069","198.47630"
"4609.02400","4.05070","22.99946","75.96124","0.01224","201.73341"
"4615.92400","4.12345","23.35300","74.77030","0.01295","204.83443"
"4622.82400","4.12313","23.03702","74.07379","0.01295","202.06287"
"4629.72400","4.12324","22.56362","73.32943","0.01295","197.91052"
"4636.62400","4.12378","22.11752","72.89411","0.01296","193.99770"
"4643.52400","4.25174","23.02303","72.32868","0.01420","201.94012"
"4650.42400","4.28949","22.63664","71.76533","0.01457","198.55103"
"4657.32400","4.36856","22.99938","70.94050","0.01534","201.73268"
"4664.22400","4.74439","23.48415","69.54336","0.01899","205.98470"
"4671.12400","4.84199","23.22996","67.39109","0.01994","203.75519"
"4678.02400","4.84220","22.04360","65.41039","0.01994","193.34935"
"4684.92400","5.00765","22.92556","63.66225","0.02155","201.08525"
"4691.82400","5.10718","23.07378","61.82819","0.02252","202.38530"
"4698.72400","5.10734","22.58359","60.16524","0.02252","198.08569"
"4705.62400","5.19131","22.96751","58.75239","0.02334","201.45314"
"4712.52400","5.22798","22.86479","57.62613","0.02370","200.55222"
"4719.42400","5.22814","22.60346","56.35502","0.02370","198.25996"
"4726.32400","5.32178","22.91818","55.17879","0.02461","201.02045"
"4733.22400","5.33325","23.17005","54.14615","0.02472","203.22972"
"4740.12400","5.33332","22.44773","53.54047","0.02472","196.89409"
"4747.02400","5.44545","22.88806","52.14146","0.02581","200.75627"
"4753.92400","5.51740","22.89396","50.49467","0.02651","200.80806"
"4760.82400","5.51763","22.46505","48.75420","0.02652","197.04596"
"4767.72400","5.52760","22.54001","48.38086","0.02661","197.70346"
"4774.62400","5.53147","22.29185","47.31174","0.02665","195.52681"
"4781.52400","5.63757","23.25227","45.82386","0.02768","203.95087"
"4788.42400","5.63741","22.72759","44.67168","0.02768","199.34880"
"4795.32400","5.63714","22.92505","44.12944","0.02768","201.08076"
"4802.22400","5.63732","22.31213","43.25675","0.02768","195.70470"
"4809.12400","5.69759","22.80986","41.96920","0.02827","200.07040"
"4816.02400","5.71793","23.14770","41.84607","0.02846","203.03362"
"4822.92400","5.71707","22.69643","40.83045","0.02846","199.07542"
"4829.82400","5.71755","22.58468","39.49262","0.02846","198.09528"
"4836.72400","5.71977","22.22311","38.47689","0.02848","194.92387"
"4843.62400","5.76456","22.93535","38.07907","0.02892","201.17105"
"4850.52400","5.79209","22.89167","36.94555","0.02919","200.78796"
"4857.42400","5.79219","22.83307","35.71732","0.02919","200.27400"
"4864.32400","5.79217","22.64419","35.38639","0.02919","198.61723"
"4871.22400","5.79242","22.60213","34.49619","0.02919","198.24832"
"4878.12400","5.84891","22.83221","33.16545","0.02974","200.26642"
"4885.02400","5.87333","23.13939","31.81332","0.02998","202.96075"
"4891.92400","5.87248","22.93482","31.56947","0.02997","201.16640"
"4898.82400","5.85213","23.34079","30.89046","0.02977","204.72725"
"4905.72400","5.82279","22.52827","30.20503","0.02948","197.60048"
"4912.62400","5.82356","22.49604","30.46517","0.02949","197.31779"
"4919.52400","5.82605","22.19412","30.71489","0.02952","194.66959"
"4926.42400","5.85492","22.69372","30.61442","0.02980","199.05170"
"4933.32400","5.87206","22.55233","30.64028","0.02996","197.81157"
"4940.22400","5.87178","22.72801","30.41144","0.02996","199.35248"
"4947.12400","5.87099","22.74415","30.27597","0.02995","199.49399"
"4954.02400","5.86396","22.49426","30.13198","0.02988","197.30214"
"4960.92400","5.84467","23.25215","30.12117","0.02970","203.94977"
"4967.82400","5.81364","22.38593","30.94796","0.02939","196.35202"
"4974.72400","5.81366","23.00896","31.60169","0.02940","201.81676"
"4981.62400","5.81380","22.37382","32.35564","0.02940","196.24580"
"4988.52400","5.81371","22.88185","32.81341","0.02940","200.70178"
"4995.42400","5.81359","23.26847","33.14576","0.02939","204.09299"
"5002.32400","5.79007","22.41309","33.95958","0.02917","196.59023"
"5009.22400","5.77200","22.48019","34.57870","0.02899","197.17879"
"5016.12400","5.77219","22.96064","35.17530","0.02899","201.39288"
"5023.02400","5.77237","22.53605","35.78017","0.02899","197.66875"
"5029.92400","5.77228","23.02207","36.36870","0.02899","201.93176"
"5036.82400","5.77202","23.17224","37.03345","0.02899","203.24890"
"5043.72400","5.71701","22.07145","37.81351","0.02845","193.59364"
"5050.62400","5.71367","22.65766","38.30135","0.02842","198.73540"
"5057.52400","5.71433","22.53413","39.07860","0.02843","197.65189"
"5064.42400","5.71480","22.69367","39.75437","0.02843","199.05127"
"5065.11700","5.71479","22.85956","39.79234","0.02843","200.50630"