File: experimental/sma_database/flexinol_isobaric_trained_50MPa.csv
Test : Start of hold value,"50.00000",MPa

Time,Extension,Load,Temperature: Chamber 3119-600 1 1,Tensile strain (Extension),Tensile stress
(s),(mm),(N),(C),(mm/mm),(MPa)
"0.00000","0.47464","0.38205","31.43096","0.00000","3.35107"
"4.80000","0.51380","0.70951","31.28490","0.00039","6.22327"
"9.60000","0.55384","0.83125","31.23995","0.00079","7.29109"
"14.40000","0.59382","1.01642","31.22062","0.00119","8.91524"
"19.20000","0.63379","1.71820","30.99179","0.00158","15.07070"
"24.00000","0.67386","2.41529","30.66167","0.00198","21.18506"
"28.80000","0.71388","2.74916","30.61659","0.00238","24.11348"
"33.60000","0.75387","3.00985","30.65286","0.00278","26.40003"
"38.40000","0.79394","3.31120","30.57975","0.00318","29.04332"
"43.20000","0.83389","4.01043","30.49110","0.00358","35.17635"
"48.00000","0.87379","4.92508","30.47258","0.00397","43.19897"
"52.77000","0.91356","5.70084","30.36199","0.00437","50.00332"
"57.47100","0.97462","6.31274","30.28571","0.00498","55.37042"
"62.27100","0.97597","5.82311","30.08291","0.00499","51.07580"
"67.07100","0.97591","5.68431","29.95404","0.00499","49.85833"
"71.87100","0.97581","5.70604","30.04403","0.00499","50.04897"
"76.67100","0.97570","6.03177","29.98473","0.00499","52.90598"
"81.47100","0.97560","6.05073","29.85288","0.00499","53.07234"
"86.27100","0.97550","6.17447","29.77394","0.00498","54.15766"
"91.07100","0.97538","5.95134","29.78303","0.00498","52.20055"
"95.87100","0.97526","5.93357","29.74695","0.00498","52.04470"
"100.67100","0.97519","5.51480","29.57892","0.00498","48.37156"
"105.47100","0.97503","5.51932","29.55095","0.00498","48.41116"
"110.27100","0.97481","5.74882","29.51143","0.00498","50.42417"
"115.07100","0.97450","6.16627","29.40579","0.00497","54.08572"
"119.87100","0.97389","6.07094","29.36464","0.00497","53.24956"
"124.67100","0.97081","6.02128","29.39973","0.00494","52.81401"
"129.47100","0.95789","6.01062","29.36710","0.00481","52.72050"
"134.27100","0.94312","5.59494","29.41395","0.00466","49.07450"
"139.07100","0.94318","5.39205","29.37043","0.00466","47.29486"
"143.87100","0.94328","5.18722","29.25912","0.00466","45.49825"
"148.67100","0.94339","4.94052","29.32627","0.00467","43.33440"
"153.47100","0.94350","5.18106","29.18119","0.00467","45.44427"
"158.27100","0.94359","5.46947","29.18419","0.00467","47.97392"
"163.07100","0.94369","5.38049","29.25508","0.00467","47.19344"
"167.87100","0.94381","5.45274","29.17030","0.00467","47.82721"
"172.67100","0.94394","5.64259","29.18187","0.00467","49.49246"
"177.47100","0.94410","5.79080","29.23206","0.00467","50.79239"
"182.27100","0.94435","5.83677","29.27582","0.00467","51.19558"
"187.07100","0.94501","5.81023","29.24372","0.00468","50.96286"
"191.87100","0.94750","5.64973","29.17143","0.00471","49.55501"
"196.67100","0.95320","5.67985","29.22273","0.00476","49.81927"
"201.47100","0.96165","5.92509","29.22719","0.00485","51.97029"
"206.27100","0.96205","5.94044","29.26912","0.00485","52.10492"
"211.07100","0.96204","5.64331","29.37093","0.00485","49.49878"
"215.87100","0.96201","5.48015","29.35938","0.00485","48.06759"
"220.67100","0.96197","5.52255","29.32238","0.00485","48.43948"
"225.47100","0.96192","5.69543","29.32674","0.00485","49.95587"
"230.27100","0.96186","5.73552","29.32140","0.00485","50.30755"
"235.07100","0.96180","5.51348","29.43299","0.00485","48.35994"
"239.87100","0.96174","5.55640","29.42179","0.00485","48.73642"
"244.67100","0.96166","5.73871","29.47643","0.00485","50.33548"
"249.47100","0.96157","5.75014","29.52891","0.00485","50.43576"
"254.27100","0.96140","5.61697","29.61276","0.00484","49.26769"
"259.07100","0.96094","6.12333","29.90700","0.00484","53.70913"
"263.87100","0.95942","6.46706","30.12057","0.00482","56.72401"
"268.67100","0.93833","5.88897","30.57007","0.00461","51.65347"
"273.47100","0.87390","5.10175","30.95861","0.00397","44.74860"
"278.27100","0.85763","4.77332","31.14011","0.00381","41.86787"
"283.07100","0.85790","5.03996","31.54535","0.00381","44.20659"
"287.87100","0.85832","5.23612","32.16827","0.00382","45.92721"
"292.67100","0.87241","5.40553","32.24267","0.00396","47.41315"
"297.47100","0.89661","5.70217","32.53173","0.00420","50.01499"
"302.27100","0.92643","6.10690","32.92428","0.00450","53.56501"
"307.07100","0.92627","6.26911","33.35449","0.00449","54.98774"
"311.87100","0.92603","6.41127","33.73265","0.00449","56.23473"
"316.67100","0.92566","6.34446","34.11447","0.00449","55.64865"
"321.47100","0.92325","6.41435","34.60178","0.00446","56.26174"
"326.27100","0.83560","5.39273","35.10286","0.00359","47.30082"
"331.07100","0.83560","5.60052","35.63592","0.00359","49.12341"
"335.87100","0.83564","5.63715","36.33765","0.00359","49.44473"
"340.67100","0.83563","5.72658","37.00383","0.00359","50.22912"
"345.47100","0.83557","5.93191","37.72047","0.00359","52.03012"
"350.27100","0.82827","6.06654","38.60128","0.00352","53.21096"
"355.07100","0.77208","5.42461","39.41337","0.00296","47.58047"
"359.87100","0.77212","5.50198","40.20033","0.00296","48.25907"
"364.67100","0.77213","5.65665","41.13368","0.00296","49.61573"
"369.47100","0.77210","5.88094","41.90735","0.00296","51.58306"
"374.27100","0.77189","6.05822","42.67525","0.00296","53.13800"
"379.07100","0.73013","5.49525","43.46549","0.00254","48.20011"
"383.87100","0.72919","5.59964","44.26740","0.00253","49.11571"
"388.67100","0.72847","5.79996","45.01286","0.00253","50.87279"
"393.47100","0.72272","5.90656","45.67501","0.00247","51.80778"
"398.27100","0.68091","5.40502","46.40852","0.00205","47.40866"
"403.07100","0.68097","5.46132","47.04115","0.00205","47.90248"
"407.87100","0.68100","5.60289","47.69452","0.00205","49.14417"
"412.67100","0.68098","5.81793","48.36554","0.00205","51.03034"
"417.47100","0.68094","5.97401","49.00203","0.00205","52.39934"
"422.27100","0.68048","5.98245","49.59120","0.00205","52.47338"
"427.07100","0.62993","5.42105","50.28620","0.00155","47.54921"
"431.87100","0.62815","5.60615","50.87301","0.00153","49.17276"
"436.67100","0.62808","5.80670","51.49403","0.00153","50.93190"
"441.47100","0.62755","5.87318","52.21852","0.00152","51.51494"
"446.27100","0.53218","4.81862","52.83621","0.00057","42.26518"
"451.07100","0.52384","4.91404","53.44914","0.00049","43.10217"
"455.87100","0.52449","5.10431","54.10761","0.00050","44.77103"
"460.67100","0.52555","5.28641","54.86320","0.00051","46.36825"
"465.47100","0.53312","5.60913","55.53987","0.00058","49.19896"
"470.27100","0.54033","5.76900","56.19369","0.00065","50.60118"
"475.07100","0.54031","5.86395","56.93828","0.00065","51.43404"
"479.87100","0.54015","6.13605","57.57448","0.00065","53.82067"
"484.67100","0.53980","6.27521","58.26257","0.00065","55.04129"
"489.47100","0.53803","6.34547","59.02746","0.00063","55.65754"
"494.27100","0.46538","5.72592","59.66649","-0.00009","50.22329"
"499.07100","0.43433","5.60228","60.30803","-0.00040","49.13886"
"503.87100","0.43412","5.80628","61.04195","-0.00040","50.92820"
"508.67100","0.41846","5.78833","61.69127","-0.00056","50.77071"
"513.47100","0.38566","5.58423","62.30892","-0.00089","48.98049"
"518.27100","0.38556","5.73607","63.00582","-0.00089","50.31239"
"523.07100","0.37229","5.82253","63.60461","-0.00102","51.07067"
"527.87100","0.34365","5.75703","64.18884","-0.00130","50.49619"
"532.67100","0.32815","5.73720","64.82633","-0.00146","50.32225"
"537.47100","0.29029","5.59160","65.54951","-0.00183","49.04519"
"542.27100","0.28841","5.82369","66.16816","-0.00185","51.08092"
"547.07100","0.24552","5.68937","66.81165","-0.00228","49.90274"
"551.87100","0.22657","5.69411","67.57206","-0.00247","49.94432"
"556.67100","0.18933","5.63067","68.23286","-0.00284","49.38783"
"561.47100","0.17234","5.80584","68.84682","-0.00301","50.92433"
"566.27100","0.14257","5.83758","69.54734","-0.00331","51.20274"
"571.07100","0.08187","5.63720","70.16730","-0.00391","49.44516"
"575.87100","0.05194","5.74741","70.80863","-0.00421","50.41184"
"580.67100","-0.00456","5.57718","71.49583","-0.00477","48.91872"
"585.47100","-0.03402","5.82929","72.15266","-0.00506","51.13001"
"590.27100","-0.11573","5.56180","72.76111","-0.00588","48.78375"
"595.07100","-0.15077","5.81808","73.36185","-0.00622","51.03167"
"599.87100","-0.23854","5.70953","74.07448","-0.00710","50.07952"
"604.67100","-0.32158","5.68817","74.72575","-0.00792","49.89218"
"609.47100","-0.39034","5.82654","75.29211","-0.00861","51.10589"
"614.27100","-0.46832","5.83531","75.96083","-0.00939","51.18285"
"619.07100","-0.57718","5.68283","76.52773","-0.01047","49.84536"
"623.87100","-0.71207","5.63987","77.16858","-0.01181","49.46859"
"628.67100","-0.84916","5.59369","77.89300","-0.01318","49.06352"
"633.47100","-0.98862","5.62895","78.57110","-0.01456","49.37281"
"638.27100","-1.11392","5.83590","79.21114","-0.01581","51.18795"
"643.07100","-1.28054","5.65634","79.96268","-0.01747","49.61302"
"647.87100","-1.44448","5.79304","80.58212","-0.01910","50.81202"
"652.67100","-1.63666","5.77359","81.24831","-0.02101","50.64144"
"657.47100","-1.85390","5.79798","81.92204","-0.02318","50.85538"
"662.27100","-2.06104","5.58468","82.56590","-0.02524","48.98447"
"667.07100","-2.28940","5.81315","83.13481","-0.02751","50.98846"
"671.87100","-2.58812","5.62816","83.73829","-0.03048","49.36586"
"676.67100","-2.95764","5.83083","84.43813","-0.03416","51.14352"
"681.47100","-3.24461","5.86182","85.06767","-0.03702","51.41533"
"686.27100","-3.61739","5.58845","85.62271","-0.04073","49.01754"
"691.07100","-3.99026","5.72025","86.30166","-0.04444","50.17359"
"695.87100","-4.32887","5.74100","86.96352","-0.04781","50.35555"
"700.67100","-4.66618","5.62639","87.62380","-0.05117","49.35036"
"705.47100","-4.89298","5.82167","88.28931","-0.05342","51.06319"
"710.27100","-5.18261","5.50020","88.96056","-0.05631","48.24350"
"715.07100","-5.34385","5.80570","89.60557","-0.05791","50.92308"
"719.87100","-5.47959","5.78786","90.28147","-0.05926","50.76661"
"724.67100","-5.67448","5.76355","90.87326","-0.06120","50.55341"
"729.47100","-5.87239","5.64003","91.52969","-0.06317","49.46995"
"734.27100","-6.03488","5.81633","92.19081","-0.06479","51.01633"
"739.07100","-6.19432","5.57676","92.77657","-0.06637","48.91505"
"743.87100","-6.30644","5.65602","93.35561","-0.06749","49.61018"
"748.67100","-6.46037","5.54031","93.93397","-0.06902","48.59528"
"753.47100","-6.57433","5.81738","94.59563","-0.07016","51.02557"
"758.27100","-6.68408","5.66548","95.25468","-0.07125","49.69316"
"763.07100","-6.79126","5.61516","95.91248","-0.07232","49.25182"
"767.87100","-6.88282","5.70106","96.63531","-0.07323","50.00531"
"772.67100","-6.88662","6.48410","97.22866","-0.07326","56.87348"
"777.47100","-7.17319","5.15498","97.81725","-0.07612","45.21549"
"782.27100","-7.17323","5.97318","98.50044","-0.07612","52.39208"
"787.07100","-7.30185","5.59435","99.13492","-0.07740","49.06932"
"791.87100","-7.47877","5.22328","99.80521","-0.07916","45.81454"
"796.67100","-7.48676","5.92975","100.50504","-0.07924","52.01114"
"801.47100","-7.57563","5.81871","101.13705","-0.08012","51.03721"
"806.27100","-7.67281","5.63156","101.86941","-0.08109","49.39563"
"811.07100","-7.74686","5.59145","102.43961","-0.08183","49.04382"
"815.87100","-7.79201","5.80802","103.04889","-0.08228","50.94345"
"820.67100","-7.88936","5.69853","103.62726","-0.08325","49.98307"
"825.47100","-7.95356","5.62557","104.35885","-0.08388","49.34310"
"830.27100","-7.99015","5.85142","105.08662","-0.08425","51.32408"
"835.07100","-8.03798","5.82604","105.79124","-0.08472","51.10151"
"839.87100","-8.08633","5.67698","106.40675","-0.08521","49.79410"
"844.67100","-8.15676","5.46275","107.02967","-0.08591","47.91496"
"849.47100","-8.18119","5.78965","107.65630","-0.08615","50.78230"
"854.27100","-8.23384","5.60353","108.19881","-0.08667","49.14985"
"859.07100","-8.25778","5.75821","108.78278","-0.08691","50.50659"
"863.87100","-8.32710","5.45347","109.37205","-0.08760","47.83360"
"868.67100","-8.32850","6.04467","109.89896","-0.08762","53.01917"
"873.47100","-8.41728","5.40733","110.51508","-0.08850","47.42892"
"878.27100","-8.42941","6.03603","111.23855","-0.08862","52.94338"
"883.07100","-8.51905","5.33329","112.00131","-0.08951","46.77950"
"887.87100","-8.51952","5.76357","112.72879","-0.08952","50.55354"
"892.67100","-8.52919","6.00830","113.34486","-0.08961","52.70011"
"897.47100","-8.61465","5.39102","114.00014","-0.09046","47.28581"
"902.27100","-8.61606","5.86580","114.65188","-0.09048","51.45027"
"907.07100","-8.65773","5.69249","115.20649","-0.09089","49.93010"
"911.87100","-8.71014","5.45038","115.85191","-0.09141","47.80653"
"916.67100","-8.71416","5.82960","116.55846","-0.09145","51.13269"
"921.47100","-8.75947","5.49776","117.19534","-0.09191","48.22204"
"926.27100","-8.77611","5.84747","117.77822","-0.09207","51.28944"
"931.07100","-8.81087","5.75617","118.49451","-0.09242","50.48869"
"935.87100","-8.81946","5.93404","119.09178","-0.09250","52.04877"
"940.67100","-8.86097","5.67563","119.67248","-0.09292","49.78224"
"945.47100","-8.90751","5.45095","120.31345","-0.09338","47.81148"
"950.27100","-8.91476","5.96284","120.98933","-0.09345","52.30139"
"955.07100","-8.99146","5.43545","121.61235","-0.09421","47.67552"
"959.87100","-8.99783","5.67562","122.27885","-0.09428","49.78210"
"964.67100","-9.01020","5.87386","122.81984","-0.09440","51.52092"
"969.47100","-9.05144","5.68755","123.43183","-0.09481","49.88680"
"974.27100","-9.06709","5.73116","124.02484","-0.09497","50.26931"
"979.07100","-9.10069","5.36030","124.51834","-0.09530","47.01637"
"983.87100","-9.10068","5.64481","124.84373","-0.09530","49.51190"
"988.67100","-9.10072","5.75222","125.27644","-0.09530","50.45399"
"993.47100","-9.10079","5.87340","125.54498","-0.09530","51.51692"
"998.27100","-9.10163","5.61986","125.61163","-0.09531","49.29303"
"1003.07100","-9.11113","5.68207","125.59338","-0.09541","49.83874"
"1007.87100","-9.11841","5.59805","125.54976","-0.09548","49.10175"
"1012.67100","-9.11830","5.42047","125.46920","-0.09548","47.54417"
"1017.47100","-9.11810","5.31141","125.33920","-0.09547","46.58755"
"1022.27100","-9.11778","5.41817","125.17466","-0.09547","47.52396"
"1027.07100","-9.11736","5.35513","125.04348","-0.09547","46.97104"
"1031.87100","-9.11598","5.36551","124.90724","-0.09545","47.06208"
"1036.67100","-9.08894","5.61001","124.63213","-0.09518","49.20663"
"1041.47100","-9.08181","5.48944","124.35519","-0.09511","48.14911"
"1046.27100","-9.03594","6.25043","123.98605","-0.09466","54.82395"
"1051.07100","-9.03606","6.00682","123.48742","-0.09466","52.68712"
"1055.87100","-9.03618","5.86697","122.96365","-0.09466","51.46046"
"1060.67100","-9.03615","5.51812","122.32352","-0.09466","48.40069"
"1065.47100","-9.03605","5.29863","121.62554","-0.09466","46.47547"
"1070.27100","-9.03558","5.16563","121.05167","-0.09465","45.30886"
"1075.07100","-8.97748","6.00340","120.38294","-0.09407","52.65715"
"1079.87100","-8.96097","5.98268","119.76842","-0.09391","52.47540"
"1084.67100","-8.95362","5.64324","118.97594","-0.09384","49.49813"
"1089.47100","-8.95333","5.57550","118.28046","-0.09383","48.90395"
"1094.27100","-8.93636","5.64469","117.62405","-0.09367","49.51082"
"1099.07100","-8.90627","5.83068","116.95206","-0.09337","51.14222"
"1103.87100","-8.90594","5.65282","116.33548","-0.09336","49.58216"
"1108.67100","-8.90566","5.46062","115.74517","-0.09336","47.89635"
"1113.47100","-8.88884","5.51210","115.08470","-0.09319","48.34784"
"1118.27100","-8.84244","6.13881","114.49317","-0.09273","53.84486"
"1123.07100","-8.84218","5.85161","113.91817","-0.09273","51.32576"
"1127.87100","-8.84218","5.56008","113.34245","-0.09273","48.76870"
"1132.67100","-8.84210","5.57334","112.82647","-0.09273","48.88505"
"1137.47100","-8.82895","5.51077","112.29607","-0.09260","48.33617"
"1142.27100","-8.79959","5.75995","111.71008","-0.09230","50.52183"
"1147.07100","-8.79844","5.53489","111.19176","-0.09229","48.54776"
"1151.87100","-8.77096","5.86559","110.66235","-0.09202","51.44836"
"1156.67100","-8.74561","5.86236","110.03973","-0.09177","51.42004"
"1161.47100","-8.74559","5.56657","109.48289","-0.09177","48.82561"
"1166.27100","-8.74537","5.50270","109.00648","-0.09176","48.26545"
"1171.07100","-8.71225","5.83861","108.51685","-0.09144","51.21172"
"1175.87100","-8.69883","5.71173","107.88767","-0.09130","50.09883"
"1180.67100","-8.69847","5.71007","107.38295","-0.09130","50.08430"
"1185.47100","-8.68447","5.52246","106.86311","-0.09116","48.43872"
"1190.27100","-8.63841","6.00608","106.31923","-0.09070","52.68067"
"1195.07100","-8.63850","5.76710","105.84200","-0.09070","50.58451"
"1199.87100","-8.63850","5.77046","105.42146","-0.09070","50.61402"
"1204.67100","-8.63839","5.30065","104.87801","-0.09070","46.49322"
"1209.47100","-8.61228","5.52509","104.39179","-0.09044","48.46177"
"1214.27100","-8.60045","5.72966","103.95130","-0.09032","50.25609"
"1219.07100","-8.59457","5.57844","103.49756","-0.09026","48.92979"
"1223.87100","-8.54970","5.91702","103.06432","-0.08982","51.89955"
"1228.67100","-8.54974","5.80304","102.64965","-0.08982","50.89980"
"1233.47100","-8.54968","5.50609","102.16550","-0.08982","48.29519"
"1238.27100","-8.53677","5.53596","101.72344","-0.08969","48.55713"
"1243.07100","-8.50946","5.74215","101.30955","-0.08942","50.36572"
"1247.87100","-8.50697","5.78702","100.82932","-0.08939","50.75922"
"1252.67100","-8.46138","5.95532","100.42297","-0.08894","52.23540"
"1257.47100","-8.44511","5.74903","100.03939","-0.08878","50.42603"
"1262.27100","-8.44512","5.67805","99.55211","-0.08878","49.80344"
"1267.07100","-8.44507","5.61812","99.07038","-0.08878","49.27782"
"1271.87100","-8.42509","5.64433","98.66194","-0.08858","49.50765"
"1276.67100","-8.40687","5.63080","98.22841","-0.08840","49.38904"
"1281.47100","-8.36139","5.91649","97.74622","-0.08794","51.89487"
"1286.27100","-8.34331","6.01496","97.30962","-0.08776","52.75852"
"1291.07100","-8.34331","5.74947","96.89856","-0.08776","50.42989"
"1295.87100","-8.34314","5.33980","96.34750","-0.08776","46.83656"
"1300.67100","-8.32311","5.36011","95.89568","-0.08756","47.01472"
"1305.47100","-8.29016","5.70783","95.44775","-0.08723","50.06461"
"1310.27100","-8.24405","5.91086","94.90527","-0.08678","51.84547"
"1315.07100","-8.24218","5.55968","94.37482","-0.08676","48.76521"
"1319.87100","-8.22075","5.41913","93.92706","-0.08654","47.53241"
"1324.67100","-8.14490","6.22647","93.40016","-0.08579","54.61380"
"1329.47100","-8.12316","6.05040","92.81612","-0.08557","53.06939"
"1334.27100","-8.12310","5.54049","92.23129","-0.08557","48.59688"
"1339.07100","-8.10698","5.37347","91.66647","-0.08541","47.13193"
"1343.87100","-8.00478","5.88970","90.89438","-0.08439","51.65990"
"1348.67100","-7.93295","5.74642","90.12785","-0.08368","50.40316"
"1353.47100","-7.87794","5.66598","89.32713","-0.08313","49.69754"
"1358.27100","-7.79086","5.75388","88.29812","-0.08226","50.46857"
"1363.07100","-7.72612","5.42521","87.30567","-0.08162","47.58573"
"1367.87100","-7.54439","5.87509","86.17926","-0.07981","51.53169"
"1372.67100","-7.42959","5.87453","84.81593","-0.07867","51.52682"
"1377.47100","-7.42885","5.49478","84.10579","-0.07866","48.19596"
"1382.27100","-7.36354","5.06250","83.09778","-0.07801","44.40429"
"1387.07100","-7.13406","5.80932","81.76907","-0.07573","50.95481"
"1391.87100","-6.98880","6.60891","80.56731","-0.07428","57.96825"
"1396.67100","-6.96016","5.03872","79.86342","-0.07400","44.19576"
"1401.47100","-6.74738","6.34657","78.82913","-0.07188","55.66718"
"1406.27100","-6.66333","4.66373","77.99322","-0.07104","40.90662"
"1411.07100","-6.31412","6.81675","76.71803","-0.06757","59.79128"
"1415.87100","-5.74831","4.98836","75.63348","-0.06194","43.75405"
"1420.67100","-5.50652","4.68570","74.54346","-0.05953","41.09929"
"1425.47100","-5.31922","5.07694","73.79163","-0.05767","44.53098"
"1430.27100","-5.21277","5.17904","72.99507","-0.05661","45.42656"
"1435.07100","-4.87023","6.14044","72.08484","-0.05320","53.85916"
"1439.87100","-4.66871","5.96391","71.42097","-0.05119","52.31082"
"1444.67100","-4.39005","6.17109","70.68114","-0.04842","54.12803"
"1449.47100","-4.09105","6.24195","69.98070","-0.04544","54.74950"
"1454.27100","-3.86257","6.34632","69.26512","-0.04317","55.66498"
"1459.07100","-3.65558","6.25385","68.68526","-0.04111","54.85391"
"1463.87100","-3.35864","6.39237","68.17816","-0.03815","56.06888"
"1468.67100","-3.16620","6.41007","67.75588","-0.03624","56.22411"
"1473.47100","-2.97060","6.53246","67.06432","-0.03429","57.29766"
"1478.27100","-2.68457","6.72372","66.40006","-0.03144","58.97527"
"1483.07100","-2.36233","6.67240","65.58002","-0.02824","58.52513"
"1487.87100","-2.06390","6.51722","64.83696","-0.02527","57.16399"
"1492.67100","-1.69925","6.52919","64.17992","-0.02164","57.26900"
"1497.47100","-1.44047","6.73986","63.28849","-0.01906","59.11683"
"1502.27100","-1.30537","6.58851","62.63686","-0.01772","57.78926"
"1507.07100","-1.14017","6.48335","61.90203","-0.01607","56.86695"
"1511.87100","-0.95651","6.89052","61.01637","-0.01424","60.43827"
"1516.67100","-0.91102","6.52668","60.50980","-0.01379","57.24701"
"1521.47100","-0.84620","6.02793","60.00163","-0.01315","52.87231"
"1526.27100","-0.70891","6.58522","59.38703","-0.01178","57.76044"
"1531.07100","-0.65440","6.15203","58.78075","-0.01124","53.96082"
"1535.87100","-0.61128","5.59432","58.30502","-0.01081","49.06902"
"1540.67100","-0.55430","5.31412","57.67342","-0.01024","46.61131"
"1545.47100","-0.47385","5.47784","57.24265","-0.00944","48.04740"
"1550.27100","-0.42049","5.49281","56.63379","-0.00891","48.17870"
"1555.07100","-0.38339","5.21109","56.13343","-0.00854","45.70761"
"1559.87100","-0.36995","4.81152","55.78032","-0.00841","42.20293"
"1564.67100","-0.29628","5.21935","55.32055","-0.00767","45.78007"
"1569.47100","-0.20965","5.34291","54.74119","-0.00681","46.86390"
"1574.27100","0.05763","6.41656","53.52993","-0.00415","56.28112"
"1579.07100","0.13277","6.15320","52.56075","-0.00340","53.97109"
"1583.87100","0.14511","5.54781","51.75843","-0.00328","48.66108"
"1588.67100","0.14772","5.25915","51.23341","-0.00325","46.12915"
"1593.47100","0.16323","4.79088","50.56526","-0.00310","42.02192"
"1598.27100","0.20356","4.88690","49.98316","-0.00270","42.86412"
"1603.07100","0.24705","5.04518","49.22447","-0.00227","44.25241"
"1607.87100","0.27176","5.05806","48.74031","-0.00202","44.36535"
"1612.67100","0.30935","6.02833","48.12902","-0.00165","52.87586"
"1617.47100","0.32487","6.01108","47.49923","-0.00149","52.72453"
"1622.27100","0.36145","6.43927","47.04510","-0.00113","56.48025"
"1627.07100","0.38925","6.25297","46.66906","-0.00085","54.84624"
"1631.87100","0.43739","6.34864","46.15726","-0.00037","55.68534"
"1636.67100","0.50000","6.33475","45.30235","0.00025","55.56349"
"1641.47100","0.54623","6.46875","44.60508","0.00071","56.73883"
"1646.27100","0.56411","6.48173","44.00883","0.00089","56.85266"
"1651.07100","0.56456","6.32171","43.41376","0.00089","55.44914"
"1655.87100","0.57495","6.23681","42.93695","0.00100","54.70448"
"1660.67100","0.61563","6.30504","42.32523","0.00140","55.30287"
"1665.47100","0.61948","6.16286","41.59113","0.00144","54.05580"
"1670.27100","0.61987","5.82146","41.01383","0.00145","51.06133"
"1675.07100","0.71111","6.51187","40.39819","0.00235","57.11702"
"1679.87100","0.71130","6.45132","39.75321","0.00236","56.58598"
"1684.67100","0.71127","5.85065","39.47151","0.00235","51.31734"
"1689.47100","0.71130","5.40168","39.21628","0.00236","47.37935"
"1694.27100","0.71129","5.34297","38.88261","0.00236","46.86436"
"1699.07100","0.71129","5.42284","38.76260","0.00236","47.56492"
"1703.87100","0.71150","5.90993","38.25640","0.00236","51.83730"
"1708.67100","0.87556","5.95045","37.70510","0.00399","52.19276"
"1713.47100","0.93582","6.86817","36.23044","0.00459","60.24221"
"1718.27100","0.93561","6.91783","35.10037","0.00459","60.67783"
"1723.07100","0.93551","5.63868","34.33660","0.00459","49.45814"
"1727.87100","0.93518","5.18756","33.28639","0.00458","45.50123"
"1732.67100","0.93520","5.06060","32.27227","0.00458","44.38764"
"1737.47100","0.93521","5.14184","31.46060","0.00458","45.10019"
"1742.27100","0.93523","5.28875","30.82411","0.00458","46.38877"
"1747.07100","0.93522","5.78199","30.66857","0.00458","50.71515"
"1751.87100","0.93517","6.27334","30.68546","0.00458","55.02485"
"1756.67100","0.93517","6.06934","30.67582","0.00458","53.23552"
"1761.47100","0.93520","5.88764","30.35752","0.00458","51.64184"
"1766.27100","0.93520","5.70696","30.36252","0.00458","50.05706"
"1771.07100","0.93521","5.39012","30.45815","0.00458","47.27794"
"1775.87100","0.93525","5.27701","30.35810","0.00458","46.28586"
"1780.67100","0.93527","5.39458","30.30355","0.00458","47.31710"
"1785.47100","0.93530","5.89254","30.00744","0.00458","51.68481"
"1790.27100","0.93536","5.84676","29.82578","0.00459","51.28320"
"1795.07100","0.93544","5.67182","29.68654","0.00459","49.74876"
"1799.87100","0.93562","5.39439","29.70790","0.00459","47.31539"
"1804.67100","0.93570","5.29148","29.85692","0.00459","46.41272"
"1809.47100","0.93567","5.77113","30.10376","0.00459","50.61988"
"1814.27100","0.93559","6.14811","30.45606","0.00459","53.92648"
"1819.07100","0.93548","6.44094","30.80926","0.00459","56.49489"
"1823.87100","0.93531","6.58220","31.27016","0.00458","57.73394"
"1828.67100","0.93506","6.32148","31.73218","0.00458","55.44710"
"1833.47100","0.92916","6.21886","32.30750","0.00452","54.54705"
"1838.27100","0.87162","5.68189","32.78305","0.00395","49.83710"
"1843.07100","0.85515","5.41903","33.26830","0.00379","47.53152"
"1847.87100","0.85522","5.44970","33.73888","0.00379","47.80057"
"1852.67100","0.85528","5.84814","34.01480","0.00379","51.29536"
"1857.47100","0.85532","5.93378","34.54607","0.00379","52.04652"
"1862.27100","0.85533","6.03666","35.15448","0.00379","52.94894"
"1867.07100","0.85532","5.95399","35.64767","0.00379","52.22375"
"1871.87100","0.85515","5.62670","36.21767","0.00379","49.35302"
"1876.67100","0.85499","5.70306","36.75701","0.00379","50.02285"
"1881.47100","0.85300","6.38905","37.20443","0.00377","56.03976"
"1886.27100","0.77998","5.28728","37.60159","0.00304","46.37596"
"1891.07100","0.78005","5.01862","38.18533","0.00304","44.01946"
"1895.87100","0.78020","5.39853","38.42146","0.00304","47.35168"
"1900.67100","0.78024","5.46132","39.10379","0.00304","47.90243"
"1905.47100","0.78044","5.57761","39.38662","0.00304","48.92243"
"1910.27100","0.78045","5.84489","39.97518","0.00304","51.26687"
"1915.07100","0.78043","5.81460","40.60328","0.00304","51.00115"
"1919.87100","0.78041","5.77460","41.02090","0.00304","50.65027"
"1924.67100","0.78035","5.89944","41.50092","0.00304","51.74527"
"1929.47100","0.78026","5.99839","41.93549","0.00304","52.61325"
"1934.27100","0.78014","6.09441","42.31807","0.00304","53.45541"
"1939.07100","0.77992","6.10632","42.71351","0.00304","53.55994"
"1943.87100","0.76228","6.00511","43.14617","0.00286","52.67220"
"1948.67100","0.69729","5.28995","43.55313","0.00222","46.39933"
"1953.47100","0.69730","5.48364","44.12270","0.00222","48.09821"
"1958.27100","0.69735","5.60908","44.65457","0.00222","49.19851"
"1963.07100","0.69734","5.80226","45.31610","0.00222","50.89290"
"1967.87100","0.69727","6.01559","46.05691","0.00222","52.76411"
"1972.67100","0.68317","6.08990","46.90512","0.00208","53.41586"
"1977.47100","0.62916","5.51785","47.70955","0.00154","48.39827"
"1982.27100","0.62681","5.69785","48.56709","0.00151","49.97710"
"1987.07100","0.59585","5.52775","49.47650","0.00121","48.48510"
"1991.87100","0.51781","4.76104","50.37472","0.00043","41.76012"
"1996.67100","0.51357","4.90558","51.21284","0.00039","43.02790"
"2001.47100","0.51490","5.07002","52.14674","0.00040","44.47026"
"2006.27100","0.53311","5.58516","52.92097","0.00058","48.98872"
"2011.07100","0.55019","6.00813","53.72433","0.00075","52.69863"
"2015.87100","0.54995","6.14909","54.54560","0.00075","53.93501"
"2020.67100","0.54916","6.20523","55.30361","0.00074","54.42747"
"2025.47100","0.53355","6.19022","55.97527","0.00059","54.29584"
"2030.27100","0.45672","5.44335","56.72640","-0.00018","47.74483"
"2035.07100","0.44340","5.49347","57.33793","-0.00031","48.18443"
"2039.87100","0.44343","5.66578","57.96086","-0.00031","49.69582"
"2044.67100","0.44337","5.80458","58.57143","-0.00031","50.91325"
"2049.47100","0.44111","6.05184","59.25446","-0.00033","53.08202"
"2054.27100","0.37690","5.41396","59.84454","-0.00097","47.48708"
"2059.07100","0.37576","5.78761","60.44556","-0.00098","50.76444"
"2063.87100","0.37568","5.78584","61.14345","-0.00099","50.74886"
"2068.67100","0.34264","5.74043","61.78886","-0.00131","50.35058"
"2073.47100","0.29532","5.42239","62.41348","-0.00178","47.56096"
"2078.27100","0.29113","5.69897","63.17060","-0.00183","49.98693"
"2083.07100","0.28793","5.96891","63.81749","-0.00186","52.35468"
"2087.87100","0.24227","5.57436","64.48731","-0.00231","48.89397"
"2092.67100","0.19604","5.44917","65.22148","-0.00277","47.79589"
"2097.47100","0.19135","5.87016","65.91191","-0.00282","51.48849"
"2102.27100","0.17061","5.86045","66.58276","-0.00303","51.40332"
"2107.07100","0.13238","5.70976","67.32681","-0.00341","50.08156"
"2111.87100","0.08490","5.73903","67.96317","-0.00388","50.33832"
"2116.67100","0.04817","5.80006","68.63715","-0.00424","50.87366"
"2121.47100","-0.00791","5.64087","69.28535","-0.00480","49.47733"
"2126.27100","-0.04386","5.88404","70.05253","-0.00516","51.61021"
"2131.07100","-0.11316","5.54800","70.69526","-0.00585","48.66275"
"2135.87100","-0.16600","5.65207","71.34307","-0.00638","49.57553"
"2140.67100","-0.22927","5.75283","72.08884","-0.00701","50.45938"
"2145.47100","-0.32427","5.54128","72.78352","-0.00795","48.60381"
"2150.27100","-0.38359","5.65450","73.35833","-0.00854","49.59688"
"2155.07100","-0.44401","5.99866","74.10830","-0.00914","52.61559"
"2159.87100","-0.58931","5.54113","74.75211","-0.01059","48.60253"
"2164.67100","-0.68864","5.61724","75.41198","-0.01158","49.27008"
"2169.47100","-0.77484","5.72360","76.09488","-0.01244","50.20296"
"2174.27100","-0.91767","5.53749","76.75352","-0.01386","48.57059"
"2179.07100","-1.01657","5.73009","77.34425","-0.01484","50.25994"
"2183.87100","-1.11614","5.89177","78.01587","-0.01583","51.67804"
"2188.67100","-1.29762","5.76537","78.61977","-0.01764","50.56931"
"2193.47100","-1.38884","6.17932","79.29370","-0.01855","54.20021"
"2198.27100","-1.61528","5.62502","79.96043","-0.02080","49.33834"
"2203.07100","-1.87641","5.39921","80.60428","-0.02340","47.35765"
"2207.87100","-2.10888","5.65064","81.21008","-0.02571","49.56306"
"2212.67100","-2.33142","5.74728","81.84033","-0.02793","50.41068"
"2217.47100","-2.56711","5.97501","82.59189","-0.03027","52.40818"
"2222.27100","-2.91163","5.53261","83.26601","-0.03370","48.52776"
"2227.07100","-3.19143","5.72841","83.88457","-0.03649","50.24517"
"2231.87100","-3.55748","5.72003","84.61443","-0.04013","50.17170"
"2236.67100","-3.95778","5.68656","85.22289","-0.04411","49.87813"
"2241.47100","-4.31534","5.87548","85.84769","-0.04767","51.53514"
"2246.27100","-4.67656","5.34734","86.57838","-0.05127","46.90270"
"2251.07100","-4.91303","5.81859","87.20518","-0.05362","51.03613"
"2255.87100","-5.19471","5.59206","87.82474","-0.05643","49.04918"
"2260.67100","-5.35795","5.94174","88.51661","-0.05805","52.11631"
"2265.47100","-5.51334","5.93482","89.09929","-0.05960","52.05567"
"2270.27100","-5.76620","5.70747","89.68033","-0.06211","50.06153"
"2275.07100","-5.97111","5.70440","90.35244","-0.06415","50.03461"
"2279.87100","-6.14637","5.65174","91.01221","-0.06590","49.57269"
"2284.67100","-6.29514","5.68883","91.66840","-0.06738","49.89796"
"2289.47100","-6.38153","5.66546","92.28907","-0.06824","49.69305"
"2294.27100","-6.57029","5.71977","92.97836","-0.07012","50.16934"
"2299.07100","-6.69554","5.73533","93.58614","-0.07136","50.30588"
"2303.87100","-6.81364","5.63545","94.23949","-0.07254","49.42980"
"2308.67100","-6.89542","5.71931","94.93378","-0.07335","50.16534"
"2313.47100","-7.00478","5.76680","95.54155","-0.07444","50.58187"
"2318.27100","-7.06592","6.06653","96.14333","-0.07505","53.21088"
"2323.07100","-7.28424","5.32654","96.89378","-0.07722","46.72027"
"2327.87100","-7.41666","5.27889","97.57086","-0.07854","46.30237"
"2332.67100","-7.44823","5.66434","98.19802","-0.07885","49.68324"
"2337.47100","-7.47546","6.06889","98.87079","-0.07913","53.23158"
"2342.27100","-7.61087","5.53142","99.48619","-0.08047","48.51736"
"2347.07100","-7.69255","5.69353","100.05904","-0.08129","49.93919"
"2351.87100","-7.74794","5.78519","100.67281","-0.08184","50.74323"
"2356.67100","-7.78863","5.80891","101.35443","-0.08224","50.95129"
"2361.47100","-7.86294","5.64095","101.90660","-0.08298","49.47801"
"2366.27100","-7.94185","5.51380","102.54341","-0.08377","48.36275"
"2371.07100","-7.98015","5.80187","103.22320","-0.08415","50.88950"
"2375.87100","-8.03847","5.69561","103.87407","-0.08473","49.95748"
"2380.67100","-8.08613","5.84782","104.46719","-0.08520","51.29250"
"2385.47100","-8.16640","5.39312","105.25529","-0.08600","47.30423"
"2390.27100","-8.18997","5.87624","105.87290","-0.08624","51.54182"
"2395.07100","-8.23842","5.80498","106.53575","-0.08672","50.91675"
"2399.87100","-8.28023","5.77143","107.19124","-0.08714","50.62249"
"2404.67100","-8.33785","5.48679","107.90127","-0.08771","48.12586"
"2409.47100","-8.35823","5.89263","108.46821","-0.08791","51.68558"
"2414.27100","-8.42330","5.48040","109.11273","-0.08856","48.06980"
"2419.07100","-8.43806","5.81469","109.80321","-0.08871","51.00193"
"2423.87100","-8.51271","5.35733","110.41911","-0.08945","46.99034"
"2428.67100","-8.51972","5.80683","111.03818","-0.08952","50.93304"
"2433.47100","-8.56526","5.71247","111.77490","-0.08997","50.10534"
"2438.27100","-8.61005","5.46009","112.34772","-0.09042","47.89169"
"2443.07100","-8.61089","5.81723","112.95206","-0.09043","51.02427"
"2447.87100","-8.64317","5.72450","113.56499","-0.09075","50.21084"
"2452.67100","-8.69411","5.53614","114.14622","-0.09125","48.55870"
"2457.47100","-8.71584","5.88954","114.71651","-0.09147","51.65849"
"2462.27100","-8.74965","5.55066","115.40321","-0.09181","48.68612"
"2467.07100","-8.77195","5.68053","116.02660","-0.09203","49.82519"
"2471.87100","-8.80570","5.65522","116.62827","-0.09237","49.60321"
"2476.67100","-8.81528","5.83107","117.34750","-0.09246","51.14564"
"2481.47100","-8.86120","5.71852","118.03252","-0.09292","50.15840"
"2486.27100","-8.90042","5.47524","118.64540","-0.09331","48.02453"
"2491.07100","-8.90760","5.72128","119.29642","-0.09338","50.18263"
"2495.87100","-8.94646","5.66541","119.98398","-0.09377","49.69259"
"2500.67100","-8.96604","5.77668","120.68795","-0.09396","50.66857"
"2505.47100","-8.99764","5.44054","121.31641","-0.09428","47.72021"
"2510.27100","-9.00111","6.04542","121.96809","-0.09431","53.02570"
"2515.07100","-9.04478","5.73609","122.53316","-0.09474","50.31249"
"2519.87100","-9.05340","5.77114","123.12639","-0.09483","50.62000"
"2524.67100","-9.10157","5.34251","123.73737","-0.09531","46.86036"
"2529.47100","-9.10461","5.65841","124.35860","-0.09534","49.63122"
"2534.27100","-9.10955","5.80113","124.82153","-0.09539","50.88300"
"2539.07100","-9.13381","5.59874","125.26352","-0.09563","49.10776"
"2543.87100","-9.13569","5.55299","125.43271","-0.09565","48.70650"
"2548.67100","-9.13561","5.48595","125.56443","-0.09565","48.11847"
"2553.47100","-9.13557","5.55196","125.58708","-0.09565","48.69752"
"2558.27100","-9.13551","5.56064","125.53819","-0.09565","48.77362"
"2563.07100","-9.13544","5.51548","125.39468","-0.09565","48.37752"
"2567.87100","-9.13535","5.47202","125.23842","-0.09565","47.99628"
"2572.67100","-9.13512","5.44089","125.09982","-0.09564","47.72329"
"2577.47100","-9.13477","5.50885","124.92939","-0.09564","48.31940"
"2582.27100","-9.13406","5.49228","124.71748","-0.09563","48.17400"
"2587.07100","-9.13177","5.46382","124.53786","-0.09561","47.92442"
"2591.87100","-9.09123","6.04350","124.28774","-0.09521","53.00889"
"2596.67100","-9.09074","5.82952","123.96944","-0.09520","51.13204"
"2601.47100","-9.09075","5.74503","123.53915","-0.09520","50.39098"
"2606.27100","-9.09067","5.58560","123.08976","-0.09520","48.99256"
"2611.07100","-9.07460","5.58531","122.63713","-0.09504","48.99002"
"2615.87100","-9.03270","6.09767","122.05394","-0.09462","53.48406"
"2620.67100","-9.03277","5.91165","121.45648","-0.09463","51.85244"
"2625.47100","-9.03274","5.52414","120.79186","-0.09462","48.45346"
"2630.27100","-9.03257","5.40650","120.06519","-0.09462","47.42164"
"2635.07100","-8.98504","5.81133","119.41082","-0.09415","50.97248"
"2639.87100","-8.98470","5.73713","118.79776","-0.09415","50.32161"
"2644.67100","-8.97943","5.53222","118.06940","-0.09409","48.52431"
"2649.47100","-8.93381","5.96157","117.40585","-0.09364","52.29022"
"2654.27100","-8.93388","5.77728","116.71016","-0.09364","50.67381"
"2659.07100","-8.93389","5.55137","116.08477","-0.09364","48.69233"
"2663.87100","-8.93378","5.49466","115.36207","-0.09364","48.19492"
"2668.67100","-8.91064","5.67459","114.77605","-0.09341","49.77306"
"2673.47100","-8.89560","5.72807","114.22406","-0.09326","50.24220"
"2678.27100","-8.88747","5.46065","113.60089","-0.09318","47.89658"
"2683.07100","-8.84631","6.03150","113.04852","-0.09277","52.90366"
"2687.87100","-8.84623","5.75432","112.53106","-0.09277","50.47240"
"2692.67100","-8.84622","5.58218","111.91105","-0.09277","48.96257"
"2697.47100","-8.84612","5.39166","111.45991","-0.09277","47.29144"
"2702.27100","-8.81402","5.77735","110.98556","-0.09245","50.67445"
"2707.07100","-8.80183","5.64604","110.41161","-0.09233","49.52264"
"2711.87100","-8.80167","5.64658","109.83372","-0.09233","49.52744"
"2716.67100","-8.79132","5.43299","109.41132","-0.09222","47.65394"
"2721.47100","-8.75132","6.07225","108.83872","-0.09182","53.26108"
"2726.27100","-8.75097","5.81234","108.38840","-0.09182","50.98131"
"2731.07100","-8.75096","5.56028","107.92867","-0.09182","48.77045"
"2735.87100","-8.75084","5.58063","107.51301","-0.09182","48.94895"
"2740.67100","-8.72062","5.67214","107.04997","-0.09152","49.75158"
"2745.47100","-8.70332","5.94734","106.58511","-0.09135","52.16541"
"2750.27100","-8.70330","5.64033","106.18280","-0.09135","49.47262"
"2755.07100","-8.70316","5.51089","105.72063","-0.09134","48.33728"
"2759.87100","-8.66920","5.69454","105.28689","-0.09101","49.94808"
"2764.67100","-8.64646","6.05123","104.83851","-0.09078","53.07666"
"2769.47100","-8.64650","5.71271","104.34954","-0.09078","50.10742"
"2774.27100","-8.64645","5.58000","103.93782","-0.09078","48.94345"
"2779.07100","-8.64633","5.58580","103.56618","-0.09078","48.99431"
"2783.87100","-8.60675","5.86576","103.07618","-0.09039","51.44992"
"2788.67100","-8.60562","5.65861","102.67012","-0.09037","49.63297"
"2793.47100","-8.59793","5.54034","102.24135","-0.09030","48.59559"
"2798.27100","-8.55036","6.10497","101.77336","-0.08982","53.54805"
"2803.07100","-8.55015","5.81484","101.35770","-0.08982","51.00326"
"2807.87100","-8.55011","5.51693","100.95806","-0.08982","48.39020"
"2812.67100","-8.54972","5.37531","100.49664","-0.08982","47.14806"
"2817.47100","-8.50906","5.79195","100.04838","-0.08941","50.80251"
"2822.27100","-8.50451","5.68577","99.62160","-0.08937","49.87117"
"2827.07100","-8.46827","5.66267","99.20009","-0.08901","49.66853"
"2831.87100","-8.43532","5.72935","98.62606","-0.08868","50.25344"
"2836.67100","-8.43530","5.67690","98.14027","-0.08868","49.79336"
"2841.47100","-8.43519","5.48159","97.65766","-0.08868","48.08024"
"2846.27100","-8.41053","5.48275","97.09727","-0.08843","48.09046"
"2851.07100","-8.34994","5.82400","96.61610","-0.08783","51.08358"
"2855.87100","-8.32550","5.84125","96.10802","-0.08759","51.23495"
"2860.67100","-8.32544","5.50811","95.44255","-0.08759","48.31291"
"2865.47100","-8.31631","5.11759","94.82912","-0.08749","44.88755"
"2870.27100","-8.15347","5.96667","94.04147","-0.08587","52.33498"
"2875.07100","-8.11797","5.91153","92.98524","-0.08552","51.85138"
"2879.87100","-8.11797","5.70005","92.18261","-0.08552","49.99643"
"2884.67100","-8.11668","4.62760","91.51093","-0.08551","40.58974"
"2889.47100","-7.88101","6.11839","90.26955","-0.08316","53.66574"
"2894.27100","-7.83178","5.76964","88.92920","-0.08267","50.60683"
"2899.07100","-7.83185","5.90169","88.04061","-0.08267","51.76503"
"2903.87100","-7.73031","5.56347","87.07086","-0.08166","48.79841"
"2908.67100","-7.60513","6.86428","85.91920","-0.08042","60.20812"
"2913.47100","-7.60478","4.92352","85.17223","-0.08041","43.18533"
"2918.27100","-7.54615","5.81570","84.10636","-0.07983","51.01078"
"2923.07100","-7.47129","5.63854","83.23581","-0.07908","49.45687"
"2927.87100","-7.40716","4.75577","82.58872","-0.07845","41.71392"
"2932.67100","-7.18759","6.68480","81.62524","-0.07626","58.63384"
"2937.47100","-7.04822","4.94117","80.58781","-0.07487","43.34013"
"2942.27100","-6.92915","4.75471","79.57994","-0.07369","41.70465"
"2947.07100","-6.75039","5.49895","78.64722","-0.07191","48.23255"
"2951.87100","-6.61606","5.96974","77.63899","-0.07057","52.36194"
"2956.67100","-6.48328","6.13490","76.88580","-0.06925","53.81055"
"2961.47100","-6.28191","6.73291","76.03475","-0.06725","59.05588"
"2966.27100","-6.14199","6.92181","75.27318","-0.06585","60.71276"
"2971.07100","-6.00217","6.36956","74.56860","-0.06446","55.86880"
"2975.87100","-5.82825","6.75181","73.97858","-0.06273","59.22167"
"2980.67100","-5.52248","6.72696","73.24449","-0.05969","59.00368"
"2985.47100","-5.21565","7.18928","72.49887","-0.05663","63.05875"
"2990.27100","-5.20099","6.11190","72.18832","-0.05649","53.60888"
"2995.07100","-5.14630","5.32117","71.76540","-0.05594","46.67314"
"2999.87100","-5.02637","4.09353","71.21392","-0.05475","35.90528"
"3004.67100","-4.66694","4.53091","70.47885","-0.05117","39.74160"
"3009.47100","-4.07205","5.25267","69.59908","-0.04525","46.07235"
"3014.27100","-3.72350","4.74932","68.74572","-0.04178","41.65736"
"3019.07100","-3.28099","4.18622","67.89043","-0.03738","36.71826"
"3023.87100","-2.74804","5.51384","66.95003","-0.03207","48.36316"
"3028.67100","-2.54747","5.02159","66.28924","-0.03008","44.04548"
"3033.47100","-2.47166","4.63814","65.84551","-0.02932","40.68219"
"3038.27100","-2.31525","4.40198","65.40385","-0.02777","38.61076"
"3043.07100","-2.06020","4.86953","64.75777","-0.02523","42.71174"
"3047.87100","-1.84966","4.75422","64.01971","-0.02313","41.70031"
"3052.67100","-1.70359","4.68634","63.60544","-0.02168","41.10493"
"3057.47100","-1.54994","4.99558","63.15363","-0.02015","43.81737"
"3062.27100","-1.43565","4.87495","62.63160","-0.01901","42.75929"
"3067.07100","-1.35436","5.43743","62.20082","-0.01820","47.69291"
"3071.87100","-1.34104","5.29839","61.83997","-0.01807","46.47335"
"3076.67100","-1.28074","5.92473","61.40381","-0.01747","51.96710"
"3081.47100","-1.22420","6.22637","61.01074","-0.01691","54.61284"
"3086.27100","-1.08264","5.14678","60.59270","-0.01550","45.14357"
"3091.07100","-0.83369","4.19081","59.82943","-0.01302","36.75849"
"3095.87100","-0.24194","7.77344","58.09466","-0.00713","68.18256"
"3100.67100","-0.19923","6.82725","56.68916","-0.00671","59.88329"
"3105.47100","-0.19937","6.59109","55.86755","-0.00671","57.81194"
"3110.27100","-0.19949","6.52386","55.27367","-0.00671","57.22227"
"3115.07100","-0.19926","5.76599","54.74981","-0.00671","50.57480"
"3119.87100","-0.10975","6.19333","53.84431","-0.00582","54.32308"
"3124.67100","0.05038","6.94455","52.96038","-0.00422","60.91224"
"3129.47100","0.07308","6.42929","52.30728","-0.00400","56.39271"
"3134.27100","0.10314","6.16059","51.43419","-0.00370","54.03589"
"3139.07100","0.11352","5.46476","50.90163","-0.00359","47.93262"
"3143.87100","0.15374","5.22210","50.58365","-0.00319","45.80417"
"3148.67100","0.20089","4.81189","50.15388","-0.00272","42.20617"
"3153.47100","0.27342","5.07536","49.17728","-0.00200","44.51710"
"3158.27100","0.30325","5.39184","48.51418","-0.00171","47.29299"
"3163.07100","0.33629","5.90881","47.84510","-0.00138","51.82747"
"3167.87100","0.37988","6.75389","46.96143","-0.00094","59.23984"
"3172.67100","0.38829","6.13995","46.53147","-0.00086","53.85484"
"3177.47100","0.39565","5.71741","45.98467","-0.00079","50.14870"
"3182.27100","0.40358","4.88615","45.65721","-0.00071","42.85748"
"3187.07100","0.47689","5.26234","45.09158","0.00002","46.15715"
"3191.87100","0.49235","5.11997","44.57595","0.00018","44.90842"
"3196.67100","0.50276","5.19000","43.70305","0.00028","45.52269"
"3201.47100","0.58554","6.24254","42.97020","0.00110","54.75473"
"3206.27100","0.59390","6.36967","42.30712","0.00119","55.86976"
"3211.07100","0.59480","6.10180","41.84555","0.00120","53.52023"
"3215.87100","0.61257","5.93924","41.14138","0.00137","52.09438"
"3220.67100","0.66595","5.99162","40.36737","0.00190","52.55387"
"3225.47100","0.66602","5.17916","40.00681","0.00190","45.42761"
"3230.27100","0.66613","4.90413","39.38711","0.00191","43.01519"
"3235.07100","0.66745","4.74875","38.87914","0.00192","41.65237"
"3239.87100","0.70252","5.54369","38.30302","0.00227","48.62495"
"3244.67100","0.77902","6.38176","37.53001","0.00303","55.97586"
"3249.47100","0.77968","6.50951","36.93624","0.00304","57.09639"
"3254.27100","0.77961","6.29975","36.52409","0.00304","55.25654"
"3259.07100","0.77963","5.97499","35.88010","0.00304","52.40799"
"3263.87100","0.77981","5.69038","35.09547","0.00304","49.91161"
"3268.67100","0.78473","5.29363","34.59532","0.00309","46.43166"
"3273.47100","0.86612","5.89222","34.15148","0.00390","51.68195"
"3278.27100","0.86652","5.19160","33.63851","0.00390","45.53669"
"3283.07100","0.86745","4.84858","32.72094","0.00391","42.52794"
"3287.87100","0.86994","5.17259","32.28363","0.00393","45.36995"
"3292.67100","0.87605","5.53708","31.53410","0.00399","48.56700"
"3297.47100","0.88701","6.24150","30.99618","0.00410","54.74562"
"3302.27100","0.89516","6.30807","30.86859","0.00419","55.32950"
"3307.07100","0.89565","5.95505","31.06128","0.00419","52.23304"
"3311.87100","0.89560","5.55370","31.06005","0.00419","48.71279"
"3316.67100","0.89555","5.42051","31.17787","0.00419","47.54452"
"3321.47100","0.89549","5.69488","31.00788","0.00419","49.95107"
"3326.27100","0.89542","6.19005","30.90603","0.00419","54.29436"
"3331.07100","0.89538","6.18739","30.62727","0.00419","54.27098"
"3335.87100","0.89535","5.92327","30.70912","0.00419","51.95429"
"3340.67100","0.89535","5.53114","30.67607","0.00419","48.51483"
"3345.47100","0.89536","5.19578","30.62666","0.00419","45.57335"
"3350.27100","0.89532","5.75871","30.48640","0.00419","50.51089"
"3355.07100","0.89524","6.29901","30.65550","0.00419","55.25003"
"3359.87100","0.89509","6.26020","30.70395","0.00418","54.90963"
"3364.67100","0.89485","6.14052","30.95164","0.00418","53.85989"
"3369.47100","0.89380","6.04241","31.60843","0.00417","52.99931"
"3374.27100","0.88743","5.65719","32.12677","0.00411","49.62045"
"3379.07100","0.85280","5.22886","32.45454","0.00376","45.86349"
"3383.87100","0.83716","5.36980","32.84738","0.00361","47.09972"
"3388.67100","0.83239","5.37969","33.26552","0.00356","47.18648"
"3393.47100","0.82616","5.55181","33.66147","0.00350","48.69615"
"3398.27100","0.82121","5.72635","34.19183","0.00345","50.22711"
"3403.07100","0.81960","5.86152","34.69279","0.00343","51.41267"
"3407.87100","0.81499","5.52573","35.02967","0.00339","48.46740"
"3412.67100","0.81056","5.49969","35.47480","0.00334","48.23900"
"3417.47100","0.80382","5.42148","36.01738","0.00328","47.55303"
"3422.27100","0.77759","5.30839","36.50061","0.00301","46.56108"
"3427.07100","0.77728","5.82445","36.98112","0.00301","51.08755"
"3431.87100","0.77726","5.84930","37.32188","0.00301","51.30550"
"3436.67100","0.77705","5.79830","37.80746","0.00301","50.85818"
"3441.47100","0.77250","5.50581","38.48637","0.00296","48.29271"
"3446.27100","0.75589","5.91180","38.77592","0.00280","51.85370"
"3451.07100","0.73148","5.34390","39.22374","0.00256","46.87257"
"3455.87100","0.73149","5.68329","39.84186","0.00256","49.84940"
"3460.67100","0.73154","5.44842","40.27058","0.00256","47.78933"
"3465.47100","0.73152","5.89521","40.55543","0.00256","51.70819"
"3470.27100","0.73146","5.96820","41.15696","0.00256","52.34846"
"3475.07100","0.73059","5.99969","41.76366","0.00255","52.62460"
"3479.87100","0.72482","5.75649","41.88429","0.00249","50.49143"
"3484.67100","0.67729","5.37273","42.24433","0.00202","47.12542"
"3489.47100","0.67070","5.42492","42.79126","0.00195","47.58318"
"3494.27100","0.65634","5.35419","43.27736","0.00181","46.96282"
"3499.07100","0.65657","5.38368","43.74672","0.00181","47.22143"
"3503.87100","0.65691","5.47997","44.25252","0.00181","48.06600"
"3508.67100","0.65699","5.77875","44.78741","0.00181","50.68674"
"3513.47100","0.65692","5.97215","45.38610","0.00181","52.38309"
"3518.27100","0.65671","6.17462","46.08712","0.00181","54.15897"
"3523.07100","0.64371","6.15718","46.81842","0.00168","54.00603"
"3527.87100","0.56408","5.31277","47.55157","0.00089","46.59948"
"3532.67100","0.56384","5.46035","48.45527","0.00089","47.89392"
"3537.47100","0.56389","5.71379","49.24413","0.00089","50.11691"
"3542.27100","0.56383","5.91214","50.08015","0.00089","51.85671"
"3547.07100","0.56363","6.11408","50.84121","0.00089","53.62793"
"3551.87100","0.49361","5.41114","51.73622","0.00019","47.46236"
"3556.67100","0.48090","5.36183","52.47227","0.00006","47.02979"
"3561.47100","0.48099","5.62506","53.20881","0.00006","49.33868"
"3566.27100","0.48096","5.77488","54.03732","0.00006","50.65276"
"3571.07100","0.48083","5.93549","54.80367","0.00006","52.06149"
"3575.87100","0.45906","5.85361","55.48497","-0.00016","51.34334"
"3580.67100","0.39268","5.24103","56.29352","-0.00082","45.97028"
"3585.47100","0.39249","5.45638","56.98384","-0.00082","47.85909"
"3590.27100","0.39255","5.65754","57.64420","-0.00082","49.62356"
"3595.07100","0.39249","5.85065","58.35973","-0.00082","51.31732"
"3599.87100","0.39229","6.01496","58.99625","-0.00082","52.75858"
"3604.67100","0.34275","5.56606","59.63026","-0.00131","48.82112"
"3609.47100","0.30441","5.46704","60.31749","-0.00169","47.95259"
"3614.27100","0.29808","5.63939","60.91618","-0.00176","49.46431"
"3619.07100","0.29806","5.78466","61.55025","-0.00176","50.73851"
"3623.87100","0.29782","6.05824","62.19178","-0.00176","53.13817"
"3627.04000","0.26569","5.74290","62.67406","-0.00208","50.37222"