File: experimental/sma_database/flexinol_monotonic_loading_austenite.csv
Time,Extension,Load,Tensile strain (Extension),Temperature: Chamber 3119-600 1 1,Tensile stress
(s),(mm),(N),(mm/mm),(C),(MPa)
"0.00000","1.13561","0.49182","0.00000","120.27256","4.31384"
"0.40000","1.14149","0.58519","0.00006","120.27256","5.13282"
"0.80000","1.14823","0.68382","0.00012","120.27122","5.99791"
"1.20000","1.15514","0.79863","0.00019","120.26595","7.00499"
"1.60000","1.16164","0.94781","0.00026","120.26595","8.31347"
"2.00000","1.16812","1.07317","0.00032","120.26151","9.41302"
"2.40000","1.17478","1.19029","0.00039","120.25546","10.44031"
"2.80000","1.18142","1.28635","0.00045","120.24613","11.28287"
"3.20000","1.18834","1.42203","0.00052","120.24613","12.47296"
"3.60000","1.19501","1.58526","0.00059","120.24038","13.90466"
"4.00000","1.20159","1.68334","0.00065","120.22961","14.76494"
"4.40000","1.20810","1.82446","0.00072","120.22040","16.00274"
"4.80000","1.21476","1.96095","0.00078","120.22040","17.19997"
"5.20000","1.22158","2.08028","0.00085","120.20921","18.24657"
"5.60000","1.22852","2.23857","0.00092","120.19996","19.63501"
"6.00000","1.23500","2.37964","0.00098","120.19996","20.87238"
"6.40000","1.24139","2.50270","0.00105","120.19564","21.95178"
"6.80000","1.24809","2.64251","0.00111","120.19439","23.17803"
"7.20000","1.25478","2.76902","0.00118","120.19784","24.28773"
"7.60000","1.26162","2.88832","0.00125","120.19784","25.33408"
"8.00000","1.26838","3.03747","0.00131","120.20056","26.64229"
"8.40000","1.27500","3.18856","0.00138","120.20350","27.96760"
"8.80000","1.28142","3.31533","0.00144","120.20737","29.07949"
"9.20000","1.28802","3.45467","0.00151","120.20737","30.30172"
"9.60000","1.29476","3.60607","0.00157","120.21482","31.62960"
"10.00000","1.30159","3.72834","0.00164","120.22543","32.70208"
"10.40000","1.30850","3.88518","0.00171","120.22543","34.07780"
"10.80000","1.31501","4.02222","0.00177","120.23043","35.27976"
"11.20000","1.32154","4.15996","0.00184","120.23513","36.48794"
"11.60000","1.32805","4.28840","0.00190","120.24007","37.61452"
"12.00000","1.33478","4.40959","0.00197","120.24007","38.67747"
"12.40000","1.34171","4.57008","0.00204","120.24559","40.08520"
"12.80000","1.34850","4.70939","0.00210","120.24286","41.30708"
"13.20000","1.35493","4.84459","0.00217","120.24286","42.49295"
"13.60000","1.36135","4.99260","0.00223","120.24387","43.79121"
"14.00000","1.36811","5.13837","0.00230","120.24191","45.06978"
"14.40000","1.37486","5.27808","0.00237","120.23454","46.29522"
"14.80000","1.38172","5.41037","0.00243","120.23454","47.45554"
"15.20000","1.38822","5.55348","0.00250","120.22333","48.71078"
"15.60000","1.39486","5.70815","0.00256","120.21558","50.06744"
"16.00000","1.40149","5.82623","0.00263","120.21558","51.10320"
"16.40000","1.40814","5.98153","0.00269","120.20944","52.46530"
"16.80000","1.41499","6.14352","0.00276","120.20231","53.88618"
"17.20000","1.42169","6.29658","0.00283","120.19624","55.22870"
"17.60000","1.42828","6.42649","0.00289","120.19624","56.36817"
"18.00000","1.43479","6.56318","0.00296","120.18702","57.56713"
"18.40000","1.44147","6.70952","0.00302","120.18191","58.85068"
"18.80000","1.44817","6.82393","0.00309","120.17528","59.85419"
"19.20000","1.45488","6.98345","0.00316","120.17528","61.25344"
"19.60000","1.46179","7.11390","0.00323","120.16809","62.39760"
"20.00000","1.46833","7.24119","0.00329","120.16388","63.51412"
"20.40000","1.47476","7.42878","0.00335","120.16388","65.15948"
"20.80000","1.48128","7.54942","0.00342","120.16159","66.21764"
"21.20000","1.48811","7.70470","0.00349","120.16053","67.57969"
"21.60000","1.49504","7.84876","0.00355","120.16261","68.84319"
"22.00000","1.50190","7.99406","0.00362","120.16261","70.11768"
"22.40000","1.50826","8.12078","0.00368","120.16440","71.22921"
"22.80000","1.51475","8.24042","0.00375","120.16644","72.27856"
"23.20000","1.52141","8.37152","0.00381","120.16644","73.42845"
"23.60000","1.52818","8.50759","0.00388","120.17125","74.62197"
"24.00000","1.53513","8.64983","0.00395","120.17694","75.86958"
"24.40000","1.54168","8.83283","0.00402","120.18275","77.47469"
"24.80000","1.54813","8.93139","0.00408","120.18275","78.33922"
"25.20000","1.55475","9.10026","0.00414","120.18655","79.82040"
"25.60000","1.56149","9.17385","0.00421","120.17867","80.46589"
"26.00000","1.56825","9.30814","0.00428","120.17429","81.64375"
"26.40000","1.57493","9.49033","0.00434","120.17429","83.24184"
"26.80000","1.58163","9.57559","0.00441","120.16969","83.98969"
"27.20000","1.58819","9.74003","0.00447","120.16628","85.43198"
"27.60000","1.59482","9.85252","0.00454","120.16628","86.41862"
"28.00000","1.60145","9.99455","0.00461","120.16010","87.66447"
"28.40000","1.60827","10.16176","0.00467","120.15458","89.13109"
"28.80000","1.61517","10.28750","0.00474","120.15211","90.23399"
"29.20000","1.62168","10.45109","0.00481","120.15211","91.66886"
"29.60000","1.62805","10.56968","0.00487","120.15421","92.70907"
"30.00000","1.63465","10.74123","0.00493","120.16063","94.21371"
"30.40000","1.64143","10.91681","0.00500","120.16096","95.75378"
"30.80000","1.64840","11.04754","0.00507","120.16096","96.90044"
"31.20000","1.65522","11.18017","0.00514","120.15954","98.06378"
"31.60000","1.66148","11.27849","0.00520","120.16325","98.92615"
"32.00000","1.66800","11.40900","0.00526","120.16325","100.07089"
"32.40000","1.67471","11.52597","0.00533","120.16199","101.09686"
"32.80000","1.68159","11.66465","0.00540","120.16190","102.31326"
"33.20000","1.68847","11.79553","0.00547","120.16091","103.46123"
"33.60000","1.69500","11.92830","0.00553","120.16091","104.62579"
"34.00000","1.70160","12.07543","0.00560","120.15384","105.91634"
"34.40000","1.70818","12.18468","0.00566","120.14389","106.87454"
"34.80000","1.71477","12.34020","0.00573","120.14240","108.23867"
"35.20000","1.72154","12.47647","0.00579","120.14240","109.43394"
"35.60000","1.72833","12.63611","0.00586","120.14144","110.83418"
"36.00000","1.73504","12.78808","0.00593","120.13938","112.16708"
"36.40000","1.74156","12.88563","0.00599","120.13938","113.02271"
"36.80000","1.74810","12.99824","0.00606","120.13695","114.01048"
"37.20000","1.75471","13.14033","0.00612","120.13582","115.25677"
"37.60000","1.76156","13.28667","0.00619","120.13443","116.54033"
"38.00000","1.76841","13.40323","0.00626","120.13443","117.56269"
"38.40000","1.77495","13.55997","0.00632","120.13814","118.93751"
"38.80000","1.78141","13.69602","0.00639","120.14255","120.13084"
"39.20000","1.78804","13.81522","0.00645","120.14255","121.17642"
"39.60000","1.79484","13.96967","0.00652","120.14330","122.53107"
"40.00000","1.80176","14.09232","0.00659","120.14493","123.60690"
"40.40000","1.80847","14.21251","0.00665","120.14915","124.66106"
"40.80000","1.81485","14.35634","0.00672","120.14915","125.92266"
"41.20000","1.82135","14.47791","0.00678","120.15324","126.98901"
"41.60000","1.82806","14.61843","0.00685","120.15599","128.22153"
"42.00000","1.83490","14.74183","0.00691","120.16094","129.30392"
"42.40000","1.84174","14.91437","0.00698","120.16094","130.81728"
"42.80000","1.84836","15.03211","0.00705","120.16166","131.85001"
"43.20000","1.85482","15.16945","0.00711","120.16109","133.05460"
"43.60000","1.86141","15.27910","0.00718","120.16109","134.01636"
"44.00000","1.86806","15.39163","0.00724","120.16376","135.00342"
"44.40000","1.87485","15.50909","0.00731","120.16645","136.03368"
"44.80000","1.88165","15.64792","0.00738","120.16635","137.25140"
"45.20000","1.88846","15.76706","0.00744","120.16635","138.29639"
"45.60000","1.89499","15.88702","0.00751","120.16775","139.34859"
"46.00000","1.90146","16.01725","0.00757","120.16649","140.49092"
"46.40000","1.90802","16.12587","0.00764","120.16364","141.44360"
"46.80000","1.91482","16.29388","0.00770","120.16364","142.91730"
"47.20000","1.92179","16.41843","0.00777","120.16023","144.00975"
"47.60000","1.92843","16.54702","0.00784","120.16080","145.13759"
"48.00000","1.93478","16.68980","0.00790","120.16080","146.38994"
"48.40000","1.94137","16.76693","0.00797","120.16433","147.06645"
"48.80000","1.94808","16.92707","0.00803","120.16620","148.47108"
"49.20000","1.95508","17.03874","0.00810","120.16467","149.45056"
"49.60000","1.96173","17.17903","0.00817","120.16467","150.68112"
"50.00000","1.96813","17.29277","0.00823","120.16409","151.67879"
"50.40000","1.97468","17.42453","0.00830","120.16876","152.83443"
"50.80000","1.98148","17.54534","0.00836","120.17191","153.89409"
"51.20000","1.98827","17.68377","0.00843","120.17191","155.10832"
"51.60000","1.99511","17.77902","0.00850","120.17574","155.94377"
"52.00000","2.00166","17.91172","0.00856","120.18245","157.10770"
"52.40000","2.00819","18.02241","0.00863","120.18719","158.07861"
"52.80000","2.01479","18.15003","0.00869","120.18719","159.19797"
"53.20000","2.02137","18.25220","0.00876","120.19113","160.09418"
"53.60000","2.02817","18.39317","0.00883","120.19514","161.33063"
"54.00000","2.03499","18.48601","0.00889","120.19514","162.14496"
"54.40000","2.04181","18.61254","0.00896","120.19121","163.25473"
"54.80000","2.04824","18.72196","0.00902","120.18954","164.21449"
"55.20000","2.05471","18.88190","0.00909","120.18675","165.61734"
"55.60000","2.06134","18.99745","0.00915","120.18675","166.63086"
"56.00000","2.06820","19.12265","0.00922","120.18459","167.72905"
"56.40000","2.07520","19.27227","0.00929","120.18453","169.04143"
"56.80000","2.08176","19.37798","0.00936","120.18546","169.96863"
"57.20000","2.08817","19.50495","0.00942","120.18546","171.08228"
"57.60000","2.09476","19.60374","0.00948","120.18784","171.94879"
"58.00000","2.10146","19.72635","0.00955","120.18483","173.02423"
"58.40000","2.10834","19.82944","0.00962","120.18483","173.92850"
"58.80000","2.11504","19.94927","0.00968","120.18333","174.97952"
"59.20000","2.12152","20.06733","0.00975","120.18084","176.01506"
"59.60000","2.12813","20.21479","0.00981","120.18121","177.30844"
"60.00000","2.13477","20.33072","0.00988","120.18121","178.32529"
"60.40000","2.14154","20.48716","0.00995","120.18389","179.69745"
"60.80000","2.14834","20.57689","0.01001","120.18968","180.48453"
"61.20000","2.15497","20.65307","0.01008","120.18968","181.15268"
"61.60000","2.16148","20.81764","0.01014","120.19927","182.59619"
"62.00000","2.16811","20.91439","0.01021","120.20786","183.44478"
"62.40000","2.17480","21.03546","0.01028","120.21388","184.50670"
"62.80000","2.18152","21.11427","0.01034","120.21388","185.19801"
"63.20000","2.18846","21.24535","0.01041","120.21734","186.34772"
"63.60000","2.19516","21.37776","0.01048","120.22086","187.50908"
"64.00000","2.20156","21.48156","0.01054","120.21828","188.41953"
"64.40000","2.20794","21.56249","0.01060","120.21828","189.12946"
"64.80000","2.21468","21.66830","0.01067","120.21729","190.05750"
"65.20000","2.22162","21.79924","0.01074","120.21106","191.20604"
"65.60000","2.22852","21.97521","0.01081","120.21106","192.74950"
"66.00000","2.23501","22.07946","0.01087","120.20621","193.66391"
"66.40000","2.24140","22.16282","0.01093","120.20267","194.39510"
"66.80000","2.24803","22.28686","0.01100","120.20602","195.48306"
"67.20000","2.25474","22.40684","0.01107","120.20602","196.53537"
"67.60000","2.26163","22.54327","0.01113","120.21007","197.73204"
"68.00000","2.26846","22.62602","0.01120","120.20934","198.45786"
"68.40000","2.27492","22.72865","0.01127","120.21500","199.35811"
"68.80000","2.28148","22.83279","0.01133","120.21500","200.27150"
"69.20000","2.28816","22.92959","0.01140","120.21743","201.12059"
"69.60000","2.29486","23.03967","0.01146","120.21711","202.08614"
"70.00000","2.30162","23.16434","0.01153","120.21711","203.17958"
"70.40000","2.30835","23.31697","0.01160","120.21561","204.51839"
"70.80000","2.31495","23.40068","0.01166","120.21461","205.25259"
"71.20000","2.32154","23.52604","0.01173","120.20801","206.35217"
"71.60000","2.32803","23.63660","0.01179","120.20801","207.32191"
"72.00000","2.33480","23.74333","0.01186","120.20351","208.25806"
"72.40000","2.34173","23.83528","0.01193","120.20170","209.06461"
"72.80000","2.34836","23.91333","0.01199","120.19963","209.74913"
"73.20000","2.35478","24.01619","0.01205","120.19963","210.65135"
"73.60000","2.36133","24.12550","0.01212","120.19637","211.61018"
"74.00000","2.36811","24.22081","0.01219","120.19505","212.44615"
"74.40000","2.37489","24.28228","0.01225","120.19150","212.98532"
"74.80000","2.38185","24.40782","0.01232","120.19150","214.08644"
"75.20000","2.38840","24.52280","0.01239","120.18221","215.09492"
"75.60000","2.39479","24.61898","0.01245","120.17342","215.93861"
"76.00000","2.40137","24.67899","0.01252","120.17342","216.46494"
"76.40000","2.40810","24.81047","0.01258","120.16478","217.61818"
"76.80000","2.41501","24.88879","0.01265","120.14971","218.30518"
"77.20000","2.42180","24.97966","0.01272","120.14572","219.10219"
"77.60000","2.42828","25.05960","0.01278","120.14572","219.80338"
"78.00000","2.43480","25.14591","0.01285","120.14275","220.56036"
"78.40000","2.44139","25.21241","0.01291","120.13971","221.14369"
"78.80000","2.44809","25.32019","0.01298","120.13971","222.08908"
"79.20000","2.45486","25.45603","0.01304","120.13673","223.28055"
"79.60000","2.46178","25.56893","0.01311","120.13337","224.27078"
"80.00000","2.46836","25.68142","0.01318","120.13486","225.25748"
"80.40000","2.47484","25.77758","0.01324","120.13486","226.10089"
"80.80000","2.48144","25.82729","0.01331","120.14063","226.53693"
"81.20000","2.48811","25.94946","0.01337","120.14795","227.60855"
"81.60000","2.49506","26.01313","0.01344","120.14795","228.16701"
"82.00000","2.50174","26.09130","0.01351","120.15787","228.85262"
"82.40000","2.50823","26.16534","0.01357","120.16916","229.50203"
"82.80000","2.51474","26.25209","0.01364","120.17326","230.26292"
"83.20000","2.52145","26.37723","0.01370","120.17326","231.36060"
"83.60000","2.52823","26.43377","0.01377","120.17459","231.85648"
"84.00000","2.53507","26.49227","0.01384","120.17517","232.36961"
"84.40000","2.54165","26.58428","0.01390","120.17519","233.17670"
"84.80000","2.54803","26.71637","0.01397","120.17519","234.33527"
"85.20000","2.55475","26.80853","0.01403","120.17282","235.14359"
"85.60000","2.56149","26.93781","0.01410","120.16729","236.27753"
"86.00000","2.56837","26.98959","0.01417","120.16729","236.73177"
"86.40000","2.57513","27.09042","0.01423","120.16344","237.61612"
"86.80000","2.58162","27.16525","0.01430","120.16311","238.27252"
"87.20000","2.58817","27.24861","0.01436","120.15825","239.00368"
"87.60000","2.59474","27.35470","0.01443","120.15825","239.93422"
"88.00000","2.60144","27.41882","0.01449","120.15569","240.49658"
"88.40000","2.60827","27.49862","0.01456","120.15289","241.19652"
"88.80000","2.61513","27.60362","0.01463","120.15182","242.11752"
"89.20000","2.62165","27.67614","0.01469","120.15182","242.75359"
"89.60000","2.62813","27.77690","0.01476","120.14854","243.63742"
"90.00000","2.63468","27.85269","0.01482","120.14672","244.30215"
"90.40000","2.64141","27.95584","0.01489","120.14314","245.20691"
"90.80000","2.64834","28.02802","0.01496","120.14314","245.84007"
"91.20000","2.65512","28.04898","0.01502","120.14133","246.02391"
"91.60000","2.66161","28.14157","0.01509","120.14278","246.83604"
"92.00000","2.66808","28.25750","0.01515","120.14278","247.85286"
"92.40000","2.67479","28.28348","0.01522","120.14127","248.08070"
"92.80000","2.68158","28.38210","0.01529","120.13759","248.94572"
"93.20000","2.68846","28.49200","0.01535","120.13596","249.90974"
"93.60000","2.69493","28.56418","0.01542","120.13596","250.54285"
"94.00000","2.70145","28.61964","0.01548","120.13523","251.02928"
"94.40000","2.70812","28.74066","0.01555","120.13812","252.09079"
"94.80000","2.71479","28.79228","0.01561","120.13812","252.54356"
"95.20000","2.72163","28.87710","0.01568","120.14123","253.28754"
"95.60000","2.72835","28.95325","0.01575","120.14342","253.95543"
"96.00000","2.73487","29.09745","0.01581","120.14436","255.22021"
"96.40000","2.74143","29.17884","0.01588","120.14436","255.93413"
"96.80000","2.74807","29.23818","0.01594","120.13950","256.45462"
"97.20000","2.75479","29.32536","0.01601","120.13483","257.21933"
"97.60000","2.76169","29.41172","0.01608","120.13483","257.97678"
"98.00000","2.76847","29.49648","0.01615","120.13137","258.72025"
"98.40000","2.77497","29.57742","0.01621","120.13241","259.43015"
"98.80000","2.78141","29.66145","0.01627","120.13565","260.16718"
"99.20000","2.78804","29.75603","0.01634","120.13565","260.99677"
"99.60000","2.79479","29.79994","0.01641","120.13708","261.38193"
"100.00000","2.80171","29.89602","0.01647","120.14029","262.22464"
"100.40000","2.80846","29.98142","0.01654","120.14246","262.97372"
"100.80000","2.81489","30.07676","0.01660","120.14246","263.80994"
"101.20000","2.82137","30.16173","0.01667","120.14199","264.55530"
"101.60000","2.82807","30.18824","0.01673","120.14556","264.78778"
"102.00000","2.83488","30.28448","0.01680","120.14556","265.63190"
"102.40000","2.84175","30.36852","0.01687","120.14531","266.36905"
"102.80000","2.84827","30.44304","0.01693","120.14546","267.02267"
"103.20000","2.85487","30.52142","0.01700","120.14406","267.71017"
"103.60000","2.86150","30.57649","0.01707","120.14406","268.19324"
"104.00000","2.86820","30.67565","0.01713","120.14736","269.06302"
"104.40000","2.87499","30.72054","0.01720","120.15335","269.45670"
"104.80000","2.88160","30.77006","0.01726","120.15903","269.89111"
"105.20000","2.88825","30.85478","0.01733","120.15903","270.63416"
"105.60000","2.89481","30.94055","0.01739","120.16511","271.38651"
"106.00000","2.90149","31.01260","0.01746","120.17352","272.01846"
"106.40000","2.90816","31.09662","0.01753","120.17352","272.75537"
"106.80000","2.91487","31.14474","0.01759","120.17610","273.17746"
"107.20000","2.92175","31.25460","0.01766","120.17570","274.14111"
"107.60000","2.92829","31.34097","0.01773","120.17310","274.89865"
"108.00000","2.93473","31.41838","0.01779","120.17310","275.57764"
"108.40000","2.94129","31.46383","0.01785","120.17345","275.97629"
"108.80000","2.94817","31.52818","0.01792","120.17651","276.54068"
"109.20000","2.95512","31.59025","0.01799","120.17864","277.08514"
"109.60000","2.96187","31.62673","0.01806","120.17864","277.40515"
"110.00000","2.96820","31.69913","0.01812","120.17745","278.04016"
"110.40000","2.97468","31.78382","0.01818","120.17955","278.78299"
"110.80000","2.98140","31.80798","0.01825","120.17955","278.99490"
"111.20000","2.98821","31.86111","0.01832","120.18510","279.46097"
"111.60000","2.99511","31.91150","0.01839","120.19408","279.90286"
"112.00000","3.00164","32.04187","0.01845","120.19977","281.04639"
"112.40000","3.00812","32.06623","0.01851","120.19977","281.26007"
"112.80000","3.01479","32.17756","0.01858","120.20213","282.23657"
"113.20000","3.02148","32.22553","0.01865","120.19969","282.65732"
"113.60000","3.02818","32.30484","0.01871","120.19395","283.35297"
"114.00000","3.03494","32.41762","0.01878","120.19395","284.34219"
"114.40000","3.04166","32.49416","0.01885","120.19139","285.01358"
"114.80000","3.04826","32.57973","0.01891","120.18602","285.76407"
"115.20000","3.05482","32.66440","0.01898","120.18602","286.50674"
"115.60000","3.06143","32.74606","0.01904","120.17414","287.22305"
"116.00000","3.06830","32.84558","0.01911","120.16670","288.09589"
"116.40000","3.07513","32.95853","0.01918","120.15685","289.08664"
"116.80000","3.08153","33.00563","0.01924","120.15685","289.49979"
"117.20000","3.08806","33.06950","0.01931","120.14785","290.05997"
"117.60000","3.09475","33.17770","0.01937","120.13882","291.00900"
"118.00000","3.10148","33.25698","0.01944","120.12878","291.70441"
"118.40000","3.10838","33.34613","0.01951","120.12878","292.48639"
"118.80000","3.11513","33.38934","0.01957","120.12256","292.86536"
"119.20000","3.12146","33.44645","0.01964","120.12299","293.36633"
"119.60000","3.12800","33.53069","0.01970","120.12299","294.10513"
"120.00000","3.13475","33.57906","0.01977","120.12392","294.52945"
"120.40000","3.14162","33.65429","0.01983","120.12637","295.18930"
"120.80000","3.14844","33.71540","0.01990","120.13083","295.72528"
"121.20000","3.15500","33.79580","0.01997","120.13083","296.43054"
"121.60000","3.16159","33.87386","0.02003","120.13524","297.11523"
"122.00000","3.16810","33.96432","0.02010","120.13435","297.90869"
"122.40000","3.17475","34.05857","0.02016","120.13570","298.73538"
"122.80000","3.18152","34.12635","0.02023","120.13570","299.32980"
"123.20000","3.18841","34.16777","0.02030","120.13737","299.69312"
"123.41500","3.19087","34.19798","0.02032","120.13737","299.95813"
"123.81500","3.18268","34.00175","0.02024","120.13584","298.23697"
"124.21500","3.17626","33.85338","0.02018","120.13226","296.93555"
"124.61500","3.16933","33.71617","0.02011","120.12221","295.73209"
"125.01500","3.16271","33.55927","0.02004","120.12221","294.35580"
"125.41500","3.15628","33.38397","0.01998","120.12022","292.81830"
"125.81500","3.14958","33.29349","0.01991","120.12194","292.02466"
"126.21500","3.14283","33.12576","0.01985","120.12268","290.55347"
"126.61500","3.13611","32.98513","0.01978","120.12268","289.31998"
"127.01500","3.12941","32.88052","0.01971","120.12376","288.40234"
"127.41500","3.12283","32.71005","0.01965","120.12544","286.90720"
"127.81500","3.11626","32.62452","0.01958","120.12544","286.15695"
"128.21500","3.10965","32.39811","0.01952","120.12720","284.17102"
"128.61500","3.10299","32.30054","0.01945","120.12581","283.31531"
"129.01500","3.09608","32.14798","0.01938","120.12296","281.97708"
"129.41500","3.08933","32.01908","0.01932","120.12296","280.84650"
"129.81500","3.08288","31.88863","0.01925","120.11615","279.70227"
"130.21500","3.07635","31.72996","0.01919","120.11062","278.31055"
"130.61500","3.06968","31.61266","0.01912","120.10892","277.28168"
"131.01500","3.06290","31.46404","0.01906","120.10892","275.97818"
"131.41500","3.05599","31.33051","0.01899","120.10744","274.80695"
"131.81500","3.04923","31.22957","0.01892","120.10719","273.92154"
"132.21500","3.04290","31.08826","0.01886","120.10719","272.68210"
"132.61500","3.03636","30.99096","0.01879","120.10257","271.82864"
"133.01500","3.02969","30.88401","0.01873","120.10023","270.89059"
"133.41500","3.02288","30.71227","0.01866","120.09512","269.38419"
"133.81500","3.01602","30.59571","0.01859","120.09512","268.36182"
"134.21500","3.00942","30.48340","0.01853","120.09196","267.37674"
"134.61500","3.00295","30.43964","0.01846","120.08752","266.99286"
"135.01500","2.99631","30.27518","0.01840","120.08752","265.55042"
"135.41500","2.98966","30.15408","0.01833","120.08427","264.48816"
"135.81500","2.98278","30.00480","0.01826","120.08647","263.17877"
"136.21500","2.97604","29.85851","0.01820","120.09023","261.89566"
"136.61500","2.96945","29.71920","0.01813","120.09023","260.67371"
"137.01500","2.96294","29.59437","0.01807","120.09314","259.57883"
"137.41500","2.95626","29.47433","0.01800","120.09446","258.52591"
"137.81500","2.94958","29.40462","0.01794","120.09808","257.91452"
"138.21500","2.94280","29.31902","0.01787","120.09808","257.16370"
"138.61500","2.93603","29.15746","0.01780","120.10136","255.74664"
"139.01500","2.92956","29.07708","0.01774","120.10207","255.04153"
"139.41500","2.92301","28.91610","0.01767","120.10207","253.62961"
"139.81500","2.91637","28.79853","0.01761","120.10561","252.59833"
"140.21500","2.90954","28.65334","0.01754","120.10802","251.32481"
"140.61500","2.90266","28.46965","0.01747","120.11282","249.71370"
"141.01500","2.89601","28.37127","0.01741","120.11282","248.85077"
"141.41500","2.88963","28.27217","0.01734","120.11625","247.98152"
"141.81500","2.88305","28.13083","0.01728","120.11434","246.74179"
"142.21500","2.87632","28.01379","0.01721","120.11434","245.71519"
"142.61500","2.86950","27.90076","0.01714","120.11234","244.72385"
"143.01500","2.86259","27.78290","0.01708","120.10971","243.69005"
"143.41500","2.85598","27.67590","0.01701","120.10724","242.75150"
"143.81500","2.84956","27.55861","0.01695","120.10724","241.72270"
"144.21500","2.84303","27.40147","0.01688","120.10420","240.34439"
"144.61500","2.83634","27.27233","0.01682","120.09837","239.21173"
"145.01500","2.82955","27.18110","0.01675","120.09259","238.41151"
"145.41500","2.82271","27.06577","0.01668","120.09259","237.39992"
"145.81500","2.81610","26.92851","0.01662","120.09115","236.19601"
"146.21500","2.80953","26.82042","0.01655","120.09034","235.24788"
"146.61500","2.80301","26.70408","0.01649","120.09073","234.22745"
"147.01500","2.79633","26.56214","0.01642","120.09073","232.98245"
"147.41500","2.78944","26.42478","0.01635","120.09753","231.77763"
"147.81500","2.78267","26.32210","0.01629","120.10040","230.87706"
"148.21500","2.77615","26.20547","0.01622","120.10040","229.85403"
"148.61500","2.76960","26.08676","0.01616","120.10451","228.81281"
"149.01500","2.76297","25.93220","0.01609","120.10387","227.45715"
"149.41500","2.75623","25.82781","0.01602","120.10504","226.54153"
"149.81500","2.74936","25.68331","0.01596","120.10504","225.27408"
"150.21500","2.74272","25.58235","0.01589","120.10770","224.38855"
"150.61500","2.73628","25.47761","0.01583","120.11015","223.46985"
"151.01500","2.72975","25.36688","0.01576","120.10905","222.49860"
"151.41500","2.72302","25.27665","0.01570","120.10905","221.70712"
"151.81500","2.71617","25.12786","0.01563","120.10623","220.40211"
"152.21500","2.70931","24.98771","0.01556","120.10793","219.17276"
"152.61500","2.70276","24.88768","0.01550","120.10793","218.29543"
"153.01500","2.69626","24.76824","0.01543","120.11076","217.24777"
"153.41500","2.68969","24.64377","0.01537","120.11203","216.15604"
"153.81500","2.68303","24.52955","0.01530","120.11566","215.15421"
"154.21500","2.67608","24.44798","0.01523","120.11566","214.43872"
"154.61500","2.66928","24.31493","0.01516","120.12077","213.27168"
"155.01500","2.66268","24.21101","0.01510","120.12649","212.36018"
"155.41500","2.65624","24.05491","0.01504","120.13548","210.99097"
"155.81500","2.64970","23.95040","0.01497","120.13548","210.07428"
"156.21500","2.64301","23.81520","0.01490","120.14856","208.88840"
"156.61500","2.63617","23.65451","0.01484","120.15623","207.47902"
"157.01500","2.62933","23.54649","0.01477","120.15623","206.53149"
"157.41500","2.62280","23.38671","0.01470","120.16047","205.13002"
"157.81500","2.61628","23.29485","0.01464","120.16231","204.32430"
"158.21500","2.60972","23.18545","0.01458","120.16193","203.36478"
"158.61500","2.60290","23.08297","0.01451","120.16193","202.46588"
"159.01500","2.59604","22.93353","0.01444","120.16095","201.15511"
"159.41500","2.58939","22.84484","0.01437","120.15952","200.37715"
"159.81500","2.58289","22.69185","0.01431","120.15778","199.03526"
"160.21500","2.57628","22.59289","0.01424","120.15778","198.16733"
"160.61500","2.56961","22.50035","0.01418","120.15423","197.35556"
"161.01500","2.56285","22.39126","0.01411","120.14657","196.39873"
"161.41500","2.55604","22.21102","0.01404","120.14657","194.81779"
"161.81500","2.54945","22.10719","0.01398","120.14331","193.90712"
"162.21500","2.54291","21.97573","0.01391","120.14153","192.75406"
"162.61500","2.53637","21.82606","0.01385","120.14386","191.44127"
"163.01500","2.52967","21.71674","0.01378","120.14386","190.48239"
"163.41500","2.52286","21.63274","0.01372","120.14305","189.74557"
"163.81500","2.51597","21.50559","0.01365","120.13932","188.63033"
"164.21500","2.50939","21.42475","0.01358","120.13320","187.92130"
"164.61500","2.50297","21.31001","0.01352","120.13320","186.91484"
"165.01500","2.49636","21.19446","0.01345","120.13612","185.90134"
"165.41500","2.48972","21.08520","0.01339","120.13875","184.94299"
"165.81500","2.48271","20.91555","0.01332","120.13875","183.45496"
"166.21500","2.47588","20.78413","0.01325","120.13639","182.30225"
"166.61500","2.46948","20.65137","0.01319","120.13451","181.13777"
"167.01500","2.46295","20.58691","0.01312","120.12663","180.57236"
"167.41500","2.45636","20.47393","0.01306","120.12663","179.58144"
"167.81500","2.44961","20.37853","0.01299","120.12257","178.74463"
"168.21500","2.44278","20.21961","0.01292","120.11998","177.35072"
"168.61500","2.43598","20.10003","0.01286","120.11998","176.30186"
"169.01500","2.42952","20.03380","0.01279","120.12086","175.72092"
"169.41500","2.42300","19.87890","0.01273","120.12162","174.36224"
"169.81500","2.41634","19.74945","0.01266","120.11807","173.22687"
"170.21500","2.40956","19.63219","0.01260","120.11807","172.19832"
"170.61500","2.40268","19.53104","0.01253","120.11211","171.31116"
"171.01500","2.39613","19.43673","0.01246","120.10422","170.48387"
"171.41500","2.38954","19.37861","0.01240","120.09492","169.97414"
"171.81500","2.38295","19.23529","0.01233","120.09492","168.71700"
"172.21500","2.37633","19.07732","0.01227","120.09239","167.33141"
"172.61500","2.36950","18.94622","0.01220","120.09257","166.18153"
"173.01500","2.36260","18.81604","0.01213","120.09257","165.03967"
"173.41500","2.35607","18.72126","0.01207","120.08827","164.20833"
"173.81500","2.34972","18.61331","0.01200","120.08160","163.26149"
"174.21500","2.34307","18.48446","0.01194","120.07594","162.13130"
"174.61500","2.33632","18.38202","0.01187","120.07594","161.23279"
"175.01500","2.32941","18.26204","0.01180","120.07076","160.18048"
"175.41500","2.32259","18.16773","0.01174","120.06704","159.35321"
"175.81500","2.31611","18.06397","0.01167","120.06704","158.44316"
"176.21500","2.30967","17.95932","0.01161","120.06100","157.52522"
"176.61500","2.30306","17.86189","0.01154","120.05493","156.67064"
"177.01500","2.29628","17.74841","0.01148","120.04533","155.67523"
"177.41500","2.28934","17.59704","0.01141","120.04533","154.34753"
"177.81500","2.28261","17.47253","0.01134","120.03780","153.25543"
"178.21500","2.27618","17.41558","0.01128","120.03259","152.75591"
"178.61500","2.26958","17.30995","0.01121","120.02937","151.82942"
"179.01500","2.26302","17.19019","0.01115","120.02937","150.77899"
"179.41500","2.25627","17.04529","0.01108","120.02699","149.50806"
"179.81500","2.24946","16.92271","0.01101","120.02065","148.43285"
"180.21500","2.24269","16.82310","0.01095","120.02065","147.55922"
"180.61500","2.23617","16.70066","0.01088","120.01559","146.48526"
"181.01500","2.22967","16.63397","0.01082","120.01067","145.90030"
"181.41500","2.22297","16.48550","0.01075","120.00980","144.59799"
"181.81500","2.21623","16.38480","0.01068","120.00980","143.71471"
"182.21500","2.20937","16.26506","0.01062","120.00849","142.66447"
"182.61500","2.20277","16.14925","0.01055","120.00780","141.64870"
"183.01500","2.19623","16.02724","0.01049","120.01113","140.57848"
"183.41500","2.18963","15.93885","0.01042","120.01113","139.80321"
"183.81500","2.18303","15.85297","0.01036","120.00809","139.04994"
"184.21500","2.17606","15.73795","0.01029","120.00808","138.04105"
"184.61500","2.16927","15.64156","0.01022","120.00808","137.19562"
"185.01500","2.16279","15.55389","0.01016","120.00490","136.42662"
"185.41500","2.15642","15.46847","0.01009","120.00121","135.67744"
"185.81500","2.14970","15.34356","0.01003","120.00788","134.58179"
"186.21500","2.14295","15.23381","0.00996","120.00788","133.61913"
"186.61500","2.13609","15.15154","0.00989","120.01328","132.89754"
"187.01500","2.12928","15.02681","0.00983","120.01802","131.80354"
"187.41500","2.12284","14.92252","0.00976","120.02155","130.88876"
"187.81500","2.11633","14.81695","0.00970","120.02155","129.96274"
"188.21500","2.10971","14.74337","0.00963","120.02255","129.31740"
"188.61500","2.10289","14.59603","0.00956","120.02216","128.02504"
"189.01500","2.09602","14.49917","0.00950","120.02216","127.17548"
"189.41500","2.08928","14.39612","0.00943","120.02368","126.27156"
"189.81500","2.08283","14.29208","0.00937","120.02580","125.35905"
"190.21500","2.07629","14.19024","0.00930","120.02808","124.46578"
"190.61500","2.06970","14.08548","0.00924","120.02808","123.54686"
"191.01500","2.06295","13.97896","0.00917","120.02935","122.61262"
"191.41500","2.05604","13.83596","0.00910","120.02662","121.35831"
"191.81500","2.04939","13.74178","0.00904","120.02485","120.53221"
"192.21500","2.04293","13.64431","0.00897","120.02485","119.67727"
"192.61500","2.03641","13.55492","0.00891","120.02473","118.89328"
"193.01500","2.02965","13.45379","0.00884","120.03030","118.00623"
"193.41500","2.02276","13.28920","0.00877","120.03030","116.56257"
"193.81500","2.01592","13.17006","0.00870","120.03706","115.51757"
"194.21500","2.00957","13.06585","0.00864","120.03461","114.60348"
"194.61500","2.00302","13.02583","0.00858","120.03360","114.25248"
"195.01500","1.99626","12.91329","0.00851","120.03360","113.26535"
"195.41500","1.98957","12.84693","0.00844","120.03139","112.68333"
"195.81500","1.98266","12.74748","0.00838","120.02960","111.81096"
"196.21500","1.97603","12.65526","0.00831","120.03106","111.00208"
"196.61500","1.96946","12.54841","0.00824","120.03106","110.06490"
"197.01500","1.96302","12.46448","0.00818","120.03388","109.32878"
"197.41500","1.95633","12.34486","0.00812","120.03350","108.27953"
"197.81500","1.94961","12.25850","0.00805","120.03350","107.52204"
"198.21500","1.94279","12.14540","0.00798","120.03148","106.53003"
"198.61500","1.93601","12.06905","0.00791","120.02931","105.86031"
"199.01500","1.92949","11.94237","0.00785","120.02868","104.74923"
"199.41500","1.92298","11.89761","0.00779","120.02868","104.35664"
"199.81500","1.91639","11.79956","0.00772","120.02686","103.49659"
"200.21500","1.90961","11.70896","0.00765","120.02847","102.70193"
"200.61500","1.90262","11.64643","0.00758","120.03751","102.15340"
"201.01500","1.89594","11.56285","0.00752","120.03751","101.42030"
"201.41500","1.88946","11.49869","0.00745","120.04727","100.85759"
"201.81500","1.88302","11.46468","0.00739","120.05299","100.55925"
"202.21500","1.87638","11.39761","0.00732","120.05299","99.97099"
"202.61500","1.86952","11.29706","0.00726","120.05776","99.08900"
"203.01500","1.86265","11.21231","0.00719","120.06404","98.34570"
"203.41500","1.85614","11.14902","0.00712","120.07606","97.79053"
"203.81500","1.84965","11.05715","0.00706","120.07606","96.98478"
"204.21500","1.84304","10.95781","0.00699","120.08276","96.11344"
"204.61500","1.83627","10.87877","0.00693","120.08957","95.42010"
"205.01500","1.82937","10.73562","0.00686","120.08957","94.16454"
"205.41500","1.82278","10.66077","0.00679","120.09265","93.50800"
"205.81500","1.81629","10.55100","0.00673","120.09787","92.54517"
"206.21500","1.80957","10.45350","0.00666","120.09955","91.68994"
"206.61500","1.80290","10.36142","0.00660","120.09955","90.88236"
"207.01500","1.79620","10.26748","0.00653","120.10100","90.05833"
"207.41500","1.78942","10.18303","0.00646","120.10424","89.31765"
"207.81500","1.78265","10.04993","0.00640","120.10570","88.15020"
"208.21500","1.77617","9.93901","0.00633","120.10570","87.17727"
"208.61500","1.76970","9.85727","0.00627","120.10703","86.46033"
"209.01500","1.76307","9.76894","0.00620","120.10716","85.68559"
"209.41500","1.75632","9.67357","0.00614","120.10716","84.84908"
"209.81500","1.74928","9.56172","0.00607","120.10630","83.86797"
"210.21500","1.74260","9.47547","0.00600","120.10563","83.11143"
"210.61500","1.73616","9.39677","0.00594","120.10452","82.42117"
"211.01500","1.72978","9.28692","0.00587","120.10452","81.45763"
"211.41500","1.72307","9.18192","0.00581","120.10802","80.53667"
"211.81500","1.71613","9.13241","0.00574","120.11440","80.10243"
"212.21500","1.70916","9.03288","0.00567","120.11841","79.22938"
"212.61500","1.70274","8.91376","0.00561","120.11841","78.18459"
"213.01500","1.69632","8.81999","0.00554","120.12433","77.36209"
"213.41500","1.68959","8.67376","0.00548","120.12972","76.07945"
"213.81500","1.68291","8.58630","0.00541","120.12972","75.31232"
"214.21500","1.67611","8.45330","0.00534","120.13109","74.14575"
"214.61500","1.66948","8.35673","0.00528","120.12866","73.29874"
"215.01500","1.66285","8.25673","0.00521","120.12531","72.42162"
"215.41500","1.65626","8.16926","0.00515","120.12531","71.65441"
"215.81500","1.64962","8.00675","0.00508","120.12463","70.22895"
"216.21500","1.64292","7.94396","0.00502","120.12851","69.67826"
"216.61500","1.63618","7.85768","0.00495","120.12267","68.92145"
"217.01500","1.62933","7.75242","0.00488","120.12267","67.99825"
"217.41500","1.62284","7.63591","0.00482","120.12000","66.97627"
"217.81500","1.61628","7.49939","0.00475","120.11202","65.77880"
"218.21500","1.60971","7.46111","0.00469","120.11202","65.44309"
"218.61500","1.60287","7.33909","0.00462","120.10781","64.37279"
"219.01500","1.59592","7.22072","0.00455","120.10729","63.33451"
"219.41500","1.58928","7.09976","0.00449","120.10876","62.27361"
"219.81500","1.58298","7.02915","0.00442","120.10876","61.65426"
"220.21500","1.57647","6.91234","0.00436","120.11211","60.62967"
"220.61500","1.56966","6.81105","0.00429","120.12189","59.74124"
"221.01500","1.56277","6.75617","0.00422","120.12453","59.25985"
"221.41500","1.55595","6.67195","0.00416","120.12453","58.52117"
"221.81500","1.54945","6.52464","0.00409","120.12733","57.22911"
"222.21500","1.54295","6.43660","0.00403","120.12926","56.45683"
"222.61500","1.53633","6.33768","0.00396","120.12926","55.58923"
"223.01500","1.52964","6.21331","0.00390","120.12711","54.49834"
"223.41500","1.52276","6.06114","0.00383","120.12583","53.16364"
"223.81500","1.51604","5.98239","0.00376","120.12676","52.47289"
"224.21500","1.50944","5.84692","0.00370","120.12676","51.28464"
"224.61500","1.50287","5.73341","0.00363","120.12835","50.28906"
"225.01500","1.49626","5.63733","0.00357","120.12776","49.44631"
"225.41500","1.48961","5.53330","0.00350","120.12776","48.53381"
"225.81500","1.48288","5.37260","0.00343","120.12126","47.12424"
"226.21500","1.47605","5.24741","0.00337","120.12016","46.02623"
"226.61500","1.46948","5.16221","0.00330","120.11761","45.27888"
"227.01500","1.46301","5.05218","0.00324","120.11761","44.31376"
"227.41500","1.45643","4.93439","0.00317","120.11320","43.28065"
"227.81500","1.44960","4.78079","0.00310","120.11025","41.93335"
"228.21500","1.44254","4.66220","0.00303","120.11171","40.89316"
"228.61500","1.43603","4.52507","0.00297","120.11171","39.69038"
"229.01500","1.42967","4.44271","0.00291","120.10526","38.96802"
"229.41500","1.42308","4.31773","0.00284","120.10540","37.87178"
"229.81500","1.41630","4.21395","0.00278","120.10540","36.96154"
"230.21500","1.40942","4.09854","0.00271","120.10782","35.94917"
"230.61500","1.40255","3.97927","0.00264","120.11069","34.90303"
"231.01500","1.39613","3.89153","0.00258","120.11197","34.13345"
"231.41500","1.38968","3.83586","0.00251","120.11197","33.64520"
"231.81500","1.38302","3.74382","0.00245","120.10751","32.83790"
"232.21500","1.37628","3.61855","0.00238","120.10186","31.73907"
"232.61500","1.36939","3.49514","0.00231","120.09871","30.65664"
"233.01500","1.36283","3.38467","0.00225","120.09871","29.68773"
"233.41500","1.35607","3.26598","0.00218","120.09676","28.64662"
"233.81500","1.34952","3.16731","0.00212","120.09715","27.78121"
"234.21500","1.34297","3.05077","0.00205","120.09610","26.75901"
"234.61500","1.33637","2.91847","0.00198","120.09610","25.59857"
"235.01500","1.32949","2.77260","0.00192","120.09509","24.31912"
"235.41500","1.32248","2.67015","0.00185","120.09305","23.42049"
"235.81500","1.31613","2.58186","0.00178","120.09305","22.64607"
"236.21500","1.30961","2.49011","0.00172","120.09187","21.84128"
"236.61500","1.30303","2.38089","0.00166","120.09431","20.88335"
"237.01500","1.29626","2.25752","0.00159","120.09799","19.80124"
"237.41500","1.28938","2.17053","0.00152","120.09799","19.03819"
"237.81500","1.28271","2.01685","0.00145","120.10946","17.69023"
"238.21500","1.27630","1.93155","0.00139","120.11798","16.94206"
"238.61500","1.26972","1.83897","0.00133","120.11798","16.13001"
"239.01500","1.26298","1.71310","0.00126","120.12281","15.02603"
"239.41500","1.25611","1.59418","0.00119","120.12675","13.98294"
"239.81500","1.24931","1.48861","0.00112","120.13000","13.05690"
"240.21500","1.24289","1.40223","0.00106","120.13000","12.29928"
"240.61500","1.23628","1.31068","0.00100","120.13105","11.49630"
"241.01500","1.22965","1.21699","0.00093","120.12901","10.67447"
"241.41500","1.22294","1.12146","0.00086","120.13364","9.83654"
"241.81500","1.21612","1.02973","0.00080","120.13364","9.03200"
"242.21500","1.20929","0.92861","0.00073","120.13819","8.14505"
"242.61500","1.20273","0.80594","0.00066","120.14184","7.06910"
"243.01500","1.19633","0.70588","0.00060","120.14184","6.19139"
"243.41500","1.18971","0.62295","0.00053","120.14164","5.46406"
"243.81500","1.18306","0.53780","0.00047","120.14286","4.71715"
"244.21500","1.17608","0.44612","0.00040","120.14245","3.91305"
"244.61500","1.16929","0.39157","0.00033","120.14245","3.43455"
"245.01500","1.16276","0.31198","0.00027","120.14173","2.73643"
"245.41500","1.15633","0.26347","0.00020","120.14101","2.31099"
"245.81500","1.14978","0.21954","0.00014","120.14082","1.92565"
"246.21500","1.14291","0.17983","0.00007","120.14082","1.57737"
"246.61500","1.13601","0.13239","0.00000","120.14910","1.16122"
"246.80000","1.13328","0.11347","-0.00002","120.14910","0.99523"