File: experimental/sma_database/flexinol_monotonic_loading_martensite.csv
Time,Extension,Load,Tensile strain (Extension),Tensile stress
(s),(mm),(N),(mm/mm),(MPa)
"0.00000","0.57943","0.00084","0.00000","0.00734"
"1.00000","0.60387","0.34538","0.00008","3.02941"
"2.00000","0.62891","0.68276","0.00015","5.98860"
"3.00000","0.65400","1.02441","0.00023","8.98529"
"4.00000","0.67911","1.36845","0.00031","12.00296"
"5.00000","0.70403","1.70593","0.00039","14.96311"
"6.00000","0.72892","2.04803","0.00047","17.96370"
"7.00000","0.75375","2.38681","0.00055","20.93521"
"8.00000","0.77879","2.73161","0.00062","23.95957"
"9.00000","0.80368","3.07880","0.00070","27.00488"
"10.00000","0.82878","3.41749","0.00078","29.97556"
"11.00000","0.85379","3.76283","0.00086","33.00464"
"12.00000","0.87915","4.10979","0.00094","36.04790"
"13.00000","0.90417","4.45721","0.00102","39.09520"
"14.00000","0.92938","4.79451","0.00110","42.05374"
"15.00000","0.95415","5.13256","0.00117","45.01884"
"16.00000","0.97911","5.47860","0.00125","48.05400"
"17.00000","1.00382","5.81463","0.00133","51.00143"
"18.00000","1.02873","6.15004","0.00141","53.94334"
"19.00000","1.05354","6.48941","0.00148","56.92005"
"20.00000","1.07865","6.82550","0.00156","59.86799"
"21.00000","1.10361","7.16186","0.00164","62.81825"
"22.00000","1.12888","7.50444","0.00172","65.82313"
"23.00000","1.15393","7.84237","0.00180","68.78722"
"24.00000","1.17933","8.18646","0.00188","71.80527"
"25.00000","1.20419","8.51322","0.00196","74.67136"
"26.00000","1.22911","8.86281","0.00203","77.73766"
"27.00000","1.25388","9.19396","0.00211","80.64230"
"28.00000","1.27884","9.52505","0.00219","83.54636"
"29.00000","1.30370","9.86652","0.00227","86.54142"
"30.00000","1.32868","10.19691","0.00235","89.43941"
"31.00000","1.35376","10.53055","0.00243","92.36584"
"32.00000","1.37894","10.86638","0.00250","95.31144"
"33.00000","1.40401","11.20234","0.00258","98.25826"
"34.00000","1.42905","11.53713","0.00266","101.19471"
"35.00000","1.45414","11.87273","0.00274","104.13838"
"36.00000","1.47902","12.20891","0.00282","107.08707"
"37.00000","1.50390","12.55023","0.00290","110.08088"
"38.00000","1.52876","12.87403","0.00297","112.92101"
"39.00000","1.55378","13.20680","0.00305","115.83982"
"40.00000","1.57872","13.53544","0.00313","118.72239"
"41.00000","1.60381","13.88262","0.00321","121.76758"
"42.00000","1.62889","14.21633","0.00329","124.69462"
"43.00000","1.65424","14.55119","0.00337","127.63175"
"44.00000","1.67919","14.88228","0.00345","130.53580"
"45.00000","1.70427","15.22326","0.00352","133.52666"
"46.00000","1.72900","15.55282","0.00360","136.41728"
"47.00000","1.75392","15.88484","0.00368","139.32951"
"48.00000","1.77865","16.21370","0.00376","142.21394"
"49.00000","1.80362","16.54186","0.00384","145.09239"
"50.00000","1.82858","16.87473","0.00391","148.01204"
"51.00000","1.85383","17.21036","0.00399","150.95592"
"52.00000","1.87885","17.54570","0.00407","153.89725"
"53.00000","1.90416","17.88063","0.00415","156.83501"
"54.00000","1.92918","18.21006","0.00423","159.72455"
"55.00000","1.95439","18.53655","0.00431","162.58821"
"56.00000","1.97906","18.85721","0.00439","165.40082"
"57.00000","2.00397","19.18049","0.00446","168.23634"
"58.00000","2.02873","19.50225","0.00454","171.05864"
"59.00000","2.05365","19.83229","0.00462","173.95349"
"60.00000","2.07856","20.15475","0.00470","176.78185"
"61.00000","2.10362","20.48280","0.00478","179.65921"
"62.00000","2.12869","20.81431","0.00485","182.56697"
"63.00000","2.15396","21.14852","0.00493","185.49835"
"64.00000","2.17922","21.48277","0.00501","188.43013"
"65.00000","2.20415","21.80891","0.00509","191.29085"
"66.00000","2.22926","22.13628","0.00517","194.16229"
"67.00000","2.25403","22.46558","0.00525","197.05061"
"68.00000","2.27890","22.78382","0.00532","199.84201"
"69.00000","2.30369","23.10373","0.00540","202.64799"
"70.00000","2.32873","23.43221","0.00548","205.52913"
"71.00000","2.35365","23.75972","0.00556","208.40182"
"72.00000","2.37880","24.08710","0.00564","211.27333"
"73.00000","2.40382","24.41114","0.00572","214.11555"
"74.00000","2.42912","24.74425","0.00580","217.03732"
"75.00000","2.45407","25.06810","0.00587","219.87791"
"76.00000","2.47909","25.39354","0.00595","222.73242"
"77.00000","2.50382","25.71663","0.00603","225.56633"
"78.00000","2.52880","26.04495","0.00611","228.44606"
"79.00000","2.55365","26.36492","0.00619","231.25262"
"80.00000","2.57868","26.69826","0.00626","234.17636"
"81.00000","2.60373","27.02557","0.00634","237.04735"
"82.00000","2.62904","27.35386","0.00642","239.92682"
"83.00000","2.65404","27.67708","0.00650","242.76184"
"84.00000","2.67923","28.00753","0.00658","245.66032"
"85.00000","2.70414","28.32879","0.00666","248.47812"
"86.00000","2.72927","28.65595","0.00674","251.34776"
"87.00000","2.75387","28.97293","0.00681","254.12808"
"88.00000","2.77877","29.29890","0.00689","256.98721"
"89.00000","2.80361","29.61470","0.00697","259.75720"
"90.00000","2.82868","29.94698","0.00705","262.67163"
"91.00000","2.85368","30.27396","0.00713","265.53964"
"92.00000","2.87871","30.59170","0.00720","268.32666"
"93.00000","2.90389","30.92595","0.00728","271.25839"
"94.00000","2.92912","31.25258","0.00736","274.12341"
"95.00000","2.95423","31.57464","0.00744","276.94824"
"96.00000","2.97904","31.90327","0.00752","279.83072"
"97.00000","3.00411","32.22457","0.00760","282.64890"
"98.00000","3.02882","32.54070","0.00768","285.42172"
"99.00000","3.05378","32.86147","0.00775","288.23529"
"100.00000","3.07860","33.18391","0.00783","291.06348"
"101.00000","3.10373","33.50782","0.00791","293.90460"
"102.00000","3.12872","33.82398","0.00799","296.67770"
"103.00000","3.15398","34.14312","0.00807","299.47690"
"104.00000","3.17910","34.45551","0.00815","302.21695"
"105.00000","3.20436","34.76875","0.00823","304.96451"
"106.00000","3.22922","35.08223","0.00830","307.71411"
"107.00000","3.25413","35.38599","0.00838","310.37839"
"108.00000","3.27885","35.69170","0.00846","313.05984"
"109.00000","3.30384","35.99342","0.00854","315.70636"
"110.00000","3.32863","36.29363","0.00861","318.33954"
"111.00000","3.35378","36.59980","0.00869","321.02502"
"112.00000","3.37875","36.90474","0.00877","323.69977"
"113.00000","3.40400","37.21866","0.00885","326.45319"
"114.00000","3.42887","37.51661","0.00893","329.06659"
"115.00000","3.45403","37.81569","0.00901","331.68982"
"116.00000","3.47888","38.11908","0.00909","334.35098"
"117.00000","3.50395","38.41829","0.00916","336.97543"
"118.00000","3.52875","38.72057","0.00924","339.62677"
"119.00000","3.55374","39.01226","0.00932","342.18527"
"120.00000","3.57873","39.31647","0.00940","344.85358"
"121.00000","3.60385","39.62049","0.00948","347.52023"
"122.00000","3.62891","39.92434","0.00956","350.18530"
"123.00000","3.65401","40.22867","0.00963","352.85468"
"124.00000","3.67920","40.52750","0.00971","355.47574"
"125.00000","3.70430","40.82969","0.00979","358.12634"
"126.00000","3.72922","41.13395","0.00987","360.79507"
"127.00000","3.75397","41.42735","0.00995","363.36850"
"128.00000","3.77890","41.72792","0.01003","366.00488"
"129.00000","3.80362","42.02052","0.01010","368.57141"
"130.00000","3.82859","42.31715","0.01018","371.17316"
"131.00000","3.85349","42.61754","0.01026","373.80795"
"132.00000","3.87869","42.92229","0.01034","376.48099"
"133.00000","3.90389","43.22121","0.01042","379.10294"
"134.00000","3.92922","43.52292","0.01050","381.74924"
"135.00000","3.95423","43.82094","0.01058","384.36325"
"136.00000","3.97940","44.12005","0.01065","386.98682"
"137.00000","4.00405","44.42140","0.01073","389.63000"
"138.00000","4.02894","44.71072","0.01081","392.16772"
"139.00000","4.05365","45.00701","0.01089","394.76657"
"140.00000","4.07875","45.31070","0.01097","397.43027"
"141.00000","4.10356","45.60435","0.01104","400.00592"
"142.00000","4.12873","45.89845","0.01112","402.58560"
"143.00000","4.15377","46.20577","0.01120","405.28116"
"144.00000","4.17911","46.50604","0.01128","407.91486"
"145.00000","4.20410","46.80742","0.01136","410.55838"
"146.00000","4.22920","47.10154","0.01144","413.13809"
"147.00000","4.25399","47.40220","0.01151","415.77533"
"148.00000","4.27894","47.69493","0.01159","418.34286"
"149.00000","4.30369","47.98729","0.01167","420.90729"
"150.00000","4.32869","48.28331","0.01175","423.50366"
"151.00000","4.35367","48.58652","0.01183","426.16324"
"152.00000","4.37884","48.88573","0.01191","428.78763"
"153.00000","4.40389","49.18003","0.01198","431.36908"
"154.00000","4.42902","49.47675","0.01206","433.97162"
"155.00000","4.45418","49.77600","0.01214","436.59641"
"156.00000","4.47916","50.07421","0.01222","439.21207"
"157.00000","4.50405","50.36890","0.01230","441.79688"
"158.00000","4.52884","50.66306","0.01238","444.37704"
"159.00000","4.55382","50.95591","0.01245","446.94568"
"160.00000","4.57865","51.25038","0.01253","449.52856"
"161.00000","4.60371","51.55030","0.01261","452.15921"
"162.00000","4.62867","51.84890","0.01269","454.77829"
"163.00000","4.65399","52.15010","0.01277","457.42023"
"164.00000","4.67912","52.44356","0.01285","459.99420"
"165.00000","4.70427","52.74030","0.01293","462.59692"
"166.00000","4.72916","53.03693","0.01300","465.19873"
"167.00000","4.75413","53.33028","0.01308","467.77185"
"168.00000","4.77889","53.62019","0.01316","470.31464"
"169.00000","4.80372","53.91108","0.01324","472.86612"
"170.00000","4.82851","54.20369","0.01332","475.43271"
"171.00000","4.85362","54.50253","0.01339","478.05383"
"172.00000","4.87858","54.79222","0.01347","480.59485"
"173.00000","4.90383","55.08403","0.01355","483.15439"
"174.00000","4.92893","55.37388","0.01363","485.69672"
"175.00000","4.95433","55.66851","0.01371","488.28091"
"176.00000","4.97923","55.95845","0.01379","490.82413"
"177.00000","5.00423","56.24585","0.01387","493.34497"
"178.00000","5.02900","56.52268","0.01394","495.77307"
"179.00000","5.05393","56.80634","0.01402","498.26111"
"180.00000","5.07872","57.08313","0.01410","500.68890"
"181.00000","5.10359","57.35154","0.01418","503.04321"
"182.00000","5.12862","57.63116","0.01426","505.49579"
"183.00000","5.15377","57.90966","0.01433","507.93860"
"184.00000","5.17888","58.19136","0.01441","510.40939"
"185.00000","5.20399","58.47210","0.01449","512.87183"
"186.00000","5.22924","58.75544","0.01457","515.35706"
"187.00000","5.25405","59.03238","0.01465","517.78619"
"188.00000","5.27897","59.30946","0.01473","520.21655"
"189.00000","5.30380","59.59526","0.01480","522.72333"
"190.00000","5.32881","59.86907","0.01488","525.12500"
"191.00000","5.35377","60.13608","0.01496","527.46698"
"192.00000","5.37883","60.40709","0.01504","529.84412"
"193.00000","5.40389","60.67987","0.01512","532.23669"
"194.00000","5.42918","60.95506","0.01520","534.65045"
"195.00000","5.45417","61.23135","0.01528","537.07385"
"196.00000","5.47927","61.50405","0.01535","539.46576"
"197.00000","5.50401","61.77316","0.01543","541.82617"
"198.00000","5.52893","62.04137","0.01551","544.17871"
"199.00000","5.55372","62.30547","0.01559","546.49524"
"200.00000","5.57866","62.57095","0.01567","548.82379"
"201.00000","5.60362","62.83391","0.01574","551.13031"
"202.00000","5.62873","63.07431","0.01582","553.23883"
"203.00000","5.65373","63.24043","0.01590","554.69598"
"204.00000","5.67899","63.29673","0.01598","555.18982"
"205.00000","5.70398","63.49720","0.01606","556.94812"
"206.00000","5.72936","63.67876","0.01614","558.54059"
"207.00000","5.75415","63.18583","0.01622","554.21704"
"208.00000","5.77902","63.50026","0.01629","556.97491"
"209.00000","5.80379","63.76731","0.01637","559.31732"
"210.00000","5.82877","63.97920","0.01645","561.17590"
"211.00000","5.85361","64.18658","0.01653","562.99481"
"212.00000","5.87865","64.35568","0.01661","564.47809"
"213.00000","5.90380","64.15115","0.01669","562.68408"
"214.00000","5.92907","64.28140","0.01676","563.82654"
"215.00000","5.95423","64.51683","0.01684","565.89154"
"216.00000","5.97927","64.64957","0.01692","567.05579"
"217.00000","6.00428","64.42876","0.01700","565.11902"
"218.00000","6.02905","64.63795","0.01708","566.95398"
"219.00000","6.05389","64.90151","0.01716","569.26569"
"220.00000","6.07865","65.19367","0.01723","571.82825"
"221.00000","6.10371","65.47589","0.01731","574.30365"
"222.00000","6.12872","65.74320","0.01739","576.64832"
"223.00000","6.15380","66.00452","0.01747","578.94043"
"224.00000","6.17881","66.25871","0.01755","581.16992"
"225.00000","6.20412","66.52464","0.01763","583.50244"
"226.00000","6.22901","66.76302","0.01770","585.59332"
"227.00000","6.25403","67.01277","0.01778","587.78400"
"228.00000","6.27891","67.26961","0.01786","590.03674"
"229.00000","6.30388","67.52620","0.01794","592.28741"
"230.00000","6.32875","67.78193","0.01802","594.53046"
"231.00000","6.35374","68.03158","0.01810","596.72015"
"232.00000","6.37868","68.27863","0.01817","598.88715"
"233.00000","6.40400","68.53181","0.01825","601.10779"
"234.00000","6.42895","68.77924","0.01833","603.27808"
"235.00000","6.45423","69.02365","0.01841","605.42188"
"236.00000","6.47909","69.26009","0.01849","607.49579"
"237.00000","6.50427","69.50781","0.01857","609.66858"
"238.00000","6.52893","69.73779","0.01864","611.68573"
"239.00000","6.55377","69.97161","0.01872","613.73663"
"240.00000","6.57862","70.21585","0.01880","615.87891"
"241.00000","6.60361","70.45445","0.01888","617.97174"
"242.00000","6.62860","70.68925","0.01896","620.03125"
"243.00000","6.65379","70.92836","0.01904","622.12848"
"244.00000","6.67899","71.17448","0.01911","624.28723"
"245.00000","6.70432","71.40812","0.01919","626.33661"
"246.00000","6.72936","71.64504","0.01927","628.41467"
"247.00000","6.75420","71.87105","0.01935","630.39703"
"248.00000","6.77908","72.10681","0.01943","632.46497"
"249.00000","6.80390","72.33955","0.01951","634.50635"
"250.00000","6.82876","72.56807","0.01958","636.51074"
"251.00000","6.85356","72.79921","0.01966","638.53815"
"252.00000","6.87867","73.03152","0.01974","640.57581"
"253.00000","6.90369","73.26298","0.01982","642.60596"
"254.00000","6.92898","73.49621","0.01990","644.65167"
"255.00000","6.95397","73.72675","0.01998","646.67383"
"256.00000","6.97930","73.95670","0.02006","648.69073"
"257.00000","7.00418","74.18934","0.02013","650.73126"
"258.00000","7.02913","74.41792","0.02021","652.73627"
"259.00000","7.05390","74.63702","0.02029","654.65796"
"260.00000","7.07882","74.86759","0.02037","656.68036"
"261.00000","7.10370","75.09101","0.02045","658.64008"
"262.00000","7.12875","75.31703","0.02052","660.62250"
"263.00000","7.15370","75.54245","0.02060","662.59973"
"264.00000","7.17900","75.77389","0.02068","664.62970"
"265.00000","7.20398","76.00123","0.02076","666.62378"
"266.00000","7.22918","76.23327","0.02084","668.65906"
"267.00000","7.25406","76.45222","0.02092","670.57953"
"268.00000","7.27909","76.67899","0.02100","672.56860"
"269.00000","7.30387","76.90292","0.02107","674.53265"
"270.00000","7.32882","77.12183","0.02115","676.45282"
"271.00000","7.35369","77.34643","0.02123","678.42279"
"272.00000","7.37877","77.57484","0.02131","680.42621"
"273.00000","7.40376","77.79814","0.02139","682.38489"
"274.00000","7.42890","78.02609","0.02146","684.38428"
"275.00000","7.45414","78.25327","0.02154","686.37689"
"276.00000","7.47930","78.47746","0.02162","688.34332"
"277.00000","7.50425","78.69874","0.02170","690.28424"
"278.00000","7.52898","78.92283","0.02178","692.24976"
"279.00000","7.55385","79.13830","0.02186","694.13971"
"280.00000","7.57864","79.36301","0.02193","696.11072"
"281.00000","7.60360","79.58221","0.02201","698.03333"
"282.00000","7.62858","79.80791","0.02209","700.01306"
"283.00000","7.65381","80.03145","0.02217","701.97375"
"284.00000","7.67894","80.25638","0.02225","703.94666"
"285.00000","7.70419","80.48499","0.02233","705.95184"
"286.00000","7.72917","80.70197","0.02241","707.85498"
"287.00000","7.75440","80.92926","0.02249","709.84863"
"288.00000","7.77912","81.14238","0.02256","711.71796"
"289.00000","7.80400","81.36800","0.02264","713.69696"
"290.00000","7.82874","81.58081","0.02272","715.56354"
"291.00000","7.85367","81.80405","0.02280","717.52167"
"292.00000","7.87851","82.02115","0.02287","719.42584"
"293.00000","7.90361","82.24358","0.02295","721.37677"
"294.00000","7.92859","82.46400","0.02303","723.31024"
"295.00000","7.95398","82.69245","0.02311","725.31396"
"296.00000","7.97899","82.91592","0.02319","727.27405"
"297.00000","8.00424","83.13464","0.02327","729.19250"
"298.00000","8.02913","83.35953","0.02335","731.16504"
"299.00000","8.05407","83.57884","0.02342","733.08868"
"300.00000","8.07885","83.79973","0.02350","735.02612"
"301.00000","8.10375","84.01312","0.02358","736.89789"
"302.00000","8.12875","84.23611","0.02366","738.85370"
"303.00000","8.15382","84.45341","0.02374","740.75977"
"304.00000","8.17889","84.67874","0.02382","742.73615"
"305.00000","8.20399","84.89938","0.02389","744.67139"
"306.00000","8.22915","85.12408","0.02397","746.64240"
"307.00000","8.25417","85.34197","0.02405","748.55353"
"308.00000","8.27909","85.56081","0.02413","750.47296"
"309.00000","8.30389","85.77623","0.02421","752.36249"
"310.00000","8.32882","85.99823","0.02429","754.30969"
"311.00000","8.35364","86.21397","0.02436","756.20197"
"312.00000","8.37862","86.42940","0.02444","758.09155"
"313.00000","8.40355","86.64804","0.02452","760.00934"
"314.00000","8.42880","86.86826","0.02460","761.94092"
"315.00000","8.45395","87.08672","0.02468","763.85712"
"316.00000","8.47921","87.30890","0.02476","765.80585"
"317.00000","8.50415","87.52522","0.02483","767.70325"
"318.00000","8.52930","87.73977","0.02491","769.58514"
"319.00000","8.55396","87.95376","0.02499","771.46210"
"320.00000","8.57880","88.16982","0.02507","773.35724"
"321.00000","8.60363","88.38457","0.02515","775.24078"
"322.00000","8.62863","88.59922","0.02522","777.12360"
"323.00000","8.65364","88.81232","0.02530","778.99274"
"324.00000","8.67887","89.03138","0.02538","780.91412"
"325.00000","8.70394","89.25025","0.02546","782.83392"
"326.00000","8.72935","89.46993","0.02554","784.76080"
"327.00000","8.75417","89.68523","0.02562","786.64917"
"328.00000","8.77924","89.90270","0.02570","788.55670"
"329.00000","8.80400","90.11790","0.02577","790.44427"
"330.00000","8.82894","90.32872","0.02585","792.29340"
"331.00000","8.85373","90.54092","0.02593","794.15460"
"332.00000","8.87868","90.74768","0.02601","795.96820"
"333.00000","8.90366","90.96243","0.02609","797.85175"
"334.00000","8.92870","91.17609","0.02617","799.72583"
"335.00000","8.95376","91.38781","0.02624","801.58289"
"336.00000","8.97891","91.60345","0.02632","803.47437"
"337.00000","9.00407","91.81763","0.02640","805.35291"
"338.00000","9.02909","92.03128","0.02648","807.22693"
"339.00000","9.05410","92.24180","0.02656","809.07343"
"340.00000","9.07896","92.44938","0.02664","810.89417"
"341.00000","9.10392","92.66113","0.02671","812.75146"
"342.00000","9.12880","92.87232","0.02679","814.60388"
"343.00000","9.15381","93.07838","0.02687","816.41125"
"344.00000","9.17877","93.28829","0.02695","818.25244"
"345.00000","9.20402","93.49892","0.02703","820.09998"
"346.00000","9.22906","93.71108","0.02711","821.96088"
"347.00000","9.25422","93.92383","0.02719","823.82690"
"348.00000","9.27898","94.11563","0.02726","825.50922"
"349.00000","9.30393","94.32285","0.02734","827.32678"
"350.00000","9.32868","94.52954","0.02742","829.13971"
"351.00000","9.35361","94.73042","0.02750","830.90173"
"352.00000","9.37857","94.93946","0.02758","832.73523"
"353.00000","9.40380","95.14414","0.02765","834.53052"
"354.00000","9.42882","95.34941","0.02773","836.33099"
"355.00000","9.45409","95.56224","0.02781","838.19775"
"356.00000","9.47907","95.76453","0.02789","839.97217"
"357.00000","9.50440","95.97218","0.02797","841.79346"
"358.00000","9.52913","96.17323","0.02805","843.55695"
"359.00000","9.55406","96.37760","0.02813","845.34949"
"360.00000","9.57876","96.57716","0.02820","847.09991"
"361.00000","9.60371","96.77499","0.02828","848.83502"
"362.00000","9.62853","96.97248","0.02836","850.56732"
"363.00000","9.65360","97.17425","0.02844","852.33704"
"364.00000","9.67872","97.37154","0.02852","854.06750"
"365.00000","9.70401","97.57578","0.02860","855.85895"
"366.00000","9.72913","97.77467","0.02867","857.60345"
"367.00000","9.75419","97.97745","0.02875","859.38208"
"368.00000","9.77929","98.17169","0.02883","861.08588"
"369.00000","9.80406","98.36665","0.02891","862.79590"
"370.00000","9.82898","98.56120","0.02899","864.50226"
"371.00000","9.85373","98.75018","0.02906","866.15985"
"372.00000","9.87874","98.94441","0.02914","867.86359"
"373.00000","9.90368","99.14256","0.02922","869.60150"
"374.00000","9.92877","99.33745","0.02930","871.31097"
"375.00000","9.95376","99.53391","0.02938","873.03412"
"376.00000","9.97912","99.72456","0.02946","874.70636"
"377.00000","10.00412","99.91685","0.02954","876.39301"
"378.00000","10.02923","100.10953","0.02961","878.08307"
"379.00000","10.05395","100.29166","0.02969","879.68054"
"380.00000","10.07889","100.48811","0.02977","881.40369"
"381.00000","10.10367","100.66306","0.02985","882.93823"
"382.00000","10.12867","100.85599","0.02993","884.63043"
"383.00000","10.15361","101.04080","0.03000","886.25146"
"384.00000","10.17887","101.23749","0.03008","887.97662"
"385.00000","10.20381","101.42374","0.03016","889.61029"
"386.00000","10.22919","101.61244","0.03024","891.26544"
"387.00000","10.25402","101.79396","0.03032","892.85760"
"388.00000","10.27925","101.98576","0.03040","894.53992"
"389.00000","10.30395","102.16457","0.03048","896.10834"
"390.00000","10.32879","102.34924","0.03055","897.72809"
"391.00000","10.35365","102.53243","0.03063","899.33490"
"392.00000","10.37869","102.71211","0.03071","900.91089"
"393.00000","10.40362","102.89542","0.03079","902.51868"
"394.00000","10.42879","103.07980","0.03087","904.13599"
"395.00000","10.45397","103.26512","0.03095","905.76147"
"396.00000","10.47922","103.44656","0.03102","907.35284"
"397.00000","10.50439","103.62951","0.03110","908.95758"
"398.00000","10.52928","103.80888","0.03118","910.53094"
"399.00000","10.55425","103.98777","0.03126","912.09998"
"400.00000","10.57885","104.15980","0.03134","913.60889"
"401.00000","10.60368","104.34128","0.03141","915.20068"
"402.00000","10.62849","104.51242","0.03149","916.70178"
"403.00000","10.65357","104.69435","0.03157","918.29755"
"404.00000","10.67858","104.86963","0.03165","919.83496"
"405.00000","10.70375","105.04321","0.03173","921.35742"
"406.00000","10.72886","105.22053","0.03181","922.91278"
"407.00000","10.75427","105.40185","0.03189","924.50317"
"408.00000","10.77923","105.57318","0.03196","926.00598"
"409.00000","10.80430","105.74956","0.03204","927.55304"
"410.00000","10.82899","105.91425","0.03212","928.99750"
"411.00000","10.85397","106.08611","0.03220","930.50494"
"412.00000","10.87871","106.25023","0.03228","931.94452"
"413.00000","10.90375","106.42844","0.03236","933.50763"
"414.00000","10.92867","106.60197","0.03243","935.02972"
"415.00000","10.95393","106.77723","0.03251","936.56696"
"416.00000","10.97888","106.94228","0.03259","938.01471"
"417.00000","11.00411","107.11875","0.03267","939.56250"
"418.00000","11.02907","107.28372","0.03275","941.00952"
"419.00000","11.05414","107.45203","0.03283","942.48584"
"420.00000","11.07892","107.61948","0.03290","943.95453"
"421.00000","11.10386","107.78889","0.03298","945.44043"
"422.00000","11.12868","107.95947","0.03306","946.93658"
"423.00000","11.15371","108.12074","0.03314","948.35114"
"424.00000","11.17864","108.29165","0.03322","949.85028"
"425.00000","11.20381","108.45985","0.03330","951.32562"
"426.00000","11.22897","108.62539","0.03337","952.77759"
"427.00000","11.25421","108.79948","0.03345","954.30463"
"428.00000","11.27925","108.96596","0.03353","955.76477"
"429.00000","11.30410","109.13122","0.03361","957.21429"
"430.00000","11.32905","109.29102","0.03369","958.61603"
"431.00000","11.35373","109.45188","0.03377","960.02692"
"432.00000","11.37873","109.61623","0.03384","961.46851"
"433.00000","11.40362","109.77926","0.03392","962.89844"
"434.00000","11.42882","109.94562","0.03400","964.35760"
"435.00000","11.45389","110.10870","0.03408","965.78809"
"436.00000","11.47913","110.27711","0.03416","967.26514"
"437.00000","11.50411","110.43309","0.03424","968.63330"
"438.00000","11.52934","110.59823","0.03432","970.08179"
"439.00000","11.55414","110.75926","0.03439","971.49426"
"440.00000","11.57903","110.92223","0.03447","972.92371"
"441.00000","11.60376","111.07148","0.03455","974.23279"
"442.00000","11.62873","111.23238","0.03463","975.64404"
"443.00000","11.65353","111.38988","0.03471","977.02557"
"444.00000","11.67862","111.54224","0.03478","978.36188"
"445.00000","11.70362","111.70251","0.03486","979.76764"
"446.00000","11.72897","111.86877","0.03494","981.22595"
"447.00000","11.75397","112.02853","0.03502","982.62726"
"448.00000","11.77924","112.18836","0.03510","984.02924"
"449.00000","11.80408","112.33961","0.03518","985.35590"
"450.00000","11.82917","112.49457","0.03526","986.71503"
"451.00000","11.85391","112.64617","0.03533","988.04474"
"452.00000","11.87874","112.80035","0.03541","989.39709"
"453.00000","11.90375","112.95072","0.03549","990.71600"
"454.00000","11.92880","113.10267","0.03557","992.04877"
"455.00000","11.95377","113.25619","0.03565","993.39532"
"456.00000","11.97891","113.41151","0.03572","994.75769"
"457.00000","12.00402","113.56536","0.03580","996.10718"
"458.00000","12.02910","113.71664","0.03588","997.43402"
"459.00000","12.05398","113.86753","0.03596","998.75757"
"460.00000","12.07881","114.02299","0.03604","1000.12109"
"461.00000","12.10382","114.18168","0.03612","1001.51306"
"462.00000","12.12869","114.32634","0.03619","1002.78186"
"463.00000","12.15374","114.47559","0.03627","1004.09094"
"464.00000","12.17871","114.61958","0.03635","1005.35400"
"465.00000","12.20396","114.77238","0.03643","1006.69415"
"466.00000","12.22907","114.92466","0.03651","1008.02991"
"467.00000","12.25433","115.07733","0.03659","1009.36902"
"468.00000","12.27921","115.22440","0.03667","1010.65900"
"469.00000","12.30427","115.37466","0.03674","1011.97693"
"470.00000","12.32891","115.51047","0.03682","1013.16815"
"471.00000","12.35377","115.65482","0.03690","1014.43433"
"472.00000","12.37857","115.80035","0.03698","1015.71075"
"473.00000","12.40368","115.94849","0.03706","1017.01007"
"474.00000","12.42863","116.09657","0.03713","1018.30896"
"475.00000","12.45385","116.24492","0.03721","1019.61017"
"476.00000","12.47885","116.39049","0.03729","1020.88696"
"477.00000","12.50421","116.54184","0.03737","1022.21454"
"478.00000","12.52922","116.67935","0.03745","1023.42065"
"479.00000","12.55427","116.82571","0.03753","1024.70435"
"480.00000","12.57907","116.97420","0.03761","1026.00684"
"481.00000","12.60398","117.11398","0.03768","1027.23291"
"482.00000","12.62875","117.24619","0.03776","1028.39258"
"483.00000","12.65366","117.38698","0.03784","1029.62744"
"484.00000","12.67862","117.53297","0.03792","1030.90796"
"485.00000","12.70377","117.67563","0.03800","1032.15930"
"486.00000","12.72886","117.82001","0.03808","1033.42566"
"487.00000","12.75404","117.96078","0.03815","1034.66040"
"488.00000","12.77924","118.10599","0.03823","1035.93408"
"489.00000","12.80420","118.24211","0.03831","1037.12805"
"490.00000","12.82912","118.37852","0.03839","1038.32446"
"491.00000","12.85386","118.51248","0.03847","1039.49951"
"492.00000","12.87884","118.64907","0.03855","1040.69751"
"493.00000","12.90373","118.78840","0.03862","1041.91956"
"494.00000","12.92875","118.92525","0.03870","1043.12000"
"495.00000","12.95372","119.06293","0.03878","1044.32751"
"496.00000","12.97900","119.20689","0.03886","1045.59021"
"497.00000","13.00404","119.33572","0.03894","1046.72021"
"498.00000","13.02913","119.47453","0.03902","1047.93774"
"499.00000","13.05403","119.60664","0.03909","1049.09656"
"500.00000","13.07903","119.74076","0.03917","1050.27295"
"501.00000","13.10379","119.87408","0.03925","1051.44238"
"502.00000","13.12876","120.00233","0.03933","1052.56726"
"503.00000","13.15365","120.13179","0.03941","1053.70276"
"504.00000","13.17883","120.78111","0.03949","1059.39807"
"505.00000","13.20378","120.91087","0.03956","1060.53625"
"506.00000","13.22903","121.04856","0.03964","1061.74402"
"507.00000","13.25403","121.17671","0.03972","1062.86804"
"508.00000","13.27938","121.31564","0.03980","1064.08667"
"509.00000","13.30414","121.45029","0.03988","1065.26770"
"510.00000","13.32909","121.57638","0.03996","1066.37354"
"511.00000","13.35382","121.70115","0.04003","1067.46802"
"512.00000","13.37869","121.82328","0.04011","1068.53918"
"513.00000","13.40349","121.94990","0.04019","1069.64978"
"514.00000","13.42852","122.08188","0.04027","1070.80750"
"515.00000","13.45360","122.20552","0.04035","1071.89197"
"516.00000","13.47887","122.33523","0.04043","1073.02966"
"517.00000","13.50412","122.46278","0.04050","1074.14844"
"518.00000","13.52927","122.59700","0.04058","1075.32568"
"519.00000","13.55438","122.72187","0.04066","1076.42102"
"520.00000","13.57919","122.84896","0.04074","1077.53564"
"521.00000","13.60406","122.97123","0.04082","1078.60815"
"522.00000","13.62879","123.09104","0.04090","1079.65906"
"523.00000","13.65379","123.21737","0.04097","1080.76709"
"524.00000","13.67869","123.33472","0.04105","1081.79639"
"525.00000","13.70375","123.46941","0.04113","1082.97778"
"526.00000","13.72874","123.59565","0.04121","1084.08508"
"527.00000","13.75413","123.72222","0.04129","1085.19531"
"528.00000","13.77918","123.84318","0.04137","1086.25623"
"529.00000","13.80428","123.96702","0.04145","1087.34241"
"530.00000","13.82910","124.08805","0.04152","1088.40405"
"531.00000","13.85398","124.20766","0.04160","1089.45313"
"532.00000","13.87878","124.32683","0.04168","1090.49841"
"533.00000","13.90363","124.44835","0.04176","1091.56433"
"534.00000","13.92853","124.56223","0.04183","1092.56323"
"535.00000","13.95374","124.68554","0.04191","1093.64478"
"536.00000","13.97874","124.80449","0.04199","1094.68811"
"537.00000","14.00401","124.92912","0.04207","1095.78125"
"538.00000","14.02903","125.04658","0.04215","1096.81152"
"539.00000","14.05431","125.17262","0.04223","1097.91699"
"540.00000","14.07904","125.29196","0.04231","1098.96387"
"541.00000","14.10394","125.40627","0.04238","1099.96643"
"542.00000","14.12875","125.52222","0.04246","1100.98352"
"543.00000","14.15374","125.63988","0.04254","1102.01550"
"544.00000","14.17870","125.76142","0.04262","1103.08154"
"545.00000","14.20375","125.87772","0.04270","1104.10168"
"546.00000","14.22885","125.99548","0.04278","1105.13452"
"547.00000","14.25413","126.11340","0.04286","1106.16882"
"548.00000","14.27919","126.22844","0.04293","1107.17786"
"549.00000","14.30423","126.34583","0.04301","1108.20752"
"550.00000","14.32929","126.46258","0.04309","1109.23157"
"551.00000","14.35400","126.56772","0.04317","1110.15381"
"552.00000","14.37883","126.67863","0.04325","1111.12659"
"553.00000","14.40362","126.79147","0.04332","1112.11633"
"554.00000","14.42863","126.90466","0.04340","1113.10913"
"555.00000","14.45355","127.00501","0.04348","1113.98938"
"556.00000","14.47879","127.12401","0.04356","1115.03308"
"557.00000","14.50380","127.22926","0.04364","1115.95630"
"558.00000","14.52926","127.35339","0.04372","1117.04504"
"559.00000","14.55422","127.46039","0.04380","1117.98352"
"560.00000","14.57931","127.56683","0.04387","1118.91711"
"561.00000","14.60405","127.67373","0.04395","1119.85486"
"562.00000","14.62902","127.77963","0.04403","1120.78369"
"563.00000","14.65379","127.88342","0.04411","1121.69409"
"564.00000","14.67870","127.98971","0.04419","1122.62634"
"565.00000","14.70360","128.09746","0.04426","1123.57141"
"566.00000","14.72883","128.20897","0.04434","1124.54956"
"567.00000","14.75378","128.31181","0.04442","1125.45166"
"568.00000","14.77906","128.42969","0.04450","1126.48547"
"569.00000","14.80398","128.53230","0.04458","1127.38562"
"570.00000","14.82910","128.64189","0.04466","1128.34680"
"571.00000","14.85392","128.74199","0.04474","1129.22473"
"572.00000","14.87886","128.84129","0.04481","1130.09583"
"573.00000","14.90379","128.95155","0.04489","1131.06287"
"574.00000","14.92881","129.05455","0.04497","1131.96631"
"575.00000","14.95378","129.15709","0.04505","1132.86572"
"576.00000","14.97881","129.26207","0.04513","1133.78650"
"577.00000","15.00399","129.36334","0.04521","1134.67480"
"578.00000","15.02923","129.46892","0.04528","1135.60083"
"579.00000","15.05418","129.57356","0.04536","1136.51868"
"580.00000","15.07905","129.67451","0.04544","1137.40417"
"581.00000","15.10393","129.77541","0.04552","1138.28906"
"582.00000","15.12876","129.86748","0.04560","1139.09668"
"583.00000","15.15368","129.97084","0.04567","1140.00330"
"584.00000","15.17862","130.06865","0.04575","1140.86121"
"585.00000","15.20382","130.17175","0.04583","1141.76550"
"586.00000","15.22888","130.27312","0.04591","1142.65466"
"587.00000","15.25409","130.37775","0.04599","1143.57239"
"588.00000","15.27905","130.47765","0.04607","1144.44861"
"589.00000","15.30436","130.58525","0.04615","1145.39246"
"590.00000","15.32918","130.67805","0.04622","1146.20642"
"591.00000","15.35410","130.78085","0.04630","1147.10815"
"592.00000","15.37881","130.87215","0.04638","1147.90881"
"593.00000","15.40378","130.97144","0.04646","1148.77979"
"594.00000","15.42858","131.06152","0.04654","1149.56995"
"595.00000","15.45363","131.16281","0.04661","1150.45837"
"596.00000","15.47865","131.25954","0.04669","1151.30676"
"597.00000","15.50403","131.36208","0.04677","1152.20618"
"598.00000","15.52905","131.45795","0.04685","1153.04700"
"599.00000","15.55427","131.55038","0.04693","1153.85779"
"600.00000","15.57911","131.64951","0.04701","1154.72729"
"601.00000","15.60410","131.74156","0.04709","1155.53467"
"602.00000","15.62881","131.83752","0.04716","1156.37634"
"603.00000","15.65377","131.93011","0.04724","1157.18848"
"604.00000","15.67866","132.01723","0.04732","1157.95264"
"605.00000","15.70380","132.11424","0.04740","1158.80359"
"606.00000","15.72874","132.20564","0.04748","1159.60522"
"607.00000","15.75382","132.30156","0.04756","1160.44653"
"608.00000","15.77900","132.40030","0.04763","1161.31262"
"609.00000","15.80405","132.48415","0.04771","1162.04810"
"610.00000","15.82908","132.57747","0.04779","1162.86658"
"611.00000","15.85393","132.66711","0.04787","1163.65295"
"612.00000","15.87896","132.75996","0.04795","1164.46729"
"613.00000","15.90377","132.84479","0.04803","1165.21130"
"614.00000","15.92877","132.93628","0.04810","1166.01379"
"615.00000","15.95371","133.02599","0.04818","1166.80066"
"616.00000","15.97891","133.11143","0.04826","1167.55017"
"617.00000","16.00401","133.20631","0.04834","1168.38232"
"618.00000","16.02924","133.30011","0.04842","1169.20508"
"619.00000","16.05413","133.37866","0.04850","1169.89404"
"620.00000","16.07929","133.46581","0.04858","1170.65845"
"621.00000","16.10390","133.55223","0.04865","1171.41650"
"622.00000","16.12875","133.63466","0.04873","1172.13953"
"623.00000","16.15351","133.72069","0.04881","1172.89404"
"624.00000","16.17855","133.80450","0.04889","1173.62927"
"625.00000","16.20352","133.89609","0.04896","1174.43250"
"626.00000","16.22876","133.97879","0.04904","1175.15796"
"627.00000","16.25382","134.06427","0.04912","1175.90771"
"628.00000","16.27930","134.15498","0.04920","1176.70337"
"629.00000","16.30421","134.23564","0.04928","1177.41077"
"630.00000","16.32943","134.32300","0.04936","1178.17700"
"631.00000","16.35411","134.39795","0.04944","1178.83447"
"632.00000","16.37910","134.48492","0.04952","1179.59729"
"633.00000","16.40377","134.55994","0.04959","1180.25525"
"634.00000","16.42865","134.63834","0.04967","1180.94299"
"635.00000","16.45357","134.71939","0.04975","1181.65393"
"636.00000","16.47870","134.80360","0.04983","1182.39258"
"637.00000","16.50380","134.88857","0.04991","1183.13782"
"638.00000","16.52901","134.96690","0.04998","1183.82483"
"639.00000","16.55422","135.05150","0.05006","1184.56689"
"640.00000","16.57931","135.12822","0.05014","1185.23987"
"641.00000","16.60420","135.21613","0.05022","1186.01086"
"642.00000","16.62892","135.28505","0.05030","1186.61536"
"643.00000","16.65385","135.37256","0.05038","1187.38293"
"644.00000","16.67865","135.44463","0.05045","1188.01514"
"645.00000","16.70365","135.52699","0.05053","1188.73755"
"646.00000","16.72862","135.61502","0.05061","1189.50964"
"647.00000","16.75388","135.69330","0.05069","1190.19629"
"648.00000","16.77891","135.77431","0.05077","1190.90686"
"649.00000","16.80423","135.84630","0.05085","1191.53821"
"650.00000","16.82914","135.93015","0.05093","1192.27368"
"651.00000","16.85419","136.00352","0.05100","1192.91736"
"652.00000","16.87893","136.07253","0.05108","1193.52258"
"653.00000","16.90382","136.14775","0.05116","1194.18237"
"654.00000","16.92867","136.22200","0.05124","1194.83362"
"655.00000","16.95380","136.29718","0.05132","1195.49304"
"656.00000","16.97870","136.37384","0.05139","1196.16541"
"657.00000","17.00390","136.44595","0.05147","1196.79797"
"658.00000","17.02889","136.51807","0.05155","1197.43054"
"659.00000","17.05429","136.59572","0.05163","1198.11157"
"660.00000","17.07913","136.66629","0.05171","1198.73059"
"661.00000","17.10414","136.73936","0.05179","1199.37158"
"662.00000","17.12886","136.80835","0.05186","1199.97656"
"663.00000","17.15378","136.87506","0.05194","1200.56177"
"664.00000","17.17860","136.95341","0.05202","1201.24902"
"665.00000","17.20363","137.02107","0.05210","1201.84241"
"666.00000","17.22857","137.09584","0.05218","1202.49829"
"667.00000","17.25379","137.17474","0.05226","1203.19031"
"668.00000","17.27898","137.24696","0.05234","1203.82385"
"669.00000","17.30412","137.32124","0.05241","1204.47534"
"670.00000","17.32936","137.39188","0.05249","1205.09485"
"671.00000","17.35428","137.46495","0.05257","1205.73584"
"672.00000","17.37915","137.53667","0.05265","1206.36487"
"673.00000","17.40384","137.60193","0.05273","1206.93726"
"674.00000","17.42875","137.67334","0.05280","1207.56360"
"675.00000","17.45362","137.73883","0.05288","1208.13806"
"676.00000","17.47863","137.80402","0.05296","1208.70984"
"677.00000","17.50359","137.86514","0.05304","1209.24597"
"678.00000","17.52890","137.93967","0.05312","1209.89966"
"679.00000","17.55397","138.00426","0.05320","1210.46619"
"680.00000","17.57916","138.07036","0.05328","1211.04602"
"681.00000","17.60409","138.13789","0.05335","1211.63831"
"682.00000","17.62910","138.20111","0.05343","1212.19287"
"683.00000","17.65387","138.26006","0.05351","1212.70984"
"684.00000","17.67878","138.32759","0.05359","1213.30225"
"685.00000","17.70366","138.39400","0.05367","1213.88464"
"686.00000","17.72884","138.46373","0.05375","1214.49634"
"687.00000","17.75374","138.52325","0.05382","1215.01843"
"688.00000","17.77890","138.59569","0.05390","1215.65381"
"689.00000","17.80389","138.65240","0.05398","1216.15125"
"690.00000","17.82914","138.72153","0.05406","1216.75757"
"691.00000","17.85399","138.78310","0.05414","1217.29761"
"692.00000","17.87898","138.84042","0.05422","1217.80042"
"693.00000","17.90382","138.89680","0.05429","1218.29492"
"694.00000","17.92881","138.95685","0.05437","1218.82153"
"695.00000","17.95370","139.01353","0.05445","1219.31885"
"696.00000","17.97875","139.07233","0.05453","1219.83447"
"697.00000","18.00379","139.13335","0.05461","1220.36963"
"698.00000","18.02906","139.19789","0.05469","1220.93579"
"699.00000","18.05417","139.26605","0.05476","1221.53369"
"700.00000","18.07916","139.32315","0.05484","1222.03455"
"701.00000","18.10426","139.38362","0.05492","1222.56494"
"702.00000","18.12901","139.44403","0.05500","1223.09473"
"703.00000","18.15384","139.49843","0.05508","1223.57190"
"704.00000","18.17863","139.55760","0.05515","1224.09094"
"705.00000","18.20366","139.61951","0.05523","1224.63391"
"706.00000","18.22865","139.68269","0.05531","1225.18811"
"707.00000","18.25381","139.74619","0.05539","1225.74500"
"708.00000","18.27889","139.80264","0.05547","1226.24023"
"709.00000","18.30424","139.86748","0.05555","1226.80896"
"710.00000","18.32918","139.92206","0.05563","1227.28760"
"711.00000","18.35422","139.98508","0.05571","1227.84045"
"712.00000","18.37893","140.03998","0.05578","1228.32190"
"713.00000","18.40392","140.10036","0.05586","1228.85156"
"714.00000","18.42878","140.15805","0.05594","1229.35754"
"715.00000","18.45373","140.21071","0.05602","1229.81946"
"716.00000","18.47861","140.26076","0.05609","1230.25842"
"717.00000","18.50387","140.31966","0.05617","1230.77502"
"718.00000","18.52873","140.37103","0.05625","1231.22571"
"719.00000","18.55404","140.43253","0.05633","1231.76514"
"720.00000","18.57906","140.48460","0.05641","1232.22192"
"721.00000","18.60419","140.54060","0.05649","1232.71301"
"722.00000","18.62906","140.58958","0.05657","1233.14270"
"723.00000","18.65399","140.64227","0.05664","1233.60486"
"724.00000","18.67881","140.69421","0.05672","1234.06042"
"725.00000","18.70384","140.74638","0.05680","1234.51794"
"726.00000","18.72875","140.79654","0.05688","1234.95789"
"727.00000","18.75384","140.84703","0.05696","1235.40076"
"728.00000","18.77887","140.90337","0.05704","1235.89490"
"729.00000","18.80414","140.95952","0.05712","1236.38745"
"730.00000","18.82917","141.01236","0.05719","1236.85095"
"731.00000","18.85402","141.05836","0.05727","1237.25439"
"732.00000","18.87897","141.11514","0.05735","1237.75244"
"733.00000","18.90369","141.15854","0.05743","1238.13306"
"734.00000","18.92860","141.21066","0.05751","1238.59033"
"735.00000","18.95355","141.25894","0.05758","1239.01379"
"736.00000","18.97872","141.30670","0.05766","1239.43262"
"737.00000","19.00384","141.34053","0.05774","1239.72937"
"738.00000","19.02909","141.40051","0.05782","1240.25549"
"739.00000","19.05403","141.44926","0.05790","1240.68311"
"740.00000","19.07943","141.50632","0.05798","1241.18359"
"741.00000","19.10422","141.55655","0.05806","1241.62415"
"742.00000","19.12916","141.60564","0.05813","1242.05469"
"743.00000","19.15382","141.64667","0.05821","1242.41455"
"744.00000","19.17878","141.70006","0.05829","1242.88293"
"745.00000","19.20357","141.75191","0.05837","1243.33765"
"746.00000","19.22862","141.80109","0.05845","1243.76904"
"747.00000","19.25361","141.85472","0.05852","1244.23950"
"748.00000","19.27895","141.91127","0.05860","1244.73547"
"749.00000","19.30399","141.95335","0.05868","1245.10461"
"750.00000","19.32928","142.00735","0.05876","1245.57825"
"751.00000","19.35422","142.06306","0.05884","1246.06689"
"752.00000","19.37925","142.10902","0.05892","1246.46997"
"753.00000","19.40390","142.14998","0.05899","1246.82922"
"754.00000","19.42883","142.19391","0.05907","1247.21460"
"755.00000","19.45359","142.23730","0.05915","1247.59521"
"756.00000","19.47872","142.28951","0.05923","1248.05310"
"757.00000","19.50363","142.33128","0.05931","1248.41956"
"758.00000","19.52876","142.37837","0.05939","1248.83252"
"759.00000","19.55394","142.42488","0.05947","1249.24048"
"760.00000","19.57924","142.47318","0.05954","1249.66406"
"761.00000","19.60426","142.51799","0.05962","1250.05713"
"762.00000","19.62910","142.55656","0.05970","1250.39551"
"763.00000","19.65402","142.59694","0.05978","1250.74963"
"764.00000","19.67881","142.63261","0.05986","1251.06250"
"765.00000","19.70374","142.67554","0.05993","1251.43909"
"766.00000","19.72861","142.71693","0.06001","1251.80212"
"767.00000","19.75383","142.75706","0.06009","1252.15417"
"768.00000","19.77889","142.80374","0.06017","1252.56360"
"769.00000","19.80410","142.84027","0.06025","1252.88391"
"770.00000","19.82906","142.88297","0.06033","1253.25842"
"771.00000","19.85425","142.92644","0.06041","1253.63977"
"772.00000","19.87902","142.96304","0.06048","1253.96082"
"773.00000","19.90390","143.00342","0.06056","1254.31494"
"774.00000","19.92866","143.03795","0.06064","1254.61780"
"775.00000","19.95370","143.08150","0.06072","1254.99976"
"776.00000","19.97860","143.11931","0.06080","1255.33142"
"777.00000","20.00371","143.15730","0.06087","1255.66467"
"778.00000","20.02872","143.19661","0.06095","1256.00952"
"779.00000","20.05419","143.24113","0.06103","1256.40002"
"780.00000","20.07911","143.28194","0.06111","1256.75793"
"781.00000","20.10439","143.32121","0.06119","1257.10242"
"782.00000","20.12916","143.35995","0.06127","1257.44226"
"783.00000","20.15412","143.40004","0.06135","1257.79382"
"784.00000","20.17883","143.43733","0.06142","1258.12085"
"785.00000","20.20366","143.47243","0.06150","1258.42871"
"786.00000","20.22857","143.51021","0.06158","1258.76013"
"787.00000","20.25362","143.54883","0.06166","1259.09888"
"788.00000","20.27864","143.58391","0.06174","1259.40662"
"789.00000","20.30385","143.62328","0.06182","1259.75183"
"790.00000","20.32915","143.66679","0.06189","1260.13354"
"791.00000","20.35423","143.70569","0.06197","1260.47473"
"792.00000","20.37925","143.73904","0.06205","1260.76733"
"793.00000","20.40405","143.77892","0.06213","1261.11707"
"794.00000","20.42902","143.81792","0.06221","1261.45911"
"795.00000","20.45378","143.84880","0.06229","1261.72998"
"796.00000","20.47879","143.89226","0.06236","1262.11121"
"797.00000","20.50365","143.92691","0.06244","1262.41516"
"798.00000","20.52885","143.96976","0.06252","1262.79089"
"799.00000","20.55389","143.99634","0.06260","1263.02405"
"800.00000","20.57909","144.03596","0.06268","1263.37170"
"801.00000","20.60399","144.06935","0.06276","1263.66443"
"802.00000","20.62912","144.10226","0.06283","1263.95313"
"803.00000","20.65394","144.12897","0.06291","1264.18738"
"804.00000","20.67889","144.16632","0.06299","1264.51501"
"805.00000","20.70372","144.19485","0.06307","1264.76526"
"806.00000","20.72879","144.22678","0.06315","1265.04529"
"807.00000","20.75371","144.25905","0.06323","1265.32837"
"808.00000","20.77891","144.29175","0.06330","1265.61523"
"809.00000","20.80388","144.32193","0.06338","1265.87988"
"810.00000","20.82929","144.35707","0.06346","1266.18811"
"811.00000","20.85415","144.38556","0.06354","1266.43799"
"812.00000","20.87923","144.41512","0.06362","1266.69727"
"813.00000","20.90397","144.44376","0.06370","1266.94849"
"814.00000","20.92887","144.47159","0.06377","1267.19263"
"815.00000","20.95367","144.49503","0.06385","1267.39819"
"816.00000","20.97868","144.52054","0.06393","1267.62195"
"817.00000","21.00370","144.55107","0.06401","1267.88977"
"818.00000","21.02891","144.57497","0.06409","1268.09937"
"819.00000","21.05400","144.59135","0.06417","1268.24304"
"819.99902","21.07903","141.44989","0.06424","1240.68860"
"820.01001","21.07934","103.87321","0.06425","911.09521"
"820.01501","21.07949","82.47527","0.06425","723.40900"