File: experimental/sma_database/flexinol_isobaric_trained_100MPa.csv
Test : Start of hold value,"100.00000",MPa

Time,Extension,Load,Temperature: Chamber 3119-600 1 1,Tensile strain (Extension),Tensile stress
(s),(mm),(N),(C),(mm/mm),(MPa)
"0.00000","1.20676","0.46379","29.11588","0.00000","4.06799"
"4.60000","1.24404","0.64249","29.14404","0.00037","5.63541"
"9.20000","1.28235","0.61932","29.06344","0.00075","5.43224"
"13.80000","1.32073","0.76404","29.03812","0.00113","6.70160"
"18.40000","1.35912","0.95671","29.07618","0.00151","8.39153"
"23.00000","1.39738","1.05972","29.05941","0.00188","9.29507"
"27.60000","1.43567","1.23008","29.09480","0.00226","10.78929"
"32.20000","1.47415","1.58990","29.16897","0.00264","13.94541"
"36.80000","1.51245","1.88323","29.12845","0.00302","16.51820"
"41.40000","1.55069","2.21849","29.01185","0.00340","19.45885"
"46.00000","1.58898","2.53550","28.99224","0.00378","22.23945"
"50.60000","1.62747","2.83020","28.97617","0.00416","24.82430"
"55.20000","1.66582","3.23551","28.91252","0.00454","28.37940"
"59.80000","1.70400","3.56986","29.03386","0.00491","31.31206"
"64.40000","1.74229","3.88294","29.05999","0.00529","34.05813"
"69.00000","1.78077","4.12027","28.93651","0.00567","36.13985"
"73.60000","1.81916","4.33641","28.83641","0.00605","38.03563"
"78.20000","1.85741","4.65814","28.87289","0.00643","40.85756"
"82.80000","1.89562","4.82989","29.03066","0.00681","42.36407"
"87.40000","1.93410","4.95399","29.11035","0.00719","43.45256"
"92.00000","1.97250","5.09126","29.15479","0.00757","44.65657"
"96.60000","2.01077","5.20573","29.19627","0.00794","45.66066"
"101.20000","2.04897","5.37985","29.19772","0.00832","47.18786"
"105.80000","2.08741","5.53535","29.16746","0.00870","48.55180"
"110.40000","2.12576","5.79484","29.12074","0.00908","50.82784"
"115.00000","2.16411","6.04813","29.15426","0.00946","53.04953"
"119.60000","2.20228","6.24714","29.18284","0.00984","54.79507"
"124.20000","2.24076","6.37618","29.24891","0.01022","55.92694"
"128.80000","2.27909","6.40787","29.23336","0.01060","56.20483"
"133.40000","2.31742","6.58265","29.18255","0.01097","57.73790"
"138.00000","2.35566","6.86525","29.16128","0.01135","60.21665"
"142.60000","2.39408","7.16996","29.21729","0.01173","62.88928"
"147.20000","2.43247","7.53875","29.26973","0.01211","66.12402"
"151.80000","2.47071","7.78329","29.27592","0.01249","68.26898"
"156.40000","2.50899","7.93809","29.22489","0.01287","69.62678"
"161.00000","2.54741","8.14401","29.23621","0.01325","71.43292"
"165.60000","2.58577","8.36911","29.35979","0.01363","73.40732"
"170.20000","2.62403","8.73313","29.29353","0.01400","76.60027"
"174.80000","2.66232","8.91899","29.22071","0.01438","78.23042"
"179.40000","2.70075","9.17332","29.16208","0.01476","80.46120"
"184.00000","2.73922","9.61838","29.20811","0.01514","84.36496"
"188.60000","2.77740","9.99486","29.25705","0.01552","87.66713"
"193.20000","2.81561","10.21035","29.28687","0.01590","89.55730"
"197.80000","2.85409","10.42392","29.28915","0.01628","91.43057"
"202.40000","2.89253","10.71329","29.22872","0.01666","93.96867"
"207.00000","2.93077","10.79275","29.27927","0.01703","94.66558"
"211.60000","2.96899","11.13179","29.27707","0.01741","97.63943"
"216.20000","3.00732","11.24844","29.33832","0.01779","98.66258"
"220.60500","3.11034","11.94868","29.38775","0.01881","104.80456"
"225.20500","3.11242","11.65968","29.37147","0.01883","102.26966"
"229.80500","3.11240","11.30385","29.42597","0.01883","99.14857"
"234.40500","3.11239","11.19652","29.41178","0.01883","98.20715"
"239.00500","3.11238","11.14888","29.48372","0.01883","97.78928"
"243.60500","3.11239","11.06597","29.54075","0.01883","97.06213"
"248.20500","3.11240","10.99242","29.59571","0.01883","96.41695"
"252.80500","3.11242","11.02191","29.66079","0.01883","96.67561"
"257.40500","3.11250","11.05466","29.65914","0.01883","96.96294"
"262.00500","3.11481","11.27677","29.68040","0.01885","98.91111"
"266.60500","3.12669","11.34233","29.65324","0.01897","99.48609"
"271.20500","3.16406","11.92049","29.59360","0.01934","104.55732"
"275.80500","3.16416","11.96404","29.57270","0.01934","104.93930"
"280.40500","3.16408","11.91478","29.56509","0.01934","104.50724"
"285.00500","3.16400","11.91668","29.59006","0.01934","104.52385"
"289.60500","3.16391","11.87428","29.63957","0.01934","104.15201"
"294.20500","3.16380","11.67398","29.87636","0.01934","102.39513"
"298.80500","3.16357","11.45094","30.30259","0.01933","100.43876"
"303.40500","3.16320","11.93571","30.44516","0.01933","104.69074"
"308.00500","3.16271","11.76174","30.91092","0.01933","103.16489"
"312.60500","3.15084","11.86147","31.27262","0.01921","104.03961"
"317.20500","3.08991","10.82848","31.71752","0.01861","94.97902"
"321.80500","3.08881","11.00208","32.03348","0.01860","96.50175"
"326.40500","3.08893","11.08868","32.53626","0.01860","97.26126"
"331.00500","3.08928","10.92682","32.73899","0.01860","95.84154"
"335.60500","3.08950","11.15394","33.00881","0.01860","97.83370"
"340.20500","3.09016","11.16211","33.43515","0.01861","97.90535"
"344.80500","3.09086","11.29418","33.85406","0.01862","99.06382"
"349.40500","3.09205","11.29879","34.22335","0.01863","99.10420"
"354.00500","3.09507","11.44879","34.60524","0.01866","100.41991"
"358.60500","3.09693","11.50788","35.02133","0.01868","100.93823"
"363.20500","3.09689","11.57467","35.48638","0.01868","101.52403"
"367.80500","3.09681","11.64832","35.97794","0.01867","102.17006"
"372.40500","3.09672","11.73365","36.50314","0.01867","102.91845"
"377.00500","3.09656","11.79602","37.12115","0.01867","103.46554"
"381.60500","3.09622","11.89296","37.72286","0.01867","104.31581"
"386.20500","3.09073","11.89219","38.43249","0.01861","104.30907"
"390.80500","3.05389","11.48998","39.14325","0.01825","100.78115"
"395.40500","3.00247","10.91677","39.88977","0.01774","95.75340"
"400.00500","3.00258","11.05719","40.70153","0.01774","96.98511"
"404.60500","3.00265","11.20462","41.47660","0.01774","98.27820"
"409.20500","3.00270","11.31306","42.29574","0.01774","99.22934"
"413.80500","3.00271","11.44497","43.04340","0.01775","100.38638"
"418.40500","3.00269","11.51573","43.83303","0.01774","101.00708"
"423.00500","3.00263","11.64154","44.52902","0.01774","102.11053"
"427.60500","3.00254","11.68325","45.14986","0.01774","102.47637"
"432.20500","3.00218","11.81482","45.82609","0.01774","103.63043"
"436.80500","2.95650","11.22922","46.52785","0.01729","98.49403"
"441.40500","2.95106","11.26749","47.13857","0.01723","98.82964"
"446.00500","2.95101","11.40347","47.80957","0.01723","100.02236"
"450.60500","2.95092","11.45916","48.42770","0.01723","100.51089"
"455.20500","2.94994","11.60530","49.06689","0.01722","101.79264"
"459.80500","2.90769","11.07861","49.66063","0.01681","97.17296"
"464.40500","2.90423","11.21050","50.26036","0.01677","98.32978"
"469.00500","2.90427","11.26697","50.88989","0.01677","98.82515"
"473.60500","2.90428","11.42623","51.49020","0.01677","100.22202"
"478.20500","2.90426","11.51386","52.12632","0.01677","100.99062"
"482.80500","2.90420","11.59025","52.72913","0.01677","101.66066"
"487.40500","2.90339","11.73732","53.32647","0.01676","102.95065"
"492.00500","2.85824","11.17382","53.98279","0.01632","98.00811"
"496.60500","2.85394","11.31249","54.59817","0.01628","99.22441"
"501.20500","2.85386","11.41020","55.24822","0.01627","100.08138"
"505.80500","2.85350","11.58252","55.89377","0.01627","101.59291"
"510.40500","2.80796","11.06051","56.52713","0.01582","97.01424"
"515.00500","2.80672","11.22426","57.19118","0.01581","98.45047"
"519.60500","2.80674","11.34830","57.84959","0.01581","99.53846"
"524.20500","2.80674","11.46246","58.49467","0.01581","100.53979"
"528.80500","2.80659","11.62409","59.15233","0.01581","101.95749"
"533.40500","2.79812","11.61002","59.85215","0.01572","101.83408"
"538.00500","2.75097","11.18827","60.48785","0.01526","98.13484"
"542.60500","2.72722","11.02416","61.08966","0.01502","96.69536"
"547.20500","2.71795","11.06419","61.73447","0.01493","97.04652"
"551.80500","2.71808","11.25202","62.36450","0.01493","98.69400"
"556.40500","2.71814","11.32971","62.99757","0.01493","99.37544"
"561.00500","2.71812","11.54265","63.51899","0.01493","101.24321"
"565.60500","2.71799","11.64064","64.10429","0.01493","102.10262"
"570.20500","2.71074","11.79270","64.74124","0.01486","103.43640"
"574.80500","2.65792","11.26647","65.38722","0.01434","98.82075"
"579.40500","2.62667","11.04870","66.00053","0.01403","96.91062"
"584.00500","2.62414","11.36336","66.65334","0.01400","99.67061"
"588.60500","2.62413","11.54284","67.25753","0.01400","101.24480"
"593.20500","2.62299","11.64351","67.87834","0.01399","102.12784"
"597.80500","2.59307","11.49212","68.54877","0.01370","100.79998"
"602.40500","2.56083","11.47605","69.15357","0.01338","100.65902"
"607.00500","2.52280","11.17058","69.83910","0.01300","97.97963"
"611.60500","2.51900","11.39794","70.45382","0.01297","99.97392"
"616.20500","2.50853","11.62916","71.07380","0.01286","102.00194"
"620.80500","2.46292","11.36310","71.68259","0.01241","99.66827"
"625.40500","2.42304","11.28500","72.32565","0.01202","98.98322"
"630.00500","2.41869","11.51604","72.96551","0.01197","101.00980"
"634.60500","2.38199","11.54271","73.53596","0.01161","101.24369"
"639.20500","2.32905","11.32383","74.15634","0.01109","99.32382"
"643.80500","2.29562","11.34581","74.79309","0.01076","99.51661"
"648.40500","2.24792","11.35758","75.43591","0.01029","99.61984"
"653.00500","2.21116","11.46158","76.08574","0.00992","100.53207"
"657.60500","2.16821","11.59471","76.71006","0.00950","101.69981"
"662.20500","2.11114","11.46809","77.35269","0.00894","100.58915"
"666.80500","2.04546","11.46992","77.95370","0.00829","100.60524"
"671.40500","1.98304","11.29302","78.58402","0.00767","99.05360"
"676.00500","1.92341","11.45454","79.22118","0.00708","100.47029"
"680.60500","1.84471","11.36851","79.84673","0.00630","99.71574"
"685.20500","1.78940","11.56366","80.50526","0.00576","101.42747"
"689.80500","1.71306","11.36485","81.11781","0.00500","99.68366"
"694.40500","1.60504","11.30909","81.71517","0.00393","99.19453"
"699.00500","1.53042","11.30480","82.25301","0.00320","99.15690"
"703.60500","1.45728","11.44640","82.82534","0.00248","100.39894"
"708.20500","1.35471","11.43155","83.38497","0.00146","100.26869"
"712.80500","1.24174","11.49985","84.00632","0.00035","100.86776"
"717.40500","1.13514","11.52723","84.62366","-0.00071","101.10791"
"722.00500","0.99745","11.29295","85.27778","-0.00207","99.05303"
"726.60500","0.88198","11.63729","85.83622","-0.00321","102.07330"
"731.20500","0.69217","11.29863","86.41896","-0.00508","99.10284"
"735.80500","0.50836","11.50668","87.08994","-0.00690","100.92764"
"740.40500","0.36245","11.56473","87.71945","-0.00834","101.43684"
"745.00500","0.00893","11.14849","88.39682","-0.01184","97.78587"
"749.60500","-0.22762","11.19621","88.96338","-0.01417","98.20448"
"754.20500","-0.43382","11.70197","89.53747","-0.01621","102.64061"
"758.80500","-0.73742","11.45378","90.21278","-0.01921","100.46367"
"763.40500","-1.01595","11.51481","90.79327","-0.02196","100.99900"
"768.00500","-1.42902","11.28349","91.47936","-0.02604","98.97005"
"772.60500","-1.82288","11.38148","92.14501","-0.02994","99.82950"
"777.20500","-2.11681","11.30918","92.76169","-0.03284","99.19537"
"781.80500","-2.37681","11.39963","93.34283","-0.03541","99.98872"
"786.40500","-2.59136","11.59414","93.90509","-0.03753","101.69478"
"791.00500","-2.84920","11.20926","94.55421","-0.04008","98.31892"
"795.60500","-3.08794","11.41542","95.18676","-0.04244","100.12718"
"800.20500","-3.26796","11.48632","95.86765","-0.04421","100.74911"
"804.80500","-3.47746","11.42110","96.47957","-0.04628","100.17703"
"809.40500","-3.68880","11.18282","97.12570","-0.04837","98.08701"
"814.00500","-3.81863","11.38818","97.71883","-0.04965","99.88827"
"818.60500","-3.97127","11.33528","98.32142","-0.05116","99.42424"
"823.20500","-4.05880","11.70125","98.85229","-0.05203","102.63424"
"827.80500","-4.18289","11.25079","99.47961","-0.05325","98.68322"
"832.40500","-4.37238","11.51597","100.04984","-0.05513","101.00913"
"837.00500","-4.41218","11.82464","100.66364","-0.05552","103.71658"
"841.60500","-4.66354","10.73958","101.32724","-0.05800","94.19922"
"846.20500","-4.74679","11.25437","101.84702","-0.05883","98.71464"
"850.80500","-4.80424","11.56911","102.46867","-0.05939","101.47527"
"855.40500","-4.84170","12.07870","103.14019","-0.05976","105.94501"
"860.00500","-5.11577","10.78741","103.72697","-0.06247","94.61877"
"864.60500","-5.22190","11.13315","104.33766","-0.06352","97.65139"
"869.20500","-5.26791","11.31099","104.92269","-0.06397","99.21118"
"873.80500","-5.37035","11.38414","105.59359","-0.06499","99.85281"
"878.40500","-5.47089","11.26021","106.22718","-0.06598","98.76579"
"883.00500","-5.53188","11.73162","106.90681","-0.06658","102.90066"
"887.60500","-5.61831","11.28005","107.55021","-0.06744","98.93987"
"892.20500","-5.70116","11.19095","108.15404","-0.06826","98.15829"
"896.80500","-5.75615","11.40696","108.76270","-0.06880","100.05301"
"901.40500","-5.81976","11.59386","109.36740","-0.06943","101.69237"
"906.00500","-5.89623","11.33242","109.98800","-0.07018","99.39918"
"910.60500","-5.97104","11.30212","110.60750","-0.07092","99.13339"
"915.20500","-6.00351","11.59842","111.13315","-0.07124","101.73234"
"919.80500","-6.05383","11.41313","111.75981","-0.07174","100.10713"
"924.40500","-6.11195","11.38687","112.33444","-0.07231","99.87682"
"929.00500","-6.16328","11.45838","113.01774","-0.07282","100.50402"
"933.60500","-6.21617","11.42112","113.60453","-0.07334","100.17721"
"938.20500","-6.26834","11.22187","114.24014","-0.07386","98.42954"
"942.80500","-6.30383","11.53454","114.80442","-0.07421","101.17202"
"947.40500","-6.38350","11.03701","115.50710","-0.07500","96.80812"
"952.00500","-6.39135","11.56687","116.15655","-0.07508","101.45562"
"956.60500","-6.43865","11.33278","116.66734","-0.07554","99.40234"
"961.20500","-6.48859","11.30417","117.24511","-0.07604","99.15137"
"965.80500","-6.51122","11.66281","117.85704","-0.07626","102.29707"
"970.40500","-6.58754","11.34889","118.49627","-0.07701","99.54361"
"975.00500","-6.62175","11.30980","119.15639","-0.07735","99.20081"
"979.60500","-6.63044","11.48742","119.79427","-0.07744","100.75877"
"984.20500","-6.68203","11.38588","120.36843","-0.07795","99.86811"
"988.80500","-6.71008","11.35635","120.96631","-0.07822","99.60906"
"993.40500","-6.72961","11.55321","121.47739","-0.07842","101.33582"
"998.00500","-6.78609","11.32687","122.05103","-0.07898","99.35050"
"1002.60500","-6.81678","11.28251","122.72009","-0.07928","98.96138"
"1007.20500","-6.82713","11.62252","123.33852","-0.07938","101.94373"
"1011.80500","-6.87550","11.26099","123.93536","-0.07986","98.77263"
"1016.40500","-6.89006","11.42763","124.46412","-0.08000","100.23429"
"1021.00500","-6.90975","11.25430","124.91908","-0.08020","98.71403"
"1025.60500","-6.91085","11.40118","125.24933","-0.08021","100.00231"
"1030.20500","-6.91220","11.26169","125.53173","-0.08022","98.77879"
"1034.80500","-6.91284","11.38379","125.61021","-0.08023","99.84977"
"1039.40500","-6.91296","11.30138","125.61500","-0.08023","99.12690"
"1044.00500","-6.91302","11.25567","125.65276","-0.08023","98.72597"
"1048.60500","-6.91298","11.33530","125.49212","-0.08023","99.42442"
"1053.20500","-6.91293","11.29119","125.34106","-0.08023","99.03751"
"1057.80500","-6.91281","11.20042","125.16747","-0.08023","98.24136"
"1062.40500","-6.91266","11.23919","124.97005","-0.08023","98.58146"
"1067.00500","-6.91250","11.15360","124.81079","-0.08022","97.83069"
"1071.60500","-6.91218","11.02254","124.60464","-0.08022","96.68114"
"1076.20500","-6.91148","11.02747","124.32230","-0.08021","96.72439"
"1080.80500","-6.90037","11.04493","124.05935","-0.08010","96.87751"
"1085.40500","-6.85667","11.58938","123.77570","-0.07967","101.65304"
"1090.00500","-6.85658","11.38035","123.32870","-0.07967","99.81960"
"1094.60500","-6.85632","11.19493","122.94488","-0.07967","98.19320"
"1099.20500","-6.80670","11.80592","122.43546","-0.07918","103.55233"
"1103.80500","-6.80655","11.63131","121.91745","-0.07918","102.02081"
"1108.40500","-6.80655","11.26288","121.37846","-0.07918","98.78924"
"1113.00500","-6.80643","11.10038","120.79665","-0.07918","97.36395"
"1117.60500","-6.75753","11.58979","120.08974","-0.07869","101.65662"
"1122.20500","-6.75009","11.41512","119.41822","-0.07862","100.12458"
"1126.80500","-6.74956","11.23182","118.75883","-0.07861","98.51681"
"1131.40500","-6.71045","11.64130","118.08430","-0.07823","102.10849"
"1136.00500","-6.71032","11.42533","117.42102","-0.07823","100.21409"
"1140.60500","-6.70846","11.11067","116.73656","-0.07821","97.45422"
"1145.20500","-6.66937","11.59673","116.11007","-0.07782","101.71754"
"1149.80500","-6.66895","11.26246","115.40036","-0.07782","98.78555"
"1154.40500","-6.64779","11.37664","114.78191","-0.07761","99.78703"
"1159.00500","-6.61640","11.68059","114.18211","-0.07730","102.45305"
"1163.60500","-6.61635","11.33005","113.61299","-0.07730","99.37843"
"1168.20500","-6.61624","11.20192","113.05882","-0.07730","98.25456"
"1172.80500","-6.59489","11.31361","112.47536","-0.07709","99.23419"
"1177.40500","-6.57084","11.51707","111.90839","-0.07685","101.01879"
"1182.00500","-6.56641","11.34715","111.33792","-0.07681","99.52834"
"1186.60500","-6.54382","11.47921","110.77964","-0.07658","100.68668"
"1191.20500","-6.51672","11.58311","110.29976","-0.07631","101.59807"
"1195.80500","-6.51674","11.36676","109.80965","-0.07631","99.70043"
"1200.40500","-6.51669","11.27215","109.31187","-0.07631","98.87051"
"1205.00500","-6.49930","11.20328","108.87880","-0.07614","98.26645"
"1209.60500","-6.46856","11.52405","108.41280","-0.07584","101.08003"
"1214.20500","-6.46851","11.26405","107.97397","-0.07584","98.79952"
"1218.80500","-6.46318","11.25157","107.51343","-0.07579","98.69000"
"1223.40500","-6.41683","11.74262","107.13756","-0.07533","102.99712"
"1228.00500","-6.41673","11.46986","106.69270","-0.07533","100.60468"
"1232.60500","-6.41664","11.19688","106.30827","-0.07533","98.21033"
"1237.20500","-6.39161","11.51792","105.90057","-0.07508","101.02625"
"1241.80500","-6.38006","11.29416","105.45676","-0.07496","99.06358"
"1246.40500","-6.37712","11.29115","105.02364","-0.07493","99.03719"
"1251.00500","-6.35151","11.42559","104.63550","-0.07468","100.21645"
"1255.60500","-6.32533","11.59674","104.24522","-0.07442","101.71761"
"1260.20500","-6.32524","11.28830","103.87787","-0.07442","99.01221"
"1264.80500","-6.32498","11.24753","103.49745","-0.07442","98.65463"
"1269.40500","-6.28297","11.56384","103.06660","-0.07400","101.42899"
"1274.00500","-6.27746","11.49070","102.68436","-0.07395","100.78749"
"1278.60500","-6.27619","11.21862","102.27145","-0.07394","98.40105"
"1283.20500","-6.21460","11.71138","101.84045","-0.07333","102.72315"
"1287.80500","-6.19835","11.77809","101.41830","-0.07317","103.30822"
"1292.40500","-6.19842","11.51453","101.01508","-0.07317","100.99648"
"1297.00500","-6.19844","11.34676","100.67423","-0.07317","99.52495"
"1301.60500","-6.19836","11.09156","100.27304","-0.07317","97.28651"
"1306.20500","-6.19622","10.96243","99.87467","-0.07315","96.15388"
"1310.80500","-6.17414","10.99938","99.46426","-0.07293","96.47799"
"1315.40500","-6.08868","11.75247","99.07554","-0.07208","103.08351"
"1320.00500","-6.08873","11.46041","98.68754","-0.07209","100.52180"
"1324.60500","-6.08871","11.25341","98.25616","-0.07209","98.70620"
"1329.20500","-6.08849","11.09877","97.80454","-0.07208","97.34981"
"1333.80500","-6.00930","11.75904","97.37068","-0.07130","103.14114"
"1338.40500","-5.99307","11.52398","96.95149","-0.07114","101.07939"
"1343.00500","-5.99301","11.17474","96.54169","-0.07114","98.01616"
"1347.60500","-5.96760","11.18327","96.01001","-0.07089","98.09100"
"1352.20500","-5.90128","11.68045","95.54336","-0.07023","102.45187"
"1356.80500","-5.89827","11.37116","95.01063","-0.07020","99.73895"
"1361.40500","-5.88590","11.14608","94.59070","-0.07008","97.76480"
"1366.00500","-5.79815","11.63062","94.12040","-0.06921","102.01478"
"1370.60500","-5.79725","11.33615","93.63158","-0.06921","99.43188"
"1375.20500","-5.76345","11.31163","93.15521","-0.06887","99.21687"
"1379.80500","-5.70027","11.43036","92.61280","-0.06825","100.25821"
"1384.40500","-5.65076","11.38632","91.96772","-0.06776","99.87199"
"1389.00500","-5.57820","11.33746","91.27847","-0.06704","99.44339"
"1393.60500","-5.50262","11.37431","90.54175","-0.06629","99.76659"
"1398.20500","-5.40830","11.49418","89.81457","-0.06536","100.81806"
"1402.80500","-5.35447","11.26098","89.07939","-0.06483","98.77257"
"1407.40500","-5.23406","11.37406","88.29217","-0.06364","99.76441"
"1412.00500","-5.11200","11.38387","87.38987","-0.06243","99.85047"
"1416.60500","-5.03569","11.28786","86.52584","-0.06168","99.00832"
"1421.20500","-4.91851","11.23621","85.64291","-0.06052","98.55532"
"1425.80500","-4.82563","11.15518","84.79169","-0.05960","97.84459"
"1430.40500","-4.66393","11.37802","83.85812","-0.05801","99.79914"
"1435.00500","-4.48672","11.25537","83.07725","-0.05626","98.72336"
"1439.60500","-4.34714","11.18473","82.11884","-0.05488","98.10375"
"1444.20500","-4.19105","11.10866","81.40498","-0.05333","97.43652"
"1448.80500","-3.73897","11.44823","80.63126","-0.04887","100.41502"
"1453.40500","-3.39495","11.43825","79.77252","-0.04547","100.32745"
"1458.00500","-2.91896","10.65687","78.90076","-0.04077","93.47376"
"1462.60500","-1.92162","11.59235","77.39287","-0.03091","101.67908"
"1467.20500","-1.02258","11.70867","75.88148","-0.02203","102.69936"
"1471.80500","-0.31447","11.69703","74.43346","-0.01503","102.59723"
"1476.40500","0.27260","11.64079","73.02911","-0.00923","102.10396"
"1481.00500","0.61230","11.57646","71.83677","-0.00587","101.53967"
"1485.60500","0.78936","12.44329","70.85516","-0.00412","109.14288"
"1490.20500","0.80416","10.55103","70.19073","-0.00398","92.54546"
"1494.80500","0.86947","11.67167","69.48197","-0.00333","102.37487"
"1499.40500","1.16726","11.51985","68.81246","-0.00039","101.04321"
"1504.00500","1.35369","11.79583","68.18523","0.00145","103.46382"
"1508.60500","1.45381","12.31605","67.13819","0.00244","108.02683"
"1513.20500","1.48341","10.17861","66.62227","0.00273","89.27891"
"1517.80500","1.65550","11.30844","65.74307","0.00443","99.18885"
"1522.40500","1.90245","12.59818","64.50805","0.00687","110.50144"
"1527.00500","2.05616","12.58190","63.70258","0.00839","110.35869"
"1531.60500","2.10982","11.19079","63.15366","0.00892","98.15697"
"1536.20500","2.14544","10.38169","62.61279","0.00927","91.06010"
"1540.80500","2.23174","10.18916","62.03069","0.01013","89.37136"
"1545.40500","2.41224","10.83036","61.15586","0.01191","94.99550"
"1550.00500","2.44123","11.18647","60.62928","0.01220","98.11903"
"1554.60500","2.44135","10.60018","60.11013","0.01220","92.97652"
"1559.20500","2.44827","10.92790","59.56047","0.01227","95.85101"
"1563.80500","2.53544","11.45988","58.85038","0.01313","100.51720"
"1568.40500","2.59059","12.02847","58.44192","0.01367","105.50443"
"1573.00500","2.60205","11.74945","57.95174","0.01379","103.05708"
"1577.60500","2.64731","11.94464","57.29298","0.01423","104.76907"
"1582.20500","2.76991","12.71802","56.39088","0.01544","111.55257"
"1586.80500","2.78868","12.49231","55.93800","0.01563","109.57284"
"1591.40500","2.79105","11.42822","55.56045","0.01565","100.23945"
"1596.00500","2.82401","10.67142","54.98226","0.01598","93.60146"
"1600.60500","2.87233","10.08983","54.41808","0.01646","88.50015"
"1605.20500","3.01374","10.88462","53.46614","0.01785","95.47140"
"1609.80500","3.06884","10.68333","52.80945","0.01840","93.70588"
"1614.40500","3.06956","10.47036","52.08290","0.01841","91.83790"
"1619.00500","3.09608","10.57281","51.47741","0.01867","92.73646"
"1623.60500","3.11294","10.81301","50.98587","0.01883","94.84330"
"1628.20500","3.13913","10.56240","50.55172","0.01909","92.64517"
"1632.80500","3.19580","10.63516","49.99164","0.01965","93.28335"
"1637.40500","3.21005","10.68240","49.00454","0.01979","93.69769"
"1642.00500","3.24566","11.12031","48.48428","0.02015","97.53871"
"1646.60500","3.26912","11.09324","48.18515","0.02038","97.30131"
"1651.20500","3.27675","11.13812","47.77438","0.02045","97.69492"
"1655.80500","3.29204","10.90184","47.16886","0.02060","95.62246"
"1660.40500","3.31547","11.01197","46.67559","0.02084","96.58849"
"1665.00500","3.36627","11.48168","46.31616","0.02134","100.70837"
"1669.60500","3.37750","10.69212","45.85925","0.02145","93.78294"
"1674.20500","3.39815","10.56799","45.05609","0.02165","92.69421"
"1678.80500","3.45072","11.06604","44.25429","0.02217","97.06269"
"1683.40500","3.47817","11.29313","43.90718","0.02244","99.05457"
"1688.00500","3.47809","10.94391","43.52876","0.02244","95.99149"
"1692.60500","3.47801","10.98000","43.15934","0.02244","96.30800"
"1697.20500","3.47806","10.57779","42.67435","0.02244","92.78020"
"1701.80500","3.47837","10.24580","41.81163","0.02244","89.86822"
"1706.40500","3.55001","11.29409","40.83411","0.02315","99.06302"
"1711.00500","3.58716","11.68073","40.08260","0.02352","102.45425"
"1715.60500","3.58721","11.61911","39.66655","0.02352","101.91379"
"1720.20500","3.58713","11.52291","39.40827","0.02352","101.07005"
"1724.80500","3.58718","11.22624","38.94497","0.02352","98.46784"
"1729.40500","3.58737","11.38714","38.29213","0.02352","99.87919"
"1734.00500","3.64200","11.98368","37.60558","0.02406","105.11156"
"1738.60500","3.64710","12.09301","37.11299","0.02411","106.07053"
"1743.20500","3.65449","11.49036","36.53143","0.02419","100.78454"
"1747.80500","3.68864","11.53216","36.05096","0.02452","101.15117"
"1752.40500","3.68949","11.08936","35.94964","0.02453","97.26728"
"1757.00500","3.68942","11.47154","35.67219","0.02453","100.61944"
"1761.60500","3.68936","11.88491","35.30044","0.02453","104.24522"
"1766.20500","3.68936","11.23880","35.23054","0.02453","98.57807"
"1770.80500","3.68938","10.74383","34.98893","0.02453","94.23655"
"1775.40500","3.96129","12.83641","32.53845","0.02722","112.59100"
"1780.00500","3.96932","13.30693","31.33692","0.02730","116.71809"
"1784.60500","3.72752","9.99602","31.43613","0.02491","87.67736"
"1789.20500","3.72853","9.99930","31.78903","0.02492","87.70610"
"1793.80500","3.78282","10.64998","31.60501","0.02545","93.41335"
"1798.40500","3.88332","11.85879","30.96376","0.02645","104.01614"
"1803.00500","3.88239","11.93072","30.53768","0.02644","104.64698"
"1807.60500","3.86231","11.30172","30.35907","0.02624","99.12994"
"1812.20500","3.80358","10.60518","30.12543","0.02566","93.02042"
"1816.80500","3.79129","10.56121","30.23642","0.02554","92.63476"
"1821.40500","3.79186","10.66340","30.06365","0.02554","93.53103"
"1826.00500","3.79287","11.31029","29.75462","0.02555","99.20506"
"1830.60500","3.82964","12.05221","29.78787","0.02592","105.71259"
"1835.20500","3.84034","11.89473","29.70604","0.02602","104.33131"
"1839.80500","3.84021","11.71103","29.73195","0.02602","102.72008"
"1844.40500","3.83992","11.67192","29.80477","0.02602","102.37703"
"1849.00500","3.83890","11.59272","30.23048","0.02601","101.68237"
"1853.60500","3.79877","11.04220","30.74137","0.02561","96.85361"
"1858.20500","3.77400","10.98989","31.09387","0.02537","96.39482"
"1862.80500","3.77406","11.08653","31.64086","0.02537","97.24245"
"1867.40500","3.77413","11.34759","31.97424","0.02537","99.53229"
"1872.00500","3.77415","11.60776","32.23806","0.02537","101.81423"
"1876.60500","3.77412","11.78909","32.61665","0.02537","103.40478"
"1881.20500","3.77406","11.88403","33.05234","0.02537","104.23751"
"1885.80500","3.77359","11.99997","33.61442","0.02536","105.25441"
"1890.40500","3.74237","11.46959","34.10630","0.02505","100.60235"
"1895.00500","3.73069","11.34536","34.56657","0.02494","99.51271"
"1899.60500","3.73073","11.33505","35.11200","0.02494","99.42224"
"1904.20500","3.73071","11.46883","35.59735","0.02494","100.59566"
"1908.80500","3.73060","11.29669","36.18917","0.02494","99.08577"
"1913.40500","3.71049","11.04813","36.71387","0.02474","96.90561"
"1918.00500","3.68379","11.26899","37.17560","0.02447","98.84280"
"1922.60500","3.68334","11.30674","37.52734","0.02447","99.17392"
"1927.20500","3.68348","11.28557","38.00526","0.02447","98.98825"
"1931.80500","3.68349","10.98833","38.65926","0.02447","96.38109"
"1936.40500","3.68347","11.68465","38.94926","0.02447","102.48870"
"1941.00500","3.68347","11.41702","39.39865","0.02447","100.14127"
"1945.60500","3.68336","11.80503","39.86927","0.02447","103.54459"
"1950.20500","3.68329","11.62342","40.27708","0.02447","101.95161"
"1954.80500","3.68272","11.87688","40.73029","0.02446","104.17476"
"1959.40500","3.65086","11.53465","41.34020","0.02415","101.17296"
"1964.00500","3.62041","10.88535","41.72362","0.02385","95.47788"
"1968.60500","3.62047","11.23880","41.97837","0.02385","98.57801"
"1973.20500","3.62052","11.26410","42.46665","0.02385","98.79996"
"1977.80500","3.62054","11.37026","42.97892","0.02385","99.73110"
"1982.40500","3.62055","11.40537","43.37256","0.02385","100.03909"
"1987.00500","3.62052","11.49903","43.77148","0.02385","100.86054"
"1991.60500","3.62046","11.66369","44.19032","0.02385","102.30482"
"1996.20500","3.62027","11.75072","44.68236","0.02385","103.06815"
"2000.80500","3.58044","11.39114","45.23112","0.02345","99.91421"
"2005.40500","3.57180","11.38980","45.81908","0.02337","99.90252"
"2010.00500","3.55937","11.46164","46.46363","0.02325","100.53257"
"2014.60500","3.53437","11.25580","47.22572","0.02300","98.72710"
"2019.20500","3.53326","11.49807","47.94971","0.02299","100.85215"
"2023.80500","3.52344","11.53291","48.76404","0.02289","101.15771"
"2028.40500","3.48082","11.13815","49.55462","0.02247","97.69523"
"2033.00500","3.48075","11.41150","50.40515","0.02247","100.09284"
"2037.60500","3.48063","11.51893","51.25099","0.02247","101.03507"
"2042.20500","3.47110","11.65396","52.06627","0.02237","102.21949"
"2046.80500","3.43530","11.30285","52.85555","0.02202","99.13983"
"2051.40500","3.42699","11.41733","53.62309","0.02194","100.14392"
"2056.00500","3.39578","11.15773","54.41617","0.02163","97.86695"
"2060.60500","3.39355","11.30176","55.16578","0.02161","99.13026"
"2065.20500","3.39215","11.52577","55.79598","0.02159","101.09514"
"2069.80500","3.38724","11.51279","56.50917","0.02154","100.98128"
"2074.40500","3.37781","11.67293","57.21678","0.02145","102.38584"
"2079.00500","3.31766","10.95540","57.87694","0.02086","96.09229"
"2083.60500","3.30530","11.09006","58.53292","0.02073","97.27340"
"2088.20500","3.30535","11.22228","59.14182","0.02074","98.43309"
"2092.80500","3.30538","11.39914","59.76794","0.02074","99.98439"
"2097.40500","3.30534","11.60799","60.40620","0.02074","101.81631"
"2102.00500","3.30498","11.75685","61.03516","0.02073","103.12199"
"2106.60500","3.28972","11.79455","61.68339","0.02058","103.45264"
"2111.20500","3.24982","11.45683","62.31345","0.02019","100.49045"
"2115.80500","3.20866","11.18266","62.95373","0.01978","98.08561"
"2120.40500","3.18503","11.12930","63.62452","0.01955","97.61754"
"2125.00500","3.17985","11.29801","64.26697","0.01950","99.09740"
"2129.60500","3.17928","11.53195","64.92951","0.01949","101.14931"
"2134.20500","3.17631","11.78345","65.57957","0.01946","103.35530"
"2138.80500","3.10188","11.15131","66.22549","0.01872","97.81064"
"2143.40500","3.08815","11.28757","66.92133","0.01859","99.00579"
"2148.00500","3.08264","11.59392","67.55682","0.01853","101.69286"
"2152.60500","3.04663","11.40333","68.23990","0.01818","100.02117"
"2157.20500","3.00060","11.26961","68.86813","0.01772","98.84826"
"2161.80500","3.00016","11.64644","69.54079","0.01772","102.15351"
"2166.40500","2.92565","11.06734","70.21879","0.01698","97.07412"
"2171.00500","2.90532","11.33052","70.87353","0.01678","99.38252"
"2175.60500","2.90346","11.71518","71.55161","0.01676","102.75645"
"2180.20500","2.76660","10.69934","72.17197","0.01541","93.84629"
"2184.80500","2.70248","10.69130","72.83919","0.01478","93.77582"
"2189.40500","2.70278","11.24305","73.46513","0.01478","98.61530"
"2194.00500","2.70274","11.63328","74.07327","0.01478","102.03806"
"2198.60500","2.70224","12.17551","74.75439","0.01478","106.79414"
"2203.20500","2.59278","11.38112","75.30525","0.01369","99.82635"
"2207.80500","2.48684","11.24411","75.92499","0.01265","98.62457"
"2212.40500","2.42034","11.20811","76.58624","0.01199","98.30888"
"2217.00500","2.38153","11.43215","77.19638","0.01161","100.27393"
"2221.60500","2.31443","11.52513","77.81999","0.01094","101.08947"
"2226.20500","2.22166","11.28914","78.45669","0.01003","99.01954"
"2230.80500","2.14538","11.42699","79.02593","0.00927","100.22870"
"2235.40500","2.07711","11.63371","79.68473","0.00860","102.04186"
"2240.00500","1.93798","11.26923","80.30641","0.00722","98.84493"
"2244.60500","1.83571","11.35202","80.96527","0.00621","99.57108"
"2249.20500","1.75691","11.41268","81.59715","0.00544","100.10316"
"2253.80500","1.63222","11.32323","82.24203","0.00420","99.31855"
"2258.40500","1.49412","11.39332","82.91998","0.00284","99.93338"
"2263.00500","1.39683","11.39734","83.55072","0.00188","99.96858"
"2267.60500","1.27354","11.53579","84.16226","0.00066","101.18298"
"2272.20500","1.14238","11.50021","84.78027","-0.00064","100.87094"
"2276.80500","0.97124","11.32078","85.37836","-0.00233","99.29713"
"2281.40500","0.78779","11.41475","86.02731","-0.00414","100.12130"
"2286.00500","0.68921","11.77102","86.66845","-0.00511","103.24623"
"2290.60500","0.31529","11.16252","87.32359","-0.00881","97.90899"
"2295.20500","0.04554","11.12362","87.95233","-0.01147","97.56774"
"2299.80500","-0.14299","11.57627","88.53562","-0.01334","101.53809"
"2304.40500","-0.35735","11.65191","89.18154","-0.01545","102.20146"
"2309.00500","-0.70149","11.32033","89.79992","-0.01886","99.29314"
"2313.60500","-0.94655","11.72275","90.40648","-0.02128","102.82288"
"2318.20500","-1.32851","11.25472","91.03011","-0.02505","98.71768"
"2322.80500","-1.73232","11.21138","91.66919","-0.02904","98.33749"
"2327.40500","-2.00901","11.44042","92.29830","-0.03177","100.34650"
"2332.00500","-2.28750","11.34214","92.83488","-0.03453","99.48441"
"2336.60500","-2.53998","11.20461","93.43501","-0.03702","98.27814"
"2341.20500","-2.73837","11.26112","94.08728","-0.03898","98.77376"
"2345.80500","-2.94134","11.50513","94.59956","-0.04099","100.91402"
"2350.40500","-3.13020","11.36609","95.26225","-0.04285","99.69448"
"2355.00500","-3.26648","11.69147","95.84879","-0.04420","102.54845"
"2359.60500","-3.44024","11.73196","96.50456","-0.04592","102.90361"
"2364.20500","-3.68712","11.19418","97.15835","-0.04836","98.18661"
"2368.80500","-3.87942","11.13167","97.79613","-0.05026","97.63835"
"2373.40500","-4.01854","11.30585","98.46126","-0.05163","99.16611"
"2378.00500","-4.08702","11.57406","99.05962","-0.05231","101.51865"
"2382.60500","-4.10960","11.99690","99.69025","-0.05253","105.22752"
"2387.20500","-4.29809","11.24795","100.25886","-0.05439","98.65827"
"2391.80500","-4.48882","11.14032","100.84408","-0.05628","97.71426"
"2396.40500","-4.59882","11.23560","101.53206","-0.05736","98.54996"
"2401.00500","-4.68667","11.41365","102.15064","-0.05823","100.11168"
"2405.60500","-4.77302","11.45051","102.80039","-0.05909","100.43498"
"2410.20500","-4.83389","11.96587","103.42005","-0.05969","104.95536"
"2414.80500","-5.05106","10.98602","104.02477","-0.06183","96.36085"
"2419.40500","-5.18304","11.11875","104.62445","-0.06314","97.52505"
"2424.00500","-5.22892","11.40138","105.18871","-0.06359","100.00407"
"2428.60500","-5.28984","11.37830","105.80391","-0.06419","99.80160"
"2433.20500","-5.39950","11.28186","106.44048","-0.06528","98.95569"
"2437.80500","-5.45733","11.22358","107.03350","-0.06585","98.44450"
"2442.40500","-5.50835","11.61701","107.68163","-0.06635","101.89537"
"2447.00500","-5.61906","11.27072","108.32621","-0.06744","98.85803"
"2451.60500","-5.66989","11.58466","108.96819","-0.06795","101.61161"
"2456.20500","-5.73150","11.42955","109.57449","-0.06856","100.25114"
"2460.80500","-5.76898","11.47092","110.17526","-0.06893","100.61404"
"2465.40500","-5.84326","11.58667","110.83306","-0.06966","101.62929"
"2470.00500","-5.92358","11.19477","111.38694","-0.07045","98.19186"
"2474.60500","-5.97880","11.32697","112.03289","-0.07100","99.35141"
"2479.20500","-6.00405","11.57280","112.65519","-0.07125","101.50763"
"2483.80500","-6.05414","11.45573","113.25092","-0.07174","100.48080"
"2488.40500","-6.12152","11.36455","113.86289","-0.07241","99.68102"
"2493.00500","-6.16172","11.36644","114.46866","-0.07281","99.69754"
"2497.60500","-6.20128","11.43797","115.05159","-0.07320","100.32500"
"2502.20500","-6.24613","11.46903","115.65827","-0.07364","100.59739"
"2506.80500","-6.29344","11.42032","116.27036","-0.07411","100.17016"
"2511.40500","-6.33213","11.28828","116.88119","-0.07449","99.01206"
"2516.00500","-6.38386","11.20509","117.47459","-0.07500","98.28236"
"2520.60500","-6.38932","11.45067","118.08192","-0.07506","100.43637"
"2525.20500","-6.43174","11.50843","118.66315","-0.07547","100.94298"
"2529.80500","-6.48699","11.13905","119.31351","-0.07602","97.70307"
"2534.40500","-6.49015","11.71195","119.95173","-0.07605","102.72816"
"2539.00500","-6.55586","11.29053","120.61067","-0.07670","99.03179"
"2543.60500","-6.57641","11.41724","121.21500","-0.07690","100.14316"
"2548.20500","-6.59257","11.65432","121.87135","-0.07706","102.22261"
"2552.80500","-6.64598","11.34451","122.53634","-0.07759","99.50520"
"2557.40500","-6.67403","11.29783","123.13815","-0.07787","99.09579"
"2562.00500","-6.67898","11.53881","123.69174","-0.07792","101.20950"
"2566.60500","-6.71389","11.28737","124.16564","-0.07826","99.00404"
"2571.20500","-6.72916","11.45475","124.62067","-0.07841","100.47220"
"2575.80500","-6.73289","11.50025","125.04093","-0.07845","100.87122"
"2580.40500","-6.77544","10.94263","125.28987","-0.07887","95.98029"
"2585.00500","-6.77526","10.98349","125.47570","-0.07887","96.33866"
"2589.60500","-6.77504","11.19131","125.56761","-0.07887","98.16148"
"2594.20500","-6.77481","11.13857","125.59318","-0.07886","97.69890"
"2598.80500","-6.77433","10.91530","125.49570","-0.07886","95.74054"
"2603.40500","-6.76899","10.97531","125.31813","-0.07881","96.26688"
"2608.00500","-6.71318","11.89339","125.22483","-0.07826","104.31955"
"2612.60500","-6.71114","11.80081","125.06899","-0.07824","103.50757"
"2617.20500","-6.71134","11.71745","124.89234","-0.07824","102.77639"
"2621.80500","-6.71159","11.64001","124.72758","-0.07824","102.09715"
"2626.40500","-6.71191","11.72199","124.52073","-0.07824","102.81618"
"2631.00500","-6.71211","11.38908","124.23276","-0.07824","99.89618"
"2635.60500","-6.71212","11.27496","123.88418","-0.07824","98.89517"
"2640.20500","-6.71201","11.05059","123.48267","-0.07824","96.92722"
"2644.80500","-6.71181","11.02973","122.96661","-0.07824","96.74421"
"2649.40500","-6.71127","10.73059","122.49383","-0.07824","94.12038"
"2654.00500","-6.65365","11.53024","121.92956","-0.07767","101.13435"
"2658.60500","-6.62078","11.74305","121.43548","-0.07734","103.00092"
"2663.20500","-6.62082","11.44378","120.83244","-0.07734","100.37594"
"2667.80500","-6.62077","11.34232","120.15136","-0.07734","99.48604"
"2672.40500","-6.61970","10.99502","119.55182","-0.07733","96.43975"
"2677.00500","-6.56718","11.62410","118.86337","-0.07681","101.95759"
"2681.60500","-6.56657","11.27960","118.23965","-0.07681","98.93585"
"2686.20500","-6.56518","11.26087","117.61458","-0.07679","98.77165"
"2690.80500","-6.51661","11.58677","116.99548","-0.07631","101.63016"
"2695.40500","-6.51662","11.56724","116.42798","-0.07631","101.45887"
"2700.00500","-6.51655","11.14152","115.82522","-0.07631","97.72478"
"2704.60500","-6.50446","11.28289","115.23682","-0.07619","98.96475"
"2709.20500","-6.46951","11.56595","114.69858","-0.07585","101.44751"
"2713.80500","-6.46944","11.36841","114.09505","-0.07585","99.71483"
"2718.40500","-6.46857","11.11405","113.60911","-0.07584","97.48383"
"2723.00500","-6.41811","11.70101","113.08926","-0.07534","102.63219"
"2727.60500","-6.41808","11.50503","112.55641","-0.07534","100.91315"
"2732.20500","-6.41803","11.23879","112.07198","-0.07534","98.57792"
"2736.80500","-6.40882","11.20885","111.55753","-0.07525","98.31537"
"2741.40500","-6.37762","11.49825","111.11826","-0.07494","100.85368"
"2746.00500","-6.37715","11.27351","110.58753","-0.07494","98.88251"
"2750.60500","-6.36769","11.29795","110.12591","-0.07484","99.09681"
"2755.20500","-6.32453","11.62606","109.73990","-0.07442","101.97480"
"2759.80500","-6.32447","11.42220","109.22941","-0.07441","100.18668"
"2764.40500","-6.32441","11.26958","108.77238","-0.07441","98.84796"
"2769.00500","-6.31932","11.12216","108.35970","-0.07436","97.55495"
"2773.60500","-6.28301","11.48857","107.91496","-0.07400","100.76881"
"2778.20500","-6.28212","11.22895","107.49302","-0.07400","98.49165"
"2782.80500","-6.26496","11.37157","107.06927","-0.07383","99.74261"
"2787.40500","-6.21739","11.75432","106.66349","-0.07336","103.09980"
"2792.00500","-6.21746","11.64263","106.25373","-0.07336","102.12015"
"2796.60500","-6.21749","11.34683","105.84354","-0.07336","99.52556"
"2801.20500","-6.21743","11.18683","105.43817","-0.07336","98.12217"
"2805.80500","-6.21703","10.90689","105.04411","-0.07335","95.66677"
"2810.40500","-6.18145","11.24199","104.66888","-0.07300","98.60603"
"2815.00500","-6.17805","11.08599","104.27462","-0.07297","97.23774"
"2819.60500","-6.09703","12.03630","103.87144","-0.07217","105.57311"
"2824.20500","-6.09689","11.74690","103.49541","-0.07217","103.03472"
"2828.80500","-6.09700","11.48236","103.10865","-0.07217","100.71430"
"2833.40500","-6.09702","11.32262","102.75284","-0.07217","99.31326"
"2838.00500","-6.09694","11.14406","102.35452","-0.07217","97.74700"
"2842.60500","-6.09675","11.06263","101.93015","-0.07216","97.03283"
"2847.20500","-6.07898","11.05450","101.51349","-0.07199","96.96147"
"2851.80500","-5.99507","11.74075","101.05364","-0.07116","102.98077"
"2856.40500","-5.99498","11.55587","100.59943","-0.07116","101.35915"
"2861.00500","-5.99493","11.32560","100.17811","-0.07116","99.33936"
"2865.60500","-5.98994","11.05692","99.73090","-0.07111","96.98270"
"2870.20500","-5.90511","11.74971","99.29543","-0.07027","103.05930"
"2874.80500","-5.89713","11.85109","98.81860","-0.07019","103.94852"
"2879.40500","-5.89704","11.07284","98.42736","-0.07019","97.12232"
"2884.00500","-5.87126","11.23836","97.90176","-0.06994","98.57418"
"2888.60500","-5.79110","11.71581","97.36224","-0.06914","102.76200"
"2893.20500","-5.79112","11.36967","96.91895","-0.06914","99.72589"
"2897.80500","-5.79081","11.04815","96.46584","-0.06914","96.90579"
"2902.40500","-5.69753","11.51301","95.93340","-0.06822","100.98319"
"2907.00500","-5.63115","11.66083","95.25215","-0.06756","102.27975"
"2911.60500","-5.60405","11.06638","94.51495","-0.06730","97.06573"
"2916.20500","-5.46619","11.73379","93.68511","-0.06593","102.91966"
"2920.80500","-5.42416","11.44013","92.93996","-0.06552","100.34397"
"2925.40500","-5.41572","11.33710","92.04898","-0.06544","99.44021"
"2930.00500","-5.31956","11.18073","91.26589","-0.06449","98.06864"
"2934.60500","-5.13958","11.63508","90.23151","-0.06271","102.05387"
"2939.20500","-5.06508","11.47371","89.29298","-0.06197","100.63850"
"2943.80500","-5.01375","11.35367","88.45473","-0.06146","99.58559"
"2948.40500","-4.99682","10.66967","87.53516","-0.06130","93.58606"
"2953.00500","-4.81620","11.34442","86.68793","-0.05951","99.50446"
"2957.60500","-4.63574","11.45041","85.75064","-0.05773","100.43409"
"2962.20500","-4.43993","11.60108","84.79560","-0.05579","101.75563"
"2966.80500","-4.34857","11.40478","83.90163","-0.05489","100.03386"
"2971.40500","-4.15917","11.17016","83.05202","-0.05302","97.97600"
"2976.00500","-3.69395","11.78494","82.14508","-0.04842","103.36834"
"2980.60500","-3.24018","11.07493","80.95614","-0.04394","97.14069"
"2985.20500","-2.63871","11.57681","79.79845","-0.03800","101.54277"
"2989.80500","-1.96957","11.18360","78.46073","-0.03138","98.09385"
"2994.40500","-1.20409","12.36934","77.06637","-0.02382","108.49422"
"2999.00500","-1.08098","11.06219","76.25770","-0.02260","97.02892"
"3003.60500","-0.98961","12.70212","75.39632","-0.02170","111.41311"
"3008.20500","-0.86510","10.12603","74.64606","-0.02047","88.81763"
"3012.80500","-0.66927","11.19583","74.02268","-0.01854","98.20115"
"3017.40500","-0.50298","12.33531","73.48324","-0.01689","108.19577"
"3022.00500","-0.44874","10.87158","72.97439","-0.01636","95.35703"
"3026.60500","-0.36803","10.62221","72.67692","-0.01556","93.16975"
"3031.20500","0.00486","12.71097","71.92258","-0.01188","111.49072"
"3035.80500","0.39508","9.95805","71.44388","-0.00802","87.34431"
"3040.40500","1.10448","12.20349","70.13348","-0.00101","107.03957"
"3045.00500","1.46927","13.39919","68.77158","0.00259","117.52726"
"3049.60500","1.53857","11.86200","67.89336","0.00328","104.04424"
"3054.20500","1.56388","11.07561","67.22201","0.00353","97.14661"
"3058.80500","1.56621","10.35983","66.79801","0.00355","90.86842"
"3063.40500","1.58456","10.35435","66.34456","0.00373","90.82030"
"3068.00500","1.64442","10.16415","65.98760","0.00432","89.15207"
"3072.60500","1.71285","10.78827","65.47295","0.00500","94.62629"
"3077.20500","1.84304","11.50797","64.86192","0.00629","100.93898"
"3081.80500","1.97986","12.17774","64.13026","0.00764","106.81372"
"3086.40500","2.12042","12.80677","63.44965","0.00903","112.33100"
"3091.00500","2.13970","11.74770","62.98646","0.00922","103.04171"
"3095.60500","2.14388","10.29019","62.52079","0.00926","90.25753"
"3100.20500","2.16003","10.66183","62.28699","0.00942","93.51727"
"3104.80500","2.21639","11.37335","61.93923","0.00998","99.75820"
"3109.40500","2.27112","12.03707","61.33783","0.01052","105.57986"
"3114.00500","2.31994","11.19934","61.00148","0.01100","98.23188"
"3118.60500","2.33358","11.03291","60.69758","0.01113","96.77215"
"3123.20500","2.38030","12.27814","59.94283","0.01160","107.69432"
"3127.80500","2.41644","10.62503","59.68423","0.01195","93.19454"
"3132.40500","2.52700","11.86631","59.14532","0.01304","104.08202"
"3137.00500","2.70521","10.48628","58.11941","0.01481","91.97751"
"3141.60500","3.06403","12.72403","56.59024","0.01835","111.60535"
"3146.20500","3.07342","12.04497","54.72311","0.01844","105.64910"
"3150.80500","3.07345","12.18290","53.85397","0.01844","106.85893"
"3155.40500","3.07347","11.73568","53.49952","0.01844","102.93626"
"3160.00500","3.08216","11.46710","52.96625","0.01853","100.58049"
"3164.60500","3.10485","11.56298","52.41760","0.01875","101.42147"
"3169.20500","3.10610","11.05081","51.96152","0.01877","96.92912"
"3173.80500","3.22260","12.15798","51.36995","0.01992","106.64036"
"3178.40500","3.29889","12.05781","50.63356","0.02067","105.76176"
"3183.00500","3.30014","11.91053","49.96191","0.02068","104.46990"
"3187.60500","3.29966","11.81098","49.43003","0.02068","103.59677"
"3192.20500","3.29938","11.51239","48.85206","0.02068","100.97778"
"3196.80500","3.29962","11.36898","48.07650","0.02068","99.71985"
"3201.40500","3.30005","11.17412","47.33458","0.02068","98.01067"
"3206.00500","3.32247","11.68046","46.78289","0.02090","102.45196"
"3210.60500","3.38017","12.31656","46.43225","0.02147","108.03130"
"3215.20500","3.39019","12.07528","46.19789","0.02157","105.91499"
"3219.80500","3.39644","11.56900","45.58508","0.02164","101.47430"
"3224.40500","3.42716","11.78869","44.82270","0.02194","103.40127"
"3229.00500","3.46998","12.27482","44.22063","0.02236","107.66518"
"3233.60500","3.47101","12.00825","43.78308","0.02237","105.32708"
"3238.20500","3.47492","11.90721","43.32549","0.02241","104.44077"
"3242.80500","3.49080","11.35659","42.77673","0.02257","99.61116"
"3247.40500","3.50644","11.46379","41.94728","0.02272","100.55147"
"3252.00500","3.61397","12.47988","41.31116","0.02378","109.46382"
"3256.60500","3.61399","12.36680","40.66232","0.02378","108.47198"
"3261.20500","3.61384","12.28544","40.24645","0.02378","107.75838"
"3265.80500","3.61378","11.89849","39.66235","0.02378","104.36427"
"3270.40500","3.61377","11.87332","39.00784","0.02378","104.14352"
"3275.00500","3.61376","11.87581","38.73594","0.02378","104.16539"
"3279.60500","3.61389","11.29885","38.18813","0.02378","99.10473"
"3284.20500","3.61426","10.83376","37.45678","0.02379","95.02535"
"3288.80500","3.69098","12.04792","36.84665","0.02455","105.67503"
"3293.40500","3.73899","11.87494","36.31478","0.02502","104.15778"
"3298.00500","3.74510","11.99546","35.59142","0.02508","105.21484"
"3302.60500","3.74494","11.23246","35.32354","0.02508","98.52241"
"3307.20500","3.74488","11.25185","34.47086","0.02508","98.69245"
"3311.80500","3.74481","11.00833","33.98224","0.02508","96.55654"
"3316.40500","3.74491","10.95338","33.30326","0.02508","96.07451"
"3321.00500","3.74508","10.65322","32.81285","0.02508","93.44173"
"3325.60500","3.75021","10.61090","32.16973","0.02513","93.07056"
"3330.20500","3.78235","10.94779","31.89915","0.02545","96.02551"
"3334.80500","3.79352","11.14849","31.32847","0.02556","97.78587"
"3339.40500","3.79431","11.39768","31.03802","0.02557","99.97159"
"3344.00500","3.79418","11.77262","31.02168","0.02557","103.26030"
"3348.60500","3.79396","12.13168","31.03954","0.02556","106.40967"
"3353.20500","3.79380","11.85809","31.20576","0.02556","104.00993"
"3357.80500","3.79372","12.05999","30.90020","0.02556","105.78090"
"3362.40500","3.79371","11.77317","30.55327","0.02556","103.26512"
"3367.00500","3.79370","11.60800","30.40634","0.02556","101.81636"
"3371.60500","3.79357","11.52513","30.61234","0.02556","101.08953"
"3376.20500","3.79333","11.32595","30.81610","0.02556","99.34244"
"3380.80500","3.79339","10.83869","30.73224","0.02556","95.06860"
"3385.40500","3.79337","11.11754","30.48601","0.02556","97.51443"
"3390.00500","3.79330","11.31400","30.44572","0.02556","99.23766"
"3394.60500","3.79301","11.77254","30.40382","0.02555","103.25954"
"3399.20500","3.79234","12.07118","30.59465","0.02555","105.87901"
"3403.80500","3.78875","12.11317","30.94879","0.02551","106.24730"
"3406.44900","3.78118","11.58104","31.27186","0.02544","101.57991"