File: experimental/sma_database/flexinol_isobaric_200MPa.csv
Test : Start of hold value,"200.00000",MPa

Time,Extension,Load,Temperature: Chamber 3119-600 1 1,Tensile strain (Extension),Tensile stress
(s),(mm),(N),(C),(mm/mm),(MPa)
"0.00000","4.92265","-0.02013","24.96641","-0.00001","-0.17655"
"7.20000","5.10190","1.79201","24.98029","0.00170","15.71816"
"14.40000","5.28221","3.75291","24.99061","0.00342","32.91759"
"21.60000","5.46216","5.59704","25.00486","0.00514","49.09285"
"28.80000","5.64188","7.27178","25.01496","0.00685","63.78239"
"36.00000","5.82204","8.87107","25.02424","0.00857","77.81013"
"43.20000","6.00234","10.41061","25.04465","0.01028","91.31381"
"50.40000","6.18198","11.94327","25.04652","0.01200","104.75706"
"57.60000","6.36208","13.44093","25.05838","0.01371","117.89337"
"64.80000","6.54233","14.95905","25.07342","0.01543","131.20917"
"72.00000","6.72206","16.46023","25.07816","0.01714","144.37637"
"79.20000","6.90218","17.97062","25.09254","0.01886","157.62433"
"86.40000","7.08247","19.49105","25.10091","0.02058","170.96034"
"93.60000","7.26206","20.99906","25.11253","0.02229","184.18745"
"100.80000","7.44211","22.53138","25.12179","0.02401","197.62775"
"107.81100","7.55626","23.31706","25.13392","0.02509","204.51915"
"115.01100","7.55630","23.09549","25.13613","0.02509","202.57567"
"122.21100","7.55615","23.00406","25.14899","0.02509","201.77374"
"129.41100","7.55595","22.93252","25.15023","0.02509","201.14624"
"136.61100","7.55582","22.86924","25.16461","0.02509","200.59119"
"143.81100","7.55572","22.86503","25.17135","0.02509","200.55426"
"151.01100","7.55550","23.01416","25.47170","0.02509","201.86230"
"158.21100","7.55261","23.29177","26.80115","0.02506","204.29736"
"165.41100","7.47101","22.46495","28.80876","0.02428","197.04510"
"172.61100","7.47040","22.86071","31.47666","0.02428","200.51643"
"179.81100","7.45415","22.93762","34.09939","0.02412","201.19098"
"187.01100","7.41163","22.45162","36.71222","0.02372","196.92816"
"194.21100","7.41178","22.57083","38.81719","0.02372","197.97375"
"201.41100","7.41199","22.49978","40.26722","0.02372","197.35059"
"208.61100","7.41251","22.49388","41.05534","0.02372","197.29884"
"215.81100","7.42454","22.46756","41.32696","0.02384","197.06799"
"223.01100","7.46727","23.08537","41.33611","0.02425","202.48689"
"230.21100","7.46729","22.96378","41.13564","0.02425","201.42044"
"237.41100","7.46725","22.77184","40.83038","0.02425","199.73689"
"244.61100","7.46727","22.76256","40.47462","0.02425","199.65550"
"251.81100","7.46736","22.67248","40.05316","0.02425","198.86540"
"259.01100","7.47395","22.62371","39.68912","0.02431","198.43761"
"266.21100","7.49616","22.93468","39.25570","0.02452","201.16519"
"273.41100","7.49837","22.90140","38.90630","0.02454","200.87331"
"280.61100","7.49837","22.77629","38.49298","0.02454","199.77594"
"287.81100","7.49840","22.75121","38.13999","0.02454","199.55591"
"295.01100","7.49922","22.74919","37.77962","0.02455","199.53821"
"302.21100","7.50601","22.75946","37.45516","0.02461","199.62833"
"309.41100","7.51331","22.82571","37.15151","0.02468","200.20938"
"316.61100","7.51527","22.73166","36.86922","0.02470","199.38449"
"323.81100","7.52050","22.78185","36.60799","0.02475","199.82474"
"331.01100","7.52124","22.76388","36.34472","0.02476","199.66707"
"338.21100","7.52317","22.75068","36.12298","0.02478","199.55125"
"345.41100","7.52985","22.89974","35.97682","0.02484","200.85872"
"352.61100","7.53012","22.94341","35.94880","0.02484","201.24181"
"359.81100","7.53005","22.92825","36.05804","0.02484","201.10881"
"367.01100","7.52992","23.03842","36.30364","0.02484","202.07516"
"374.21100","7.52971","23.01354","36.64626","0.02484","201.85690"
"381.41100","7.52920","23.13172","37.04465","0.02484","202.89346"
"388.61100","7.52728","23.17105","37.46670","0.02482","203.23849"
"395.81100","7.50280","22.78243","37.89703","0.02458","199.82976"
"403.01100","7.50040","22.80433","38.27949","0.02456","200.02188"
"410.21100","7.49473","22.71793","38.59341","0.02451","199.26407"
"417.41100","7.49462","22.71758","38.87459","0.02451","199.26097"
"424.61100","7.49464","22.78024","39.09279","0.02451","199.81061"
"431.81100","7.49466","22.80204","39.29763","0.02451","200.00175"
"439.01100","7.49467","22.75150","39.45930","0.02451","199.55853"
"446.21100","7.49467","22.85143","39.65448","0.02451","200.43495"
"453.41100","7.49466","22.85110","39.83508","0.02451","200.43210"
"460.61100","7.49463","22.88893","40.02855","0.02451","200.76390"
"467.81100","7.49458","22.87348","40.25113","0.02451","200.62840"
"475.01100","7.48753","22.71465","40.50761","0.02444","199.23524"
"482.21100","7.47501","22.61726","40.78891","0.02432","198.38107"
"489.41100","7.47508","22.70741","41.06112","0.02432","199.17180"
"496.61100","7.47516","22.72868","41.31522","0.02432","199.35837"
"503.81100","7.47522","22.76882","41.57559","0.02432","199.71039"
"511.01100","7.47527","22.76310","41.84045","0.02432","199.66026"
"518.21100","7.47531","22.73669","42.10725","0.02432","199.42856"
"525.41100","7.47532","22.81264","42.35764","0.02432","200.09479"
"532.61100","7.47531","22.82971","42.59736","0.02432","200.24449"
"539.81100","7.47530","22.86788","42.81500","0.02432","200.57927"
"547.01100","7.47527","22.83072","43.02982","0.02432","200.25339"
"554.21100","7.47521","22.90038","43.27179","0.02432","200.86433"
"561.41100","7.47514","22.95026","43.50201","0.02432","201.30185"
"568.61100","7.47504","22.94752","43.74769","0.02432","201.27779"
"575.81100","7.47417","22.97004","43.98992","0.02431","201.47533"
"583.01100","7.46194","22.79462","44.22574","0.02419","199.93671"
"590.21100","7.46149","22.72476","44.49037","0.02419","199.32394"
"597.41100","7.46129","22.77038","44.72919","0.02419","199.72408"
"604.61100","7.46099","22.76561","44.97200","0.02419","199.68227"
"611.81100","7.45957","22.78744","45.20667","0.02417","199.87370"
"619.01100","7.45460","22.81474","45.44931","0.02412","200.11316"
"626.21100","7.45418","22.85933","45.66789","0.02412","200.50432"
"633.41100","7.45396","22.79431","45.91782","0.02412","199.93398"
"640.61100","7.45342","22.78123","46.18430","0.02411","199.81926"
"647.81100","7.43076","22.51513","46.40969","0.02390","197.48526"
"655.01100","7.41582","22.34871","46.65284","0.02376","196.02550"
"662.21100","7.41679","22.26954","46.91201","0.02376","195.33112"
"669.41100","7.44419","22.75815","47.14289","0.02403","199.61681"
"676.61100","7.46378","23.06750","47.39408","0.02421","202.33017"
"683.81100","7.46357","23.03567","47.62965","0.02421","202.05098"
"691.01100","7.46313","23.12385","47.86998","0.02421","202.82445"
"698.21100","7.46165","23.14648","48.11562","0.02419","203.02293"
"705.41100","7.41093","22.38647","48.34468","0.02371","196.35670"
"712.61100","7.41031","22.37023","48.58437","0.02370","196.21428"
"719.81100","7.41088","22.40866","48.82435","0.02371","196.55135"
"727.01100","7.41556","22.44536","49.07223","0.02375","196.87325"
"734.21100","7.45193","23.10774","49.30261","0.02410","202.68315"
"741.41100","7.45701","23.09263","49.54438","0.02415","202.55061"
"748.61100","7.45662","23.13863","49.79342","0.02414","202.95412"
"755.81100","7.45515","23.14324","50.04756","0.02413","202.99457"
"763.01100","7.40642","22.43189","50.28711","0.02367","196.75511"
"770.21100","7.40664","22.46501","50.52191","0.02367","197.04562"
"777.41100","7.40698","22.58521","50.75834","0.02367","198.09995"
"784.61100","7.40767","22.55577","50.99573","0.02368","197.84167"
"791.81100","7.40922","22.65417","51.23615","0.02369","198.70474"
"799.01100","7.42262","22.89077","51.43783","0.02382","200.78009"
"806.21100","7.42333","22.85718","51.67653","0.02383","200.48547"
"813.41100","7.42328","22.85611","51.91853","0.02383","200.47606"
"820.61100","7.42321","22.98684","52.20405","0.02383","201.62271"
"827.81100","7.42310","22.96980","52.45534","0.02382","201.47328"
"835.01100","7.42295","22.97162","52.71310","0.02382","201.48924"
"842.21100","7.42267","23.01809","52.91831","0.02382","201.89680"
"849.41100","7.42193","22.92365","53.14811","0.02381","201.06845"
"856.61100","7.41389","22.89026","53.38211","0.02374","200.77556"
"863.81100","7.40823","22.78866","53.63090","0.02368","199.88443"
"871.01100","7.40633","22.78506","53.86396","0.02366","199.85287"
"878.21100","7.40398","22.86821","54.10154","0.02364","200.58215"
"885.41100","7.38959","22.58788","54.36016","0.02351","198.12335"
"892.61100","7.38964","22.63171","54.58640","0.02351","198.50778"
"899.81100","7.38972","22.65506","54.81019","0.02351","198.71259"
"907.01100","7.38979","22.71009","55.05332","0.02351","199.19531"
"914.21100","7.38983","22.83757","55.30101","0.02351","200.31342"
"921.41100","7.38986","22.71543","55.54029","0.02351","199.24214"
"928.61100","7.38987","22.80836","55.77720","0.02351","200.05724"
"935.81100","7.38986","22.81066","56.04410","0.02351","200.07738"
"943.01100","7.38982","22.83030","56.29220","0.02351","200.24963"
"950.21100","7.38977","22.81210","56.52918","0.02351","200.09000"
"957.41100","7.38969","22.91001","56.77096","0.02351","200.94881"
"964.61100","7.38956","22.96663","56.98819","0.02350","201.44540"
"971.81100","7.37007","22.67416","57.19289","0.02332","198.88011"
"979.01100","7.36581","22.59384","57.45078","0.02328","198.17558"
"986.21100","7.36591","22.65329","57.72122","0.02328","198.69710"
"993.41100","7.36600","22.78022","57.97965","0.02328","199.81041"
"1000.61100","7.36606","22.76033","58.21355","0.02328","199.63596"
"1007.81100","7.36612","22.80709","58.46634","0.02328","200.04611"
"1015.01100","7.36617","22.84651","58.68518","0.02328","200.39188"
"1022.21100","7.36617","22.90742","58.91658","0.02328","200.92612"
"1029.41100","7.36616","22.89689","59.16944","0.02328","200.83379"
"1036.61100","7.36613","22.80612","59.39334","0.02328","200.03758"
"1043.81100","7.36608","22.85573","59.62678","0.02328","200.47273"
"1051.01100","7.36600","22.96229","59.84622","0.02328","201.40735"
"1058.21100","7.36592","22.89092","60.00603","0.02328","200.78139"
"1065.41100","7.36583","22.80067","60.11555","0.02328","199.98981"
"1072.61100","7.36577","22.86873","60.17146","0.02328","200.58676"
"1079.81100","7.36574","22.72975","60.15514","0.02328","199.36771"
"1087.01100","7.36576","22.67715","60.08974","0.02328","198.90636"
"1094.21100","7.36581","22.61737","60.00883","0.02328","198.38202"
"1101.41100","7.36588","22.67047","59.94706","0.02328","198.84772"
"1108.61100","7.36599","22.64617","59.90034","0.02328","198.63461"
"1115.81100","7.36610","22.72695","59.90443","0.02328","199.34317"
"1123.01100","7.36622","22.76944","59.94756","0.02328","199.71584"
"1130.21100","7.36639","22.66093","60.02187","0.02328","198.76407"
"1137.41100","7.36652","22.86548","60.15086","0.02329","200.55827"
"1144.61100","7.36658","22.72641","60.31870","0.02329","199.33839"
"1151.81100","7.36659","22.89999","60.51731","0.02329","200.86095"
"1159.01100","7.36657","22.91281","60.71441","0.02329","200.97336"
"1166.21100","7.36652","22.95497","60.90564","0.02329","201.34314"
"1173.41100","7.36646","22.81830","61.09507","0.02328","200.14439"
"1180.61100","7.36639","22.89863","61.26201","0.02328","200.84897"
"1187.81100","7.36629","23.00353","61.40161","0.02328","201.76909"
"1195.01100","7.36620","22.95042","61.50507","0.02328","201.30324"
"1202.21100","7.36610","22.79981","61.60631","0.02328","199.98222"
"1209.41100","7.36595","22.93319","61.69672","0.02328","201.15213"
"1216.61100","7.36576","22.77068","61.79395","0.02328","199.72673"
"1223.81100","7.36467","22.82150","61.87118","0.02327","200.17247"
"1231.01100","7.35742","22.77828","61.95570","0.02320","199.79341"
"1238.21100","7.35721","22.84792","62.04277","0.02320","200.40424"
"1245.41100","7.35720","22.68426","62.14918","0.02320","198.96875"
"1252.61100","7.35719","22.85620","62.27603","0.02320","200.47685"
"1259.81100","7.35717","22.93886","62.40015","0.02320","201.20187"
"1267.01100","7.35714","22.72506","62.53141","0.02320","199.32658"
"1274.21100","7.35706","22.96514","62.69488","0.02320","201.43239"
"1281.41100","7.32414","22.41800","62.81216","0.02288","196.63329"
"1288.61100","7.32412","22.46758","62.93349","0.02288","197.06818"
"1295.81100","7.32521","22.44008","63.07556","0.02289","196.82700"
"1303.01100","7.36522","22.93800","63.19441","0.02327","201.19429"
"1310.21100","7.36833","22.96516","63.30341","0.02330","201.43256"
"1317.41100","7.36808","23.00063","63.40978","0.02330","201.74364"
"1324.61100","7.36754","22.96214","63.54774","0.02329","201.40608"
"1331.81100","7.36564","22.98296","63.68655","0.02328","201.58868"
"1339.01100","7.32311","22.40079","63.77692","0.02287","196.48233"
"1346.21100","7.31968","22.49368","63.88682","0.02284","197.29706"
"1353.41100","7.32050","22.50061","64.00636","0.02285","197.35789"
"1360.61100","7.33938","22.64529","64.12331","0.02303","198.62694"
"1367.81100","7.36660","23.04320","64.27189","0.02329","202.11707"
"1375.01100","7.36627","23.11842","64.37351","0.02328","202.77682"
"1382.21100","7.36553","23.07197","64.49336","0.02328","202.36943"
"1389.41100","7.34277","22.69676","64.59638","0.02306","199.07837"
"1396.61100","7.31726","22.54609","64.71050","0.02282","197.75682"
"1403.81100","7.31772","22.43094","64.83694","0.02282","196.74681"
"1411.01100","7.31909","22.45720","64.95836","0.02283","196.97710"
"1418.21100","7.35791","23.04654","65.07202","0.02320","202.14632"
"1425.41100","7.36387","23.05067","65.14387","0.02326","202.18260"
"1432.61100","7.36335","23.22956","65.27701","0.02326","203.75168"
"1439.81100","7.35773","23.17011","65.42384","0.02320","203.23021"
"1447.01100","7.31541","22.47729","65.54520","0.02280","197.15334"
"1454.21100","7.31569","22.47936","65.66167","0.02280","197.17148"
"1461.41100","7.31613","22.60368","65.79012","0.02281","198.26193"
"1468.61100","7.31704","22.66770","65.91802","0.02281","198.82343"
"1475.81100","7.32699","22.82401","66.03003","0.02291","200.19450"
"1483.01100","7.33512","22.79831","66.15041","0.02299","199.96906"
"1490.21100","7.33537","22.84777","66.26608","0.02299","200.40289"
"1497.41100","7.33530","22.99051","66.37671","0.02299","201.65488"
"1504.61100","7.33522","22.80672","66.49276","0.02299","200.04282"
"1511.81100","7.33509","22.88636","66.60935","0.02299","200.74138"
"1519.01100","7.33495","23.00933","66.72037","0.02298","201.81998"
"1526.21100","7.33471","22.86236","66.85815","0.02298","200.53088"
"1533.41100","7.33418","23.04348","66.98408","0.02298","202.11954"
"1540.61100","7.33239","22.90621","67.09819","0.02296","200.91548"
"1547.81100","7.31766","22.75459","67.22886","0.02282","199.58556"
"1555.01100","7.31760","22.82733","67.35822","0.02282","200.22360"
"1562.21100","7.31761","22.66433","67.46003","0.02282","198.79387"
"1569.41100","7.31759","22.93812","67.59087","0.02282","201.19539"
"1576.61100","7.31757","22.71499","67.71462","0.02282","199.23830"
"1583.81100","7.31752","22.71888","67.80589","0.02282","199.27237"
"1591.01100","7.31743","22.85316","67.89428","0.02282","200.45018"
"1598.21100","7.31474","22.94034","67.97461","0.02279","201.21487"
"1605.41100","7.31025","22.79484","68.12418","0.02275","199.93861"
"1612.61100","7.30982","22.69129","68.28973","0.02274","199.03035"
"1619.81100","7.30936","22.96323","68.40868","0.02274","201.41566"
"1627.01100","7.30711","22.72672","68.52225","0.02272","199.34119"
"1634.21100","7.29484","22.60130","68.65024","0.02260","198.24101"
"1641.41100","7.29463","22.58550","68.79115","0.02260","198.10251"
"1648.61100","7.29471","22.81149","68.90543","0.02260","200.08464"
"1655.81100","7.29481","22.72525","69.02008","0.02260","199.32825"
"1663.01100","7.29489","22.78618","69.13822","0.02260","199.86266"
"1670.21100","7.29495","22.86786","69.26054","0.02260","200.57913"
"1677.41100","7.29502","22.70786","69.37522","0.02260","199.17570"
"1684.61100","7.29505","22.81074","69.47457","0.02260","200.07806"
"1691.81100","7.29505","22.73391","69.60235","0.02260","199.40419"
"1699.01100","7.29504","22.88644","69.70632","0.02260","200.74205"
"1706.21100","7.29501","22.93745","69.79467","0.02260","201.18950"
"1713.41100","7.29496","22.95814","69.92022","0.02260","201.37097"
"1720.61100","7.29487","22.77045","70.07208","0.02260","199.72473"
"1727.81100","7.29476","22.93922","70.20752","0.02260","201.20505"
"1735.01100","7.29459","23.01862","70.30447","0.02260","201.90143"
"1742.21100","7.29081","23.01494","70.44296","0.02256","201.86917"
"1749.41100","7.26907","22.57295","70.57063","0.02236","197.99243"
"1756.61100","7.26920","22.80345","70.71642","0.02236","200.01416"
"1763.81100","7.26933","22.63573","70.82087","0.02236","198.54300"
"1771.01100","7.26947","22.81594","70.93073","0.02236","200.12369"
"1778.21100","7.26959","22.79692","71.04933","0.02236","199.95685"
"1785.41100","7.26968","22.87077","71.16495","0.02236","200.60464"
"1792.61100","7.26977","22.64828","71.27962","0.02236","198.65312"
"1799.81100","7.26981","22.87134","71.38751","0.02236","200.60965"
"1807.01100","7.26981","22.90583","71.50956","0.02236","200.91219"
"1814.21100","7.26979","22.78081","71.63137","0.02236","199.81558"
"1821.41100","7.26975","22.74970","71.73306","0.02236","199.54272"
"1828.61100","7.26968","22.95893","71.85089","0.02236","201.37787"
"1835.81100","7.26957","23.07169","71.94946","0.02236","202.36696"
"1843.01100","7.26941","23.01897","72.08739","0.02236","201.90453"
"1850.21100","7.26912","22.85687","72.21999","0.02236","200.48274"
"1857.41100","7.24744","22.61707","72.35642","0.02215","198.37933"
"1864.61100","7.22033","22.29387","72.47160","0.02189","195.54449"
"1871.81100","7.22114","22.46668","72.59056","0.02190","197.06026"
"1879.01100","7.23257","22.66054","72.70722","0.02201","198.76067"
"1886.21100","7.27788","23.24982","72.82300","0.02244","203.92934"
"1893.41100","7.27726","23.32436","72.94907","0.02243","204.58316"
"1900.61100","7.25906","23.07863","73.03890","0.02226","202.42783"
"1907.81100","7.21423","22.49434","73.18197","0.02183","197.30292"
"1915.01100","7.21460","22.41763","73.32323","0.02184","196.63004"
"1922.21100","7.21538","22.55479","73.45696","0.02184","197.83311"
"1929.41100","7.22259","22.55192","73.55197","0.02191","197.80792"
"1936.61100","7.23214","22.95803","73.66784","0.02200","201.37006"
"1943.81100","7.23216","22.98482","73.78918","0.02200","201.60495"
"1951.01100","7.23210","22.78185","73.89189","0.02200","199.82469"
"1958.21100","7.23202","22.82830","74.00744","0.02200","200.23210"
"1965.41100","7.23189","22.97244","74.12684","0.02200","201.49644"
"1972.61100","7.23166","23.00989","74.23204","0.02200","201.82486"
"1979.81100","7.23115","22.98037","74.35307","0.02200","201.56599"
"1987.01100","7.22811","22.95749","74.50674","0.02197","201.36528"
"1994.21100","7.21753","22.99045","74.60846","0.02187","201.65439"
"2001.41100","7.21230","22.88869","74.71756","0.02182","200.76180"
"2008.61100","7.19478","22.74280","74.82293","0.02165","199.48218"
"2015.81100","7.19472","22.86217","74.97461","0.02165","200.52917"
"2023.01100","7.19474","22.82650","75.10258","0.02165","200.21632"
"2030.21100","7.19477","22.90573","75.20201","0.02165","200.91124"
"2037.41100","7.19475","22.91817","75.32527","0.02165","201.02042"
"2044.61100","7.19471","22.78493","75.46352","0.02165","199.85173"
"2051.81100","7.19462","22.78095","75.56191","0.02165","199.81685"
"2059.01100","7.17125","22.63291","75.66395","0.02142","198.51834"
"2066.21100","7.16988","22.55489","75.74443","0.02141","197.83395"
"2073.41100","7.16999","22.66215","75.86161","0.02141","198.77475"
"2080.61100","7.17006","22.74150","75.97529","0.02141","199.47081"
"2087.81100","7.17008","22.72505","76.11201","0.02141","199.32649"
"2095.01100","7.17006","22.90776","76.21426","0.02141","200.92912"
"2102.21100","7.16999","23.02449","76.35873","0.02141","201.95297"
"2109.41100","7.16985","23.05421","76.48862","0.02141","202.21364"
"2116.61100","7.15830","22.88653","76.61635","0.02130","200.74290"
"2123.81100","7.11797","22.35086","76.74180","0.02092","196.04436"
"2131.01100","7.11858","22.53919","76.85207","0.02092","197.69627"
"2138.21100","7.12588","22.70729","76.94888","0.02099","199.17073"
"2145.41100","7.14539","22.97701","77.09544","0.02118","201.53651"
"2152.61100","7.16639","23.16714","77.20367","0.02138","203.20419"
"2159.81100","7.16560","23.39747","77.34306","0.02137","205.22447"
"2167.01100","7.11586","22.72839","77.47437","0.02090","199.35582"
"2174.21100","7.11580","22.75015","77.61043","0.02090","199.54669"
"2181.41100","7.11582","22.85549","77.73271","0.02090","200.47064"
"2188.61100","7.11579","22.95564","77.83505","0.02090","201.34906"
"2195.81100","7.11571","22.99803","77.98467","0.02089","201.72089"
"2203.01100","7.11450","23.05955","78.10719","0.02088","202.26047"
"2210.21100","7.07542","22.41903","78.21658","0.02051","196.64233"
"2217.41100","7.07562","22.54424","78.33903","0.02051","197.74054"
"2224.61100","7.07590","22.66480","78.47231","0.02052","198.79803"
"2231.81100","7.07619","22.63858","78.58278","0.02052","198.56801"
"2239.01100","7.07640","22.74120","78.68400","0.02052","199.46812"
"2246.21100","7.07643","22.73770","78.79375","0.02052","199.43748"
"2253.41100","7.07638","22.79341","78.91582","0.02052","199.92610"
"2260.61100","7.07630","23.00428","79.05088","0.02052","201.77565"
"2267.81100","7.07615","23.11326","79.19003","0.02052","202.73161"
"2275.01100","7.07588","22.97720","79.29907","0.02052","201.53813"
"2282.21100","7.07388","23.17722","79.39534","0.02050","203.29257"
"2289.41100","7.02406","22.63954","79.50411","0.02002","198.57646"
"2296.61100","7.02422","22.58501","79.59502","0.02002","198.09816"
"2303.81100","7.02431","22.81792","79.71024","0.02002","200.14107"
"2311.01100","7.02433","22.75705","79.88473","0.02002","199.60719"
"2318.21100","7.02427","22.82460","80.04047","0.02002","200.19971"
"2325.41100","7.02415","22.87355","80.16940","0.02002","200.62900"
"2332.61100","7.02393","22.96163","80.26672","0.02002","201.40161"
"2339.81100","7.00005","22.79654","80.33253","0.01979","199.95354"
"2347.01100","6.98373","22.67569","80.41719","0.01964","198.89352"
"2354.21100","6.98378","22.81028","80.58363","0.01964","200.07404"
"2361.41100","6.98377","22.77569","80.70244","0.01964","199.77071"
"2368.61100","6.98369","22.95990","80.79922","0.01964","201.38644"
"2375.81100","6.98325","22.92942","80.95369","0.01963","201.11908"
"2383.01100","6.92914","22.50157","81.09950","0.01912","197.36629"
"2390.21100","6.92937","22.51184","81.22923","0.01912","197.45639"
"2397.41100","6.92980","22.67878","81.33574","0.01912","198.92068"
"2404.61100","6.93018","22.64488","81.43552","0.01913","198.62328"
"2411.81100","6.93044","22.82424","81.55904","0.01913","200.19655"
"2419.01100","6.93054","22.95074","81.67068","0.01913","201.30611"
"2426.21100","6.93048","22.90984","81.82087","0.01913","200.94731"
"2433.41100","6.93035","23.06525","81.94735","0.01913","202.31046"
"2440.61100","6.93012","23.03744","82.05754","0.01913","202.06651"
"2447.81100","6.92982","23.11143","82.16187","0.01912","202.71553"
"2455.01100","6.92961","23.14021","82.27678","0.01912","202.96799"
"2462.21100","6.88565","22.67205","82.36671","0.01870","198.86159"
"2469.41100","6.87244","22.69023","82.46127","0.01858","199.02104"
"2476.61100","6.87240","22.81186","82.56090","0.01858","200.08794"
"2483.81100","6.87227","22.91488","82.71626","0.01857","200.99149"
"2491.01100","6.86745","22.94777","82.82616","0.01853","201.28001"
"2498.21100","6.79215","22.24504","82.95267","0.01781","195.11618"
"2505.41100","6.79241","22.39877","83.09754","0.01781","196.46465"
"2512.61100","6.79268","22.52098","83.24163","0.01782","197.53654"
"2519.81100","6.79299","22.58031","83.36098","0.01782","198.05693"
"2527.01100","6.79342","22.65324","83.46264","0.01782","198.69662"
"2534.21100","6.79380","22.76345","83.59733","0.01783","199.66333"
"2541.41100","6.79400","22.83914","83.72874","0.01783","200.32721"
"2548.61100","6.79403","22.87168","83.84949","0.01783","200.61259"
"2555.81100","6.79397","22.94777","83.97827","0.01783","201.28004"
"2563.01100","6.79388","23.03533","84.09813","0.01783","202.04799"
"2570.21100","6.79374","23.04856","84.19061","0.01783","202.16411"
"2577.41100","6.79354","23.15650","84.27306","0.01782","203.11082"
"2584.61100","6.79319","23.20756","84.38948","0.01782","203.55873"
"2591.81100","6.79191","23.31152","84.49641","0.01781","204.47052"
"2599.01100","6.67059","22.13181","84.61475","0.01665","194.12309"
"2606.21100","6.67082","22.31791","84.75851","0.01665","195.75542"
"2613.41100","6.67146","22.38568","84.87362","0.01666","196.34978"
"2620.61100","6.67328","22.48341","84.96152","0.01668","197.20702"
"2627.81100","6.69386","22.87993","85.08585","0.01687","200.68498"
"2635.01100","6.69485","22.95228","85.23184","0.01688","201.31955"
"2642.21100","6.69473","23.05515","85.34588","0.01688","202.22183"
"2649.41100","6.69455","23.07468","85.49763","0.01688","202.39316"
"2656.61100","6.69417","23.16519","85.61568","0.01688","203.18707"
"2663.81100","6.69176","23.27690","85.72520","0.01685","204.16687"
"2671.01100","6.62815","22.61275","85.88148","0.01625","198.34148"
"2678.21100","6.62456","22.72994","86.00082","0.01621","199.36938"
"2685.41100","6.62435","22.84011","86.10230","0.01621","200.33571"
"2692.61100","6.62394","22.85668","86.21269","0.01621","200.48103"
"2699.81100","6.62003","22.93630","86.32561","0.01617","201.17943"
"2707.01100","6.59640","22.81300","86.45528","0.01595","200.09789"
"2714.21100","6.58878","22.83567","86.53207","0.01587","200.29680"
"2721.41100","6.58186","22.85005","86.66517","0.01581","200.42293"
"2728.61100","6.55832","22.68505","86.80559","0.01558","198.97562"
"2735.81100","6.54078","22.66101","86.93317","0.01542","198.76479"
"2743.01100","6.54055","22.78121","87.04996","0.01541","199.81908"
"2750.21100","6.54040","22.85388","87.15376","0.01541","200.45651"
"2757.41100","6.53788","22.91492","87.26409","0.01539","200.99188"
"2764.61100","6.52088","22.85686","87.38214","0.01523","200.48265"
"2771.81100","6.49944","22.68509","87.53786","0.01502","198.97600"
"2779.01100","6.49367","22.79852","87.66586","0.01497","199.97087"
"2786.21100","6.48951","22.83229","87.73593","0.01493","200.26714"
"2793.41100","6.48576","22.90451","87.87063","0.01489","200.90060"
"2800.61100","6.44475","22.65894","88.00092","0.01450","198.74658"
"2807.81100","6.44160","22.71733","88.15878","0.01447","199.25880"
"2815.01100","6.44143","22.79994","88.25716","0.01447","199.98334"
"2822.21100","6.44104","22.97748","88.33167","0.01446","201.54063"
"2829.41100","6.43795","22.99494","88.48789","0.01444","201.69379"
"2836.61100","6.34430","22.28112","88.59165","0.01354","195.43272"
"2843.81100","6.34449","22.43029","88.70904","0.01354","196.74110"
"2851.01100","6.34466","22.55245","88.84074","0.01355","197.81255"
"2858.21100","6.34481","22.64102","88.96733","0.01355","198.58948"
"2865.41100","6.34488","22.79045","89.09156","0.01355","199.90018"
"2872.61100","6.34487","22.87447","89.21204","0.01355","200.63707"
"2879.81100","6.34482","22.94209","89.36826","0.01355","201.23019"
"2887.01100","6.34473","23.06217","89.47675","0.01355","202.28343"
"2894.21100","6.34458","23.12134","89.56120","0.01355","202.80241"
"2901.41100","6.34433","23.22060","89.66965","0.01354","203.67311"
"2908.61100","6.33320","23.14782","89.80708","0.01344","203.03471"
"2915.81100","6.19383","22.14632","89.92384","0.01211","194.25029"
"2923.01100","6.19449","22.37288","90.05731","0.01211","196.23752"
"2930.21100","6.19560","22.54696","90.19337","0.01213","197.76442"
"2937.41100","6.21410","22.79970","90.27965","0.01230","199.98123"
"2944.61100","6.21447","22.87604","90.43100","0.01231","200.65086"
"2951.81100","6.21444","22.93820","90.50364","0.01231","201.19606"
"2959.01100","6.21436","23.01348","90.63107","0.01230","201.85635"
"2966.21100","6.21419","23.10031","90.73497","0.01230","202.61801"
"2973.41100","6.21386","23.16835","90.81985","0.01230","203.21480"
"2980.61100","6.21238","23.19042","90.94978","0.01229","203.40837"
"2987.81100","6.15359","22.68143","91.03827","0.01173","198.94388"
"2995.01100","6.13711","22.78872","91.20158","0.01157","199.88493"
"3002.21100","6.12308","22.77856","91.31644","0.01143","199.79582"
"3009.41100","6.10230","22.79301","91.44967","0.01124","199.92259"
"3016.61100","6.09732","22.91243","91.60403","0.01119","200.97003"
"3023.81100","6.05262","22.62580","91.73052","0.01076","198.45599"
"3031.01100","6.05259","22.76507","91.88507","0.01076","199.67749"
"3038.21100","6.05258","22.79233","92.00872","0.01076","199.91661"
"3045.41100","6.05248","22.93920","92.10413","0.01076","201.20482"
"3052.61100","6.04457","22.86812","92.20568","0.01069","200.58138"
"3059.81100","6.00577","22.74714","92.27611","0.01032","199.52022"
"3067.01100","6.00316","22.82439","92.39765","0.01029","200.19785"
"3074.21100","6.00083","22.91204","92.48946","0.01027","200.96661"
"3081.41100","5.95212","22.68852","92.58649","0.00981","199.00607"
"3088.61100","5.95197","22.77080","92.71703","0.00980","199.72775"
"3095.81100","5.95114","22.98338","92.86188","0.00980","201.59239"
"3103.01100","5.91727","22.70521","93.00093","0.00947","199.15251"
"3110.21100","5.90563","22.81932","93.11794","0.00936","200.15340"
"3117.41100","5.90205","22.94784","93.24038","0.00933","201.28061"
"3124.61100","5.85563","22.68921","93.38865","0.00889","199.01218"
"3131.81100","5.85510","22.85584","93.51607","0.00888","200.47369"
"3139.01100","5.84089","22.89479","93.61018","0.00874","200.81531"
"3146.21100","5.81096","22.77791","93.75085","0.00846","199.79013"
"3153.41100","5.80968","22.96535","93.86703","0.00845","201.43417"
"3160.61100","5.76106","22.59101","93.99348","0.00798","198.15085"
"3167.81100","5.75960","22.82733","94.11816","0.00797","200.22362"
"3175.01100","5.75951","22.86070","94.21371","0.00797","200.51630"
"3182.21100","5.74639","22.84854","94.32267","0.00784","200.40968"
"3189.41100","5.70936","22.75746","94.45107","0.00749","199.61073"
"3196.61100","5.70409","22.85923","94.56823","0.00744","200.50339"
"3203.81100","5.67045","22.62697","94.66895","0.00712","198.46623"
"3211.01100","5.66932","22.86120","94.75468","0.00711","200.52066"
"3218.21100","5.66405","22.89764","94.89616","0.00706","200.84033"
"3225.41100","5.62129","22.75919","95.00311","0.00665","199.62595"
"3232.61100","5.60799","22.80839","95.13469","0.00653","200.05746"
"3239.81100","5.57494","22.73844","95.28048","0.00621","199.44395"
"3247.01100","5.57245","22.90300","95.47639","0.00619","200.88733"
"3254.21100","5.56001","22.90409","95.61118","0.00607","200.89687"
"3261.41100","5.52423","22.69990","95.72760","0.00573","199.10591"
"3268.61100","5.51715","22.77451","95.81307","0.00566","199.76035"
"3275.81100","5.47833","22.63993","95.90636","0.00529","198.57990"
"3283.01100","5.47706","22.76009","96.01363","0.00528","199.63382"
"3290.21100","5.47615","22.92550","96.10200","0.00527","201.08464"
"3297.41100","5.45970","22.91109","96.19131","0.00511","200.95825"
"3304.61100","5.41542","22.66730","96.28570","0.00469","198.81996"
"3311.81100","5.40530","22.86941","96.44485","0.00459","200.59274"
"3319.01100","5.36634","22.69918","96.58605","0.00422","199.09958"
"3326.21100","5.35990","22.90421","96.73034","0.00416","200.89790"
"3333.41100","5.32970","22.82285","96.89317","0.00387","200.18428"
"3340.61100","5.32382","22.86211","96.99046","0.00382","200.52872"
"3347.81100","5.27564","22.67539","97.09511","0.00336","198.89088"
"3355.01100","5.27467","22.82605","97.19895","0.00335","200.21236"
"3362.21100","5.25216","22.71523","97.28215","0.00313","199.24034"
"3369.41100","5.25030","22.96408","97.38455","0.00312","201.42305"
"3376.61100","5.23323","22.95602","97.55429","0.00295","201.35236"
"3383.81100","5.17363","22.69369","97.72612","0.00239","199.05141"
"3391.01100","5.17105","22.93323","97.85135","0.00236","201.15248"
"3398.21100","5.13758","22.71135","97.95444","0.00204","199.20628"
"3405.41100","5.13022","22.90727","98.06745","0.00197","200.92480"
"3412.61100","5.06896","22.59201","98.12679","0.00139","198.15961"
"3419.81100","5.06560","22.80497","98.22870","0.00136","200.02748"
"3427.01100","5.06256","22.94711","98.38237","0.00133","201.27426"
"3434.21100","5.03558","22.79958","98.51973","0.00107","199.98018"
"3441.41100","4.96751","22.54439","98.65470","0.00042","197.74187"
"3448.61100","4.96601","22.74101","98.78544","0.00041","199.46648"
"3455.81100","4.96537","22.88177","98.87554","0.00040","200.70116"
"3463.01100","4.94619","22.77506","99.01003","0.00022","199.76515"
"3470.21100","4.90174","22.55702","99.11335","-0.00021","197.85266"
"3477.41100","4.89140","22.77102","99.22385","-0.00030","199.72968"
"3484.61100","4.88908","22.99404","99.34293","-0.00033","201.68585"
"3491.81100","4.85197","22.79967","99.46157","-0.00068","199.98096"
"3499.01100","4.83206","22.80608","99.56857","-0.00087","200.03725"
"3506.21100","4.78657","22.77385","99.69016","-0.00130","199.75449"
"3513.41100","4.78405","22.85480","99.80327","-0.00133","200.46457"
"3520.61100","4.75631","22.84377","99.92865","-0.00159","200.36777"
"3527.81100","4.73996","22.91700","100.06834","-0.00175","201.01016"
"3535.01100","4.68956","22.78661","100.18116","-0.00223","199.86646"
"3542.21100","4.66967","22.77008","100.30562","-0.00242","199.72150"
"3549.41100","4.65311","22.90360","100.41352","-0.00258","200.89261"
"3556.61100","4.61981","22.82954","100.55788","-0.00289","200.24304"
"3563.81100","4.59020","22.85109","100.71268","-0.00318","200.43204"
"3571.01100","4.56036","22.77116","100.79811","-0.00346","199.73094"
"3578.21100","4.53883","22.85650","100.89305","-0.00366","200.47948"
"3585.41100","4.49523","22.79934","101.03542","-0.00408","199.97807"
"3592.61100","4.48488","22.87847","101.16300","-0.00418","200.67221"
"3599.81100","4.44161","22.82242","101.22791","-0.00459","200.18054"
"3607.01100","4.40384","22.79657","101.30954","-0.00495","199.95384"
"3614.21100","4.39535","22.94116","101.46165","-0.00503","201.22206"
"3621.41100","4.35612","22.86224","101.60427","-0.00541","200.52982"
"3628.61100","4.30768","22.74731","101.78107","-0.00587","199.52176"
"3635.81100","4.30073","23.00052","101.85682","-0.00593","201.74271"
"3643.01100","4.21595","22.55818","101.96471","-0.00674","197.86287"
"3650.21100","4.20783","22.83159","102.08240","-0.00682","200.26099"
"3657.41100","4.16510","22.70882","102.13484","-0.00723","199.18416"
"3664.61100","4.07788","22.56556","102.30602","-0.00806","197.92758"
"3671.81100","4.05357","22.74184","102.47970","-0.00829","199.47379"
"3679.01100","4.02559","22.84698","102.62548","-0.00856","200.39601"
"3686.21100","4.01464","22.91588","102.73125","-0.00866","201.00027"
"3693.41100","3.96641","22.83883","102.92239","-0.00912","200.32446"
"3700.61100","3.91950","22.77078","103.02914","-0.00957","199.72760"
"3707.81100","3.89650","22.78835","103.10950","-0.00979","199.88167"
"3715.01100","3.87133","22.92953","103.19630","-0.01003","201.12003"
"3722.21100","3.82251","22.70570","103.30460","-0.01049","199.15678"
"3729.41100","3.79885","22.83453","103.39417","-0.01072","200.28680"
"3736.61100","3.75983","22.78759","103.53015","-0.01109","199.87508"
"3743.81100","3.71769","22.82935","103.64431","-0.01149","200.24135"
"3751.01100","3.66220","22.82068","103.75358","-0.01202","200.16533"
"3758.21100","3.59875","22.86105","103.86214","-0.01262","200.51941"
"3765.41100","3.54365","22.75071","103.94111","-0.01315","199.55154"
"3772.61100","3.44500","22.69008","104.10255","-0.01409","199.01973"
"3779.81100","3.29579","22.48544","104.25017","-0.01551","197.22485"
"3787.01100","3.18723","22.80144","104.40661","-0.01655","199.99651"
"3794.21100","3.10771","22.91400","104.55750","-0.01730","200.98378"
"3801.41100","2.99110","22.88103","104.73662","-0.01842","200.69460"
"3808.61100","2.82851","22.74219","104.84041","-0.01997","199.47681"
"3815.81100","2.69280","22.91803","104.87675","-0.02126","201.01913"
"3823.01100","2.54916","22.80019","104.93674","-0.02263","199.98558"
"3830.21100","2.28479","22.73768","105.03648","-0.02515","199.43732"
"3837.41100","2.08531","22.88280","105.11688","-0.02705","200.71021"
"3844.61100","1.87315","22.64233","105.21593","-0.02907","198.60097"
"3851.81100","1.67116","22.78443","105.35059","-0.03100","199.84737"
"3859.01100","1.46497","22.65180","105.48055","-0.03296","198.68399"
"3866.21100","1.29819","22.71337","105.59454","-0.03455","199.22404"
"3873.41100","1.05696","22.86957","105.75918","-0.03685","200.59412"
"3880.61100","0.67234","22.81410","105.96813","-0.04052","200.10757"
"3887.81100","0.36178","22.83995","106.08272","-0.04348","200.33434"
"3895.01100","-0.03922","22.80832","106.21508","-0.04730","200.05692"
"3902.21100","-0.48644","22.68206","106.42747","-0.05156","198.94939"
"3909.41100","-0.76605","22.76422","106.54416","-0.05422","199.67007"
"3916.61100","-0.95344","22.86977","106.58517","-0.05601","200.59587"
"3923.81100","-1.09932","22.67103","106.64339","-0.05740","198.85268"
"3931.01100","-1.23671","22.80404","106.74026","-0.05871","200.01930"
"3938.21100","-1.35554","22.66478","106.83081","-0.05984","198.79784"
"3945.41100","-1.44170","22.84432","106.95536","-0.06066","200.37268"
"3952.61100","-1.52405","22.84366","107.06441","-0.06145","200.36684"
"3959.81100","-1.60543","22.70280","107.17704","-0.06222","199.13129"
"3967.01100","-1.66043","22.98521","107.33604","-0.06275","201.60841"
"3974.21100","-1.73671","22.89437","107.50205","-0.06348","200.81165"
"3981.41100","-1.86768","22.43411","107.68888","-0.06472","196.77460"
"3988.61100","-1.92967","22.77436","107.77659","-0.06531","199.75903"
"3995.81100","-1.98014","22.69026","107.87883","-0.06580","199.02135"
"4003.01100","-2.02133","22.83757","107.98074","-0.06619","200.31345"
"4010.21100","-2.08159","22.79595","108.08794","-0.06676","199.94841"
"4017.41100","-2.12072","22.76834","108.22015","-0.06714","199.70622"
"4024.61100","-2.17796","22.72441","108.35554","-0.06768","199.32089"
"4031.81100","-2.18683","22.92387","108.49876","-0.06777","201.07039"
"4039.01100","-2.24156","22.86676","108.61890","-0.06829","200.56947"
"4046.21100","-2.28756","22.84551","108.74493","-0.06873","200.38312"
"4053.41100","-2.31675","22.81665","108.83256","-0.06900","200.12997"
"4060.61100","-2.36459","22.68898","108.93869","-0.06946","199.01015"
"4067.81100","-2.38750","22.85486","109.03674","-0.06968","200.46510"
"4075.01100","-2.42162","22.73322","109.14707","-0.07000","199.39818"
"4082.21100","-2.46069","22.80036","109.24465","-0.07038","199.98703"
"4089.41100","-2.49691","22.80176","109.34008","-0.07072","199.99931"
"4096.61100","-2.53346","22.75623","109.42475","-0.07107","199.60001"
"4103.81100","-2.56137","22.89227","109.56898","-0.07134","200.79318"
"4111.01100","-2.58910","22.82246","109.74889","-0.07160","200.18088"
"4118.21100","-2.61979","22.79498","109.90162","-0.07189","199.93983"
"4125.41100","-2.66046","22.78158","110.05658","-0.07228","199.82234"
"4132.61100","-2.66634","22.84517","110.17339","-0.07234","200.38010"
"4139.81100","-2.68870","22.80653","110.26182","-0.07255","200.04115"
"4147.01100","-2.70346","22.92478","110.32224","-0.07269","201.07840"
"4154.21100","-2.74255","22.67435","110.41129","-0.07306","198.88181"
"4161.41100","-2.75973","22.82009","110.51978","-0.07323","200.16006"
"4168.61100","-2.78126","22.80786","110.65720","-0.07343","200.05280"
"4175.81100","-2.79926","22.88913","110.83012","-0.07360","200.76567"
"4183.01100","-2.82227","22.84579","111.00104","-0.07382","200.38551"
"4190.21100","-2.85549","22.70749","111.12463","-0.07414","199.17249"
"4197.41100","-2.85943","22.90501","111.25960","-0.07418","200.90500"
"4204.61100","-2.89097","22.69163","111.37325","-0.07448","199.03337"
"4211.81100","-2.89677","22.88646","111.47695","-0.07453","200.74222"
"4219.01100","-2.91210","22.82145","111.58324","-0.07468","200.17200"
"4226.21100","-2.94569","22.75500","111.64680","-0.07500","199.58919"
"4233.41100","-2.94762","22.90907","111.77883","-0.07502","200.94061"
"4240.61100","-2.95765","22.91528","111.88478","-0.07511","200.99501"
"4247.81100","-2.99414","22.72298","112.01429","-0.07546","199.30832"
"4255.01100","-3.00037","22.84298","112.12824","-0.07552","200.36084"
"4262.21100","-3.01478","22.77115","112.25822","-0.07566","199.73083"
"4269.41100","-3.04747","22.76362","112.35548","-0.07597","199.66476"
"4276.61100","-3.04876","22.84049","112.55319","-0.07598","200.33905"
"4283.81100","-3.06372","22.80577","112.64497","-0.07612","200.03447"
"4291.01100","-3.08285","22.76408","112.77414","-0.07631","199.66887"
"4298.21100","-3.08891","22.86287","112.87218","-0.07636","200.53531"
"4305.41100","-3.10519","22.82912","112.97169","-0.07652","200.23935"
"4312.61100","-3.13783","22.61015","113.05658","-0.07683","198.31868"
"4319.81100","-3.13791","22.90039","113.13664","-0.07683","200.86443"
"4327.01100","-3.13895","23.00614","113.30152","-0.07684","201.79198"
"4334.21100","-3.15522","22.87183","113.44975","-0.07699","200.61391"
"4341.41100","-3.18509","22.73049","113.54974","-0.07728","199.37421"
"4348.61100","-3.19101","22.81568","113.69556","-0.07734","200.12144"
"4355.81100","-3.22392","22.55544","113.84518","-0.07765","197.83885"
"4363.01100","-3.23385","22.69112","113.97446","-0.07774","199.02885"
"4370.21100","-3.23391","22.87397","114.05793","-0.07774","200.63274"
"4377.41100","-3.23459","22.99231","114.16447","-0.07775","201.67070"
"4384.61100","-3.25716","22.78947","114.33779","-0.07797","199.89151"
"4391.81100","-3.27608","22.79325","114.43645","-0.07815","199.92465"
"4399.01100","-3.28180","22.86903","114.53910","-0.07820","200.58937"
"4406.21100","-3.29191","22.82344","114.65910","-0.07830","200.18953"
"4413.41100","-3.32181","22.67122","114.79951","-0.07858","198.85431"
"4420.61100","-3.32533","22.87619","114.90134","-0.07862","200.65216"
"4427.81100","-3.32867","22.92375","115.02077","-0.07865","201.06932"
"4435.01100","-3.33884","22.92413","115.11562","-0.07874","201.07266"
"4442.21100","-3.35917","22.75116","115.25412","-0.07894","199.55554"
"4449.41100","-3.36908","22.75295","115.39141","-0.07903","199.57118"
"4456.61100","-3.37270","22.83296","115.50716","-0.07907","200.27303"
"4463.81100","-3.38056","22.90160","115.59794","-0.07914","200.87502"
"4471.01100","-3.38207","22.99276","115.76041","-0.07916","201.67462"
"4478.21100","-3.43734","22.45527","115.87821","-0.07968","196.96022"
"4485.41100","-3.43731","22.67346","115.94566","-0.07968","198.87399"
"4492.61100","-3.43729","22.82949","116.04953","-0.07968","200.24255"
"4499.81100","-3.43733","22.96892","116.11071","-0.07968","201.46553"
"4507.01100","-3.43766","23.08014","116.23672","-0.07969","202.44106"
"4514.21100","-3.47946","22.67082","116.36951","-0.08009","198.85083"
"4521.41100","-3.48063","22.79455","116.51579","-0.08010","199.93613"
"4528.61100","-3.48209","22.91091","116.65399","-0.08011","200.95671"
"4535.81100","-3.53415","22.36651","116.76622","-0.08061","196.18163"
"4543.01100","-3.53412","22.69366","116.92941","-0.08061","199.05119"
"4550.21100","-3.53410","22.81981","117.11685","-0.08061","200.15762"
"4557.41100","-3.53412","22.91701","117.22361","-0.08061","201.01021"
"4564.61100","-3.53422","23.02356","117.34638","-0.08061","201.94479"
"4571.81100","-3.54977","22.86856","117.47501","-0.08076","200.58527"
"4579.01100","-3.57237","22.72522","117.57066","-0.08097","199.32802"
"4586.21100","-3.57300","22.80500","117.67151","-0.08098","200.02776"
"4593.41100","-3.57377","22.91144","117.76816","-0.08098","200.96133"
"4600.61100","-3.61210","22.39025","117.88401","-0.08135","196.38986"
"4607.81100","-3.62850","22.46420","117.97543","-0.08151","197.03851"
"4615.01100","-3.62838","22.64145","118.12785","-0.08150","198.59320"
"4622.21100","-3.62831","22.73286","118.20561","-0.08150","199.39502"
"4629.41100","-3.62830","22.82716","118.28304","-0.08150","200.22211"
"4636.61100","-3.62834","23.02407","118.35602","-0.08150","201.94923"
"4643.81100","-3.62844","23.10762","118.52096","-0.08151","202.68208"
"4651.01100","-3.62879","23.14423","118.68288","-0.08151","203.00317"
"4658.21100","-3.67138","22.70667","118.83112","-0.08191","199.16528"
"4665.41100","-3.72332","22.18362","118.98481","-0.08241","194.57753"
"4672.61100","-3.72466","22.48956","119.12429","-0.08242","197.26099"
"4679.81100","-3.72444","22.59604","119.27827","-0.08242","198.19495"
"4687.01100","-3.72424","22.66982","119.38148","-0.08242","198.84207"
"4694.21100","-3.72411","22.77980","119.45952","-0.08242","199.80672"
"4701.41100","-3.72409","22.91084","119.62830","-0.08242","200.95607"
"4708.61100","-3.72414","22.91000","119.75105","-0.08242","200.94876"
"4715.81100","-3.72425","22.98480","119.85812","-0.08242","201.60486"
"4723.01100","-3.72446","23.06215","119.89388","-0.08242","202.28328"
"4730.21100","-3.72532","23.10969","119.99113","-0.08243","202.70026"
"4737.41100","-3.76140","22.67252","120.06460","-0.08277","198.86574"
"4744.61100","-3.76669","22.78612","120.16607","-0.08282","199.86217"
"4751.81100","-3.76736","22.91044","120.32375","-0.08283","200.95261"
"4759.01100","-3.77890","22.77622","120.46053","-0.08294","199.77534"
"4766.21100","-3.80553","22.51354","120.62203","-0.08319","197.47133"
"4773.41100","-3.80634","22.63683","120.74567","-0.08320","198.55266"
"4780.61100","-3.80630","22.77282","120.88491","-0.08320","199.74553"
"4787.81100","-3.80635","22.86613","121.00796","-0.08320","200.56389"
"4795.01100","-3.80647","23.00064","121.12922","-0.08320","201.74373"
"4802.21100","-3.82295","22.76969","121.29504","-0.08336","199.71800"
"4809.41100","-3.83110","22.78288","121.41311","-0.08344","199.83377"
"4816.61100","-3.83234","22.85025","121.49378","-0.08345","200.42468"
"4823.81100","-3.85551","22.64811","121.61847","-0.08367","198.65167"
"4831.01100","-3.85571","22.76906","121.74605","-0.08367","199.71249"
"4838.21100","-3.85570","22.87215","121.84083","-0.08367","200.61673"
"4845.41100","-3.85579","22.96615","121.91563","-0.08367","201.44121"
"4852.61100","-3.86198","22.86276","122.00093","-0.08373","200.53435"
"4859.81100","-3.88003","22.71213","122.11700","-0.08390","199.21313"
"4867.01100","-3.88098","22.79983","122.25143","-0.08391","199.98242"
"4874.21100","-3.89947","22.67345","122.40469","-0.08409","198.87387"
"4881.41100","-3.90527","22.66709","122.50940","-0.08414","198.81813"
"4888.61100","-3.90526","22.79789","122.69758","-0.08414","199.96539"
"4895.81100","-3.90531","22.85222","122.79261","-0.08414","200.44197"
"4903.01100","-3.90590","22.92522","122.90985","-0.08415","201.08228"
"4910.21100","-3.92191","22.76796","122.98447","-0.08430","199.70284"
"4917.41100","-3.92562","22.87397","123.08006","-0.08434","200.63271"
"4924.61100","-3.92767","22.89175","123.23444","-0.08436","200.78868"
"4931.81100","-3.94999","22.60384","123.32442","-0.08457","198.26332"
"4939.01100","-3.95166","22.80794","123.43089","-0.08459","200.05350"
"4946.21100","-3.95175","22.87012","123.61457","-0.08459","200.59897"
"4953.41100","-3.95288","22.87504","123.78321","-0.08460","200.64209"
"4960.61100","-3.96747","22.73011","123.90244","-0.08474","199.37091"
"4967.81100","-3.96856","22.80236","124.00466","-0.08475","200.00462"
"4975.01100","-3.97042","22.90685","124.16792","-0.08476","200.92114"
"4982.21100","-3.99519","22.53840","124.27847","-0.08500","197.68932"
"4989.41100","-3.99608","22.73980","124.37402","-0.08501","199.45586"
"4996.61100","-3.99604","22.76762","124.45864","-0.08501","199.69991"
"5003.81100","-3.99603","22.86077","124.52610","-0.08501","200.51692"
"5011.01100","-3.99610","22.90455","124.64100","-0.08501","200.90094"
"5018.21100","-4.00055","22.96603","124.80791","-0.08505","201.44022"
"5025.41100","-4.01134","22.86212","124.90598","-0.08515","200.52878"
"5032.61100","-4.01743","22.86853","125.09417","-0.08521","200.58496"
"5039.81100","-4.02078","22.85097","125.26691","-0.08524","200.43098"
"5047.01100","-4.02793","22.81107","125.34873","-0.08531","200.08096"
"5054.21100","-4.03574","22.82883","125.41634","-0.08539","200.23674"
"5061.41100","-4.04029","22.80919","125.52863","-0.08543","200.06448"
"5068.61100","-4.04089","22.85709","125.61430","-0.08544","200.48468"
"5075.81100","-4.04218","22.96572","125.70558","-0.08545","201.43747"
"5083.01100","-4.05183","22.82600","125.84909","-0.08554","200.21194"
"5090.21100","-4.05810","22.80555","125.98615","-0.08560","200.03255"
"5097.41100","-4.05876","22.90002","126.06860","-0.08561","200.86121"
"5104.61100","-4.06401","22.80658","126.23558","-0.08566","200.04161"
"5111.81100","-4.06772","22.83779","126.38071","-0.08569","200.31538"
"5119.01100","-4.07464","22.82710","126.50821","-0.08576","200.22162"
"5126.21100","-4.09969","22.49537","126.63657","-0.08600","197.31197"
"5133.41100","-4.09958","22.64128","126.71179","-0.08600","198.59171"
"5140.61100","-4.09943","22.69437","126.79656","-0.08599","199.05742"
"5147.81100","-4.09933","22.75689","126.93920","-0.08599","199.60576"
"5155.01100","-4.09928","22.78462","127.05650","-0.08599","199.84900"
"5162.21100","-4.09931","22.93013","127.20360","-0.08599","201.12532"
"5169.41100","-4.09938","22.96138","127.36137","-0.08599","201.39937"
"5176.61100","-4.09953","22.98979","127.47825","-0.08599","201.64859"
"5183.81100","-4.09994","22.99217","127.59428","-0.08600","201.66943"
"5191.01100","-4.11386","22.84150","127.68937","-0.08613","200.34789"
"5198.21100","-4.12155","22.83451","127.82825","-0.08620","200.28664"
"5205.41100","-4.13248","22.68413","127.92161","-0.08631","198.96759"
"5212.61100","-4.13771","22.67167","128.12566","-0.08636","198.85832"
"5219.81100","-4.13768","22.69067","128.22557","-0.08636","199.02493"
"5227.01100","-4.13767","22.82038","128.28134","-0.08636","200.16269"
"5234.21100","-4.13768","22.85149","128.38205","-0.08636","200.43553"
"5241.41100","-4.13774","22.87085","128.49135","-0.08636","200.60536"
"5248.61100","-4.13867","22.95675","128.58424","-0.08637","201.35881"
"5255.81100","-4.15422","22.70733","128.72316","-0.08652","199.17111"
"5263.01100","-4.15444","22.79110","128.84781","-0.08652","199.90585"
"5270.21100","-4.15485","22.89763","128.97906","-0.08652","200.84024"
"5277.41100","-4.16361","22.80924","129.13420","-0.08661","200.06493"
"5284.61100","-4.16735","22.77965","129.26747","-0.08664","199.80544"
"5291.81100","-4.17108","22.73266","129.35806","-0.08668","199.39326"
"5299.01100","-4.17172","22.82143","129.43439","-0.08668","200.17183"
"5306.21100","-4.19207","22.55221","129.61780","-0.08688","197.81049"
"5310.97400","-4.19580","22.12324","0.00000","-0.08691","194.04790"