File: experimental/sma_database/flexinol_untrained_cyclic_temperature_0p.csv
Time,Extension,Load,Tensile strain (Extension),Tensile stress,Temperature: Chamber 3119-600 1 1
(s),(mm),(N),(mm/mm),(MPa),(C)
"0.00000","0.00000","-0.00294","0.00000","-0.02579","28.11190"
"0.80000","0.00000","-0.00017","0.00000","-0.00150","28.12546"
"1.60000","0.00000","-0.00512","0.00000","-0.04491","28.13434"
"2.40000","0.00000","0.00047","0.00000","0.00409","28.14607"
"3.20000","0.00000","0.00092","0.00000","0.00811","28.14931"
"4.00000","0.00000","-0.00229","0.00000","-0.02006","28.16743"
"4.80000","0.00000","0.00198","0.00000","0.01734","28.17609"
"5.60000","0.00000","0.00388","0.00000","0.03408","28.18488"
"6.40000","0.00000","0.00074","0.00000","0.00648","28.19188"
"7.20000","0.00000","0.00428","0.00000","0.03757","28.20251"
"8.00000","0.00000","0.00176","0.00000","0.01542","28.21138"
"8.80000","0.00000","0.00275","0.00000","0.02411","28.21550"
"9.60000","0.00000","0.00231","0.00000","0.02024","28.22934"
"10.40000","0.00000","0.00176","0.00000","0.01544","28.23936"
"11.20000","0.00000","-0.00039","0.00000","-0.00341","28.24748"
"12.00000","0.00000","0.00142","0.00000","0.01242","28.25506"
"12.80000","0.00000","0.00194","0.00000","0.01701","28.26417"
"13.60000","0.00000","0.00170","0.00000","0.01488","28.26738"
"14.40000","0.00000","0.00365","0.00000","0.03199","28.28105"
"15.20000","0.00000","0.00021","0.00000","0.00183","28.28751"
"16.00000","0.00000","0.00507","0.00000","0.04444","28.29347"
"16.80000","0.00000","0.00544","0.00000","0.04774","28.29743"
"17.60000","0.00000","0.00379","0.00000","0.03327","28.30144"
"18.40000","0.00000","0.00702","0.00000","0.06160","28.31497"
"19.20000","0.00000","0.00184","0.00000","0.01610","28.31549"
"20.00000","0.00000","0.00187","0.00000","0.01644","28.32326"
"20.80000","0.00000","-0.00226","0.00000","-0.01980","28.32890"
"21.60000","0.00000","-0.00084","0.00000","-0.00738","28.34084"
"22.40000","0.00000","0.00328","0.00000","0.02873","28.34539"
"23.20000","0.00000","0.00073","0.00000","0.00641","28.35628"
"24.00000","0.00000","0.01519","0.00000","0.13325","28.36167"
"24.80000","0.00000","0.02733","0.00000","0.23971","28.37921"
"25.60000","0.00000","0.03568","0.00000","0.31297","28.41767"
"26.40000","0.00000","0.03463","0.00000","0.30372","28.45448"
"27.20000","0.00000","0.03474","0.00000","0.30475","28.58536"
"28.00000","0.00000","0.03561","0.00000","0.31235","28.64753"
"28.80000","0.00000","0.03319","0.00000","0.29111","28.79846"
"29.60000","0.00000","0.04056","0.00000","0.35574","28.87811"
"30.40000","0.00000","0.04279","0.00000","0.37535","29.09734"
"31.20000","0.00000","0.03579","0.00000","0.31393","29.19034"
"32.00000","0.00000","0.02987","0.00000","0.26196","29.39992"
"32.80000","0.00000","0.03070","0.00000","0.26928","29.51027"
"33.60000","0.00000","0.03131","0.00000","0.27461","29.68410"
"34.40000","0.00000","0.03805","0.00000","0.33374","29.92886"
"35.20000","0.00000","0.04166","0.00000","0.36539","30.05730"
"36.00000","0.00000","0.03423","0.00000","0.30028","30.38952"
"36.80000","0.00000","0.03630","0.00000","0.31838","30.52809"
"37.60000","0.00000","0.03876","0.00000","0.33998","30.81859"
"38.40000","0.00000","0.03720","0.00000","0.32630","31.04524"
"39.20000","0.00000","0.04184","0.00000","0.36703","31.36038"
"40.00000","0.00000","0.03842","0.00000","0.33696","31.51468"
"40.80000","0.00000","0.03868","0.00000","0.33928","31.67335"
"41.60000","0.00000","0.03677","0.00000","0.32251","32.07388"
"42.40000","0.00000","0.04514","0.00000","0.39591","32.24323"
"43.20000","0.00000","0.03889","0.00000","0.34113","32.58371"
"44.00000","0.00000","0.03868","0.00000","0.33923","32.84500"
"44.80000","0.00000","0.04595","0.00000","0.40306","33.20174"
"45.60000","0.00000","0.03656","0.00000","0.32071","33.38218"
"46.40000","0.00000","0.04298","0.00000","0.37695","33.83873"
"47.20000","0.00000","0.04463","0.00000","0.39146","34.01887"
"48.00000","0.00000","0.03880","0.00000","0.34028","34.38596"
"48.80000","0.00000","0.04196","0.00000","0.36801","34.56748"
"49.60000","0.00000","0.04633","0.00000","0.40636","34.75333"
"50.40000","0.00000","0.03945","0.00000","0.34601","35.22564"
"51.20000","0.00000","0.05371","0.00000","0.47107","35.41744"
"52.00000","0.00000","0.04556","0.00000","0.39960","35.79504"
"52.80000","0.00000","0.04510","0.00000","0.39558","35.98822"
"53.60000","0.00000","0.03863","0.00000","0.33884","36.46211"
"54.40000","0.00000","0.04605","0.00000","0.40387","36.65216"
"55.20000","0.00000","0.04277","0.00000","0.37517","37.03360"
"56.00000","0.00000","0.05201","0.00000","0.45618","37.22230"
"56.80000","0.00000","0.05270","0.00000","0.46225","37.72127"
"57.60000","0.00000","0.04688","0.00000","0.41120","37.91896"
"58.40000","0.00000","0.04475","0.00000","0.39252","38.31376"
"59.20000","0.00000","0.04513","0.00000","0.39583","38.61182"
"60.00000","0.00000","0.04141","0.00000","0.36320","38.81372"
"60.80000","0.00000","0.05273","0.00000","0.46247","39.21119"
"61.60000","0.00000","0.04212","0.00000","0.36946","39.50824"
"62.40000","0.00000","0.04665","0.00000","0.40920","39.90860"
"63.20000","0.00000","0.04755","0.00000","0.41710","40.10943"
"64.00000","0.00000","0.04661","0.00000","0.40881","40.50824"
"64.80000","0.00000","0.05043","0.00000","0.44229","40.81227"
"65.60000","0.00000","0.04752","0.00000","0.41677","41.21859"
"66.40000","0.00000","0.05759","0.00000","0.50514","41.42130"
"67.20000","0.00000","0.05229","0.00000","0.45869","41.62683"
"68.00000","0.00000","0.04851","0.00000","0.42546","42.13582"
"68.80000","0.00000","0.05804","0.00000","0.50912","42.33937"
"69.60000","0.00000","0.04964","0.00000","0.43536","42.84023"
"70.40000","0.00000","0.05681","0.00000","0.49833","43.04018"
"71.20000","0.00000","0.06222","0.00000","0.54576","43.43594"
"72.00000","0.00000","0.06364","0.00000","0.55820","43.63526"
"72.80000","0.00000","0.06684","0.00000","0.58629","44.13699"
"73.60000","0.00000","0.06252","0.00000","0.54836","44.33566"
"74.40000","0.00000","0.05935","0.00000","0.52054","44.72562"
"75.20000","0.00000","0.06050","0.00000","0.53062","44.92583"
"76.00000","0.00000","0.06306","0.00000","0.55309","45.22470"
"76.80000","0.00000","0.06255","0.00000","0.54860","45.61136"
"77.60000","0.00000","0.06326","0.00000","0.55491","45.80447"
"78.40000","0.00000","0.06338","0.00000","0.55595","46.29181"
"79.20000","0.00000","0.07273","0.00000","0.63792","46.48915"
"80.00000","0.00000","0.07367","0.00000","0.64620","46.89607"
"80.80000","0.00000","0.07535","0.00000","0.66090","47.09544"
"81.60000","0.00000","0.07792","0.00000","0.68347","47.58940"
"82.40000","0.00000","0.08061","0.00000","0.70707","47.78495"
"83.20000","0.00000","0.08175","0.00000","0.71705","48.16825"
"84.00000","0.00000","0.08588","0.00000","0.75331","48.36358"
"84.80000","0.00000","0.08498","0.00000","0.74537","48.84594"
"85.60000","0.00000","0.08944","0.00000","0.78447","49.03933"
"86.40000","0.00000","0.09452","0.00000","0.82905","49.23191"
"87.20000","0.00000","0.08919","0.00000","0.78232","49.60981"
"88.00000","0.00000","0.10672","0.00000","0.93605","49.88836"
"88.80000","0.00000","0.11135","0.00000","0.97669","50.26542"
"89.60000","0.00000","0.11487","0.00000","1.00753","50.45077"
"90.40000","0.00000","0.11698","0.00000","1.02610","50.91077"
"91.20000","0.00000","0.12846","0.00000","1.12672","51.09768"
"92.00000","0.00000","0.14615","0.00000","1.28187","51.48256"
"92.80000","0.00000","0.15263","0.00000","1.33876","51.66939"
"93.60000","0.00000","0.16350","0.00000","1.43406","52.14408"
"94.40000","0.00000","0.18522","0.00000","1.62463","52.33764"
"95.20000","0.00000","0.18860","0.00000","1.65424","52.52965"
"96.00000","0.00000","0.21882","0.00000","1.91936","53.01428"
"96.80000","0.00000","0.23954","0.00000","2.10108","53.20618"
"97.60000","0.00000","0.24862","0.00000","2.18074","53.58334"
"98.40000","0.00000","0.31114","0.00000","2.72909","53.77044"
"99.20000","0.00000","0.31675","0.00000","2.77827","54.23183"
"100.00000","0.00000","0.33698","0.00000","2.95575","54.41702"
"100.80000","0.00000","0.41560","0.00000","3.64531","54.78278"
"101.60000","0.00000","0.40136","0.00000","3.52046","55.05610"
"102.40000","0.00000","0.45153","0.00000","3.96046","55.23813"
"103.20000","0.00000","0.55820","0.00000","4.89611","55.59821"
"104.00000","0.00000","0.54942","0.00000","4.81908","55.77310"
"104.80000","0.00000","0.61720","0.00000","5.41358","56.21351"
"105.60000","0.00000","0.68332","0.00000","5.99355","56.38967"
"106.40000","0.00000","0.70231","0.00000","6.16009","56.75224"
"107.20000","0.00000","0.79151","0.00000","6.94247","56.93776"
"108.00000","0.00000","0.84116","0.00000","7.37804","57.38943"
"108.80000","0.00000","0.88349","0.00000","7.74932","57.56853"
"109.60000","0.00000","0.98851","0.00000","8.67043","57.99635"
"110.40000","0.00000","1.01865","0.00000","8.93483","58.16526"
"111.20000","0.00000","1.07863","0.00000","9.46095","58.33964"
"112.00000","0.00000","1.20700","0.00000","10.58684","58.68957"
"112.80000","0.00000","1.22229","0.00000","10.72095","58.85865"
"113.60000","0.00000","1.30497","0.00000","11.44622","59.29951"
"114.40000","0.00000","1.38629","0.00000","12.15945","59.47633"
"115.20000","0.00000","1.43510","0.00000","12.58754","59.81999"
"116.00000","0.00000","1.50303","0.00000","13.18340","60.07721"
"116.80000","0.00000","1.53695","0.00000","13.48095","60.42533"
"117.60000","0.00000","1.61539","0.00000","14.16896","60.59421"
"118.40000","0.00000","1.72717","0.00000","15.14940","60.92916"
"119.20000","0.00000","1.82396","0.00000","15.99832","61.17213"
"120.00000","0.00000","1.93238","0.00000","16.94931","61.50213"
"120.80000","0.00000","2.01594","0.00000","17.68226","61.66775"
"121.60000","0.00000","2.09243","0.00000","18.35319","61.83763"
"122.40000","0.00000","2.13242","0.00000","18.70396","62.24646"
"123.20000","0.00000","2.24183","0.00000","19.66356","62.40503"
"124.00000","0.00000","2.35180","0.00000","20.62813","62.71315"
"124.80000","0.00000","2.42586","0.00000","21.27776","62.86744"
"125.60000","0.00000","2.54431","0.00000","22.31669","63.26449"
"126.40000","0.00000","2.65437","0.00000","23.28206","63.42819"
"127.20000","0.00000","2.72346","0.00000","23.88809","63.75540"
"128.00000","0.00000","2.80537","0.00000","24.60656","63.99401"
"128.80000","0.00000","2.92422","0.00000","25.64901","64.30956"
"129.60001","0.00000","3.02453","0.00000","26.52879","64.46764"
"130.39999","0.00000","3.10091","0.00000","27.19878","64.62472"
"131.20000","0.00000","3.22076","0.00000","28.24999","65.01417"
"132.00000","0.00000","3.29280","0.00000","28.88192","65.16870"
"132.80000","0.00000","3.37725","0.00000","29.62260","65.46793"
"133.60001","0.00000","3.54797","0.00000","31.12007","65.69621"
"134.39999","0.00000","3.63414","0.00000","31.87583","66.00691"
"135.20000","0.00000","3.71001","0.00000","32.54134","66.16319"
"136.00000","0.00000","3.83614","0.00000","33.64762","66.56864"
"136.80000","0.00000","3.99623","0.00000","35.05180","66.72697"
"137.60001","0.00000","4.10914","0.00000","36.04219","67.04611"
"138.39999","0.00000","4.22535","0.00000","37.06152","67.20626"
"139.20000","0.00000","4.35376","0.00000","38.18781","67.43998"
"140.00000","0.00000","4.48256","0.00000","39.31750","67.75476"
"140.80000","0.00000","4.55047","0.00000","39.91315","67.90491"
"141.60001","0.00000","4.75111","0.00000","41.67303","68.28368"
"142.39999","0.00000","4.87318","0.00000","42.74376","68.43646"
"143.20000","0.00000","4.99179","0.00000","43.78413","68.73309"
"144.00000","0.00000","5.11332","0.00000","44.85007","68.88184"
"144.80000","0.00000","5.29437","0.00000","46.43812","69.24870"
"145.60001","0.00000","5.39856","0.00000","47.35196","69.38733"
"146.39999","0.00000","5.57867","0.00000","48.93172","69.53348"
"147.20000","0.00000","5.71255","0.00000","50.10606","69.82872"
"148.00000","0.00000","5.85952","0.00000","51.39512","70.05497"
"148.80000","0.00000","5.98436","0.00000","52.49015","70.34278"
"149.60001","0.00000","6.10931","0.00000","53.58611","70.48921"
"150.39999","0.00000","6.23437","0.00000","54.68305","70.86433"
"151.20000","0.00000","6.33290","0.00000","55.54732","71.01867"
"152.00000","0.00000","6.54146","0.00000","57.37662","71.31202"
"152.80000","0.00000","6.66779","0.00000","58.48470","71.52738"
"153.60001","0.00000","6.78424","0.00000","59.50606","71.67216"
"154.39999","0.00000","6.90501","0.00000","60.56543","71.96194"
"155.20000","0.00000","7.14184","0.00000","62.64267","72.10703"
"156.00000","0.00000","7.33278","0.00000","64.31750","72.46616"
"156.80000","0.00000","7.47001","0.00000","65.52112","72.61380"
"157.60001","0.00000","7.62800","0.00000","66.90691","72.90592"
"158.39999","0.00000","7.73925","0.00000","67.88268","73.05631"
"159.20000","0.00000","7.87246","0.00000","69.05112","73.42323"
"160.00000","0.00000","8.12700","0.00000","71.28377","73.56273"
"160.80000","0.00000","8.26698","0.00000","72.51155","73.92770"
"161.60001","0.00000","8.41624","0.00000","73.82073","74.07363"
"162.39999","0.00000","8.48570","0.00000","74.42993","74.21710"
"163.20000","0.00000","8.67173","0.00000","76.06166","74.49426"
"164.00000","0.00000","8.80531","0.00000","77.23330","74.62981"
"164.80000","0.00000","8.87862","0.00000","77.87632","74.99274"
"165.60001","0.00000","9.03276","0.00000","79.22838","75.13694"
"166.39999","0.00000","9.20864","0.00000","80.77103","75.42591"
"167.20000","0.00000","9.31021","0.00000","81.66190","75.63544"
"168.00000","0.00000","9.46094","0.00000","82.98401","75.91405"
"168.80000","0.00000","9.63034","0.00000","84.46989","76.04462"
"169.60001","0.00000","9.71138","0.00000","85.18069","76.25291"
"170.39999","0.00000","9.85208","0.00000","86.41483","76.50976"
"171.20000","0.00000","10.06975","0.00000","88.32404","76.63584"
"172.00000","0.00000","10.23134","0.00000","89.74136","76.88845"
"172.80000","0.00000","10.35738","0.00000","90.84694","77.08577"
"173.60001","0.00000","10.52197","0.00000","92.29053","77.35749"
"174.39999","0.00000","10.60007","0.00000","92.97555","77.49327"
"175.20000","0.00000","10.76503","0.00000","94.42247","77.83271"
"176.00000","0.00000","10.88987","0.00000","95.51746","77.97684"
"176.80000","0.00000","11.07251","0.00000","97.11946","78.25810"
"177.60001","0.00000","11.14997","0.00000","97.79888","78.40309"
"178.39999","0.00000","11.39283","0.00000","99.92908","78.60670"
"179.20000","0.00000","11.52022","0.00000","101.04645","78.87023"
"180.00000","0.00000","11.69702","0.00000","102.59718","79.00040"
"180.80000","0.00000","11.77635","0.00000","103.29298","79.33383"
"181.60001","0.00000","11.86375","0.00000","104.05962","79.46232"
"182.39999","0.00000","12.02432","0.00000","105.46796","79.71639"
"183.20000","0.00000","12.15701","0.00000","106.63185","79.83579"
"184.00000","0.00000","12.26070","0.00000","107.54135","80.15102"
"184.80000","0.00000","12.46184","0.00000","109.30555","80.27533"
"185.60001","0.00000","12.63862","0.00000","110.85617","80.52818"
"186.39999","0.00000","12.76973","0.00000","112.00613","80.72118"
"187.20000","0.00000","12.92684","0.00000","113.38424","80.85119"
"188.00000","0.00000","12.97380","0.00000","113.79611","81.11310"
"188.80000","0.00000","13.15009","0.00000","115.34238","81.24036"
"189.60001","0.00000","13.25088","0.00000","116.22642","81.55577"
"190.39999","0.00000","13.44127","0.00000","117.89642","81.68481"
"191.20000","0.00000","13.63615","0.00000","119.60576","81.93924"
"192.00000","0.00000","13.74893","0.00000","120.59492","82.12985"
"192.80000","0.00000","13.87073","0.00000","121.66325","82.37402"
"193.60001","0.00000","14.00569","0.00000","122.84702","82.49685"
"194.39999","0.00000","14.07789","0.00000","123.48029","82.61837"
"195.20000","0.00000","14.11214","0.00000","123.78073","82.91782"
"196.00000","0.00000","14.22859","0.00000","124.80218","83.03622"
"196.80000","0.00000","14.36504","0.00000","125.99896","83.26228"
"197.60001","0.00000","14.51791","0.00000","127.33983","83.43452"
"198.39999","0.00000","14.72672","0.00000","129.17133","83.66625"
"199.20000","0.00000","14.82330","0.00000","130.01851","83.78110"
"200.00000","0.00000","14.95996","0.00000","131.21716","84.07421"
"200.80000","0.00000","15.12247","0.00000","132.64255","84.19382"
"201.60001","0.00000","15.29174","0.00000","134.12730","84.31367"
"202.39999","0.00000","15.43610","0.00000","135.39345","84.62199"
"203.20000","0.00000","15.60765","0.00000","136.89819","84.74791"
"204.00000","0.00000","15.63159","0.00000","137.10817","84.99130"
"204.80000","0.00000","15.80424","0.00000","138.62251","85.11883"
"205.60001","0.00000","15.91037","0.00000","139.55339","85.41071"
"206.39999","0.00000","16.12664","0.00000","141.45039","85.52995"
"207.20000","0.00000","16.24895","0.00000","142.52321","85.76926"
"208.00000","0.00000","16.34732","0.00000","143.38603","85.95188"
"208.80000","0.00000","16.47874","0.00000","144.53870","86.07127"
"209.60001","0.00000","16.55432","0.00000","145.20163","86.30957"
"210.39999","0.00000","16.71484","0.00000","146.60962","86.42918"
"211.20000","0.00000","16.83494","0.00000","147.66299","86.72464"
"212.00000","0.00000","16.93303","0.00000","148.52344","86.84301"
"212.80000","0.00000","17.02447","0.00000","149.32544","87.07288"
"213.60001","0.00000","17.12669","0.00000","150.22205","87.18587"
"214.39999","0.00000","17.34385","0.00000","152.12675","87.45674"
"215.20000","0.00000","17.56458","0.00000","154.06287","87.57018"
"216.00000","0.00000","17.60009","0.00000","154.37433","87.79791"
"216.80000","0.00000","17.64196","0.00000","154.74156","87.91455"
"217.60001","0.00000","17.71094","0.00000","155.34660","88.19341"
"218.39999","0.00000","17.88803","0.00000","156.89990","88.30457"
"219.20000","0.00000","18.11359","0.00000","158.87833","88.41388"
"220.00000","0.00000","18.20555","0.00000","159.68495","88.69762"
"220.80000","0.00000","18.23800","0.00000","159.96953","88.81590"
"221.60001","0.00000","18.40820","0.00000","161.46240","89.04015"
"222.39999","0.00000","18.55511","0.00000","162.75105","89.15003"
"223.20000","0.00000","18.61130","0.00000","163.24384","89.42569"
"224.00000","0.00000","18.79682","0.00000","164.87114","89.53688"
"224.80000","0.00000","18.92558","0.00000","166.00053","89.75771"
"225.60001","0.00000","19.05589","0.00000","167.14345","89.86749"
"226.39999","0.00000","19.09311","0.00000","167.46989","90.13689"
"227.20000","0.00000","19.33686","0.00000","169.60794","90.25404"
"228.00000","0.00000","19.40589","0.00000","170.21342","90.36756"
"228.80000","0.00000","19.48263","0.00000","170.88647","90.65060"
"229.60001","0.00000","19.57422","0.00000","171.68987","90.76426"
"230.39999","0.00000","19.64184","0.00000","172.28299","90.97556"
"231.20000","0.00000","19.88785","0.00000","174.44075","91.07589"
"232.00000","0.00000","20.05460","0.00000","175.90338","91.33698"
"232.80000","0.00000","20.15481","0.00000","176.78238","91.45387"
"233.60001","0.00000","20.20273","0.00000","177.20268","91.67839"
"234.39999","0.00000","20.28589","0.00000","177.93210","91.84466"
"235.20000","0.00000","20.45710","0.00000","179.43378","92.06067"
"236.00000","0.00000","20.66035","0.00000","181.21657","92.16747"
"236.80000","0.00000","20.83341","0.00000","182.73451","92.27637"
"237.60001","0.00000","20.89214","0.00000","183.24966","92.55017"
"238.39999","0.00000","20.92394","0.00000","183.52859","92.65681"
"239.20000","0.00000","20.99919","0.00000","184.18861","92.85490"
"240.00000","0.00000","21.26147","0.00000","186.48909","93.00142"
"240.80000","0.00000","21.37919","0.00000","187.52170","93.21086"
"241.60001","0.00000","21.46241","0.00000","188.25163","93.32065"
"242.39999","0.00000","21.48089","0.00000","188.41373","93.53139"
"243.20000","0.00000","21.68310","0.00000","190.18733","93.68419"
"244.00000","0.00000","21.87709","0.00000","191.88884","93.89622"
"244.80000","0.00000","21.93467","0.00000","192.39391","93.99797"
"245.60001","0.00000","22.06241","0.00000","193.51437","94.10429"
"246.39999","0.00000","22.15609","0.00000","194.33601","94.36764"
"247.20000","0.00000","22.32938","0.00000","195.85596","94.47514"
"248.00000","0.00000","22.40507","0.00000","196.51984","94.68898"
"248.80000","0.00000","22.54817","0.00000","197.77504","94.79943"
"249.60001","0.00000","22.55708","0.00000","197.85323","95.06573"
"250.39999","0.00000","22.71282","0.00000","199.21924","95.16395"
"251.20000","0.00000","22.85378","0.00000","200.45558","95.42314"
"252.00000","0.00000","22.96710","0.00000","201.44960","95.52962"
"252.80000","0.00000","23.08734","0.00000","202.50420","95.63785"
"253.60001","0.00000","23.20035","0.00000","203.49545","95.85622"
"254.39999","0.00000","23.43921","0.00000","205.59058","96.01647"
"255.20000","0.00000","23.46605","0.00000","205.82593","96.23243"
"256.00000","0.00000","23.60801","0.00000","207.07117","96.34039"
"256.79999","0.00000","23.84492","0.00000","209.14908","96.61323"
"257.60001","0.00000","23.82352","0.00000","208.96146","96.72203"
"258.39999","0.00000","24.00289","0.00000","210.53471","96.94738"
"259.20001","0.00000","24.07375","0.00000","211.15628","97.05927"
"260.00000","0.00000","24.13626","0.00000","211.70456","97.32965"
"260.79999","0.00000","24.07214","0.00000","211.14214","97.43602"
"261.60001","0.00000","24.20790","0.00000","212.33290","97.53770"
"262.39999","0.00000","24.35024","0.00000","213.58141","97.72353"
"263.20001","0.00000","24.36316","0.00000","213.69470","97.85973"
"264.00000","0.00000","24.63057","0.00000","216.04025","98.04176"
"264.79999","0.00000","24.72521","0.00000","216.87035","98.12865"
"265.60001","0.00000","24.87035","0.00000","218.14342","98.31165"
"266.39999","0.00000","24.99573","0.00000","219.24312","98.45574"
"267.20001","0.00000","25.11178","0.00000","220.26108","98.65225"
"268.00000","0.00000","25.10611","0.00000","220.21129","98.75393"
"268.79999","0.00000","25.30502","0.00000","221.95598","98.94284"
"269.60001","0.00000","25.37214","0.00000","222.54466","99.09093"
"270.39999","0.00000","25.51475","0.00000","223.79559","99.28448"
"271.20001","0.00000","25.65133","0.00000","224.99359","99.37805"
"272.00000","0.00000","25.75628","0.00000","225.91405","99.62520"
"272.79999","0.00000","25.78533","0.00000","226.16891","99.72691"
"273.60001","0.00000","25.84558","0.00000","226.69736","99.82565"
"274.39999","0.00000","25.99421","0.00000","228.00101","100.07518"
"275.20001","0.00000","26.09992","0.00000","228.92821","100.16248"
"276.00000","0.00000","26.26749","0.00000","230.39801","100.32801"
"276.79999","0.00000","26.34618","0.00000","231.08821","100.41785"
"277.60001","0.00000","26.49330","0.00000","232.37863","100.65073"
"278.39999","0.00000","26.67059","0.00000","233.93370","100.74272"
"279.20001","0.00000","26.69848","0.00000","234.17831","100.93340"
"280.00000","0.00000","26.83568","0.00000","235.38171","101.02180"
"280.79999","0.00000","26.98927","0.00000","236.72888","101.15639"
"281.60001","0.00000","27.11160","0.00000","237.80188","101.34715"
"282.39999","0.00000","27.15241","0.00000","238.15990","101.44163"
"283.20001","0.00000","27.23969","0.00000","238.92542","101.70142"
"284.00000","0.00000","27.29944","0.00000","239.44951","101.80489"
"284.79999","0.00000","27.51354","0.00000","241.32745","101.99227"
"285.60001","0.00000","27.62220","0.00000","242.28049","102.13190"
"286.39999","0.00000","27.70200","0.00000","242.98047","102.33631"
"287.20001","0.00000","27.77612","0.00000","243.63054","102.43722"
"288.00000","0.00000","27.90332","0.00000","244.74623","102.53577"
"288.79999","0.00000","27.99576","0.00000","245.55704","102.78523"
"289.60001","0.00000","28.10427","0.00000","246.50887","102.88736"
"290.39999","0.00000","28.21909","0.00000","247.51595","103.08949"
"291.20001","0.00000","28.31364","0.00000","248.34531","103.22411"
"292.00000","0.00000","28.41441","0.00000","249.22914","103.38905"
"292.79999","0.00000","28.51057","0.00000","250.07262","103.47392"
"293.60001","0.00000","28.61890","0.00000","251.02274","103.68692"
"294.39999","0.00000","28.77538","0.00000","252.39525","103.77190"
"295.20001","0.00000","28.95921","0.00000","254.00771","103.86124"
"296.00000","0.00000","29.07552","0.00000","255.02786","104.05563"
"296.79999","0.00000","29.21403","0.00000","256.24274","104.20575"
"297.60001","0.00000","29.37786","0.00000","257.67975","104.40166"
"298.39999","0.00000","29.40858","0.00000","257.94925","104.50156"
"299.20001","0.00000","29.45082","0.00000","258.31967","104.75126"
"300.00000","0.00000","29.58788","0.00000","259.52191","104.84305"
"300.79999","0.00000","29.73947","0.00000","260.85156","105.01425"
"301.60001","0.00000","29.72302","0.00000","260.70731","105.09770"
"302.39999","0.00000","29.92464","0.00000","262.47574","105.30533"
"303.20001","0.00000","30.00280","0.00000","263.16129","105.39347"
"304.00000","0.00000","30.18697","0.00000","264.77664","105.48611"
"304.79999","0.00000","30.28685","0.00000","265.65271","105.68933"
"305.60001","0.00000","30.30924","0.00000","265.84912","105.84760"
"306.39999","0.00000","30.36718","0.00000","266.35733","106.04552"
"307.20001","0.00000","30.37543","0.00000","266.42972","106.13829"
"308.00000","0.00000","30.44477","0.00000","267.03790","106.35951"
"308.79999","0.00000","30.59647","0.00000","268.36847","106.44507"
"309.60001","0.00000","30.80153","0.00000","270.16708","106.62572"
"310.39999","0.00000","30.78148","0.00000","269.99121","106.76314"
"311.20001","0.00000","31.00912","0.00000","271.98798","106.85693"
"312.00000","0.00000","31.08907","0.00000","272.68915","107.04530"
"312.79999","0.00000","31.20186","0.00000","273.67850","107.17922"
"313.60001","0.00000","31.31030","0.00000","274.62964","107.36557"
"314.39999","0.00000","31.36911","0.00000","275.14551","107.46065"
"315.20001","0.00000","31.55638","0.00000","276.78806","107.69742"
"316.00000","0.00000","31.57453","0.00000","276.94727","107.78855"
"316.79999","0.00000","31.68231","0.00000","277.89264","107.87773"
"317.60001","0.00000","31.86808","0.00000","279.52203","108.04350"
"318.39999","0.00000","31.99357","0.00000","280.62277","108.16828"
"319.20001","0.00000","32.07505","0.00000","281.33743","108.34643"
"320.00000","0.00000","32.09784","0.00000","281.53732","108.43674"
"320.79999","0.00000","32.20178","0.00000","282.44904","108.64983"
"321.60001","0.00000","32.16356","0.00000","282.11374","108.74231"
"322.39999","0.00000","32.23768","0.00000","282.76389","108.93176"
"323.20001","0.00000","32.40690","0.00000","284.24814","109.02310"
"324.00000","0.00000","32.56521","0.00000","285.63672","109.23446"
"324.79999","0.00000","32.68661","0.00000","286.70157","109.32010"
"325.60001","0.00000","32.69849","0.00000","286.80573","109.40759"
"326.39999","0.00000","32.94692","0.00000","288.98480","109.56956"
"327.20001","0.00000","32.92575","0.00000","288.79910","109.69924"
"328.00000","0.00000","33.01332","0.00000","289.56720","109.85942"
"328.79999","0.00000","33.14935","0.00000","290.76031","109.93903"
"329.60001","0.00000","33.24708","0.00000","291.61755","110.14321"
"330.39999","0.00000","33.32355","0.00000","292.28833","110.22385"
"331.20001","0.00000","33.42348","0.00000","293.16483","110.38918"
"332.00000","0.00000","33.41911","0.00000","293.12646","110.52471"
"332.79999","0.00000","33.46071","0.00000","293.49139","110.61559"
"333.60001","0.00000","33.68129","0.00000","295.42612","110.79385"
"334.39999","0.00000","33.76793","0.00000","296.18607","110.87712"
"335.20001","0.00000","33.89633","0.00000","297.31232","111.08795"
"336.00000","0.00000","33.89138","0.00000","297.26886","111.17267"
"336.79999","0.00000","33.94178","0.00000","297.71097","111.34592"
"337.60001","0.00000","34.02389","0.00000","298.43115","111.45882"
"338.39999","0.00000","34.18843","0.00000","299.87436","111.60911"
"339.20001","0.00000","34.23501","0.00000","300.28290","111.68547"
"340.00000","0.00000","34.33674","0.00000","301.17523","111.88017"
"340.79999","0.00000","34.45007","0.00000","302.16922","111.95553"
"341.60001","0.00000","34.43356","0.00000","302.02441","112.03488"
"342.39999","0.00000","34.61174","0.00000","303.58731","112.19746"
"343.20001","0.00000","34.54138","0.00000","302.97018","112.27607"
"344.00000","0.00000","34.51863","0.00000","302.77066","112.45536"
"344.79999","0.00000","34.63512","0.00000","303.79242","112.51579"
"345.60001","0.00000","34.72530","0.00000","304.58334","112.67070"
"346.39999","0.00000","34.75168","0.00000","304.81479","112.73720"
"347.20001","0.00000","34.82547","0.00000","305.46194","112.88644"
"348.00000","0.00000","34.92450","0.00000","306.33060","112.95862"
"348.79999","0.00000","34.85955","0.00000","305.76086","113.13107"
"349.60001","0.00000","34.88758","0.00000","306.00681","113.19810"
"350.39999","0.00000","34.99941","0.00000","306.98764","113.25880"
"351.20001","0.00000","35.02797","0.00000","307.23816","113.36921"
"352.00000","0.00000","34.96365","0.00000","306.67398","113.45276"
"352.79999","0.00000","34.92351","0.00000","306.32193","113.55137"
"353.60001","0.00000","34.90367","0.00000","306.14792","113.59663"
"354.39999","0.00000","34.94972","0.00000","306.55182","113.69362"
"355.20001","0.00000","35.05249","0.00000","307.45322","113.73641"
"356.00000","0.00000","35.11497","0.00000","308.00122","113.81640"
"356.79999","0.00000","35.18001","0.00000","308.57172","113.84984"
"357.60001","0.00000","35.33944","0.00000","309.97015","113.89772"
"358.39999","0.00000","35.21659","0.00000","308.89264","113.97781"
"359.20001","0.00000","35.31924","0.00000","309.79291","114.02255"
"360.00000","0.00000","35.37951","0.00000","310.32156","114.13004"
"360.79999","0.00000","35.44860","0.00000","310.92764","114.17540"
"361.60001","0.00000","35.44666","0.00000","310.91058","114.26598"
"362.39999","0.00000","35.36336","0.00000","310.17996","114.30863"
"363.20001","0.00000","35.33077","0.00000","309.89407","114.40891"
"364.00000","0.00000","35.40381","0.00000","310.53473","114.44279"
"364.79999","0.00000","35.43459","0.00000","310.80472","114.51277"
"365.60001","0.00000","35.55454","0.00000","311.85681","114.56919"
"366.39999","0.00000","35.49655","0.00000","311.34814","114.60722"
"367.20001","0.00000","35.48660","0.00000","311.26093","114.68217"
"368.00000","0.00000","35.51816","0.00000","311.53769","114.71797"
"368.79999","0.00000","35.48920","0.00000","311.28372","114.80284"
"369.60001","0.00000","35.46438","0.00000","311.06604","114.83952"
"370.39999","0.00000","35.44861","0.00000","310.92767","114.90522"
"371.20001","0.00000","35.55918","0.00000","311.89749","114.94244"
"372.00000","0.00000","35.58102","0.00000","312.08908","114.98294"
"372.79999","0.00000","35.55953","0.00000","311.90060","115.01108"
"373.60001","0.00000","35.50101","0.00000","311.38733","115.03607"
"374.39999","0.00000","35.62281","0.00000","312.45560","115.08112"
"375.20001","0.00000","35.73270","0.00000","313.41949","115.09680"
"376.00000","0.00000","35.68200","0.00000","312.97479","115.13264"
"376.79999","0.00000","35.63565","0.00000","312.56824","115.17389"
"377.60001","0.00000","35.78122","0.00000","313.84506","115.21246"
"378.39999","0.00000","35.84166","0.00000","314.37518","115.23411"
"379.20001","0.00000","35.83574","0.00000","314.32324","115.29572"
"380.00000","0.00000","35.83534","0.00000","314.31976","115.31902"
"380.79999","0.00000","35.76200","0.00000","313.67648","115.36404"
"381.60001","0.00000","35.84577","0.00000","314.41125","115.38447"
"382.39999","0.00000","35.78713","0.00000","313.89694","115.41624"
"383.20001","0.00000","35.76598","0.00000","313.71136","115.44877"
"384.00000","0.00000","35.78681","0.00000","313.89410","115.46067"
"384.79999","0.00000","35.96939","0.00000","315.49561","115.49126"
"385.60001","0.00000","35.92067","0.00000","315.06824","115.51767"
"386.39999","0.00000","36.01639","0.00000","315.90784","115.59215"
"387.20001","0.00000","35.90899","0.00000","314.96579","115.62293"
"388.00000","0.00000","35.95186","0.00000","315.34180","115.67966"
"388.79999","0.00000","35.98281","0.00000","315.61325","115.69829"
"389.60001","0.00000","36.02358","0.00000","315.97086","115.71887"
"390.39999","0.00000","36.02153","0.00000","315.95294","115.75771"
"391.20001","0.00000","35.96915","0.00000","315.49344","115.78300"
"392.00000","0.00000","36.01954","0.00000","315.93546","115.81525"
"392.79999","0.00000","35.99167","0.00000","315.69098","115.83031"
"393.60001","0.00000","36.10422","0.00000","316.67819","115.87326"
"394.39999","0.00000","36.01918","0.00000","315.93228","115.88622"
"395.20001","0.00000","36.02622","0.00000","315.99402","115.90779"
"396.00000","0.00000","36.08908","0.00000","316.54535","115.92883"
"396.79999","0.00000","36.08849","0.00000","316.54025","115.94326"
"397.60001","0.00000","36.28490","0.00000","318.26297","115.98377"
"398.39999","0.00000","36.30500","0.00000","318.43924","116.00685"
"399.20001","0.00000","36.19685","0.00000","317.49069","116.04805"
"400.00000","0.00000","36.21954","0.00000","317.68964","116.06288"
"400.79999","0.00000","36.14122","0.00000","317.00275","116.10542"
"401.60001","0.00000","36.15145","0.00000","317.09244","116.11697"
"402.39999","0.00000","36.26234","0.00000","318.06506","116.13786"
"403.20001","0.00000","36.30861","0.00000","318.47092","116.15274"
"404.00000","0.00000","36.25886","0.00000","318.03455","116.17326"
"404.79999","0.00000","36.33191","0.00000","318.67526","116.23172"
"405.60001","0.00000","36.37449","0.00000","319.04874","116.25529"
"406.39999","0.00000","36.33048","0.00000","318.66275","116.29938"
"407.20001","0.00000","36.36025","0.00000","318.92389","116.31419"
"408.00000","0.00000","36.42653","0.00000","319.50519","116.34600"
"408.79999","0.00000","36.45397","0.00000","319.74594","116.36575"
"409.60001","0.00000","36.42394","0.00000","319.48251","116.41646"
"410.39999","0.00000","36.47503","0.00000","319.93060","116.43758"
"411.20001","0.00000","36.43182","0.00000","319.55167","116.47916"
"412.00000","0.00000","36.46576","0.00000","319.84933","116.49776"
"412.79999","0.00000","36.56201","0.00000","320.69357","116.54373"
"413.60001","0.00000","36.67253","0.00000","321.66299","116.56172"
"414.39999","0.00000","36.61000","0.00000","321.11447","116.58430"
"415.20001","0.00000","36.68474","0.00000","321.77008","116.62672"
"416.00000","0.00000","36.67643","0.00000","321.69720","116.65592"
"416.79999","0.00000","36.70784","0.00000","321.97266","116.69497"
"417.60001","0.00000","36.68560","0.00000","321.77756","116.71066"
"418.39999","0.00000","36.67229","0.00000","321.66089","116.76096"
"419.20001","0.00000","36.57544","0.00000","320.81131","116.78517"
"420.00000","0.00000","36.66901","0.00000","321.63205","116.80716"
"420.79999","0.00000","36.64682","0.00000","321.43750","116.84230"
"421.60001","0.00000","36.79927","0.00000","322.77463","116.85766"
"422.39999","0.00000","36.82147","0.00000","322.96933","116.89085"
"423.20001","0.00000","36.82771","0.00000","323.02405","116.91559"
"424.00000","0.00000","36.85994","0.00000","323.30676","116.96651"
"424.79999","0.00000","36.92584","0.00000","323.88480","116.98605"
"425.60001","0.00000","36.99538","0.00000","324.49475","117.02998"
"426.39999","0.00000","36.90342","0.00000","323.68814","117.06856"
"427.20001","0.00000","36.94017","0.00000","324.01053","117.11552"
"428.00000","0.00000","36.99556","0.00000","324.49637","117.13663"
"428.79999","0.00000","37.01131","0.00000","324.63452","117.16260"
"429.60001","0.00000","36.98197","0.00000","324.37711","117.22681"
"430.39999","0.00000","37.00204","0.00000","324.55319","117.25378"
"431.20001","0.00000","37.09171","0.00000","325.33972","117.29395"
"432.00000","0.00000","37.07637","0.00000","325.20517","117.31885"
"432.79999","0.00000","37.13782","0.00000","325.74414","117.36241"
"433.60001","0.00000","37.12885","0.00000","325.66547","117.38006"
"434.39999","0.00000","37.17168","0.00000","326.04108","117.41786"
"435.20001","0.00000","37.23726","0.00000","326.61633","117.43095"
"436.00000","0.00000","37.20220","0.00000","326.30884","117.44589"
"436.79999","0.00000","37.23892","0.00000","326.63089","117.47037"
"437.60001","0.00000","37.37353","0.00000","327.81158","117.48877"
"438.39999","0.00000","37.21555","0.00000","326.42587","117.54041"
"439.20001","0.00000","37.15347","0.00000","325.88135","117.56872"
"440.00000","0.00000","37.31623","0.00000","327.30905","117.62504"
"440.79999","0.00000","37.28561","0.00000","327.04044","117.65305"
"441.60001","0.00000","37.31819","0.00000","327.32620","117.70882"
"442.39999","0.00000","37.35963","0.00000","327.68970","117.72921"
"443.20001","0.00000","37.39168","0.00000","327.97076","117.78613"
"444.00000","0.00000","37.44500","0.00000","328.43848","117.80742"
"444.79999","0.00000","37.39208","0.00000","327.97427","117.82551"
"445.60001","0.00000","37.46036","0.00000","328.57318","117.85941"
"446.39999","0.00000","37.41250","0.00000","328.15338","117.87673"
"447.20001","0.00000","37.56974","0.00000","329.53256","117.90572"
"448.00000","0.00000","37.52097","0.00000","329.10477","117.92124"
"448.79999","0.00000","37.53163","0.00000","329.19833","117.95673"
"449.60001","0.00000","37.64928","0.00000","330.23026","117.97179"
"450.39999","0.00000","37.59101","0.00000","329.71921","118.00968"
"451.20001","0.00000","37.51619","0.00000","329.06293","118.03429"
"452.00000","0.00000","37.52874","0.00000","329.17294","118.04824"
"452.79999","0.00000","37.58380","0.00000","329.65591","118.06079"
"453.60001","0.00000","37.57179","0.00000","329.55057","118.06744"
"454.39999","0.00000","37.64449","0.00000","330.18820","118.11005"
"455.20001","0.00000","37.62250","0.00000","329.99536","118.13117"
"456.00000","0.00000","37.54837","0.00000","329.34515","118.18369"
"456.79999","0.00000","37.53954","0.00000","329.26770","118.20212"
"457.60001","0.00000","37.54235","0.00000","329.29236","118.22820"
"458.39999","0.00000","37.67415","0.00000","330.44843","118.23603"
"459.20001","0.00000","37.68044","0.00000","330.50354","118.24426"
"460.00000","0.00000","37.70303","0.00000","330.70172","118.26585"
"460.79999","0.00000","37.76102","0.00000","331.21036","118.27776"
"461.60001","0.00000","37.69252","0.00000","330.60950","118.29742"
"462.39999","0.00000","37.83018","0.00000","331.81702","118.31925"
"463.20001","0.00000","37.73097","0.00000","330.94675","118.35423"
"464.00000","0.00000","37.77283","0.00000","331.31396","118.37086"
"464.79999","0.00000","37.78321","0.00000","331.40500","118.41574"
"465.60001","0.00000","37.77997","0.00000","331.37656","118.43071"
"466.39999","0.00000","37.81684","0.00000","331.69998","118.44701"
"467.20001","0.00000","37.77671","0.00000","331.34796","118.48800"
"468.00000","0.00000","37.76919","0.00000","331.28198","118.50085"
"468.79999","0.00000","37.73516","0.00000","330.98352","118.53226"
"469.60001","0.00000","37.85594","0.00000","332.04294","118.54503"
"470.39999","0.00000","37.93225","0.00000","332.71222","118.57480"
"471.20001","0.00000","38.01696","0.00000","333.45526","118.58750"
"472.00000","0.00000","37.92807","0.00000","332.67554","118.61651"
"472.79999","0.00000","37.85799","0.00000","332.06088","118.63916"
"473.60001","0.00000","37.83386","0.00000","331.84927","118.65238"
"474.39999","0.00000","37.89065","0.00000","332.34738","118.67242"
"475.20001","0.00000","37.92488","0.00000","332.64758","118.67338"
"476.00000","0.00000","38.06898","0.00000","333.91159","118.68393"
"476.79999","0.00000","38.17193","0.00000","334.81454","118.69352"
"477.60001","0.00000","38.06215","0.00000","333.85165","118.72861"
"478.39999","0.00000","37.96781","0.00000","333.02417","118.74780"
"479.20001","0.00000","37.93251","0.00000","332.71457","118.77458"
"480.00000","0.00000","38.04775","0.00000","333.72531","118.78421"
"480.79999","0.00000","38.09465","0.00000","334.13672","118.78765"
"481.60001","0.00000","38.04298","0.00000","333.68347","118.79263"
"482.39999","0.00000","38.00866","0.00000","333.38242","118.81107"
"483.20001","0.00000","38.04754","0.00000","333.72351","118.81876"
"484.00000","0.00000","37.97914","0.00000","333.12354","118.82849"
"484.79999","0.00000","37.99078","0.00000","333.22565","118.84395"
"485.60001","0.00000","38.00699","0.00000","333.36780","118.85316"
"486.39999","0.00000","38.05127","0.00000","333.75620","118.87495"
"487.20001","0.00000","38.12481","0.00000","334.40125","118.89632"
"488.00000","0.00000","38.10742","0.00000","334.24872","118.93217"
"488.79999","0.00000","38.14390","0.00000","334.56866","118.94448"
"489.60001","0.00000","38.16076","0.00000","334.71652","118.95588"
"490.39999","0.00000","38.05558","0.00000","333.79401","118.97214"
"491.20001","0.00000","38.08319","0.00000","334.03619","118.97646"
"492.00000","0.00000","38.21748","0.00000","335.21405","118.99615"
"492.79999","0.00000","38.17940","0.00000","334.88007","119.00905"
"493.60001","0.00000","38.19657","0.00000","335.03064","119.03603"
"494.39999","0.00000","38.26070","0.00000","335.59311","119.04977"
"495.20001","0.00000","38.21754","0.00000","335.21463","119.07529"
"496.00000","0.00000","38.19671","0.00000","335.03189","119.08883"
"496.79999","0.00000","38.20523","0.00000","335.10660","119.11186"
"497.60001","0.00000","38.27692","0.00000","335.73541","119.11311"
"498.39999","0.00000","38.36901","0.00000","336.54321","119.11705"
"499.20001","0.00000","38.42730","0.00000","337.05444","119.13435"
"500.00000","0.00000","38.36771","0.00000","336.53180","119.15158"
"500.79999","0.00000","38.24778","0.00000","335.47980","119.19213"
"501.60001","0.00000","38.28305","0.00000","335.78918","119.19969"
"502.39999","0.00000","38.29844","0.00000","335.92416","119.21076"
"503.20001","0.00000","38.28782","0.00000","335.83099","119.21410"
"504.00000","0.00000","38.31285","0.00000","336.05057","119.23417"
"504.79999","0.00000","38.26870","0.00000","335.66330","119.24788"
"505.60001","0.00000","38.32673","0.00000","336.17227","119.25805"
"506.39999","0.00000","38.32507","0.00000","336.15778","119.26785"
"507.20001","0.00000","38.31835","0.00000","336.09882","119.27293"
"508.00000","0.00000","38.34743","0.00000","336.35385","119.27816"
"508.79999","0.00000","38.33099","0.00000","336.20966","119.28115"
"509.60001","0.00000","38.36531","0.00000","336.51068","119.29348"
"510.39999","0.00000","38.44733","0.00000","337.23010","119.30285"
"511.20001","0.00000","38.44245","0.00000","337.18732","119.32737"
"512.00000","0.00000","38.41684","0.00000","336.96268","119.34471"
"512.79999","0.00000","38.44733","0.00000","337.23013","119.35185"
"513.59998","0.00000","38.35364","0.00000","336.40833","119.35861"
"514.40002","0.00000","38.41867","0.00000","336.97879","119.36707"
"515.20001","0.00000","38.40677","0.00000","336.87436","119.37848"
"516.00000","0.00000","38.36670","0.00000","336.52292","119.39254"
"516.79999","0.00000","38.36565","0.00000","336.51373","119.41774"
"517.59998","0.00000","38.35047","0.00000","336.38055","119.42433"
"518.40002","0.00000","38.30196","0.00000","335.95502","119.43201"
"519.20001","0.00000","38.35036","0.00000","336.37961","119.43352"
"520.00000","0.00000","38.30411","0.00000","335.97394","119.43002"
"520.79999","0.00000","38.39391","0.00000","336.76160","119.42352"
"521.59998","0.00000","38.46909","0.00000","337.42102","119.42262"
"522.40002","0.00000","38.47364","0.00000","337.46088","119.43836"
"523.20001","0.00000","38.32253","0.00000","336.13547","119.45161"
"524.00000","0.00000","38.45121","0.00000","337.26413","119.47305"
"524.79999","0.00000","38.45520","0.00000","337.29919","119.48442"
"525.59998","0.00000","38.51279","0.00000","337.80426","119.50524"
"526.40002","0.00000","38.64432","0.00000","338.95795","119.51143"
"527.20001","0.00000","38.57057","0.00000","338.31110","119.51608"
"528.00000","0.00000","38.59417","0.00000","338.51807","119.54618"
"528.79999","0.00000","38.49103","0.00000","337.61340","119.55892"
"529.59998","0.00000","38.56328","0.00000","338.24713","119.58451"
"530.40002","0.00000","38.52853","0.00000","337.94232","119.60308"
"531.20001","0.00000","38.53586","0.00000","338.00662","119.63129"
"532.00000","0.00000","38.56724","0.00000","338.28189","119.63937"
"532.79999","0.00000","38.55505","0.00000","338.17496","119.64803"
"533.59998","0.00000","38.54562","0.00000","338.09229","119.65148"
"534.40002","0.00000","38.66465","0.00000","339.13632","119.65363"
"535.20001","0.00000","38.58083","0.00000","338.40112","119.65961"
"536.00000","0.00000","38.60006","0.00000","338.56973","119.67292"
"536.79999","0.00000","38.55667","0.00000","338.18915","119.67345"
"537.59998","0.00000","38.55936","0.00000","338.21280","119.67596"
"538.40002","0.00000","38.71157","0.00000","339.54785","119.67678"
"539.20001","0.00000","38.64774","0.00000","338.98792","119.68079"
"540.00000","0.00000","38.67089","0.00000","339.19104","119.70525"
"540.79999","0.00000","38.66950","0.00000","339.17886","119.71909"
"541.59998","0.00000","38.61945","0.00000","338.73981","119.74186"
"542.40002","0.00000","38.62879","0.00000","338.82175","119.76199"
"543.20001","0.00000","38.65552","0.00000","339.05621","119.79069"
"544.00000","0.00000","38.65172","0.00000","339.02289","119.80283"
"544.79999","0.00000","38.59797","0.00000","338.55142","119.80965"
"545.59998","0.00000","38.63806","0.00000","338.90308","119.80313"
"546.40002","0.00000","38.64318","0.00000","338.94797","119.79604"
"547.20001","0.00000","38.68512","0.00000","339.31580","119.79529"
"548.00000","0.00000","38.70150","0.00000","339.45947","119.79623"
"548.79999","0.00000","38.73072","0.00000","339.71582","119.81753"
"549.59998","0.00000","38.69193","0.00000","339.37558","119.82702"
"550.40002","0.00000","38.55132","0.00000","338.14224","119.83606"
"551.20001","0.00000","38.60633","0.00000","338.62473","119.84096"
"552.00000","0.00000","38.61832","0.00000","338.72995","119.84716"
"552.79999","0.00000","38.63559","0.00000","338.88135","119.85011"
"553.59998","0.00000","38.64302","0.00000","338.94653","119.86652"
"554.40002","0.00000","38.59835","0.00000","338.55472","119.87649"
"555.20001","0.00000","38.67483","0.00000","339.22559","119.88436"
"556.00000","0.00000","38.54394","0.00000","338.07748","119.89003"
"556.79999","0.00000","38.67125","0.00000","339.19421","119.88325"
"557.59998","0.00000","38.64978","0.00000","339.00589","119.88074"
"558.40002","0.00000","38.56144","0.00000","338.23099","119.87782"
"559.20001","0.00000","38.53719","0.00000","338.01828","119.86906"
"560.00000","0.00000","38.50552","0.00000","337.74057","119.86933"
"560.11902","0.00000","38.51792","0.00000","337.84930","119.86933"