File: dynamic_model/curve_fitting/flexinol_isobaric_50MPa.csv
Test : Start of hold value,50,MPa,,,
,,,,,
Time,Extension,Load,Temperature: Chamber 3119-600 1 1,Tensile strain (Extension),Tensile stress
(s),(mm),(N),(C),(mm/mm),(MPa)
0,6.63084,-0.00032,55.35814,-0.00001,-0.00283
7.7,6.82267,1.11484,55.44079,0.00179,9.77855
15.4,7.01523,2.65156,55.54156,0.0036,23.25746
23.1,7.20751,4.16254,55.58165,0.0054,36.51058
30.8,7.40022,5.66161,55.63744,0.00721,49.65922
38.384,7.53985,6.46753,55.70293,0.00852,56.72814
46.084,7.53777,6.42793,55.75243,0.0085,56.38081
53.784,7.44012,5.18359,55.79711,0.00758,45.46647
61.484,7.441,5.27197,55.86134,0.00759,46.24159
69.184,7.45546,5.33873,55.91114,0.00772,46.82719
76.884,7.50522,5.95777,55.96725,0.00819,52.25691
84.584,7.50498,5.94767,56.02538,0.00819,52.16837
92.284,7.50443,5.93872,56.06622,0.00818,52.08986
99.984,7.50238,6.02385,56.10749,0.00816,52.83653
107.684,7.4659,5.55805,56.18086,0.00782,48.75092
115.384,7.45411,5.31022,56.22913,0.00771,46.57714
123.084,7.45474,5.28168,56.23306,0.00772,46.32677
130.784,7.46592,5.50338,56.27392,0.00782,48.27139
138.484,7.49897,5.85261,56.30655,0.00813,51.33451
146.184,7.49887,5.96803,56.35265,0.00813,52.34695
153.884,7.49869,5.87899,56.39189,0.00813,51.5659
161.584,7.49843,5.92726,56.44073,0.00813,51.98936
169.284,7.49788,5.90608,56.44416,0.00812,51.80353
176.984,7.49626,5.83221,56.47067,0.00811,51.15559
184.684,7.48589,5.76214,56.53251,0.00801,50.54104
192.384,7.47277,5.53252,56.56623,0.00789,48.52696
200.084,7.47243,5.52416,56.55434,0.00788,48.45367
207.784,7.47255,5.64329,56.57089,0.00788,49.49854
215.484,7.47267,5.60626,56.6089,0.00789,49.1738
223.184,7.47281,5.5371,56.62261,0.00789,48.56717
230.884,7.47307,5.5858,56.65558,0.00789,48.99429
238.584,7.47356,5.62384,56.6786,0.00789,49.32794
246.284,7.4755,5.54099,56.72722,0.00791,48.60125
253.984,7.49575,5.86189,56.74752,0.0081,51.41592
261.684,7.49595,5.84796,56.73627,0.0081,51.29372
269.384,7.49587,5.80196,56.78126,0.0081,50.89032
277.084,7.49581,5.75387,56.81921,0.0081,50.46849
284.784,7.49575,5.77131,56.84361,0.0081,50.62144
292.484,7.49569,5.7292,56.82368,0.0081,50.25212
300.184,7.49564,5.754,56.8178,0.0081,50.46961
307.884,7.4956,5.6691,56.8392,0.0081,49.72495
315.584,7.49555,5.71948,56.85442,0.0081,50.16687
323.284,7.49552,5.64618,56.8708,0.0081,49.52388
330.984,7.4955,5.74113,56.87245,0.0081,50.35669
338.684,7.49549,5.7583,56.90538,0.0081,50.50737
346.384,7.4955,5.65833,56.92787,0.0081,49.6305
354.084,7.49552,5.67787,56.93749,0.0081,49.80184
361.784,7.49554,5.62975,56.96115,0.0081,49.37982
369.484,7.49557,5.65764,56.97121,0.0081,49.62445
377.184,7.49561,5.63507,56.9665,0.0081,49.42644
384.884,7.49567,5.63018,56.97215,0.0081,49.38354
392.584,7.49575,5.65263,56.96058,0.0081,49.58047
400.284,7.49586,5.60163,56.99375,0.0081,49.13311
407.984,7.49601,5.53201,56.99248,0.0081,48.52253
415.684,7.49837,5.54355,56.99947,0.00813,48.62368
423.384,7.5127,5.75905,56.99981,0.00826,50.51395
431.084,7.51505,5.78587,57.00256,0.00828,50.74916
438.784,7.51504,5.759,57.01126,0.00828,50.51346
446.484,7.51502,5.68175,57.01422,0.00828,49.8359
454.184,7.51501,5.64617,57.01346,0.00828,49.52379
461.884,7.51502,5.69103,57.02358,0.00828,49.91734
469.584,7.51504,5.72925,57.02789,0.00828,50.25256
477.284,7.51508,5.61501,57.03319,0.00828,49.2505
484.984,7.51515,5.68066,57.0336,0.00828,49.82633
492.684,7.51572,5.61605,57.049,0.00829,49.25962
500.384,7.53312,5.75609,57.04745,0.00845,50.48795
508.084,7.5376,5.77508,57.04968,0.00849,50.65449
515.784,7.5375,5.76451,57.03194,0.00849,50.5618
523.484,7.53742,5.78831,57.03914,0.00849,50.7706
531.184,7.53734,5.77736,57.03928,0.00849,50.67454
538.884,7.53728,5.75054,57.01889,0.00849,50.4393
546.584,7.53722,5.73711,57.02577,0.00849,50.3215
554.284,7.53718,5.75082,57.01799,0.00849,50.44176
561.984,7.53716,5.73944,57.01122,0.00849,50.34193
569.684,7.53715,5.71305,57.01041,0.00849,50.11048
577.384,7.53716,5.7107,57.01833,0.00849,50.08982
585.084,7.53718,5.68981,57.02623,0.00849,49.90662
592.784,7.5372,5.71087,57.02657,0.00849,50.0913
600.484,7.53724,5.63445,57.01358,0.00849,49.42099
608.184,7.53729,5.61044,57.00319,0.00849,49.21038
615.884,7.53736,5.62124,57.00114,0.00849,49.30514
623.584,7.53744,5.58149,57.01068,0.00849,48.95646
631.284,7.53757,5.62939,56.98266,0.00849,49.37668
638.984,7.53781,5.53532,56.98956,0.0085,48.5515
646.684,7.54658,5.70717,56.97819,0.00858,50.0589
654.384,7.55299,5.67115,56.96037,0.00864,49.74289
662.084,7.55508,5.64522,56.96325,0.00866,49.51544
669.784,7.55664,5.65224,56.9467,0.00867,49.57703
677.484,7.57056,5.75206,56.95813,0.0088,50.45261
685.184,7.57103,5.71539,56.95325,0.00881,50.13099
692.884,7.57102,5.76484,56.93695,0.00881,50.56471
700.584,7.57101,5.69697,56.93228,0.00881,49.96938
708.284,7.57102,5.66506,56.92956,0.00881,49.68948
715.984,7.57106,5.63098,56.91512,0.00881,49.3906
723.684,7.57115,5.61644,56.89888,0.00881,49.26302
731.384,7.59422,5.91335,56.91511,0.00903,51.86732
739.084,7.59527,5.88353,56.90325,0.00904,51.60577
746.784,7.59519,5.88849,56.87926,0.00903,51.64928
754.484,7.59513,5.82762,56.87676,0.00903,51.11534
762.184,7.59509,5.69684,56.86135,0.00903,49.96829
769.884,7.59507,5.6509,56.86086,0.00903,49.56532
777.584,7.59506,5.67829,56.8527,0.00903,49.80555
785.284,7.59507,5.62118,56.83871,0.00903,49.30464
792.984,7.59509,5.63925,56.81604,0.00903,49.46314
800.684,7.59513,5.67992,56.7972,0.00903,49.81984
808.384,7.59519,5.66294,56.77763,0.00903,49.67088
816.084,7.59527,5.62193,56.77642,0.00904,49.3112
823.784,7.59541,5.52577,56.75508,0.00904,48.46774
831.484,7.61142,5.75322,56.75329,0.00919,50.46277
839.184,7.61399,5.82783,56.74058,0.00921,51.11721
846.884,7.614,5.77559,56.73364,0.00921,50.65901
854.584,7.61403,5.67567,56.70797,0.00921,49.78259
862.284,7.61403,5.68468,56.70063,0.00921,49.86156
869.984,7.61405,5.63679,56.69306,0.00921,49.44151
877.684,7.61408,5.59448,56.69415,0.00921,49.0704
885.384,7.61412,5.58285,56.68802,0.00921,48.96844
893.084,7.61419,5.60222,56.67533,0.00921,49.13829
900.784,7.64579,5.97126,56.658,0.00951,52.37528
908.484,7.64566,5.92482,56.66837,0.00951,51.96793
916.184,7.64553,5.87343,56.63609,0.00951,51.51716
923.884,7.64541,5.72844,56.61448,0.00951,50.24546
931.584,7.64529,5.69713,56.58779,0.0095,49.97081
939.284,7.64521,5.68678,56.57744,0.0095,49.88004
946.984,7.64517,5.66185,56.55873,0.0095,49.66135
954.684,7.64517,5.60537,56.56797,0.0095,49.16597
962.384,7.64519,5.6343,56.5443,0.0095,49.41969
970.084,7.64523,5.64585,56.53101,0.0095,49.52104
977.784,7.64529,5.59389,56.51389,0.0095,49.06524
985.484,7.64538,5.58285,56.49286,0.00951,48.96839
993.184,7.64551,5.65238,56.46975,0.00951,49.57832
1000.884,7.64567,5.5585,56.46261,0.00951,48.75488
1008.584,7.64639,5.58341,56.43157,0.00951,48.97337
1016.284,7.66091,5.69527,56.41544,0.00965,49.95444
1023.984,7.6828,5.98215,56.39743,0.00986,52.47075
1031.684,7.68272,5.91594,56.3864,0.00986,51.89002
1039.384,7.68257,5.82499,56.36351,0.00985,51.0923
1047.084,7.68242,5.78127,56.35935,0.00985,50.70885
1054.784,7.68228,5.75153,56.35437,0.00985,50.44794
1062.484,7.68213,5.80007,56.33638,0.00985,50.87368
1070.184,7.68202,5.72772,56.32887,0.00985,50.23912
1077.884,7.68194,5.75946,56.30443,0.00985,50.51753
1085.584,7.68189,5.74333,56.27865,0.00985,50.37603
1093.284,7.68187,5.66681,56.26157,0.00985,49.70485
1100.984,7.68187,5.74609,56.24148,0.00985,50.40025
1108.684,7.68188,5.7198,56.22602,0.00985,50.16966
1116.384,7.68191,5.65627,56.20504,0.00985,49.61243
1124.084,7.68196,5.66513,56.18788,0.00985,49.69016
1131.784,7.68203,5.65251,56.16531,0.00985,49.5794
1139.484,7.68212,5.6934,56.14253,0.00985,49.9381
1147.184,7.68222,5.62474,56.12758,0.00985,49.33582
1154.884,7.68235,5.55289,56.11919,0.00985,48.70564
1162.584,7.6825,5.58675,56.09151,0.00985,49.00266
1170.284,7.68271,5.5837,56.07887,0.00986,48.97592
1177.984,7.68466,5.60503,56.07748,0.00987,49.16299
1185.684,7.70031,5.80736,56.0491,0.01002,50.93764
1193.384,7.70044,5.81852,56.03073,0.01002,51.03551
1201.084,7.70043,5.75125,56.00537,0.01002,50.44553
1208.784,7.70042,5.72866,55.99029,0.01002,50.24734
1216.484,7.70042,5.63987,55.97871,0.01002,49.46858
1224.184,7.70045,5.64235,55.96368,0.01002,49.49035
1231.884,7.70049,5.72478,55.94879,0.01002,50.21335
1239.584,7.70056,5.6809,55.93275,0.01002,49.82841
1247.284,7.71706,5.87869,55.92473,0.01018,51.5633
1254.984,7.72059,5.87351,55.90556,0.01021,51.5179
1262.684,7.72049,5.75882,55.86345,0.01021,50.51188
1270.384,7.72039,5.8518,55.84141,0.01021,51.32748
1278.084,7.7203,5.81607,55.82631,0.01021,51.01403
1285.784,7.72022,5.70931,55.81425,0.01021,50.07763
1293.484,7.72017,5.74113,55.78084,0.01021,50.35673
1301.184,7.72012,5.66259,55.75914,0.01021,49.66781
1308.884,7.7201,5.64117,55.75132,0.01021,49.47993
1316.584,7.72009,5.62581,55.73707,0.01021,49.34528
1324.284,7.72009,5.66492,55.71679,0.01021,49.68826
1331.984,7.72012,5.66409,55.69489,0.01021,49.68098
1339.684,7.72016,5.65163,55.66816,0.01021,49.5717
1347.384,7.72022,5.62299,55.64251,0.01021,49.32046
1355.084,7.72029,5.62426,55.61035,0.01021,49.33161
1362.784,7.72039,5.63945,55.59675,0.01021,49.46492
1370.484,7.72049,5.62205,55.58586,0.01021,49.31226
1378.184,7.72063,5.64136,55.56958,0.01021,49.48161
1385.884,7.72949,5.75371,55.56264,0.01029,50.46706
1393.584,7.73174,5.71108,55.54123,0.01032,50.0932
1401.284,7.7318,5.68341,55.51931,0.01032,49.85043
1408.984,7.73189,5.6879,55.4948,0.01032,49.88981
1416.684,7.7321,5.64827,55.49787,0.01032,49.54224
1424.384,7.73846,5.69329,55.48069,0.01038,49.93709
1432.084,7.73853,5.72801,55.44188,0.01038,50.24169
1439.784,7.73853,5.74379,55.42675,0.01038,50.38005
1447.484,7.73854,5.74833,55.38766,0.01038,50.41987
1455.184,7.73855,5.65641,55.35413,0.01038,49.61361
1462.884,7.73858,5.67347,55.33887,0.01038,49.76329
1470.584,7.73862,5.64698,55.33059,0.01038,49.5309
1478.284,7.73868,5.69451,55.30469,0.01038,49.94781
1485.984,7.755,5.80477,55.285,0.01053,50.91498
1493.684,7.75523,5.84334,55.27264,0.01054,51.25325
1501.384,7.75514,5.79261,55.24904,0.01053,50.80826
1509.084,7.75506,5.78873,55.23538,0.01053,50.77424
1516.784,7.755,5.78853,55.21766,0.01053,50.77248
1524.484,7.75495,5.78457,55.1923,0.01053,50.73778
1532.184,7.75492,5.71089,55.16615,0.01053,50.09145
1539.884,7.75491,5.74512,55.14946,0.01053,50.39176
1547.584,7.75491,5.66208,55.11729,0.01053,49.66335
1555.284,7.75492,5.72296,55.0866,0.01053,50.1974
1562.984,7.75495,5.68058,55.06505,0.01053,49.82563
1570.684,7.75498,5.67161,55.05213,0.01053,49.74692
1578.384,7.75501,5.61463,55.03661,0.01053,49.24717
1586.084,7.75506,5.68444,55.01809,0.01053,49.85949
1593.784,7.75513,5.59785,54.99057,0.01053,49.09995
1601.484,7.75503,6.02064,55.27529,0.01053,52.8084
1609.184,7.75328,6.41475,56.57424,0.01052,56.26517
1616.884,7.62688,5.56909,58.62872,0.00933,48.84773
1624.584,7.57945,5.80516,61.26033,0.00889,50.9184
1632.284,7.50343,5.71705,63.74443,0.00817,50.14555
1639.984,7.43877,5.61217,65.97765,0.00757,49.22561
1647.684,7.41627,5.6554,67.85106,0.00736,49.60475
1655.384,7.39825,5.50469,69.00979,0.00719,48.28291
1663.084,7.39849,5.45084,69.59235,0.00719,47.81056
1670.784,7.39935,5.26416,69.76637,0.0072,46.17311
1678.484,7.42943,5.41716,69.66407,0.00748,47.51509
1686.184,7.4669,5.68036,69.40313,0.00783,49.82372
1693.884,7.4828,5.82017,69.02346,0.00798,51.05004
1701.584,7.49622,5.81184,68.66383,0.00811,50.97695
1709.284,7.49625,5.72314,68.30708,0.00811,50.19894
1716.984,7.49623,5.80397,68.078,0.00811,50.90793
1724.684,7.49615,5.88092,68.05659,0.00811,51.58285
1732.384,7.49587,6.01453,68.22478,0.0081,52.75475
1740.084,7.49411,6.15593,68.58039,0.00809,53.99501
1747.784,7.43016,5.57785,69.00958,0.00749,48.92456
1755.484,7.41613,5.57723,69.49681,0.00736,48.91916
1763.184,7.41542,5.73029,70.04988,0.00735,50.2617
1770.884,7.4084,5.79815,70.46861,0.00728,50.85685
1778.584,7.39629,5.72335,70.83876,0.00717,50.20078
1786.284,7.39016,5.64133,71.14078,0.00711,49.48136
1793.984,7.38309,5.66345,71.31193,0.00705,49.67542
1801.684,7.38234,5.6562,71.39597,0.00704,49.61177
1809.384,7.38235,5.70164,71.47469,0.00704,50.01038
1817.084,7.38235,5.69573,71.54616,0.00704,49.95853
1824.784,7.38232,5.77075,71.63761,0.00704,50.61657
1832.484,7.38218,5.82527,71.75462,0.00704,51.09472
1840.184,7.34396,5.49957,71.90438,0.00668,48.23797
1847.884,7.34398,5.66076,72.0534,0.00668,49.6518
1855.584,7.34399,5.70632,72.27567,0.00668,50.05144
1863.284,7.3439,5.90361,72.43092,0.00668,51.78185
1870.984,7.33588,5.81231,72.60303,0.0066,50.98109
1878.684,7.29588,5.584,72.79553,0.00623,48.97854
1886.384,7.29529,5.7052,72.94539,0.00622,50.04163
1894.084,7.29525,5.72785,73.12192,0.00622,50.24022
1901.784,7.28657,5.78265,73.286,0.00614,50.72092
1909.484,7.24961,5.44443,73.41429,0.00579,47.75434
1917.184,7.24972,5.58701,73.5642,0.00579,49.00491
1924.884,7.24974,5.79053,73.73626,0.00579,50.79003
1932.584,7.24966,5.81136,73.85856,0.00579,50.97277
1940.284,7.24739,5.92209,73.99341,0.00577,51.944
1947.984,7.20511,5.59207,74.13964,0.00538,49.04933
1955.684,7.19903,5.5348,74.31299,0.00532,48.54698
1963.384,7.19904,5.65358,74.43722,0.00532,49.58884
1971.084,7.19892,5.80275,74.56996,0.00532,50.89726
1978.784,7.16704,5.52858,74.69165,0.00502,48.49242
1986.484,7.15363,5.60137,74.78215,0.00489,49.13091
1994.184,7.15365,5.75133,74.92899,0.00489,50.44619
2001.884,7.15357,5.77932,75.0387,0.00489,50.69174
2009.584,7.14289,5.76843,75.16438,0.00479,50.59616
2017.284,7.10963,5.64452,75.32177,0.00448,49.50932
2024.984,7.10836,5.79045,75.46851,0.00447,50.7893
2032.684,7.09715,5.85051,75.61388,0.00436,51.31615
2040.384,7.05902,5.58094,75.7625,0.00401,48.95165
2048.084,7.05903,5.63976,75.87302,0.00401,49.46761
2055.784,7.05885,5.81712,76.03379,0.004,51.02322
2063.484,7.03434,5.64488,76.15927,0.00377,49.51255
2071.184,7.01186,5.68942,76.29685,0.00356,49.90318
2078.884,7.01163,5.77079,76.41403,0.00356,50.61689
2086.584,6.98893,5.68998,76.55793,0.00335,49.90811
2094.284,6.95789,5.59712,76.67723,0.00306,49.09356
2101.984,6.95791,5.65088,76.7917,0.00306,49.56514
2109.684,6.95783,5.8491,76.93691,0.00306,51.30376
2117.384,6.9372,5.73141,77.04138,0.00286,50.2715
2125.084,6.90888,5.7035,77.18803,0.0026,50.02664
2132.784,6.89712,5.71598,77.30354,0.00249,50.13612
2140.484,6.86684,5.6027,77.44483,0.0022,49.14257
2148.184,6.86678,5.72456,77.5432,0.0022,50.21136
2155.884,6.86487,5.83672,77.66684,0.00219,51.19521
2163.584,6.83356,5.66405,77.79836,0.00189,49.68068
2171.284,6.81591,5.79215,77.92578,0.00173,50.8042
2178.984,6.78889,5.69142,78.08573,0.00147,49.9207
2186.684,6.7675,5.68265,78.19704,0.00127,49.84381
2194.384,6.76019,5.80029,78.34243,0.0012,50.87566
2202.084,6.72451,5.51561,78.50176,0.00087,48.37867
2209.784,6.7154,5.72088,78.62624,0.00078,50.17913
2217.484,6.67236,5.51883,78.7447,0.00038,48.40689
2225.184,6.6714,5.70306,78.87228,0.00037,50.02286
2232.884,6.67039,5.83886,78.97023,0.00036,51.21398
2240.584,6.64108,5.74082,79.10561,0.00009,50.35402
2248.284,6.60893,5.59196,79.23558,-0.00021,49.04833
2255.984,6.58552,5.55476,79.36627,-0.00043,48.72208
2263.684,6.57619,5.73263,79.50327,-0.00052,50.28218
2271.384,6.56846,5.77961,79.61771,-0.00059,50.69424
2279.084,6.54267,5.74516,79.72669,-0.00084,50.39206
2286.784,6.51235,5.58649,79.83564,-0.00112,49.00036
2294.484,6.47954,5.55846,79.9696,-0.00143,48.75451
2302.184,6.47014,5.77174,80.10075,-0.00152,50.62522
2309.884,6.45286,5.82715,80.23685,-0.00168,51.11126
2317.584,6.38224,5.4697,80.37287,-0.00234,47.97594
2325.284,6.38181,5.74684,80.50687,-0.00234,50.40683
2332.984,6.37312,5.81556,80.6331,-0.00243,51.00958
2340.684,6.3197,5.58659,80.77976,-0.00293,49.00122
2348.384,6.30597,5.66641,80.90349,-0.00306,49.70134
2356.084,6.28299,5.78999,81.01676,-0.00327,50.78527
2363.784,6.26928,5.77661,81.16805,-0.0034,50.66793
2371.484,6.22276,5.60197,81.23266,-0.00384,49.13613
2379.184,6.19032,5.63795,81.36594,-0.00414,49.45174
2386.884,6.1867,5.77471,81.52344,-0.00417,50.65128
2394.584,6.16766,5.83663,81.63513,-0.00435,51.19437
2402.284,6.1207,5.69423,81.78266,-0.00479,49.9454
2409.984,6.08408,5.73736,81.90752,-0.00514,50.32368
2417.684,6.07072,5.83322,82.04179,-0.00526,51.16452
2425.384,6.0361,5.72181,82.19376,-0.00559,50.18732
2433.084,5.98849,5.63378,82.31599,-0.00603,49.41511
2440.784,5.98517,5.87527,82.44199,-0.00606,51.5333
2448.484,5.84463,5.26269,82.54585,-0.00738,46.16019
2456.184,5.84279,5.61615,82.66079,-0.0074,49.26055
2463.884,5.84279,5.75886,82.76922,-0.0074,50.51223
2471.584,5.84271,5.92346,82.89203,-0.0074,51.95602
2479.284,5.84212,6.11518,83.03476,-0.00741,53.63758
2486.984,5.69716,5.54153,83.18908,-0.00877,48.60603
2494.684,5.69659,5.81431,83.34303,-0.00877,50.9986
2502.384,5.64049,5.55241,83.46358,-0.0093,48.70147
2510.084,5.55853,5.56296,83.56844,-0.01007,48.79398
2517.784,5.55831,5.8422,83.70483,-0.01007,51.2432
2525.484,5.51413,5.50822,83.85068,-0.01048,48.31381
2533.184,5.48242,5.77161,83.95885,-0.01078,50.62404
2540.884,5.41102,5.536,84.08691,-0.01145,48.55748
2548.584,5.38311,5.77739,84.24185,-0.01171,50.6748
2556.284,5.33932,5.73472,84.35818,-0.01212,50.30053
2563.984,5.29275,5.77465,84.44685,-0.01256,50.65074
2571.684,5.22027,5.56002,84.5668,-0.01324,48.76815
2579.384,5.15412,5.63179,84.70196,-0.01386,49.3977
2587.084,5.07964,5.82911,84.8436,-0.01456,51.12843
2594.784,4.98468,5.65017,84.98586,-0.01545,49.55893
2602.484,4.8859,5.65864,85.13126,-0.01637,49.63319
2610.184,4.73723,5.72042,85.26536,-0.01777,50.17511
2617.884,4.57292,5.65278,85.40181,-0.01931,49.58184
2625.584,4.37877,5.75464,85.5096,-0.02113,50.47525
2633.284,4.10239,5.6692,85.59626,-0.02372,49.7258
2640.984,3.86136,5.60966,85.71993,-0.02598,49.20362
2648.684,3.63598,5.73744,85.86009,-0.0281,50.32438
2656.384,3.43436,5.7124,85.98403,-0.02999,50.10476
2664.084,3.23785,5.72268,86.09619,-0.03183,50.19488
2671.784,3.02897,5.79662,86.20901,-0.03379,50.84341
2679.484,2.78744,5.61766,86.30826,-0.03605,49.27378
2687.184,2.49346,5.78748,86.48946,-0.03881,50.76326
2694.884,2.12693,5.79777,86.64446,-0.04225,50.85356
2702.584,1.73666,5.68744,86.76987,-0.04591,49.88585
2710.284,1.32097,5.70073,86.92172,-0.04981,50.00235
2717.984,1.04265,5.71043,87.03758,-0.05242,50.08745
2725.684,0.84461,5.55278,87.17281,-0.05427,48.70469
2733.384,0.71064,5.72218,87.29397,-0.05553,50.19054
2741.084,0.5799,5.68699,87.43082,-0.05676,49.88182
2748.784,0.46542,5.68493,87.55746,-0.05783,49.86383
2756.484,0.36074,5.46116,87.69733,-0.05881,47.90108
2764.184,0.25256,5.63462,87.81038,-0.05983,49.42255
2771.884,0.19947,5.52875,87.9241,-0.06032,48.49392
2779.584,0.16563,5.79217,88.03849,-0.06064,50.80442
2787.284,0.13584,5.83226,88.17273,-0.06092,51.15607
2794.984,0.06385,5.80331,88.29821,-0.06159,50.90217
2802.684,0.02558,5.80355,88.4271,-0.06195,50.90419
2810.384,-0.03914,5.69106,88.55387,-0.06256,49.91757
2818.084,-0.07608,5.76935,88.66797,-0.06291,50.60423
2825.784,-0.12203,5.80504,88.78446,-0.06334,50.91733
2833.484,-0.16412,5.79003,88.89735,-0.06373,50.78565
2841.184,-0.20923,5.75956,89.04066,-0.06416,50.51836
2848.884,-0.25878,5.67815,89.18159,-0.06462,49.80432
2856.584,-0.30805,5.73797,89.31328,-0.06508,50.32903
2864.284,-0.3409,5.68232,89.45766,-0.06539,49.84091
2871.984,-0.38191,5.54613,89.58592,-0.06578,48.64631
2879.684,-0.40133,5.76643,89.72007,-0.06596,50.57866
2887.384,-0.42955,5.61315,89.83633,-0.06622,49.2342
2895.084,-0.45358,5.76184,89.96721,-0.06645,50.53843
2902.784,-0.49682,5.67778,90.11591,-0.06685,49.80107
2910.484,-0.4989,5.81752,90.2336,-0.06687,51.02674
2918.184,-0.54596,5.62184,90.36119,-0.06731,49.31038
2925.884,-0.5476,5.88566,90.49094,-0.06733,51.62443
2933.584,-0.59441,5.53757,90.5661,-0.06777,48.57129
2941.284,-0.59512,5.79584,90.7061,-0.06777,50.83656
2948.984,-0.62026,5.58563,90.86908,-0.06801,48.99281
2956.684,-0.6366,5.74957,90.9895,-0.06816,50.43076
2964.384,-0.6449,5.77835,91.14356,-0.06824,50.68318
2972.084,-0.68455,5.61405,91.26331,-0.06861,49.2421
2979.784,-0.68483,5.78612,91.39577,-0.06862,50.75131
2987.484,-0.69998,5.77262,91.50478,-0.06876,50.63298
2995.184,-0.72719,5.62597,91.61118,-0.06901,49.34662
3002.884,-0.731,5.715,91.71783,-0.06905,50.12755
3010.584,-0.74086,5.69594,91.81123,-0.06914,49.96039
3018.284,-0.78532,5.5221,91.96407,-0.06956,48.43553
3025.984,-0.78638,5.73424,92.10347,-0.06957,50.29634
3033.684,-0.80717,5.63739,92.26646,-0.06976,49.44683
3041.384,-0.82844,5.63094,92.40574,-0.06996,49.39027
3049.084,-0.83007,5.92811,92.51466,-0.06998,51.99676
3056.784,-0.88322,5.44315,92.66984,-0.07048,47.74305
3064.484,-0.88351,5.69969,92.80894,-0.07048,49.99329
3072.184,-0.88356,5.80827,92.90652,-0.07048,50.94567
3079.884,-0.88436,5.88837,93.03973,-0.07049,51.64821
3087.584,-0.91963,5.6217,93.17206,-0.07082,49.30918
3095.284,-0.92552,5.74983,93.31822,-0.07087,50.43305
3102.984,-0.92664,5.77847,93.41202,-0.07088,50.68428
3110.684,-0.97436,5.394,93.51742,-0.07133,47.312
3118.384,-0.97447,5.72977,93.62448,-0.07133,50.25714
3126.084,-0.97455,5.83464,93.76463,-0.07133,51.17692
3133.784,-0.98494,5.80562,93.87919,-0.07143,50.92236
3141.484,-1.016,5.58415,94.02716,-0.07172,48.97987
3149.184,-1.01889,5.66302,94.16447,-0.07175,49.6716
3156.884,-1.02382,5.85072,94.29471,-0.0718,51.318
3164.584,-1.07141,5.39739,94.46467,-0.07224,47.34171
3172.284,-1.07146,5.64831,94.62318,-0.07224,49.54258
3179.984,-1.07148,5.81139,94.7832,-0.07224,50.97301
3187.684,-1.07175,5.87725,94.90622,-0.07224,51.55068
3195.384,-1.09511,5.69192,95.00613,-0.07246,49.92513
3203.084,-1.09696,5.72982,95.07446,-0.07248,50.25756
3210.784,-1.11978,5.65529,95.17423,-0.07269,49.60385
3218.484,-1.11993,5.77921,95.27204,-0.0727,50.69073
3226.184,-1.1291,5.75749,95.36588,-0.07278,50.50027
3233.884,-1.16876,5.53601,95.51991,-0.07315,48.55756
3241.584,-1.16868,5.59815,95.67753,-0.07315,49.10259
3249.284,-1.1687,5.84488,95.8352,-0.07315,51.26678
3256.984,-1.16884,5.81616,95.99419,-0.07316,51.01485
3264.684,-1.19472,5.60084,96.11698,-0.0734,49.12622
3272.384,-1.21337,5.56306,96.25865,-0.07357,48.79481
3280.084,-1.21347,5.72005,96.3981,-0.07357,50.17188
3287.784,-1.21574,5.88694,96.50819,-0.07359,51.63562
3295.484,-1.25804,5.41498,96.60214,-0.07399,47.49599
3303.184,-1.2643,5.58358,96.72987,-0.07405,48.97485
3310.884,-1.26424,5.64799,96.86846,-0.07405,49.53974
3318.584,-1.2643,5.80265,96.98124,-0.07405,50.8963
3326.284,-1.26446,5.88365,97.10746,-0.07405,51.60677
3333.984,-1.28183,5.66027,97.2669,-0.07421,49.64748
3341.684,-1.29532,5.60938,97.38344,-0.07434,49.20109
3349.384,-1.30735,5.66922,97.54272,-0.07445,49.72598
3357.084,-1.30834,5.81192,97.65684,-0.07446,50.97765
3364.784,-1.31696,5.70038,97.76655,-0.07454,49.99927
3372.484,-1.32896,5.67353,97.88643,-0.07466,49.76377
3380.184,-1.33468,5.76508,97.9901,-0.07471,50.56678
3387.884,-1.3565,5.61437,98.13904,-0.07491,49.24486
3395.584,-1.35671,5.6533,98.25537,-0.07492,49.58633
3403.284,-1.35682,5.78038,98.38576,-0.07492,50.70097
3410.984,-1.36365,5.7582,98.50019,-0.07498,50.50642
3418.684,-1.38131,5.66767,98.62023,-0.07515,49.71244
3426.384,-1.38634,5.75912,98.77418,-0.07519,50.51453
3434.084,-1.39378,5.78131,98.92271,-0.07526,50.70921
3441.784,-1.40912,5.62133,99.06393,-0.07541,49.3059
3449.484,-1.4159,5.71311,99.18156,-0.07547,50.11094
3457.184,-1.41843,5.74939,99.29465,-0.0755,50.42915
3464.884,-1.4285,5.63916,99.45065,-0.07559,49.46229
3472.584,-1.45066,5.46685,99.5732,-0.0758,47.95092
3480.284,-1.453,5.62703,99.69357,-0.07582,49.35595
3487.984,-1.45301,5.75135,99.80981,-0.07582,50.4464
3495.684,-1.45307,5.87608,99.9445,-0.07582,51.54045
3503.384,-1.46727,5.78276,100.08588,-0.07595,50.72187
3511.084,-1.46828,5.78429,100.19766,-0.07596,50.73529
3518.784,-1.47707,5.78384,100.29465,-0.07605,50.73133
3526.484,-1.48888,5.61215,100.43547,-0.07616,49.22546
3534.184,-1.50616,5.55606,100.58339,-0.07632,48.73343
3541.884,-1.50618,5.65525,100.73238,-0.07632,49.60343
3549.584,-1.50624,5.77429,100.8591,-0.07632,50.64757
3557.284,-1.50706,5.86942,100.96568,-0.07633,51.48196
3564.984,-1.54644,5.36491,101.07236,-0.0767,47.05679
3572.684,-1.54665,5.49036,101.20324,-0.0767,48.15716
3580.384,-1.54653,5.57755,101.32964,-0.0767,48.92197
3588.084,-1.54648,5.69656,101.46051,-0.0767,49.96579
3595.784,-1.54651,5.75319,101.60031,-0.0767,50.46255
3603.484,-1.5466,5.90707,101.74326,-0.0767,51.81226
3611.184,-1.54678,5.92932,101.87563,-0.0767,52.00737
3618.884,-1.56435,5.80004,102.00457,-0.07686,50.87345
3626.584,-1.57321,5.78421,102.14021,-0.07695,50.73456
3634.284,-1.58135,5.64481,102.25522,-0.07702,49.51191
3641.984,-1.58787,5.62297,102.37363,-0.07708,49.32034
3649.684,-1.5909,5.64084,102.49956,-0.07711,49.47704
3657.384,-1.59414,5.69907,102.61031,-0.07714,49.98784
3665.084,-1.59754,5.72884,102.71924,-0.07718,50.24897
3672.784,-1.61438,5.64275,102.87707,-0.07733,49.49382
3680.484,-1.61795,5.68321,102.99188,-0.07737,49.84869
3688.184,-1.61831,5.75029,103.13628,-0.07737,50.4371
3695.884,-1.61986,5.80536,103.2939,-0.07738,50.92014
3703.584,-1.64965,5.42653,103.41916,-0.07766,47.59731
3711.284,-1.64979,5.52349,103.53188,-0.07767,48.44777
3718.984,-1.6497,5.56793,103.65645,-0.07766,48.83755
3726.684,-1.64963,5.64548,103.75812,-0.07766,49.51781
3734.384,-1.64963,5.67546,103.89072,-0.07766,49.7807
3742.084,-1.64969,5.8168,104.03577,-0.07766,51.02047
3749.784,-1.64981,5.88356,104.14265,-0.07767,51.60604
3757.484,-1.6507,5.87587,104.25267,-0.07767,51.53855
3765.184,-1.66843,5.64468,104.41129,-0.07784,49.51079
3772.884,-1.67583,5.6746,104.47915,-0.07791,49.77321
3780.584,-1.69203,5.56976,104.59416,-0.07806,48.85357
3788.284,-1.692,5.62902,104.75696,-0.07806,49.37342
3795.984,-1.692,5.75146,104.89031,-0.07806,50.44735
3803.684,-1.69208,5.80805,105.07256,-0.07806,50.94367
3811.384,-1.69357,5.81873,105.25336,-0.07808,51.03738
3819.084,-1.71572,5.48947,105.35119,-0.07828,48.1494
3826.784,-1.71628,5.62547,105.48222,-0.07829,49.34225
3834.484,-1.71634,5.73017,105.57761,-0.07829,50.26061
3842.184,-1.71667,5.85591,105.66075,-0.07829,51.36351
3849.884,-1.7423,5.49815,105.79344,-0.07853,48.22551
3857.584,-1.74789,5.41694,105.94438,-0.07859,47.51317
3865.284,-1.74776,5.54557,106.07374,-0.07858,48.64143
3872.984,-1.74766,5.57716,106.19002,-0.07858,48.91856
3880.684,-1.74761,5.61804,106.30067,-0.07858,49.27707
3888.384,-1.74762,5.78723,106.40993,-0.07858,50.76113
3896.084,-1.74769,5.91952,106.57116,-0.07858,51.92143
3903.784,-1.74782,5.93053,106.73358,-0.07858,52.01803
3911.484,-1.74812,6.05592,106.88729,-0.07859,53.11783
3919.184,-1.76875,5.61341,107.01457,-0.07878,49.23648
3926.884,-1.7742,5.62057,107.15312,-0.07883,49.29924
3934.584,-1.77442,5.65931,107.2711,-0.07883,49.63908
3942.284,-1.77502,5.70295,107.35526,-0.07884,50.02187
3949.984,-1.78888,5.5861,107.47572,-0.07897,48.99691
3957.684,-1.78946,5.66185,107.56552,-0.07898,49.66132
3965.384,-1.78948,5.68951,107.68734,-0.07898,49.90392
3973.084,-1.78955,5.75324,107.81889,-0.07898,50.46292
3980.784,-1.79395,5.82333,107.98563,-0.07902,51.07775
3988.484,-1.80156,5.72121,108.1067,-0.07909,50.18204
3996.184,-1.80655,5.65037,108.22038,-0.07914,49.56065
4003.884,-1.81123,5.67616,108.39688,-0.07918,49.78687
4011.584,-1.81862,5.66805,108.49367,-0.07925,49.71574
4019.284,-1.82003,5.60979,108.58833,-0.07926,49.20471
4026.984,-1.82017,5.78189,108.69239,-0.07926,50.71421
4034.684,-1.82652,5.65538,108.87049,-0.07932,49.60464
4042.384,-1.8454,5.51443,109.00187,-0.0795,48.3683
4050.084,-1.84531,5.54871,109.15593,-0.0795,48.669
4057.784,-1.84525,5.70318,109.25964,-0.0795,50.02388
4065.484,-1.84523,5.77773,109.39397,-0.0795,50.67777
4073.184,-1.84526,5.78983,109.54202,-0.0795,50.78387
4080.884,-1.84533,5.77875,109.67506,-0.0795,50.68671
4088.584,-1.84547,5.90356,109.76077,-0.0795,51.78147
4096.284,-1.85875,5.7179,109.869,-0.07963,50.15301
4103.984,-1.86542,5.68755,110.05075,-0.07969,49.88675
4111.684,-1.8692,5.71847,110.17537,-0.07972,50.158
4119.384,-1.87029,5.77749,110.33646,-0.07973,50.67567
4127.084,-1.88061,5.5988,110.45824,-0.07983,49.10832
4134.784,-1.88648,5.57991,110.56477,-0.07989,48.94261
4142.484,-1.88648,5.61563,110.66629,-0.07989,49.25595
4150.184,-1.8865,5.78851,110.77858,-0.07989,50.77232
4157.884,-1.88657,5.78797,110.93438,-0.07989,50.76758
4165.584,-1.89863,5.73541,111.04832,-0.08,50.30661
4173.284,-1.89882,5.80333,111.17421,-0.08,50.90231
4180.984,-1.89971,5.79066,111.29677,-0.08001,50.79119
4188.684,-1.90219,5.71741,111.4492,-0.08003,50.14867
4196.384,-1.91466,5.56959,111.58089,-0.08015,48.85214
4204.084,-1.91559,5.64674,111.70615,-0.08016,49.52878
4211.784,-1.91565,5.73493,111.83608,-0.08016,50.30239
4219.484,-1.91635,5.78236,111.94234,-0.08017,50.71833
4227.184,-1.93648,5.51297,112.05282,-0.08035,48.35546
4234.884,-1.93881,5.62864,112.20839,-0.08038,49.37003
4242.584,-1.93874,5.62429,112.35788,-0.08038,49.3319
4250.284,-1.93869,5.64172,112.46264,-0.08037,49.48482
4257.984,-1.93868,5.64353,112.58405,-0.08037,49.50064
4265.684,-1.9387,5.73981,112.73902,-0.08037,50.3452
4273.384,-1.93874,5.78026,112.82649,-0.08038,50.69994
4281.084,-1.93885,5.84942,112.97357,-0.08038,51.3066
4288.784,-1.94159,5.90825,113.12363,-0.0804,51.82258
4296.484,-1.95262,5.75093,113.26205,-0.08051,50.44268
4304.184,-1.95848,5.70899,113.37079,-0.08056,50.07482
4311.884,-1.95933,5.73619,113.44608,-0.08057,50.31342
4319.584,-1.96125,5.72783,113.59321,-0.08059,50.24006
4327.284,-1.98043,5.41648,113.709,-0.08077,47.50919
4334.984,-1.98078,5.56033,113.84113,-0.08077,48.77086
4342.684,-1.98072,5.58878,114.02367,-0.08077,49.02047
4350.384,-1.9807,5.70883,114.16425,-0.08077,50.0734
4358.084,-1.9807,5.79625,114.28912,-0.08077,50.84023
4365.784,-1.98073,5.82787,114.39779,-0.08077,51.11758
4373.484,-1.98079,5.81195,114.5159,-0.08077,50.97789
4381.184,-1.98095,5.83269,114.64124,-0.08077,51.15986
4388.884,-1.99343,5.68348,114.74705,-0.08089,49.85105
4396.584,-2.0005,5.63562,114.86921,-0.08095,49.43132
4404.284,-2.00051,5.61249,114.94823,-0.08095,49.22841
4411.984,-2.00054,5.75851,115.05508,-0.08095,50.50919
4419.684,-2.00078,5.85511,115.22989,-0.08096,51.35648
4427.384,-2.01479,5.61106,115.40621,-0.08109,49.21583
4435.084,-2.02931,5.41911,115.57117,-0.08122,47.53223
4442.784,-2.02919,5.4718,115.71295,-0.08122,47.99437
4450.484,-2.02907,5.558,115.85448,-0.08122,48.75042
4458.184,-2.02893,5.61351,115.98971,-0.08122,49.23737
4465.884,-2.02887,5.66803,116.13155,-0.08122,49.71555
4473.584,-2.02882,5.66838,116.20498,-0.08122,49.71865
4481.284,-2.02881,5.73101,116.32771,-0.08122,50.26795
4488.984,-2.02883,5.76199,116.44387,-0.08122,50.53969
4496.684,-2.02889,5.87182,116.52021,-0.08122,51.50307
4504.384,-2.02898,5.86756,116.69061,-0.08122,51.46569
4512.084,-2.02912,5.94665,116.78748,-0.08122,52.15941
4519.784,-2.02953,5.97567,116.91515,-0.08123,52.41395
4527.484,-2.04613,5.7046,117.04236,-0.08138,50.03633
4535.184,-2.04878,5.64079,117.17215,-0.08141,49.4766
4542.884,-2.04988,5.70187,117.30962,-0.08142,50.01241
4550.584,-2.05288,5.683,117.42341,-0.08145,49.84682
4558.284,-2.05637,5.66548,117.56511,-0.08148,49.69317
4565.984,-2.06239,5.70932,117.67322,-0.08153,50.07777
4573.684,-2.07238,5.60653,117.79848,-0.08163,49.17611
4581.384,-2.07237,5.62718,117.9385,-0.08163,49.35724
4589.084,-2.07235,5.66631,118.06918,-0.08163,49.70047
4596.784,-2.07235,5.72592,118.22536,-0.08163,50.22335
4604.484,-2.07241,5.8218,118.37807,-0.08163,51.06427
4612.184,-2.07283,5.76832,118.51903,-0.08163,50.59525
4619.884,-2.08151,5.61357,118.60573,-0.08171,49.23792
4627.584,-2.08633,5.64855,118.76887,-0.08176,49.54472
4635.284,-2.08761,5.67305,118.89963,-0.08177,49.75955
4642.984,-2.08811,5.66899,119.0189,-0.08178,49.72397
4650.684,-2.08857,5.71124,119.11324,-0.08178,50.09457
4658.384,-2.08955,5.74834,119.20176,-0.08179,50.42
4666.084,-2.09502,5.68264,119.31817,-0.08184,49.84373
4673.784,-2.09689,5.75128,119.46719,-0.08186,50.44577
4681.484,-2.10559,5.66401,119.62905,-0.08194,49.68032
4689.184,-2.10638,5.65721,119.72607,-0.08195,49.62062
4696.884,-2.10709,5.67623,119.88249,-0.08195,49.78745
4704.584,-2.10802,5.74011,120.07211,-0.08196,50.34778
4712.284,-2.11028,5.71945,120.17986,-0.08198,50.16656
4719.984,-2.11201,5.74449,120.2829,-0.082,50.38623
4727.684,-2.11378,5.72998,120.41234,-0.08202,50.25892
4735.384,-2.13142,5.43249,120.53614,-0.08218,47.64954
4743.084,-2.13506,5.48048,120.63026,-0.08222,48.0705
4750.784,-2.13495,5.56168,120.75525,-0.08222,48.78277
4758.484,-2.13487,5.61562,120.89956,-0.08221,49.25582
4766.184,-2.13481,5.62045,121.01469,-0.08221,49.29823
4773.884,-2.13476,5.65042,121.13253,-0.08221,49.56107
4781.584,-2.13475,5.65493,121.25986,-0.08221,49.60069
4789.284,-2.13477,5.72605,121.4057,-0.08221,50.22445
4796.984,-2.1348,5.76613,121.5244,-0.08221,50.57597
4804.684,-2.13487,5.82361,121.65903,-0.08221,51.08019
4812.384,-2.13497,5.90172,121.78092,-0.08222,51.76528
4820.084,-2.13526,5.99053,121.91592,-0.08222,52.54425
4827.784,-2.13872,5.94944,122.09396,-0.08225,52.18386
4835.484,-2.15546,5.67694,122.25724,-0.08241,49.79374
4843.184,-2.16073,5.53515,122.36391,-0.08246,48.55006
4850.884,-2.16069,5.55967,122.45824,-0.08246,48.76507
4858.584,-2.16064,5.5795,122.57163,-0.08246,48.93903
4866.284,-2.16062,5.61367,122.68051,-0.08246,49.23875
4873.984,-2.16062,5.67977,122.79166,-0.08246,49.81856
4881.684,-2.16064,5.76643,122.94495,-0.08246,50.57861
4889.384,-2.16069,5.84543,123.05798,-0.08246,51.27161
4897.084,-2.16078,5.90471,123.18121,-0.08246,51.79157
4904.784,-2.16225,5.91339,123.32374,-0.08247,51.86771
4912.484,-2.17666,5.65521,123.44672,-0.08261,49.60308
4920.184,-2.17835,5.61063,123.56009,-0.08262,49.21212
4927.884,-2.1785,5.61514,123.72024,-0.08262,49.25168
4935.584,-2.17853,5.64997,123.82925,-0.08262,49.55716
4943.284,-2.17858,5.67892,123.98141,-0.08262,49.81107
4950.984,-2.17879,5.76539,124.09467,-0.08263,50.56951
4958.684,-2.18235,5.68597,124.24371,-0.08266,49.87295
4966.384,-2.18528,5.72556,124.38638,-0.08269,50.22013
4974.084,-2.18706,5.74298,124.47513,-0.0827,50.37292
4981.784,-2.19235,5.74251,124.61691,-0.08275,50.36881
4989.484,-2.19318,5.77329,124.73535,-0.08276,50.63885
4997.184,-2.19383,5.76787,124.89813,-0.08277,50.59129
5004.884,-2.19533,5.69762,124.98129,-0.08278,49.97508
5012.584,-2.20091,5.65309,125.08662,-0.08283,49.58455
5020.284,-2.2025,5.5842,125.21336,-0.08285,48.98026
5027.984,-2.20333,5.63634,125.29697,-0.08286,49.43763
5035.684,-2.20407,5.69302,125.47856,-0.08286,49.93475
5043.384,-2.20649,5.70266,125.61966,-0.08289,50.01934
5051.084,-2.21038,5.69492,125.77976,-0.08292,49.95142
5058.784,-2.22298,5.51199,125.88823,-0.08304,48.34688
5066.484,-2.22337,5.56137,126.01986,-0.08304,48.78003
5074.184,-2.2233,5.64323,126.17336,-0.08304,49.49807
5081.884,-2.22324,5.67879,126.30703,-0.08304,49.80998
5089.584,-2.22321,5.66371,126.41435,-0.08304,49.67765
5097.284,-2.22321,5.67963,126.56359,-0.08304,49.81733
5104.984,-2.22322,5.70808,126.65642,-0.08304,50.06685
5112.684,-2.22326,5.73199,126.79832,-0.08304,50.27657
5120.384,-2.22333,5.77607,126.91866,-0.08304,50.66323
5128.084,-2.22353,5.85014,127.02107,-0.08305,51.31292
5135.784,-2.22729,5.83724,127.17303,-0.08308,51.19977
5143.484,-2.23924,5.64208,127.25206,-0.08319,49.48791
5151.184,-2.24018,5.68495,127.39324,-0.0832,49.86399
5158.884,-2.24029,5.72639,127.54348,-0.0832,50.22742
5166.584,-2.24038,5.7986,127.71224,-0.0832,50.86082
5174.284,-2.241,5.79552,127.86002,-0.08321,50.83378
5181.984,-2.2495,5.65104,127.99159,-0.08329,49.5665
5189.684,-2.2538,5.59747,128.07198,-0.08333,49.09662
5197.384,-2.25492,5.61409,128.20357,-0.08334,49.24245
5205.084,-2.25496,5.63353,128.32172,-0.08334,49.41294
5212.784,-2.255,5.69127,128.45686,-0.08334,49.91943
5220.484,-2.25514,5.72962,128.53685,-0.08334,50.25581
5228.184,-2.256,5.78979,128.65408,-0.08335,50.78352
5235.884,-2.26188,5.70846,128.83693,-0.08341,50.07018
5243.584,-2.2682,5.64874,128.96581,-0.08346,49.54632
5251.284,-2.26963,5.66906,129.09784,-0.08348,49.72456
5258.984,-2.27018,5.71106,129.22667,-0.08348,50.093
5266.684,-2.27054,5.71369,129.33633,-0.08349,50.11602
5274.384,-2.27122,5.72419,129.46158,-0.08349,50.20817
5282.084,-2.27292,5.72969,129.61461,-0.08351,50.25643
5289.784,-2.27911,5.61667,129.76642,-0.08357,49.26504
5297.484,-2.28354,5.59226,129.86885,-0.08361,49.05096
5305.184,-2.284,5.64708,130.0161,-0.08361,49.53176
5312.884,-2.28419,5.6827,130.06131,-0.08361,49.84423
5320.584,-2.28422,5.72254,130.07884,-0.08362,50.19372
5328.284,-2.28425,5.74909,130.08804,-0.08362,50.4266
5335.984,-2.28426,5.73682,130.02513,-0.08362,50.3189
5343.684,-2.28427,5.74306,130.00392,-0.08362,50.37362
5351.384,-2.28428,5.71417,129.99013,-0.08362,50.12025
5359.084,-2.28431,5.68603,129.9978,-0.08362,49.87344
5366.784,-2.2844,5.67871,129.98701,-0.08362,49.80927
5374.484,-2.28465,5.70048,129.96696,-0.08362,50.00018
5382.184,-2.28559,5.70193,129.9234,-0.08363,50.01294
5389.884,-2.28683,5.7105,129.99376,-0.08364,50.08805
5397.584,-2.28732,5.67901,130.00371,-0.08364,49.81188
5405.284,-2.28752,5.71036,129.97375,-0.08365,50.0868
5412.984,-2.28765,5.72193,129.94716,-0.08365,50.18832
5420.684,-2.28781,5.73856,129.95195,-0.08365,50.33418
5428.384,-2.28809,5.72213,129.96527,-0.08365,50.19006
5436.084,-2.28845,5.74979,130.0166,-0.08365,50.43267
5443.784,-2.28886,5.76299,130.04041,-0.08366,50.54852
5451.484,-2.28947,5.7409,130.07738,-0.08366,50.3547
5459.184,-2.29048,5.69649,130.06572,-0.08367,49.9652
5466.884,-2.29129,5.6946,130.08301,-0.08368,49.94858
5474.584,-2.29164,5.70233,130.07626,-0.08368,50.01637
5482.284,-2.29182,5.69786,130.07449,-0.08369,49.97722
5489.984,-2.29183,5.66521,130.02959,-0.08369,49.69085
5497.684,-2.29181,5.64133,130.01131,-0.08369,49.48137
5505.384,-2.2918,5.64376,129.99959,-0.08369,49.50265
5513.084,-2.29179,5.63518,130.0457,-0.08369,49.42738
5520.784,-2.29178,5.66373,130.04453,-0.08369,49.67786
5528.484,-2.29179,5.67257,130.10805,-0.08369,49.75538
5536.184,-2.29179,5.70719,130.07735,-0.08369,50.05901
5543.884,-2.29179,5.70661,130.07114,-0.08369,50.05397
5551.584,-2.2918,5.71932,130.0509,-0.08369,50.16539
5559.284,-2.2918,5.69903,130.02388,-0.08369,49.9875
5566.984,-2.29181,5.74211,130.02182,-0.08369,50.36534
5574.684,-2.29182,5.70082,130.06248,-0.08369,50.00315
5582.384,-2.29184,5.76434,130.11075,-0.08369,50.5603
5590.084,-2.29185,5.73044,130.11681,-0.08369,50.26299
5597.784,-2.29189,5.71954,130.06908,-0.08369,50.16737
5605.484,-2.29195,5.73235,130.04095,-0.08369,50.27976
5613.184,-2.29224,5.7653,130.04495,-0.08369,50.56873
5620.884,-2.29351,5.67894,130.07574,-0.0837,49.81128
5628.584,-2.29585,5.67091,130.06813,-0.08372,49.7408
5636.284,-2.2966,5.65285,130.07648,-0.08373,49.5824
5643.984,-2.29667,5.585,130.07217,-0.08373,48.98725
5651.684,-2.29664,5.60165,130.03561,-0.08373,49.13335
5659.384,-2.29661,5.60738,130.06136,-0.08373,49.18359
5667.084,-2.29658,5.62032,130.0347,-0.08373,49.29711
5674.784,-2.29655,5.63294,130.01115,-0.08373,49.4078
5682.484,-2.29652,5.73888,130.03786,-0.08373,50.33701
5690.184,-2.29648,5.6889,130.03526,-0.08373,49.89861
5697.884,-2.29646,5.70534,130.05121,-0.08373,50.04277
5705.584,-2.29643,5.68541,130.0728,-0.08373,49.86799
5713.284,-2.29641,5.6199,130.10625,-0.08373,49.29343
5720.984,-2.29639,5.60985,130.08636,-0.08373,49.20523
5728.684,-2.29638,5.61658,130.05597,-0.08373,49.26428
5736.384,-2.29637,5.60471,130.04016,-0.08373,49.16018
5744.084,-2.29635,5.63682,130.04617,-0.08373,49.44179
5751.784,-2.29634,5.6755,130.05917,-0.08373,49.7811
5759.484,-2.29633,5.72605,130.04895,-0.08373,50.2245
5767.184,-2.2963,5.75784,130.03583,-0.08373,50.5033
5774.884,-2.29624,5.75174,130.03244,-0.08373,50.44976
5782.584,-2.2962,5.70222,130.02344,-0.08373,50.01547
5790.284,-2.29612,5.65277,130.03256,-0.08373,49.58171
5797.984,-2.29607,5.64861,130.05827,-0.08373,49.5452
5805.684,-2.29599,5.62103,130.04008,-0.08373,49.30327
5813.384,-2.29593,5.61885,129.99168,-0.08372,49.2842
5821.084,-2.29588,5.63812,129.9942,-0.08372,49.45325
5828.784,-2.29585,5.68846,130.07326,-0.08372,49.89478
5836.484,-2.29582,5.70418,130.07343,-0.08372,50.03266
5844.184,-2.29579,5.76327,130.0979,-0.08372,50.55094
5851.884,-2.29575,5.73666,130.05888,-0.08372,50.31752
5859.584,-2.29571,5.76808,130.03751,-0.08372,50.59312
5867.284,-2.29567,5.68586,130.03664,-0.08372,49.87193
5874.984,-2.29562,5.65162,129.99837,-0.08372,49.57166
5882.684,-2.29557,5.60275,130.02078,-0.08372,49.14296
5890.384,-2.29556,5.66181,129.99823,-0.08372,49.661
5898.084,-2.29555,5.61924,130.0239,-0.08372,49.28759
5905.784,-2.29554,5.65463,130.06874,-0.08372,49.59804
5913.484,-2.29553,5.68958,130.08299,-0.08372,49.90454
5921.184,-2.29551,5.71526,130.06424,-0.08372,50.12981
5928.884,-2.29547,5.73223,130.06389,-0.08372,50.27869
5936.584,-2.29536,5.72014,130.06961,-0.08372,50.1726
5944.284,-2.29521,5.69952,130.06616,-0.08372,49.99176
5951.984,-2.29511,5.69937,130.05878,-0.08372,49.99041
5959.684,-2.29501,5.68708,130.07487,-0.08372,49.88269
5967.384,-2.29497,5.65565,130.08537,-0.08372,49.60695
5975.084,-2.29492,5.64851,130.05283,-0.08372,49.54438
5982.784,-2.29487,5.66452,130.05145,-0.08372,49.68479
5990.484,-2.29477,5.68109,130.05505,-0.08371,49.83011
5998.184,-2.29464,5.65549,130.03751,-0.08371,49.6056
6005.884,-2.29449,5.68254,130.01482,-0.08371,49.84287
6013.584,-2.29437,5.69344,129.99408,-0.08371,49.93847
6021.284,-2.29423,5.76287,129.94121,-0.08371,50.54744
6028.984,-2.29409,5.77793,129.95493,-0.08371,50.67955
6036.684,-2.29406,5.75646,129.97734,-0.08371,50.49124
6044.384,-2.294,5.72145,130.00926,-0.08371,50.18413
6052.084,-2.29398,5.70155,130.08464,-0.08371,50.00958
6059.784,-2.29399,5.71304,130.11385,-0.08371,50.11038
6067.484,-2.29398,5.69473,130.11069,-0.08371,49.94973
6075.184,-2.29398,5.71254,130.09666,-0.08371,50.10595
6082.884,-2.29399,5.68786,130.08394,-0.08371,49.88953
6090.584,-2.29399,5.69807,130.07388,-0.08371,49.97908
6098.284,-2.29398,5.7079,130.0779,-0.08371,50.06524
6105.984,-2.29398,5.68455,130.06749,-0.08371,49.86049
6113.684,-2.29397,5.67613,130.04561,-0.08371,49.78662
6121.384,-2.29395,5.63231,130.02623,-0.08371,49.40226
6129.084,-2.29394,5.67782,130.00052,-0.08371,49.80139
6136.784,-2.29392,5.68066,130.00812,-0.08371,49.82631
6144.484,-2.29389,5.70485,129.97002,-0.08371,50.03855
6152.184,-2.29386,5.74311,129.94124,-0.08371,50.37408
6159.884,-2.29381,5.72129,129.96759,-0.08371,50.1827
6167.584,-2.29378,5.78534,129.98578,-0.0837,50.74454
6175.284,-2.29376,5.79977,130.0154,-0.0837,50.87111
6182.984,-2.29374,5.74079,130.05644,-0.0837,50.35377
6190.684,-2.29372,5.70529,130.05965,-0.0837,50.04241
6198.384,-2.29372,5.66389,130.01523,-0.0837,49.67926
6206.084,-2.29372,5.66219,130.01154,-0.0837,49.66431
6213.784,-2.29372,5.65802,130.05661,-0.0837,49.62775
6221.484,-2.29372,5.65211,130.04582,-0.0837,49.57591
6229.184,-2.29372,5.65498,130.05008,-0.0837,49.60106
6236.884,-2.29372,5.74309,130.00912,-0.0837,50.37391
6244.584,-2.29372,5.73101,130.04478,-0.0837,50.26794
6252.284,-2.29372,5.71721,130.02615,-0.0837,50.14689
6259.984,-2.29371,5.70824,130.02187,-0.0837,50.06828
6267.684,-2.29371,5.70017,130.05853,-0.0837,49.99743
6275.384,-2.29371,5.66967,130.02898,-0.0837,49.72997
6283.084,-2.29371,5.67128,129.98724,-0.0837,49.7441
6290.784,-2.29371,5.70303,130.02249,-0.0837,50.02252
6298.484,-2.29371,5.70492,130.04385,-0.0837,50.03913
6306.184,-2.29371,5.7154,129.97424,-0.0837,50.13104
6313.884,-2.29371,5.70989,129.97264,-0.0837,50.08268
6321.584,-2.29371,5.69777,129.96671,-0.0837,49.97644
6329.284,-2.29371,5.71269,129.9921,-0.0837,50.10727
6336.984,-2.29371,5.73243,130.02402,-0.0837,50.28047
6344.684,-2.29372,5.69013,130.06026,-0.0837,49.90942
6352.384,-2.29372,5.69928,130.0383,-0.0837,49.98968
6360.084,-2.29372,5.69386,130.02505,-0.0837,49.94209
6367.784,-2.29372,5.69542,130.0108,-0.0837,49.95576
6375.484,-2.29372,5.68097,130.0209,-0.0837,49.82902
6383.184,-2.29372,5.70669,130.05803,-0.0837,50.05466
6390.884,-2.29372,5.69085,130.04541,-0.0837,49.91575
6398.584,-2.29373,5.68436,130.07887,-0.0837,49.85876
6406.284,-2.29373,5.68605,130.02473,-0.0837,49.87362
6413.984,-2.29373,5.6946,130.01157,-0.0837,49.94863
6421.684,-2.29373,5.71982,130.00661,-0.0837,50.16982
6429.384,-2.29373,5.7019,129.98079,-0.0837,50.01265
6437.084,-2.29373,5.72972,129.96892,-0.0837,50.25666
6444.784,-2.29373,5.73113,130.0096,-0.0837,50.26907
6452.484,-2.29373,5.69117,130.02771,-0.0837,49.91854
6460.184,-2.29374,5.66793,130.04977,-0.0837,49.7147
6467.884,-2.29374,5.6722,130.01036,-0.0837,49.75214
6475.584,-2.29374,5.68922,130.02061,-0.0837,49.90138
6483.284,-2.29374,5.69137,130.011,-0.0837,49.92026
6490.984,-2.29374,5.69684,129.99132,-0.0837,49.96827
6498.684,-2.29374,5.71347,129.98967,-0.0837,50.11411
6506.384,-2.29375,5.72628,130.00897,-0.0837,50.22652
6514.084,-2.29375,5.77601,130.04201,-0.0837,50.66264
6521.784,-2.29376,5.74945,130.06288,-0.0837,50.42974
6529.484,-2.29376,5.72393,130.05386,-0.0837,50.20585
6537.184,-2.29376,5.6943,130.0674,-0.0837,49.94602
6544.884,-2.29376,5.66778,130.05602,-0.0837,49.71338
6552.584,-2.29376,5.64298,130.02185,-0.0837,49.49582
6560.284,-2.29377,5.65814,129.98746,-0.0837,49.62879
6567.984,-2.29377,5.65633,129.99353,-0.0837,49.6129
6575.684,-2.29377,5.67737,129.97462,-0.0837,49.79747
6583.384,-2.29378,5.71433,129.99506,-0.0837,50.12164
6591.084,-2.29379,5.74169,130.0415,-0.0837,50.36166
6598.784,-2.29379,5.72426,130.06296,-0.0837,50.20874
6606.484,-2.29379,5.75474,130.02254,-0.0837,50.47615
6614.184,-2.29379,5.78107,130.02959,-0.0837,50.70705
6621.884,-2.29379,5.71688,130.0218,-0.0837,50.14407
6629.584,-2.29379,5.70782,129.99745,-0.0837,50.06459
6637.284,-2.29379,5.67162,129.96437,-0.0837,49.74702
6644.984,-2.29379,5.66252,129.96648,-0.0837,49.66726
6652.684,-2.29379,5.61373,129.98088,-0.0837,49.23932
6660.384,-2.29379,5.65193,129.97015,-0.0837,49.57434
6668.084,-2.2938,5.71901,129.98114,-0.0837,50.16272
6675.784,-2.2938,5.70472,130.03802,-0.0837,50.03735
6683.484,-2.29381,5.77371,130.04352,-0.08371,50.64248
6691.184,-2.29383,5.79003,130.05975,-0.08371,50.78562
6698.884,-2.29383,5.81397,130.06097,-0.08371,50.99563
6706.584,-2.29384,5.77639,130.0367,-0.08371,50.66602
6714.284,-2.29384,5.73723,130.03383,-0.08371,50.32256
6721.984,-2.29385,5.66687,130.04428,-0.08371,49.70542
6729.684,-2.29386,5.63995,130.03452,-0.08371,49.46926
6737.384,-2.29386,5.63761,129.98772,-0.08371,49.44875
6745.084,-2.29387,5.63635,129.98022,-0.08371,49.43765
6752.784,-2.29387,5.67885,129.9857,-0.08371,49.81048
6760.484,-2.29388,5.74441,130.00105,-0.08371,50.38549
6768.184,-2.29389,5.78981,129.99055,-0.08371,50.7837
6775.884,-2.29389,5.757,129.99826,-0.08371,50.4959
6783.584,-2.2939,5.76435,130.00815,-0.08371,50.56038
6791.284,-2.2939,5.7322,130.02025,-0.08371,50.27843
6798.984,-2.29391,5.70884,130.05069,-0.08371,50.07355
6806.684,-2.29391,5.68977,130.06514,-0.08371,49.90624
6814.384,-2.29391,5.66486,130.03043,-0.08371,49.68776
6822.084,-2.29391,5.67134,130.00925,-0.08371,49.74463
6829.784,-2.29391,5.66045,129.9953,-0.08371,49.64906
6837.484,-2.29391,5.65078,130.019,-0.08371,49.56425
6845.184,-2.29391,5.68383,129.96597,-0.08371,49.85417
6852.884,-2.29391,5.67137,129.96272,-0.08371,49.74489
6860.584,-2.29391,5.68407,129.96021,-0.08371,49.85623
6868.284,-2.29391,5.71697,129.96675,-0.08371,50.14483
6875.984,-2.29391,5.7231,129.96574,-0.08371,50.19862
6883.684,-2.29392,5.70468,130.00034,-0.08371,50.03704
6891.384,-2.29392,5.70301,130.03717,-0.08371,50.02234
6899.084,-2.29392,5.72023,130.03995,-0.08371,50.17339
6906.784,-2.29392,5.70218,130.03447,-0.08371,50.01506
6914.484,-2.29392,5.72094,130.03856,-0.08371,50.17967
6922.184,-2.29392,5.70525,130.00507,-0.08371,50.04199
6929.884,-2.29392,5.691,130.00447,-0.08371,49.91706
6937.584,-2.29392,5.71399,130.01141,-0.08371,50.11871
6945.284,-2.29392,5.69287,129.99806,-0.08371,49.93342
6952.984,-2.29392,5.74303,129.98869,-0.08371,50.37341
6960.684,-2.29392,5.74645,129.97559,-0.08371,50.40336
6968.384,-2.29393,5.75342,130.00223,-0.08371,50.46457
6976.084,-2.29393,5.72723,130.01787,-0.08371,50.23479
6983.784,-2.29393,5.67364,130.01421,-0.08371,49.76476
6991.484,-2.29394,5.64081,129.98491,-0.08371,49.47682
6999.184,-2.29394,5.65541,129.95451,-0.08371,49.60485
7006.884,-2.29395,5.68331,130.00357,-0.08371,49.84957
7014.584,-2.29395,5.70599,130.02654,-0.08371,50.04852
7022.284,-2.29396,5.73748,130.04504,-0.08371,50.32473
7029.984,-2.29396,5.73108,130.02235,-0.08371,50.26862
7037.684,-2.29396,5.74698,130.04062,-0.08371,50.40804
7045.384,-2.29397,5.72921,130.01642,-0.08371,50.25216
7053.084,-2.29397,5.71074,130.0262,-0.08371,50.09021
7060.784,-2.29397,5.69301,130.03278,-0.08371,49.93462
7068.484,-2.29398,5.66702,130.04578,-0.08371,49.70671
7076.184,-2.29398,5.64541,130.01968,-0.08371,49.51717
7083.884,-2.29399,5.64848,130.0078,-0.08371,49.54411
7091.584,-2.29399,5.6938,129.99054,-0.08371,49.94156
7099.284,-2.294,5.73735,129.99689,-0.08371,50.32355
7106.984,-2.294,5.72657,130.04256,-0.08371,50.22907
7114.684,-2.294,5.75231,130.03096,-0.08371,50.45481
7122.384,-2.29401,5.76798,129.99704,-0.08371,50.59223
7130.084,-2.29401,5.749,129.98857,-0.08371,50.4258
7137.784,-2.29401,5.73934,129.99362,-0.08371,50.34101
7145.484,-2.29401,5.71009,130.03163,-0.08371,50.0845
7153.184,-2.29402,5.69457,130.03674,-0.08371,49.94839
7160.884,-2.29402,5.6893,130.05045,-0.08371,49.90211
7168.584,-2.29402,5.69179,130.01187,-0.08371,49.92395
7176.284,-2.29402,5.70193,130.01726,-0.08371,50.01289
7183.984,-2.29402,5.69113,130.00397,-0.08371,49.91818
7191.684,-2.29402,5.67549,130.01212,-0.08371,49.78102
7199.384,-2.29402,5.69808,130.00356,-0.08371,49.97914
7207.084,-2.29402,5.70485,129.98112,-0.08371,50.03848
7214.784,-2.29401,5.71911,129.98158,-0.08371,50.16363
7222.484,-2.29401,5.73144,130.01341,-0.08371,50.27171
7230.184,-2.29401,5.71409,130.04152,-0.08371,50.11957
7237.884,-2.29401,5.72972,130.01851,-0.08371,50.25666
7245.584,-2.29401,5.69622,130.01057,-0.08371,49.96279
7253.284,-2.29401,5.68501,129.99829,-0.08371,49.86448
7260.984,-2.29401,5.67272,129.99583,-0.08371,49.75673
7268.684,-2.294,5.68296,129.98256,-0.08371,49.84651
7276.384,-2.294,5.69577,129.96619,-0.08371,49.95887
7284.084,-2.294,5.68966,129.97879,-0.08371,49.90525
7291.784,-2.29399,5.44746,129.9427,-0.08371,47.78093
7299.484,1.30204,3.71696,120.83535,-0.04998,32.60232
7303.045,4.89501,5.85655,115.90694,-0.01629,51.36914