File: experimental/sma_database/results from first training/flexinol_isobaric_200MPa.csv
Test : Start of hold value,"200.00000",MPa

Time,Extension,Load,Temperature: Chamber 3119-600 1 1,Tensile strain (Extension),Tensile stress
(s),(mm),(N),(C),(mm/mm),(MPa)
"0.00000","1.16631","0.00178","29.64571","-0.00001","0.01561"
"8.40000","1.23605","0.59833","29.72639","0.00068","5.24810"
"16.80000","1.30618","1.79934","29.65955","0.00137","15.78239"
"25.20000","1.37625","2.43585","29.63109","0.00207","21.36535"
"33.60000","1.44611","3.67411","29.65177","0.00276","32.22647"
"42.00000","1.51610","4.16505","29.83105","0.00345","36.53255"
"50.40000","1.58631","5.61371","29.64838","0.00414","49.23911"
"58.80000","1.65612","6.37572","29.58356","0.00483","55.92284"
"67.20000","1.72611","7.33377","29.77683","0.00552","64.32616"
"75.60000","1.79631","8.60546","29.72393","0.00622","75.48042"
"84.00000","1.86606","9.09278","29.91049","0.00691","79.75480"
"92.40000","1.93606","10.37470","29.69240","0.00760","90.99879"
"100.80000","2.00624","11.20424","29.87459","0.00829","98.27493"
"109.20000","2.07616","12.20878","29.87578","0.00898","107.08595"
"117.60000","2.14606","13.31075","29.85679","0.00968","116.75156"
"126.00000","2.21620","13.86292","29.86462","0.01037","121.59478"
"134.39999","2.28615","15.13799","29.76378","0.01106","132.77873"
"142.80000","2.35609","15.71709","29.95258","0.01175","137.85809"
"151.20000","2.42624","16.88239","29.87632","0.01245","148.07924"
"159.60001","2.49615","17.83767","29.96541","0.01314","156.45821"
"168.00000","2.56608","18.58360","29.96233","0.01383","163.00087"
"176.39999","2.63617","19.72396","29.91167","0.01452","173.00325"
"184.80000","2.70625","20.23000","29.93839","0.01521","177.44188"
"193.20000","2.77609","21.49495","29.85444","0.01590","188.53702"
"201.60001","2.84620","22.09184","30.00101","0.01660","193.77249"
"209.80200","2.93962","23.45481","29.85015","0.01752","205.72737"
"218.20200","2.93907","23.44153","29.91194","0.01751","205.61092"
"226.60201","2.93792","23.05766","29.99142","0.01750","202.24390"
"235.00200","2.91366","22.89020","29.91324","0.01726","200.77504"
"243.40199","2.89514","22.32344","30.03528","0.01708","195.80389"
"251.80200","2.89553","22.51245","29.90734","0.01708","197.46176"
"260.20200","2.89625","22.64555","30.00093","0.01709","198.62915"
"268.60199","2.91520","22.65872","30.04532","0.01728","198.74471"
"277.00201","2.92531","23.11222","29.92136","0.01738","202.72241"
"285.40201","2.92515","22.79390","30.14959","0.01738","199.93040"
"293.80200","2.92494","22.89820","30.19322","0.01737","200.84525"
"302.20200","2.92442","23.01824","30.26699","0.01737","201.89813"
"310.60199","2.91990","23.08458","30.46767","0.01732","202.48004"
"319.00201","2.89565","22.75879","30.64214","0.01708","199.62248"
"327.40201","2.89578","22.75083","30.79739","0.01709","199.55261"
"335.80200","2.89594","22.74981","30.99537","0.01709","199.54362"
"344.20200","2.89609","22.75056","31.17282","0.01709","199.55026"
"352.60199","2.89625","22.59873","31.45560","0.01709","198.21852"
"361.00201","2.89631","22.79945","31.64774","0.01709","199.97910"
"369.40201","2.89646","22.90877","31.69218","0.01709","200.93796"
"377.80200","2.89646","22.59230","32.11620","0.01709","198.16216"
"386.20200","2.89642","22.98415","32.15436","0.01709","201.59914"
"394.60199","2.89631","22.91337","32.53343","0.01709","200.97826"
"403.00201","2.89627","22.88208","32.53397","0.01709","200.70383"
"411.40201","2.89610","23.01041","32.87008","0.01709","201.82947"
"419.80200","2.89579","22.95472","33.14611","0.01709","201.34099"
"428.20200","2.87920","22.71647","33.37918","0.01692","199.25128"
"436.60199","2.87730","22.77201","33.58799","0.01690","199.73842"
"445.00201","2.87720","22.72404","33.78476","0.01690","199.31763"
"453.40201","2.87714","22.79768","34.02838","0.01690","199.96355"
"461.80200","2.87190","22.89543","34.33346","0.01685","200.82095"
"470.20200","2.86252","22.67235","34.74449","0.01676","198.86421"
"478.60199","2.86238","22.80991","35.14210","0.01676","200.07083"
"487.00201","2.86216","22.84555","35.53032","0.01675","200.38345"
"495.40201","2.84162","22.52991","35.91282","0.01655","197.61484"
"503.80200","2.83791","22.62468","36.32186","0.01651","198.44615"
"512.20203","2.83812","22.54926","36.65783","0.01652","197.78456"
"520.60199","2.83836","22.62151","36.99037","0.01652","198.41829"
"529.00201","2.83866","22.77309","37.31897","0.01652","199.74783"
"537.40198","2.83903","22.77275","37.61019","0.01653","199.74492"
"545.80200","2.83921","22.81389","37.96003","0.01653","200.10577"
"554.20203","2.83924","22.87962","38.27596","0.01653","200.68228"
"562.60199","2.83921","22.88601","38.58215","0.01653","200.73834"
"571.00201","2.83912","22.89664","38.88778","0.01653","200.83153"
"579.40198","2.83899","23.01384","39.19294","0.01652","201.85950"
"587.80200","2.83874","23.02876","39.47598","0.01652","201.99042"
"596.20203","2.83786","23.09649","39.84639","0.01651","202.58450"
"604.60199","2.81720","22.76814","40.11254","0.01631","199.70445"
"613.00201","2.81612","22.82672","40.41600","0.01630","200.21823"
"621.40198","2.81601","22.75303","40.70748","0.01630","199.57191"
"629.80200","2.81590","22.88180","40.98789","0.01630","200.70142"
"638.20203","2.81453","22.84038","41.29185","0.01628","200.33804"
"646.60199","2.79078","22.57796","41.59365","0.01605","198.03635"
"655.00201","2.79092","22.62201","41.93879","0.01605","198.42268"
"663.40198","2.79113","22.59974","42.21946","0.01605","198.22740"
"671.80200","2.79138","22.65363","42.50312","0.01605","198.70001"
"680.20203","2.79172","22.69304","42.77219","0.01606","199.04575"
"688.60199","2.79213","22.74010","43.03830","0.01606","199.45854"
"697.00201","2.79238","22.85451","43.37243","0.01606","200.46198"
"705.40198","2.79243","22.80605","43.67976","0.01606","200.03694"
"713.80200","2.79240","22.84883","43.94815","0.01606","200.41219"
"722.20203","2.79232","22.90578","44.22106","0.01606","200.91170"
"730.60199","2.79219","22.89468","44.52108","0.01606","200.81436"
"739.00201","2.79197","23.03329","44.82909","0.01606","202.03011"
"747.40198","2.79137","22.97827","45.10104","0.01605","201.54750"
"755.80200","2.77637","22.85721","45.35840","0.01591","200.48567"
"764.20203","2.76420","22.72343","45.64474","0.01579","199.31232"
"772.60199","2.76425","22.70748","45.94173","0.01579","199.17235"
"781.00201","2.76429","22.82548","46.23784","0.01579","200.20740"
"789.40198","2.76431","22.84550","46.50508","0.01579","200.38301"
"797.80200","2.76430","22.79896","46.78516","0.01579","199.97475"
"806.20203","2.76425","22.84703","47.07180","0.01579","200.39645"
"814.60199","2.76413","22.88660","47.38293","0.01578","200.74345"
"823.00201","2.73778","22.51223","47.67608","0.01552","197.45976"
"831.40198","2.73659","22.52208","47.94194","0.01551","197.54616"
"839.80200","2.73684","22.60980","48.24373","0.01552","198.31564"
"848.20203","2.73712","22.59203","48.50380","0.01552","198.15974"
"856.60199","2.73753","22.68196","48.78308","0.01552","198.94852"
"865.00201","2.73813","22.75426","49.04861","0.01553","199.58269"
"873.40198","2.73888","22.75568","49.35568","0.01554","199.59512"
"881.80200","2.73924","22.88099","49.63039","0.01554","200.69424"
"890.20203","2.73925","22.85047","49.89526","0.01554","200.42661"
"898.60199","2.73919","22.83747","50.15001","0.01554","200.31252"
"907.00201","2.73908","22.94433","50.41837","0.01554","201.24988"
"915.40198","2.73888","22.96391","50.74036","0.01554","201.42155"
"923.80200","2.73850","23.04716","51.03996","0.01553","202.15184"
"932.20203","2.73668","23.09344","51.30404","0.01551","202.55774"
"940.60199","2.71654","22.80111","51.56876","0.01531","199.99361"
"949.00201","2.71529","22.74335","51.82974","0.01530","199.48698"
"957.40198","2.71424","22.88172","52.11006","0.01529","200.70067"
"965.80200","2.71074","22.76978","52.43011","0.01526","199.71883"
"974.20203","2.70857","22.82840","52.74095","0.01524","200.23303"
"982.60199","2.69473","22.56338","53.01847","0.01510","197.90846"
"991.00201","2.69485","22.71074","53.29754","0.01510","199.20099"
"999.40198","2.69497","22.77324","53.56134","0.01510","199.74921"
"1007.80200","2.69507","22.80919","53.81507","0.01510","200.06453"
"1016.20203","2.69511","22.77273","54.09175","0.01510","199.74469"
"1024.60205","2.69508","22.81332","54.39379","0.01510","200.10075"
"1033.00195","2.69505","22.88063","54.65009","0.01510","200.69116"
"1041.40198","2.69495","22.92992","54.92548","0.01510","201.12344"
"1049.80200","2.69476","22.92138","55.18839","0.01510","201.04857"
"1058.20203","2.68251","22.77203","55.46918","0.01498","199.73860"
"1066.60205","2.66934","22.72084","55.78134","0.01485","199.28957"
"1075.00195","2.66944","22.69346","56.05913","0.01485","199.04939"
"1083.40198","2.66952","22.70061","56.37314","0.01485","199.11215"
"1091.80200","2.66958","22.79023","56.60086","0.01485","199.89824"
"1100.20203","2.66959","22.77036","56.88479","0.01485","199.72394"
"1108.60205","2.66956","22.83288","57.14271","0.01485","200.27226"
"1117.00195","2.66948","22.87665","57.41224","0.01485","200.65617"
"1125.40198","2.66933","22.98993","57.75287","0.01485","201.64978"
"1133.80200","2.63750","22.53856","58.05322","0.01453","197.69080"
"1142.20203","2.63657","22.54949","58.29552","0.01452","197.78661"
"1150.60205","2.63686","22.62726","58.54646","0.01453","198.46873"
"1159.00195","2.63721","22.61766","58.82790","0.01453","198.38454"
"1167.40198","2.63780","22.70518","59.10471","0.01454","199.15225"
"1175.80200","2.63854","22.80343","59.39183","0.01454","200.01399"
"1184.20203","2.63917","22.81819","59.66959","0.01455","200.14345"
"1192.60205","2.63929","22.85241","59.96904","0.01455","200.44362"
"1201.00195","2.63923","22.87635","60.25746","0.01455","200.65361"
"1209.40198","2.63913","22.93909","60.53069","0.01455","201.20386"
"1217.80200","2.63897","22.97739","60.81647","0.01455","201.53979"
"1226.20203","2.63864","22.98851","61.15032","0.01454","201.63733"
"1234.60205","2.63747","23.04190","61.41264","0.01453","202.10562"
"1243.00195","2.61235","22.68028","61.67617","0.01428","198.93378"
"1251.40198","2.60018","22.61270","61.96725","0.01416","198.34100"
"1259.80200","2.60036","22.58441","62.21962","0.01417","198.09293"
"1268.20203","2.60052","22.76947","62.50454","0.01417","199.71608"
"1276.60205","2.60062","22.80807","62.73010","0.01417","200.05467"
"1285.00195","2.60066","22.76337","63.03364","0.01417","199.66260"
"1293.40198","2.60065","22.91329","63.30550","0.01417","200.97755"
"1301.80200","2.60059","22.89758","63.59044","0.01417","200.83975"
"1310.20203","2.60046","23.01310","63.88978","0.01417","201.85306"
"1318.60205","2.60021","22.96867","64.16136","0.01416","201.46330"
"1327.00195","2.58687","22.91450","64.47434","0.01403","200.98816"
"1335.40198","2.57247","22.71682","64.78326","0.01389","199.25433"
"1343.80200","2.57250","22.74047","65.05122","0.01389","199.46178"
"1352.20203","2.57251","22.78573","65.33658","0.01389","199.85875"
"1360.60205","2.57249","22.83051","65.58594","0.01389","200.25154"
"1369.00195","2.57242","22.84454","65.82526","0.01389","200.37453"
"1377.40198","2.55476","22.64343","66.11766","0.01372","198.61058"
"1385.80200","2.54250","22.62722","66.36643","0.01359","198.46838"
"1394.20203","2.54266","22.64609","66.62330","0.01360","198.63393"
"1402.60205","2.54278","22.71028","66.91979","0.01360","199.19698"
"1411.00195","2.54287","22.83223","67.19541","0.01360","200.26662"
"1419.40198","2.54289","22.86190","67.51563","0.01360","200.52682"
"1427.80200","2.54281","22.94163","67.79893","0.01360","201.22612"
"1436.20203","2.54267","23.00573","68.11047","0.01360","201.78844"
"1444.60205","2.54236","23.00794","68.40475","0.01359","201.80775"
"1453.00195","2.51938","22.79095","68.71265","0.01337","199.90448"
"1461.40198","2.50732","22.68072","68.97686","0.01325","198.93762"
"1469.80200","2.50740","22.67723","69.23576","0.01325","198.90706"
"1478.20203","2.50746","22.77157","69.45875","0.01325","199.73457"
"1486.60205","2.50744","22.78776","69.72792","0.01325","199.87657"
"1495.00195","2.50737","22.98728","70.04050","0.01325","201.62659"
"1503.40198","2.50680","22.95055","70.31686","0.01324","201.30441"
"1511.80200","2.48247","22.66415","70.60540","0.01300","198.79230"
"1520.20203","2.48211","22.78738","70.83076","0.01300","199.87325"
"1528.60205","2.48136","22.83557","71.13252","0.01299","200.29585"
"1537.00195","2.45162","22.47929","71.41736","0.01270","197.17084"
"1545.40198","2.45079","22.60386","71.68302","0.01269","198.26355"
"1553.80200","2.45091","22.69298","71.90842","0.01269","199.04520"
"1562.20203","2.45092","22.89751","72.23514","0.01269","200.83922"
"1570.60205","2.45084","22.95312","72.57782","0.01269","201.32698"
"1579.00195","2.45060","23.06220","72.83994","0.01269","202.28375"
"1587.40198","2.42508","22.84813","73.15849","0.01243","200.40608"
"1595.80200","2.41057","22.71139","73.43517","0.01229","199.20667"
"1604.20203","2.41056","22.73481","73.68852","0.01229","199.41208"
"1612.60205","2.41050","22.91154","73.99545","0.01229","200.96225"
"1621.00195","2.39729","22.80344","74.28300","0.01216","200.01408"
"1629.40198","2.38653","22.75369","74.53622","0.01205","199.57774"
"1637.80200","2.38438","22.85496","74.77760","0.01203","200.46597"
"1646.20203","2.35417","22.56072","74.99402","0.01173","197.88509"
"1654.60205","2.35396","22.76184","75.30331","0.01173","199.64922"
"1663.00195","2.35398","22.84866","75.60291","0.01173","200.41071"
"1671.40198","2.35386","22.97956","75.88599","0.01173","201.55884"
"1679.80200","2.32972","22.83796","76.18877","0.01149","200.31686"
"1688.20203","2.30884","22.77061","76.46858","0.01128","199.72609"
"1696.60205","2.30802","22.80916","76.75868","0.01128","200.06427"
"1705.00195","2.29809","22.87460","77.03006","0.01118","200.63826"
"1713.40198","2.28906","22.94424","77.29581","0.01109","201.24902"
"1721.80200","2.24887","22.45256","77.53752","0.01069","196.93643"
"1730.20203","2.24897","22.72073","77.86233","0.01069","199.28859"
"1738.60205","2.24900","22.90652","78.15359","0.01069","200.91824"
"1747.00195","2.24889","23.03474","78.40288","0.01069","202.04283"
"1755.40198","2.23681","22.97877","78.68305","0.01057","201.55191"
"1763.80200","2.19955","22.71590","78.95199","0.01020","199.24625"
"1772.20203","2.19895","22.83290","79.21031","0.01020","200.27246"
"1780.60205","2.19068","22.93562","79.51066","0.01012","201.17348"
"1789.00195","2.14675","22.67451","79.78306","0.00968","198.88324"
"1797.40198","2.14667","22.80041","80.08308","0.00968","199.98746"
"1805.80200","2.14536","22.92653","80.41006","0.00967","201.09373"
"1814.20203","2.10718","22.63546","80.64873","0.00929","198.54068"
"1822.60205","2.10310","22.79682","80.94391","0.00925","199.95598"
"1831.00195","2.09388","22.88385","81.21720","0.00916","200.71936"
"1839.40198","2.05459","22.57310","81.49944","0.00877","197.99373"
"1847.80200","2.05462","22.82621","81.74432","0.00877","200.21379"
"1856.20203","2.05452","22.99114","82.00716","0.00877","201.66040"
"1864.60205","2.02967","22.84818","82.31989","0.00853","200.40645"
"1873.00195","2.00611","22.73270","82.55783","0.00829","199.39359"
"1881.40198","2.00415","22.90792","82.87167","0.00827","200.93047"
"1889.80200","1.95334","22.53600","83.15971","0.00777","197.66832"
"1898.20203","1.95330","22.81178","83.48244","0.00777","200.08722"
"1906.60205","1.95033","23.10361","83.71898","0.00774","202.64693"
"1915.00195","1.91074","22.77241","84.01749","0.00735","199.74190"
"1923.40198","1.90941","23.01061","84.29868","0.00734","201.83118"
"1931.80200","1.85622","22.52899","84.54819","0.00681","197.60683"
"1940.20203","1.85626","22.70317","84.80653","0.00681","199.13454"
"1948.60205","1.85616","23.06666","85.10175","0.00681","202.32285"
"1957.00195","1.82287","22.77432","85.38853","0.00648","199.75864"
"1965.40198","1.79181","22.72634","85.64177","0.00617","199.33778"
"1973.80200","1.76656","22.72621","85.93214","0.00592","199.33664"
"1982.20203","1.76592","22.98734","86.20160","0.00592","201.62706"
"1990.60205","1.75478","22.97153","86.53649","0.00581","201.48839"
"1999.00195","1.66825","22.35426","86.81911","0.00495","196.07423"
"2007.40198","1.66839","22.58427","87.08356","0.00495","198.09167"
"2015.80200","1.66845","22.84718","87.36635","0.00495","200.39775"
"2024.20203","1.66834","23.05175","87.62749","0.00495","202.19205"
"2032.60205","1.66435","23.12406","87.90566","0.00491","202.82626"
"2041.00195","1.59704","22.67080","88.19568","0.00425","198.85066"
"2049.40210","1.57258","22.70622","88.47214","0.00401","199.16138"
"2057.80200","1.57053","22.87268","88.74512","0.00399","200.62141"
"2066.20190","1.52381","22.62749","89.02498","0.00352","198.47081"
"2074.60205","1.51595","22.87527","89.26263","0.00345","200.64412"
"2083.00195","1.47494","22.61175","89.51890","0.00304","198.33269"
"2091.40210","1.46721","22.92426","89.83103","0.00297","201.07379"
"2099.80200","1.42714","22.71556","90.13727","0.00257","199.24330"
"2108.20190","1.40820","22.87177","90.48532","0.00238","200.61339"
"2116.60205","1.37288","22.68138","90.73103","0.00203","198.94345"
"2125.00195","1.37188","22.94097","91.02666","0.00202","201.22035"
"2133.40210","1.32986","22.85753","91.27189","0.00161","200.48854"
"2141.80200","1.30190","22.82698","91.55906","0.00133","200.22055"
"2150.20190","1.27969","22.83384","91.82718","0.00111","200.28075"
"2158.60205","1.25604","22.84913","92.09660","0.00088","200.41486"
"2167.00195","1.23112","22.91558","92.35219","0.00063","200.99765"
"2175.40210","1.22733","23.08566","92.64227","0.00059","202.48949"
"2183.80200","1.15327","22.59861","92.92542","-0.00014","198.21744"
"2192.20190","1.14366","22.95219","93.19920","-0.00023","201.31883"
"2200.60205","1.10662","22.79698","93.47420","-0.00060","199.95737"
"2209.00195","1.07267","22.84591","93.73611","-0.00093","200.38661"
"2217.40210","1.05411","22.78315","94.04170","-0.00112","199.83611"
"2225.80200","0.99073","22.55128","94.32320","-0.00174","197.80231"
"2234.20190","0.98915","22.83323","94.62122","-0.00176","200.27534"
"2242.60205","0.95717","22.79027","94.87833","-0.00208","199.89859"
"2251.00195","0.91969","22.70062","95.15293","-0.00245","199.11218"
"2259.40210","0.89323","22.80268","95.41250","-0.00271","200.00745"
"2267.80200","0.88250","23.06058","95.65936","-0.00281","202.26953"
"2276.20190","0.83676","22.82778","95.98743","-0.00327","200.22760"
"2284.60205","0.78259","22.74708","96.25610","-0.00380","199.51973"
"2293.00195","0.76736","22.79757","96.55081","-0.00395","199.96263"
"2301.40210","0.73994","22.92062","96.82167","-0.00422","201.04189"
"2309.80200","0.67812","22.78227","97.12463","-0.00483","199.82841"
"2318.20190","0.64644","22.75086","97.39609","-0.00515","199.55284"
"2326.60205","0.60348","22.64864","97.69418","-0.00557","198.65630"
"2335.00195","0.59764","22.82874","98.00841","-0.00563","200.23599"
"2343.40210","0.55460","22.78753","98.27260","-0.00606","199.87450"
"2351.80200","0.50707","22.74812","98.55036","-0.00653","199.52884"
"2360.20190","0.49939","22.93265","98.83233","-0.00660","201.14737"
"2368.60205","0.45072","22.82106","99.07877","-0.00708","200.16859"
"2377.00195","0.40347","22.74144","99.32263","-0.00755","199.47021"
"2385.40210","0.37331","22.65346","99.60265","-0.00785","198.69858"
"2393.80200","0.33799","22.74631","99.87601","-0.00820","199.51295"
"2402.20190","0.30474","22.91643","100.17266","-0.00853","201.00516"
"2410.60205","0.25689","22.65942","100.47515","-0.00900","198.75081"
"2419.00195","0.20991","22.68112","100.75107","-0.00946","198.94115"
"2427.40210","0.19189","22.87626","100.99609","-0.00964","200.65277"
"2435.80200","0.13401","22.70303","101.33467","-0.01021","199.13332"
"2444.20190","0.10608","22.88249","101.59570","-0.01049","200.70747"
"2452.60205","0.05673","22.79607","101.84743","-0.01098","199.94945"
"2461.00195","0.01477","22.84736","102.14251","-0.01139","200.39929"
"2469.40210","-0.01643","22.78488","102.40435","-0.01170","199.85129"
"2477.80200","-0.04274","22.90334","102.67937","-0.01196","200.89030"
"2486.20190","-0.09954","22.74999","102.94686","-0.01252","199.54521"
"2494.60205","-0.13037","23.00465","103.22877","-0.01283","201.77893"
"2503.00195","-0.21197","22.62272","103.50010","-0.01363","198.42894"
"2511.40210","-0.22200","22.98048","103.80126","-0.01373","201.56691"
"2519.80200","-0.28685","22.68893","104.11606","-0.01437","199.00966"
"2528.20190","-0.32287","22.77034","104.38061","-0.01473","199.72375"
"2536.60205","-0.37321","22.87741","104.68831","-0.01523","200.66286"
"2545.00195","-0.41877","22.79239","104.96262","-0.01568","199.91714"
"2553.40210","-0.46806","22.76277","105.21386","-0.01616","199.65738"
"2561.80200","-0.48146","22.99642","105.50063","-0.01630","201.70673"
"2570.20190","-0.56493","22.68070","105.76099","-0.01712","198.93750"
"2578.60205","-0.57652","23.01015","106.04124","-0.01724","201.82718"
"2587.00195","-0.62806","22.73771","106.30045","-0.01775","199.43752"
"2595.40210","-0.76378","22.57431","106.59277","-0.01909","198.00429"
"2603.80200","-0.76374","22.79561","106.89397","-0.01909","199.94543"
"2612.20190","-0.76421","23.15947","107.17894","-0.01909","203.13689"
"2620.60205","-0.87358","22.60332","107.43295","-0.02017","198.25876"
"2629.00195","-0.94220","22.72705","107.76726","-0.02085","199.34399"
"2637.40210","-0.94280","22.92271","108.02476","-0.02086","201.06026"
"2645.80200","-1.00210","22.73514","108.29999","-0.02144","199.41501"
"2654.20190","-1.05138","22.77977","108.54260","-0.02193","199.80643"
"2662.60205","-1.08809","22.85044","108.80308","-0.02229","200.42632"
"2671.00195","-1.16382","22.70447","109.11700","-0.02304","199.14600"
"2679.40210","-1.20263","22.86262","109.38294","-0.02342","200.53311"
"2687.80200","-1.25172","22.78876","109.60789","-0.02391","199.88533"
"2696.20190","-1.31481","22.76431","109.87081","-0.02453","199.67081"
"2704.60205","-1.35806","22.91325","110.17297","-0.02496","200.97726"
"2713.00195","-1.43068","22.80692","110.47636","-0.02568","200.04463"
"2721.40210","-1.48708","22.81590","110.75577","-0.02624","200.12340"
"2729.80200","-1.55921","22.65717","111.06557","-0.02695","198.73109"
"2738.20190","-1.60401","22.83030","111.32419","-0.02739","200.24966"
"2746.60205","-1.68812","22.79841","111.66064","-0.02822","199.96992"
"2755.00195","-1.72985","22.84216","111.88328","-0.02864","200.35373"
"2763.40210","-1.78482","22.95099","112.19353","-0.02918","201.30829"
"2771.80200","-1.86142","22.78673","112.48491","-0.02994","199.86754"
"2780.20190","-1.92320","22.69365","112.77643","-0.03055","199.05107"
"2788.60205","-1.96357","22.84372","112.99702","-0.03095","200.36736"
"2797.00195","-2.01864","22.90106","113.30315","-0.03149","200.87029"
"2805.40210","-2.07032","22.88273","113.54013","-0.03200","200.70953"
"2813.80200","-2.15512","22.74459","113.87986","-0.03284","199.49786"
"2822.20190","-2.22188","22.86261","114.10746","-0.03350","200.53305"
"2830.60205","-2.29189","22.69153","114.42222","-0.03419","199.03249"
"2839.00195","-2.35161","22.90489","114.67884","-0.03478","200.90393"
"2847.40210","-2.40665","22.80221","114.97758","-0.03533","200.00327"
"2855.80200","-2.45313","22.91767","115.25204","-0.03579","201.01604"
"2864.20190","-2.54244","22.64971","115.50667","-0.03667","198.66563"
"2872.60205","-2.59824","22.66718","115.74854","-0.03722","198.81886"
"2881.00195","-2.63368","22.78934","115.96375","-0.03757","199.89043"
"2889.40210","-2.71704","22.76488","116.30066","-0.03839","199.67587"
"2897.80200","-2.80365","22.63824","116.63211","-0.03925","198.56505"
"2906.20190","-2.86375","22.76127","116.94105","-0.03984","199.64417"
"2914.60205","-2.92279","22.81965","117.23391","-0.04043","200.15630"
"2923.00195","-2.98717","22.78793","117.54632","-0.04106","199.87799"
"2931.40210","-3.05244","22.73998","117.82307","-0.04171","199.45743"
"2939.80200","-3.09105","22.85855","118.05078","-0.04209","200.49745"
"2948.20190","-3.16434","22.65856","118.33553","-0.04282","198.74333"
"2956.60205","-3.19974","22.87617","118.59679","-0.04317","200.65204"
"2965.00195","-3.25693","22.71434","118.81979","-0.04373","199.23253"
"2973.40210","-3.30515","22.82652","119.07046","-0.04421","200.21649"
"2981.80200","-3.37735","22.81774","119.39584","-0.04492","200.13953"
"2990.20190","-3.43556","22.88835","119.73037","-0.04550","200.75883"
"2998.60205","-3.51117","22.76472","120.04243","-0.04624","199.67442"
"3007.00195","-3.56608","22.80150","120.29169","-0.04679","199.99704"
"3015.40210","-3.60061","22.89248","120.51022","-0.04713","200.79504"
"3023.80200","-3.67039","22.72035","120.83852","-0.04782","199.28523"
"3032.20190","-3.71182","22.75329","121.06583","-0.04823","199.57417"
"3040.60205","-3.76944","22.85173","121.35293","-0.04880","200.43764"
"3049.00195","-3.80986","22.87811","121.61205","-0.04920","200.66905"
"3057.40210","-3.87121","22.84062","121.90033","-0.04980","200.34016"
"3065.80200","-3.95379","22.55340","122.17228","-0.05062","197.82089"
"3074.20190","-3.99834","22.83040","122.50626","-0.05106","200.25056"
"3082.60205","-4.04948","22.74228","122.80858","-0.05157","199.47766"
"3091.00195","-4.08371","22.86367","123.10375","-0.05190","200.54233"
"3099.40210","-4.13818","22.75417","123.36385","-0.05244","199.58189"
"3107.80200","-4.15157","23.00161","123.58963","-0.05257","201.75229"
"3116.20190","-4.22813","22.79721","123.91614","-0.05333","199.95943"
"3124.60205","-4.25320","22.81928","124.20533","-0.05358","200.15302"
"3133.00195","-4.28938","22.85117","124.48235","-0.05394","200.43268"
"3141.40210","-4.34174","22.70489","124.70110","-0.05445","199.14967"
"3149.80200","-4.36902","22.70305","124.99112","-0.05472","199.13356"
"3158.20190","-4.38302","22.83127","125.12663","-0.05486","200.25818"
"3166.60205","-4.38403","22.90185","125.19737","-0.05487","200.87726"
"3175.00195","-4.40954","22.56916","125.18375","-0.05512","197.95915"
"3183.40210","-4.41659","22.57836","125.10703","-0.05519","198.03983"
"3191.80200","-4.41650","22.62979","125.05298","-0.05519","198.49098"
"3200.20190","-4.41634","22.68297","124.98789","-0.05519","198.95738"
"3208.60205","-4.41609","22.69772","124.90807","-0.05519","199.08675"
"3217.00195","-4.41583","22.61345","124.76655","-0.05519","198.34760"
"3225.40210","-4.41513","22.43014","124.56454","-0.05518","196.73979"
"3233.80200","-4.36562","22.91771","124.30924","-0.05469","201.01639"
"3242.20190","-4.33865","23.09749","124.03219","-0.05442","202.59325"
"3250.60205","-4.33878","22.84983","123.78515","-0.05442","200.42099"
"3259.00195","-4.33877","22.76011","123.41382","-0.05442","199.63403"
"3267.40210","-4.33869","22.57211","123.08903","-0.05442","197.98502"
"3275.80200","-4.33821","22.49198","122.75494","-0.05442","197.28221"
"3284.20190","-4.29609","22.85738","122.50770","-0.05400","200.48723"
"3292.60205","-4.27341","22.99398","122.34063","-0.05378","201.68530"
"3301.00195","-4.27352","22.91439","122.05357","-0.05378","200.98721"
"3309.40210","-4.27357","22.81769","121.78954","-0.05378","200.13908"
"3317.80200","-4.27353","22.64438","121.60651","-0.05378","198.61893"
"3326.20190","-4.27342","22.60714","121.37994","-0.05378","198.29224"
"3334.60205","-4.23894","22.90650","121.07330","-0.05344","200.91803"
"3343.00195","-4.22342","22.83696","120.77106","-0.05328","200.30804"
"3351.40210","-4.22140","22.73443","120.54025","-0.05326","199.40874"
"3359.80200","-4.17736","23.10854","120.26944","-0.05283","202.69017"
"3368.20190","-4.17745","22.85534","119.94875","-0.05283","200.46927"
"3376.60205","-4.17750","22.78203","119.66669","-0.05283","199.82631"
"3385.00195","-4.17742","22.69388","119.42561","-0.05283","199.05312"
"3393.40210","-4.17696","22.49424","119.15125","-0.05283","197.30197"
"3401.80200","-4.13475","22.89608","118.91437","-0.05241","200.82666"
"3410.20190","-4.13164","22.75773","118.54936","-0.05238","199.61316"
"3418.60205","-4.08424","23.07648","118.25850","-0.05191","202.40895"
"3427.00195","-4.08049","23.02387","118.04980","-0.05187","201.94748"
"3435.40210","-4.08055","22.77285","117.77589","-0.05187","199.74574"
"3443.80200","-4.08046","22.66434","117.46156","-0.05187","198.79402"
"3452.20190","-4.08014","22.50377","117.17264","-0.05187","197.38564"
"3460.60205","-4.03691","22.86266","116.90174","-0.05144","200.53352"
"3469.00195","-4.03185","22.65811","116.63969","-0.05139","198.73933"
"3477.40210","-3.98328","23.02124","116.33771","-0.05091","201.92448"
"3485.80200","-3.98339","22.81447","116.02668","-0.05091","200.11084"
"3494.20190","-3.98342","22.69784","115.78908","-0.05091","199.08780"
"3502.60205","-3.98327","22.54475","115.47543","-0.05091","197.74503"
"3511.00195","-3.94558","22.96933","115.22101","-0.05054","201.46913"
"3519.40210","-3.93594","22.84112","114.93978","-0.05044","200.34456"
"3527.80200","-3.91507","22.89224","114.66357","-0.05024","200.79292"
"3536.20190","-3.88264","23.00114","114.41837","-0.04992","201.74817"
"3544.60205","-3.88273","22.81207","114.11366","-0.04992","200.08977"
"3553.00195","-3.88269","22.63435","113.83495","-0.04992","198.53094"
"3561.40210","-3.87803","22.53685","113.53277","-0.04987","197.67577"
"3569.80200","-3.83787","22.74234","113.22816","-0.04947","199.47818"
"3578.20190","-3.78152","23.27175","112.91205","-0.04892","204.12169"
"3586.60205","-3.78170","22.99968","112.67166","-0.04892","201.73529"
"3595.00195","-3.78178","22.87928","112.35462","-0.04892","200.67928"
"3603.40210","-3.78173","22.61440","112.15115","-0.04892","198.35594"
"3611.80200","-3.78144","22.38537","111.85539","-0.04892","196.34708"
"3620.20190","-3.73325","22.88846","111.56213","-0.04844","200.75977"
"3628.60205","-3.69340","23.14942","111.32217","-0.04805","203.04875"
"3637.00195","-3.69346","22.92348","111.05921","-0.04805","201.06693"
"3645.40210","-3.69336","22.69828","110.80691","-0.04804","199.09169"
"3653.80200","-3.65057","22.92888","110.49266","-0.04762","201.11433"
"3662.20190","-3.63511","22.83824","110.12476","-0.04747","200.31934"
"3670.60205","-3.58965","23.04748","109.82736","-0.04702","202.15456"
"3679.00195","-3.58972","22.78611","109.56847","-0.04702","199.86209"
"3687.40210","-3.58964","22.64631","109.28798","-0.04702","198.63589"
"3695.80200","-3.56939","22.63411","108.99904","-0.04682","198.52885"
"3704.20190","-3.52971","22.89217","108.71803","-0.04643","200.79233"
"3712.60205","-3.50730","22.83824","108.43547","-0.04621","200.31932"
"3721.00195","-3.50682","22.70992","108.14554","-0.04620","199.19377"
"3729.40210","-3.46169","22.96664","107.91256","-0.04575","201.44553"
"3737.80200","-3.45963","22.61313","107.63315","-0.04573","198.34480"
"3746.20190","-3.40913","23.01537","107.33968","-0.04524","201.87292"
"3754.60205","-3.40163","22.84585","107.06409","-0.04516","200.38608"
"3763.00195","-3.40158","22.62858","106.81110","-0.04516","198.48033"
"3771.40210","-3.40143","22.48859","106.55139","-0.04516","197.25247"
"3779.80200","-3.32677","23.10290","106.27934","-0.04442","202.64073"
"3788.20190","-3.25843","23.23310","106.00639","-0.04375","203.78276"
"3796.60205","-3.25868","23.07837","105.73949","-0.04375","202.42555"
"3805.00195","-3.25904","23.01726","105.53089","-0.04375","201.88953"
"3813.40210","-3.25908","22.73605","105.27302","-0.04375","199.42300"
"3821.80200","-3.25894","22.54006","105.01572","-0.04375","197.70393"
"3830.20190","-3.25866","22.43412","104.77072","-0.04375","196.77464"
"3838.60205","-3.17195","23.03100","104.55100","-0.04289","202.01009"
"3847.00195","-3.14334","22.97220","104.26945","-0.04261","201.49431"
"3855.40210","-3.14340","22.85662","104.07090","-0.04261","200.48055"
"3863.80200","-3.14337","22.62758","103.86557","-0.04261","198.47154"
"3872.20190","-3.14320","22.58529","103.64742","-0.04261","198.10062"
"3880.60205","-3.07059","23.00800","103.44174","-0.04189","201.80830"
"3889.00195","-3.06990","22.73832","103.24332","-0.04188","199.44292"
"3897.40210","-3.06878","22.59743","103.00578","-0.04187","198.20709"
"3905.80200","-3.01278","22.96158","102.81698","-0.04132","201.40112"
"3914.20190","-3.00076","22.89390","102.58917","-0.04120","200.80751"
"3922.60205","-3.00065","22.80284","102.39566","-0.04120","200.00877"
"3931.00195","-2.98369","22.72809","102.20298","-0.04103","199.35318"
"3939.40210","-2.96703","22.75800","102.02283","-0.04087","199.61548"
"3947.80200","-2.90994","23.06124","101.82210","-0.04030","202.27530"
"3956.20190","-2.90884","22.72642","101.64105","-0.04029","199.33852"
"3964.60205","-2.90868","22.58045","101.43234","-0.04029","198.05818"
"3973.00195","-2.87732","22.82813","101.24759","-0.03998","200.23059"
"3981.40210","-2.84796","22.83516","101.05097","-0.03969","200.29225"
"3989.80200","-2.82245","22.76073","100.86211","-0.03944","199.63947"
"3998.20190","-2.82048","22.59584","100.61713","-0.03942","198.19321"
"4006.60205","-2.78027","22.79790","100.40733","-0.03902","199.96545"
"4015.00195","-2.77464","22.70755","100.27129","-0.03896","199.17299"
"4023.40210","-2.71631","22.94879","100.05257","-0.03839","201.28900"
"4031.80200","-2.71447","22.70876","99.85992","-0.03837","199.18362"
"4040.20190","-2.69169","22.71311","99.63390","-0.03814","199.22176"
"4048.60205","-2.67465","22.66257","99.42537","-0.03798","198.77849"
"4057.00195","-2.61123","22.95440","99.18906","-0.03735","201.33815"
"4065.40210","-2.60458","22.85198","98.98639","-0.03728","200.43985"
"4073.80200","-2.58993","22.72575","98.74783","-0.03714","199.33267"
"4082.20190","-2.52330","23.01098","98.49331","-0.03648","201.83444"
"4090.60205","-2.50596","22.79702","98.21951","-0.03631","199.95776"
"4099.00195","-2.49103","22.72655","98.00948","-0.03616","199.33966"
"4107.40186","-2.45793","22.79194","97.75945","-0.03583","199.91322"
"4115.80176","-2.42982","22.79009","97.47651","-0.03556","199.89694"
"4124.20215","-2.38759","22.76565","97.22218","-0.03514","199.68257"
"4132.60205","-2.32932","22.94275","96.93093","-0.03456","201.23601"
"4141.00195","-2.28863","22.79493","96.60006","-0.03416","199.93941"
"4149.40186","-2.23960","22.93934","96.29328","-0.03368","201.20612"
"4157.80176","-2.17191","23.13245","95.98514","-0.03301","202.89990"
"4166.20215","-2.13848","22.78314","95.64111","-0.03268","199.83598"
"4174.60205","-1.99222","23.43430","95.30758","-0.03123","205.54750"
"4183.00195","-1.99167","22.63307","94.83681","-0.03122","198.51973"
"4191.40186","-1.91947","22.89272","94.46836","-0.03051","200.79720"
"4199.80176","-1.85460","22.56210","94.09383","-0.02987","197.89723"
"4208.20215","-1.80297","22.31994","93.67723","-0.02936","195.77318"
"4216.60205","-1.69831","22.50719","93.19753","-0.02832","197.41562"
"4225.00195","-1.61961","22.77655","92.76067","-0.02755","199.77824"
"4233.40186","-1.51467","22.90356","92.22788","-0.02651","200.89223"
"4241.80176","-1.43373","23.00694","91.69834","-0.02571","201.79901"
"4250.20215","-1.38343","23.05102","91.25101","-0.02521","202.18567"
"4258.60205","-1.25584","23.44234","90.74625","-0.02395","205.61803"
"4267.00195","-1.20034","23.02358","90.30026","-0.02340","201.94501"
"4275.40186","-1.13058","23.05989","89.78416","-0.02271","202.26349"
"4283.80176","-1.04058","23.36914","89.32648","-0.02182","204.97597"
"4292.20215","-0.98369","23.30784","88.90679","-0.02126","204.43831"
"4300.60205","-0.94355","22.97811","88.54632","-0.02086","201.54611"
"4309.00195","-0.90643","22.85045","88.21126","-0.02050","200.42639"
"4317.40186","-0.85115","22.78968","87.86647","-0.01995","199.89336"
"4325.80176","-0.74825","22.97139","87.46391","-0.01893","201.48718"
"4334.20215","-0.73616","22.47745","87.08681","-0.01881","197.15472"
"4342.60205","-0.64828","22.65203","86.82131","-0.01795","198.68599"
"4351.00195","-0.60315","22.54768","86.47638","-0.01750","197.77071"
"4359.40186","-0.50669","22.77121","86.07611","-0.01655","199.73134"
"4367.80176","-0.47922","22.53050","85.81315","-0.01627","197.62004"
"4376.20215","-0.44932","22.15400","85.51324","-0.01598","194.31764"
"4384.60205","-0.36871","22.33980","85.16177","-0.01518","195.94742"
"4393.00195","-0.34434","22.07259","84.78748","-0.01494","193.60361"
"4401.40186","-0.26357","22.15700","84.37895","-0.01414","194.34401"
"4409.80176","-0.23371","22.13718","84.06706","-0.01385","194.17014"
"4418.20215","-0.18863","22.40637","83.79754","-0.01340","196.53125"
"4426.60205","-0.17505","22.11889","83.61781","-0.01327","194.00974"
"4435.00195","-0.11162","22.65895","83.29090","-0.01264","198.74670"
"4443.40186","-0.07600","22.66741","83.02960","-0.01229","198.82095"
"4451.80176","-0.05932","22.95157","82.72256","-0.01212","201.31337"
"4460.20215","-0.00102","23.27426","82.48978","-0.01155","204.14371"
"4468.60205","0.01942","23.39616","82.33141","-0.01135","205.21292"
"4477.00195","0.04040","23.44694","82.05389","-0.01114","205.65839"
"4485.40186","0.12329","23.66978","81.75320","-0.01032","207.61296"
"4493.80176","0.13389","23.13560","81.50629","-0.01021","202.92757"
"4502.20215","0.18525","23.28897","81.26268","-0.00971","204.27281"
"4510.60205","0.20894","22.67068","81.03613","-0.00947","198.84964"
"4519.00195","0.23598","22.37959","80.79681","-0.00920","196.29643"
"4527.40186","0.28048","22.14853","80.55512","-0.00877","194.26974"
"4535.80176","0.32587","22.27926","80.25228","-0.00832","195.41638"
"4544.20215","0.32589","22.33543","80.06343","-0.00832","195.90903"
"4552.60205","0.38025","23.01916","79.76630","-0.00778","201.90616"
"4561.00195","0.41494","23.49224","79.43452","-0.00744","206.05568"
"4569.40186","0.41514","23.16328","79.22089","-0.00743","203.17029"
"4577.80176","0.52266","23.81204","79.00551","-0.00637","208.86076"
"4586.20215","0.52283","22.91302","78.85650","-0.00637","200.97527"
"4594.60205","0.52288","22.41244","78.64348","-0.00637","196.58449"
"4603.00195","0.55156","22.25738","78.35777","-0.00609","195.22444"
"4611.40186","0.60536","22.29428","78.16866","-0.00555","195.54808"
"4619.80176","0.60556","22.01964","77.92465","-0.00555","193.13921"
"4628.20215","0.62856","22.34900","77.63958","-0.00532","196.02806"
"4636.60205","0.67409","22.70146","77.38290","-0.00487","199.11961"
"4645.00195","0.70936","23.02634","77.14548","-0.00453","201.96919"
"4653.40186","0.74409","23.51209","76.93130","-0.00418","206.22984"
"4661.80176","0.78499","23.43206","76.61153","-0.00378","205.52782"
"4670.20215","0.80146","23.21679","76.32793","-0.00362","203.63965"
"4678.60205","0.85867","23.30555","76.07704","-0.00305","204.41815"
"4687.00195","0.88031","22.92240","75.83685","-0.00284","201.05753"
"4695.40186","0.88272","22.47300","75.68952","-0.00281","197.11572"
"4703.80176","0.92497","22.47020","75.39871","-0.00239","197.09114"
"4712.20215","0.99336","22.43754","75.11762","-0.00172","196.80466"
"4720.60205","0.99659","22.11599","74.77505","-0.00169","193.98433"
"4729.00195","1.00264","22.03288","74.54493","-0.00163","193.25534"
"4737.40186","1.08191","22.82177","74.35062","-0.00084","200.17480"
"4745.80176","1.08213","22.69568","74.02399","-0.00084","199.06888"
"4754.20215","1.08231","22.51140","73.76123","-0.00084","197.45255"
"4762.60205","1.15825","23.35174","73.50224","-0.00009","204.82335"
"4771.00195","1.16486","23.24150","73.23111","-0.00002","203.85638"
"4779.40186","1.16797","23.23293","72.98569","0.00001","203.78125"
"4787.80176","1.23005","23.56218","72.74973","0.00062","206.66914"
"4796.20215","1.23677","23.26796","72.43620","0.00069","204.08852"
"4804.60205","1.27577","23.49362","72.10485","0.00107","206.06778"
"4813.00195","1.29313","23.16067","71.86002","0.00124","203.14738"
"4821.40186","1.34394","23.36601","71.57991","0.00175","204.94852"
"4829.80176","1.36729","23.18378","71.21133","0.00198","203.35013"
"4838.20215","1.38700","22.98072","70.96140","0.00217","201.56906"
"4846.60205","1.42061","22.88611","70.72647","0.00250","200.73920"
"4855.00195","1.43829","22.59342","70.38939","0.00268","198.17192"
"4863.40186","1.50653","23.04870","70.19463","0.00335","202.16534"
"4871.80176","1.57430","23.05587","69.87563","0.00402","202.22816"
"4880.20215","1.57414","22.56498","69.40768","0.00402","197.92250"
"4888.60205","1.57433","21.84465","69.04568","0.00402","191.60432"
"4897.00195","1.57531","21.64813","68.66094","0.00403","189.88062"
"4905.40186","1.84236","23.49774","68.43949","0.00667","206.10391"
"4913.80176","1.74119","22.21597","68.07765","0.00567","194.86128"
"4922.20215","1.72168","22.13945","67.79560","0.00548","194.19006"
"4930.60205","1.72225","22.20271","67.52235","0.00549","194.74489"
"4939.00195","1.77772","23.25903","67.13715","0.00603","204.01012"
"4947.40186","1.81805","23.52495","66.80109","0.00643","206.34256"
"4955.80176","1.82113","22.72255","66.51350","0.00646","199.30457"
"4964.20215","1.84075","22.58193","66.31819","0.00666","198.07118"
"4972.60205","1.85072","22.26777","66.07198","0.00676","195.31563"
"4981.00195","1.86575","22.18331","65.86050","0.00690","194.57478"
"4989.40186","1.87265","22.51993","65.72369","0.00697","197.52737"
"4997.80176","1.89644","23.15560","65.42742","0.00721","203.10294"
"5006.20215","1.91305","23.51875","65.19285","0.00737","206.28818"
"5014.60205","1.91454","23.20809","64.96880","0.00739","203.56332"
"5023.00195","1.95285","23.33833","64.72311","0.00777","204.70572"
"5031.40186","1.95654","23.05385","64.48918","0.00780","202.21043"
"5039.80176","1.96253","22.72328","64.29796","0.00786","199.31097"
"5048.20215","1.98949","22.74796","64.23525","0.00813","199.52748"
"5056.60205","2.01248","22.72478","63.96060","0.00836","199.32411"
"5065.00195","2.01251","22.50053","63.81943","0.00836","197.35716"
"5073.40186","2.01338","22.30183","63.59304","0.00836","195.61433"
"5081.80176","2.05196","22.54096","63.29150","0.00875","197.71181"
"5090.20215","2.05576","22.37069","63.09927","0.00878","196.21835"
"5098.60205","2.06860","22.34478","62.77575","0.00891","195.99104"
"5107.00195","2.10861","22.78640","62.62343","0.00931","199.86458"
"5115.40186","2.10863","22.62132","62.34663","0.00931","198.41666"
"5123.80176","2.10958","22.50436","62.01993","0.00931","197.39079"
"5132.20215","2.15001","22.84558","61.81826","0.00971","200.38371"
"5140.60205","2.15555","22.79948","61.59497","0.00977","199.97931"
"5149.00195","2.21964","23.47499","61.23884","0.01040","205.90434"
"5157.40186","2.24544","23.28817","60.86683","0.01066","204.26573"
"5165.80176","2.24533","23.02108","60.38884","0.01066","201.92308"
"5174.20215","2.24539","22.67421","60.00900","0.01066","198.88052"
"5182.60205","2.24592","22.53332","59.52126","0.01066","197.64481"
"5191.00195","2.43047","24.09743","58.79864","0.01249","211.36391"
"5199.40186","2.42915","23.56389","58.49505","0.01247","206.68413"
"5207.80176","2.35505","22.36030","58.14516","0.01174","196.12715"
"5216.20215","2.35459","22.31533","57.98191","0.01174","195.73273"
"5224.60205","2.36747","21.91238","57.79102","0.01186","192.19841"
"5233.00195","2.43699","22.67710","57.56042","0.01255","198.90587"
"5241.40186","2.43706","22.29548","57.30492","0.01255","195.55867"
"5249.80176","2.43718","22.08136","56.79213","0.01255","193.68056"
"5258.20215","2.43797","22.08667","56.60728","0.01256","193.72710"
"5266.60205","2.47010","22.64140","56.32401","0.01288","198.59276"
"5275.00195","2.49405","23.14581","55.90040","0.01312","203.01707"
"5283.40186","2.49398","23.12100","55.67620","0.01311","202.79947"
"5291.80176","2.49400","23.31310","55.40170","0.01311","204.48441"
"5300.20215","2.50271","23.11470","55.14048","0.01320","202.74417"
"5308.60205","2.53107","23.27078","54.97705","0.01348","204.11324"
"5317.00195","2.53397","22.97576","54.66904","0.01351","201.52550"
"5325.40186","2.53689","22.65814","54.35987","0.01354","198.73962"
"5333.80176","2.55029","22.66117","54.18512","0.01367","198.76614"
"5342.20215","2.56515","22.45977","53.89188","0.01382","196.99965"
"5350.60205","2.58469","22.40164","53.66316","0.01401","196.48981"
"5359.00195","2.58463","22.39523","53.46029","0.01401","196.43355"
"5367.40186","2.58462","22.62095","53.17286","0.01401","198.41344"
"5375.80176","2.58515","22.76559","52.89843","0.01402","199.68210"
"5384.20215","2.61409","23.30589","52.64890","0.01430","204.42122"
"5392.60205","2.63122","23.44526","52.28122","0.01447","205.64357"
"5401.00195","2.63162","23.15466","51.89492","0.01448","203.09471"
"5409.40186","2.63977","23.01189","51.71695","0.01456","201.84241"
"5417.80176","2.64418","22.77582","51.52947","0.01460","199.77179"
"5426.20215","2.67668","22.85117","51.31973","0.01492","200.43268"
"5434.60205","2.68453","22.63659","51.03189","0.01500","198.55063"
"5443.00195","2.68456","22.15960","50.73009","0.01500","194.36684"
"5451.40186","2.68624","22.20947","50.39383","0.01502","194.80420"
"5459.80176","2.72663","22.88125","49.88748","0.01541","200.69656"
"5468.20215","2.72833","23.28662","49.64060","0.01543","204.25214"
"5476.60205","2.72832","23.28489","49.28465","0.01543","204.23694"
"5485.00195","2.72838","23.03435","49.15091","0.01543","202.03940"
"5493.40186","2.72888","22.57078","48.88622","0.01544","197.97333"
"5501.80176","2.75323","22.70947","48.69627","0.01568","199.18979"
"5510.20215","2.77189","22.38222","48.46711","0.01586","196.31944"
"5518.60205","2.77728","22.40372","48.30582","0.01591","196.50801"
"5527.00195","2.77718","22.54722","48.14320","0.01591","197.76674"
"5535.40186","2.77724","22.43345","47.68283","0.01591","196.76880"
"5543.80176","2.79026","23.09490","47.24611","0.01604","202.57051"
"5552.20215","2.81088","23.46938","47.05329","0.01625","205.85519"
"5560.60205","2.81094","23.08504","46.80821","0.01625","202.48404"
"5569.00195","2.81131","22.69204","46.70512","0.01625","199.03697"
"5577.40186","2.83066","22.71910","46.23618","0.01644","199.27429"
"5585.80176","2.83321","22.37763","46.01820","0.01647","196.27916"
"5594.20215","2.83511","22.24229","45.75460","0.01649","195.09213"
"5602.60205","2.84320","22.34920","45.49204","0.01657","196.02986"
"5611.00195","2.86885","23.07785","45.19576","0.01682","202.42094"
"5619.40186","2.86870","23.20967","45.03156","0.01682","203.57724"
"5627.80176","2.86870","23.18398","44.60314","0.01682","203.35185"
"5636.20215","2.86878","23.17628","44.34692","0.01682","203.28435"
"5644.60205","2.86890","22.90829","44.24934","0.01682","200.93369"
"5653.00195","2.87984","22.91740","44.08718","0.01693","201.01367"
"5661.40186","2.89947","22.84283","43.66016","0.01712","200.35957"
"5669.80176","2.91382","22.91800","43.23689","0.01726","201.01888"
"5678.20215","2.91380","22.49286","43.11464","0.01726","197.28995"
"5686.60205","2.91385","22.35764","42.76479","0.01726","196.10387"
"5695.00195","2.91393","22.15446","42.46023","0.01727","194.32173"
"5703.40186","2.92075","22.39841","42.34491","0.01733","196.46147"
"5711.80176","2.92953","22.67089","42.12685","0.01742","198.85143"
"5720.20215","2.93626","22.72037","41.73077","0.01749","199.28545"
"5728.60205","2.95985","23.20123","41.34488","0.01772","203.50313"
"5737.00195","2.96285","23.44297","41.13230","0.01775","205.62352"
"5745.40186","2.96275","23.36492","40.86604","0.01775","204.93893"
"5753.80176","2.96275","23.17341","40.51196","0.01775","203.25917"
"5762.20215","2.96283","22.84376","40.27251","0.01775","200.36774"
"5770.60205","2.96307","22.78644","39.89428","0.01775","199.86496"
"5779.00195","2.98245","22.94530","39.71096","0.01794","201.25838"
"5787.40186","2.98425","22.66261","39.49293","0.01796","198.77882"
"5795.80176","2.98746","22.59466","39.15302","0.01799","198.18283"
"5804.20215","3.00376","22.56397","38.79665","0.01815","197.91367"
"5812.60205","3.00461","22.22653","38.65114","0.01816","194.95386"
"5821.00195","3.00464","22.47746","38.35835","0.01816","197.15485"
"5829.40186","3.00662","22.58390","37.94911","0.01818","198.08844"
"5837.80176","3.01973","22.96008","37.64913","0.01831","201.38799"
"5846.20215","3.01975","23.11510","37.40717","0.01831","202.74768"
"5854.60205","3.01978","23.04908","37.21304","0.01831","202.16859"
"5863.00195","3.02718","23.23555","36.72329","0.01839","203.80418"
"5871.40186","3.03327","23.14343","36.58247","0.01845","202.99622"
"5879.80176","3.03671","22.98437","36.34409","0.01848","201.60106"
"5888.20215","3.04966","23.18361","36.12998","0.01861","203.34860"
"5896.60205","3.05488","22.98181","35.83991","0.01866","201.57861"
"5905.00195","3.05490","22.95391","35.59941","0.01866","201.33392"
"5913.40186","3.05490","22.73372","35.23631","0.01866","199.40254"
"5921.80176","3.05498","22.60332","35.01026","0.01866","198.25879"
"5930.20215","3.06166","22.50908","34.60197","0.01873","197.43222"
"5938.60205","3.07448","22.49697","34.33734","0.01885","197.32594"
"5947.00195","3.07431","22.47765","34.23022","0.01885","197.15646"
"5955.40186","3.07423","22.44396","33.95601","0.01885","196.86102"
"5963.80176","3.07423","22.51881","33.71640","0.01885","197.51750"
"5972.20215","3.07428","22.58802","33.31272","0.01885","198.12456"
"5980.60205","3.07440","22.65591","32.94318","0.01885","198.72006"
"5989.00195","3.07797","22.90966","32.66172","0.01889","200.94577"
"5997.40186","3.09837","23.08124","32.44680","0.01909","202.45071"
"6005.80176","3.10031","23.31120","32.00849","0.01911","204.46774"
"6014.20215","3.10024","23.18577","31.89200","0.01911","203.36754"
"6022.60205","3.10025","23.25938","31.64888","0.01911","204.01326"
"6031.00195","3.10032","23.04084","31.26935","0.01911","202.09636"
"6039.40186","3.10048","22.97555","30.94879","0.01911","201.52368"
"6047.80176","3.11653","23.10304","30.71710","0.01927","202.64194"
"6056.20215","3.11658","23.02451","30.51245","0.01927","201.95308"
"6064.60205","3.11651","22.95125","30.35441","0.01927","201.31055"
"6073.00195","3.11642","22.91138","30.27493","0.01927","200.96080"
"6081.40186","3.11628","22.60010","30.35716","0.01927","198.23050"
"6089.80176","3.11615","22.45165","30.38275","0.01926","196.92847"
"6098.20215","3.11611","22.40612","30.19604","0.01926","196.52905"
"6106.60205","3.11607","22.65728","30.04489","0.01926","198.73210"
"6115.00195","3.11598","23.22090","29.72386","0.01926","203.67569"
"6123.40186","3.11578","23.17442","29.92991","0.01926","203.26797"
"6131.80176","3.11515","22.97569","30.13724","0.01925","201.52489"
"6140.20215","3.11274","22.64057","30.44271","0.01923","198.58548"
"6148.60205","3.09579","22.59043","30.44432","0.01906","198.14568"
"6157.00195","3.09168","23.02497","30.49384","0.01902","201.95718"
"6165.40186","3.09062","22.53265","30.90044","0.01901","197.63893"
"6173.80176","3.09049","23.11792","31.10034","0.01901","202.77242"
"6182.20215","3.09014","22.97821","31.31306","0.01901","201.54698"
"6183.20117","3.09000","23.08932","31.27987","0.01901","202.52155"