File: experimental/sma_database/results from second training/flexinol_isobaric_trained_172MPa.csv
Test : Start of hold value,"172.00000",MPa

Time,Extension,Load,Temperature: Chamber 3119-600 1 1,Tensile strain (Extension),Tensile stress
(s),(mm),(N),(C),(mm/mm),(MPa)
"0.00000","0.32852","0.73363","31.14114","0.00000","6.43487"
"8.00000","0.39454","0.91003","30.91783","0.00066","7.98207"
"16.00000","0.46135","1.49190","30.58503","0.00132","13.08575"
"24.00000","0.52793","1.71225","30.51117","0.00199","15.01854"
"32.00000","0.59451","2.57634","30.41354","0.00265","22.59767"
"40.00000","0.66115","3.22113","30.34206","0.00332","28.25327"
"48.00000","0.72795","3.73335","30.26827","0.00398","32.74601"
"56.00000","0.79460","4.34219","30.21983","0.00465","38.08630"
"64.00000","0.86110","4.93591","30.08686","0.00531","43.29395"
"72.00000","0.92794","5.51897","29.94046","0.00597","48.40808"
"80.00000","0.99465","6.26793","29.73832","0.00664","54.97740"
"88.00000","1.06117","6.87979","29.78861","0.00730","60.34420"
"96.00000","1.12784","7.48391","29.58440","0.00797","65.64304"
"104.00000","1.19462","8.05412","29.46787","0.00863","70.64449"
"112.00000","1.26137","8.73619","29.50200","0.00930","76.62708"
"120.00000","1.32781","9.15864","29.55333","0.00996","80.33247"
"128.00000","1.39444","9.55160","29.51550","0.01062","83.77921"
"136.00000","1.46135","10.00920","29.38655","0.01129","87.79292"
"144.00000","1.52795","10.43420","29.40575","0.01195","91.52072"
"152.00000","1.59451","10.65879","29.48104","0.01262","93.49062"
"160.00000","1.66120","11.23279","29.35711","0.01328","98.52531"
"168.00000","1.72793","11.80739","29.49294","0.01395","103.56529"
"176.00000","1.79461","12.45530","29.49103","0.01461","109.24823"
"184.00000","1.86122","13.04532","29.44620","0.01528","114.42341"
"192.00000","1.92785","13.65586","29.44686","0.01594","119.77859"
"200.00000","1.99468","14.39761","29.27044","0.01661","126.28467"
"208.00000","2.06119","15.14491","29.05200","0.01727","132.83936"
"216.00000","2.12781","15.50957","29.10350","0.01793","136.03792"
"224.00000","2.19461","15.91781","29.23816","0.01860","139.61868"
"232.00000","2.26133","16.25914","29.33369","0.01926","142.61255"
"240.00000","2.32786","16.74826","29.43551","0.01993","146.90271"
"248.00000","2.39443","17.66640","29.19966","0.02059","154.95595"
"256.00000","2.46130","18.57701","29.33910","0.02126","162.94315"
"264.00000","2.52797","19.08330","29.49028","0.02192","167.38388"
"272.00000","2.59451","19.43219","29.39304","0.02259","170.44405"
"279.85600","2.74195","20.37939","29.30941","0.02406","178.75215"
"287.85600","2.71498","19.59913","29.44421","0.02379","171.90833"
"295.85600","2.65915","19.06620","29.49601","0.02323","167.23387"
"303.85600","2.65970","19.61976","29.49194","0.02324","172.08928"
"311.85600","2.66032","19.19991","30.16884","0.02324","168.40671"
"319.85600","2.66064","19.75283","30.84808","0.02324","173.25647"
"327.85600","2.66059","19.92183","31.66443","0.02324","174.73882"
"335.85600","2.66046","19.88395","32.46165","0.02324","174.40652"
"343.85600","2.66025","19.89491","33.17442","0.02324","174.50272"
"351.85600","2.65971","20.14127","33.74259","0.02324","176.66357"
"359.85600","2.61191","18.85623","34.79120","0.02276","165.39224"
"367.85600","2.60898","19.39807","35.17990","0.02273","170.14478"
"375.85600","2.60909","19.50520","35.93956","0.02273","171.08449"
"383.85600","2.60915","19.55548","36.67464","0.02273","171.52551"
"391.85600","2.60913","19.75808","37.37445","0.02273","173.30255"
"399.85600","2.60902","19.79254","38.18171","0.02273","173.60481"
"407.85600","2.60056","19.92578","39.07458","0.02265","174.77344"
"415.85600","2.55374","19.35543","40.23136","0.02218","169.77084"
"423.85600","2.55365","19.69095","41.51806","0.02218","172.71375"
"431.85600","2.54834","19.83443","42.88245","0.02213","173.97223"
"439.85600","2.50521","19.36696","44.33392","0.02170","169.87198"
"447.85600","2.50531","19.67202","45.77647","0.02170","172.54770"
"455.85600","2.50526","19.73791","47.16494","0.02170","173.12560"
"463.85600","2.50468","19.92749","48.37428","0.02169","174.78851"
"471.85600","2.46349","19.49027","49.57806","0.02128","170.95352"
"479.85600","2.46161","19.49424","50.68426","0.02126","170.98836"
"487.85600","2.46155","19.67915","51.75499","0.02126","172.61020"
"495.85600","2.44743","19.61467","52.81515","0.02112","172.04468"
"503.85600","2.41424","19.43464","53.82199","0.02079","170.46558"
"511.85600","2.41433","19.58015","54.92260","0.02079","171.74191"
"519.85600","2.41430","19.76434","55.95137","0.02079","173.35744"
"527.85600","2.40948","19.79191","57.03836","0.02074","173.59926"
"535.85600","2.36803","19.39982","58.18346","0.02033","170.16014"
"543.85600","2.36151","19.59459","59.28978","0.02026","171.86855"
"551.85600","2.36000","19.73530","60.43405","0.02025","173.10277"
"559.85600","2.31202","19.31141","61.59148","0.01977","169.38472"
"567.85600","2.31206","19.59418","62.77008","0.01977","171.86494"
"575.85600","2.31192","19.78642","63.83812","0.01977","173.55107"
"583.85600","2.27646","19.63153","64.97137","0.01942","172.19250"
"591.85600","2.26310","19.62704","66.05811","0.01928","172.15317"
"599.85600","2.23502","19.55099","67.18771","0.01900","171.48608"
"607.85600","2.21337","19.52531","68.29717","0.01879","171.26085"
"615.85600","2.20689","19.78433","69.40020","0.01872","173.53281"
"623.85600","2.15462","19.39260","70.52630","0.01820","170.09682"
"631.85600","2.13988","19.60990","71.54127","0.01805","172.00278"
"639.85600","2.11526","19.69257","72.65626","0.01781","172.72794"
"647.85600","2.06915","19.61406","73.72578","0.01735","172.03934"
"655.85600","2.02851","19.51395","74.76529","0.01694","171.16122"
"663.85600","2.00231","19.84800","75.86201","0.01668","174.09128"
"671.85600","1.83397","18.59533","77.01501","0.01501","163.10376"
"679.85600","1.81691","19.12816","77.98732","0.01484","167.77739"
"687.85600","1.81708","19.77211","79.08016","0.01484","173.42561"
"695.85600","1.81509","20.53431","80.16622","0.01482","180.11101"
"703.85600","1.58313","19.25012","81.32719","0.01250","168.84709"
"711.85600","1.58298","20.00342","82.43777","0.01250","175.45447"
"719.85600","1.41075","19.23788","83.52071","0.01079","168.73972"
"727.85600","1.38944","20.01601","84.51385","0.01057","175.56490"
"735.85600","1.24557","19.57800","85.55753","0.00914","171.72298"
"743.85600","1.04824","19.16208","86.62962","0.00717","168.07491"
"751.85600","1.00232","19.77835","87.67132","0.00672","173.48035"
"759.85600","0.71313","19.19467","88.84978","0.00383","168.36070"
"767.85600","0.71068","20.30227","89.87900","0.00381","178.07579"
"775.85600","0.44756","19.55886","91.01908","0.00119","171.55513"
"783.85600","0.22035","19.46832","92.05090","-0.00108","170.76103"
"791.85600","0.00266","19.64065","93.14222","-0.00325","172.27255"
"799.85600","-0.26211","19.60676","94.25488","-0.00589","171.97527"
"807.85600","-0.52821","19.82555","95.26197","-0.00854","173.89430"
"815.85600","-0.92470","19.48504","96.39326","-0.01249","170.90761"
"823.85600","-1.23076","20.10878","97.46498","-0.01554","176.37863"
"831.85600","-1.80084","19.38256","98.52435","-0.02122","170.00873"
"839.85600","-2.31499","19.53963","99.59830","-0.02635","171.38646"
"847.85600","-2.69958","19.80226","100.72226","-0.03018","173.69003"
"855.85600","-3.10024","19.49437","101.79680","-0.03418","170.98944"
"863.85600","-3.51476","19.55691","102.90999","-0.03831","171.53802"
"871.85600","-3.75450","19.83847","103.96307","-0.04070","174.00769"
"879.85600","-4.08992","19.48881","105.00964","-0.04404","170.94070"
"887.85600","-4.41462","19.43385","106.02682","-0.04728","170.45862"
"895.85600","-4.56138","19.56536","107.00500","-0.04874","171.61217"
"903.85600","-4.79583","19.60182","108.05620","-0.05108","171.93192"
"911.85600","-4.95821","19.61582","109.10063","-0.05269","172.05475"
"919.85600","-5.14180","19.60528","110.18181","-0.05452","171.96230"
"927.85600","-5.29732","19.74613","111.30263","-0.05607","173.19771"
"935.85600","-5.53566","19.38000","112.33376","-0.05845","169.98628"
"943.85600","-5.66350","19.46505","113.43830","-0.05972","170.73228"
"951.85600","-5.83692","19.64351","114.51167","-0.06145","172.29764"
"959.85600","-5.99068","19.38108","115.64410","-0.06299","169.99576"
"967.85600","-6.12266","19.42080","116.75323","-0.06430","170.34422"
"975.85600","-6.21708","19.41253","117.82877","-0.06524","170.27165"
"983.85600","-6.34225","19.67098","118.92753","-0.06649","172.53857"
"991.85600","-6.50573","19.28747","120.10628","-0.06812","169.17470"
"999.85600","-6.52194","19.96155","121.22968","-0.06828","175.08722"
"1007.85600","-6.62138","19.63134","122.14664","-0.06927","172.19087"
"1015.85600","-6.66805","20.08093","123.23753","-0.06974","176.13434"
"1023.85600","-6.80416","19.56531","124.19626","-0.07109","171.61174"
"1031.85600","-6.80424","19.87626","124.98178","-0.07109","174.33914"
"1039.85600","-6.83652","19.39775","125.47877","-0.07142","170.14203"
"1047.85600","-6.84343","19.34538","125.58150","-0.07148","169.68265"
"1055.85600","-6.84329","19.33935","125.52464","-0.07148","169.62978"
"1063.85600","-6.84301","19.05224","125.32346","-0.07148","167.11148"
"1071.85600","-6.84215","19.03500","124.88560","-0.07147","166.96022"
"1079.85600","-6.81649","19.33109","124.63960","-0.07122","169.55736"
"1087.85600","-6.78477","19.49340","124.29485","-0.07090","170.98094"
"1095.85600","-6.66239","20.91000","123.81054","-0.06968","183.40625"
"1103.85600","-6.66250","20.49208","123.11843","-0.06968","179.74062"
"1111.85600","-6.70871","19.28627","122.27110","-0.07014","169.16417"
"1119.85600","-6.70816","18.78777","121.23162","-0.07014","164.79169"
"1127.85600","-6.67262","18.84491","120.09008","-0.06978","165.29294"
"1135.85600","-6.48587","20.48493","118.91036","-0.06792","179.67793"
"1143.85600","-6.49151","19.85459","117.80704","-0.06798","174.14900"
"1151.85600","-6.50174","19.26340","116.69094","-0.06808","168.96358"
"1159.85600","-6.50099","18.81821","115.51204","-0.06807","165.05875"
"1167.85600","-6.37503","19.79167","114.48036","-0.06682","173.59717"
"1175.85600","-6.32285","19.90781","113.45644","-0.06630","174.61584"
"1183.85600","-6.32284","19.31093","112.50842","-0.06630","169.38049"
"1191.85600","-6.29344","19.22874","111.58598","-0.06600","168.65958"
"1199.85600","-6.20457","19.69670","110.72440","-0.06512","172.76414"
"1207.85600","-6.20443","19.33258","109.91558","-0.06512","169.57040"
"1215.85600","-6.11525","19.87935","109.08379","-0.06423","174.36620"
"1223.85600","-6.11508","19.30723","108.30216","-0.06423","169.34804"
"1231.85600","-6.03215","19.92940","107.52954","-0.06340","174.80525"
"1239.85600","-6.01981","19.43006","106.83405","-0.06328","170.42543"
"1247.85600","-5.94950","19.78383","106.08504","-0.06257","173.52840"
"1255.85600","-5.91454","19.64318","105.44117","-0.06223","172.29471"
"1263.85600","-5.87193","19.65526","104.69566","-0.06180","172.40068"
"1271.85600","-5.81847","19.55369","103.92398","-0.06127","171.50977"
"1279.85600","-5.76231","19.77265","103.22649","-0.06071","173.43036"
"1287.85600","-5.72473","19.51802","102.50274","-0.06033","171.19688"
"1295.85600","-5.66283","19.71615","101.80660","-0.05972","172.93480"
"1303.85600","-5.62275","19.41990","101.09833","-0.05932","170.33630"
"1311.85600","-5.53997","19.75631","100.50342","-0.05849","173.28697"
"1319.85600","-5.50951","19.34492","99.77158","-0.05819","169.67857"
"1327.85600","-5.37392","19.60281","98.99286","-0.05684","171.94061"
"1335.85600","-5.31428","19.51719","98.17757","-0.05624","171.18968"
"1343.85600","-5.15837","19.76583","97.35236","-0.05469","173.37054"
"1351.85600","-5.01156","20.12923","96.39150","-0.05323","176.55795"
"1359.85600","-4.93254","19.25291","95.47569","-0.05244","168.87158"
"1367.85600","-4.59819","19.65967","94.31067","-0.04911","172.43936"
"1375.85600","-4.26483","19.54155","92.98814","-0.04578","171.40329"
"1383.85600","-3.92558","19.49140","91.63274","-0.04240","170.96341"
"1391.85600","-3.21294","19.94708","89.98682","-0.03530","174.96027"
"1399.85600","-2.67796","20.41581","88.27415","-0.02997","179.07164"
"1407.85600","-2.34025","19.40328","86.97826","-0.02660","170.19054"
"1415.85600","-1.58780","19.54170","85.34975","-0.01910","171.40459"
"1423.85600","-0.94379","19.64621","83.87565","-0.01268","172.32127"
"1431.85600","-0.52601","19.33996","82.28313","-0.00852","169.63509"
"1439.85600","-0.00336","20.51163","80.71715","-0.00331","179.91209"
"1447.85600","0.56310","20.38766","78.85064","0.00234","178.82477"
"1455.85600","0.77753","18.19870","77.11307","0.00448","159.62489"
"1463.85600","0.98603","18.93738","75.25063","0.00655","166.10402"
"1471.85600","0.99303","20.07584","74.11460","0.00662","176.08968"
"1479.85600","1.23522","20.37667","73.32710","0.00904","178.72832"
"1487.85600","1.23536","19.14629","72.41098","0.00904","167.93642"
"1495.85600","1.23993","18.70027","71.93877","0.00908","164.02423"
"1503.85600","1.41432","19.98707","71.36550","0.01082","175.31108"
"1511.85600","1.52980","20.32142","70.49760","0.01197","178.24376"
"1519.85600","1.65235","19.02715","69.01495","0.01319","166.89140"
"1527.85600","2.14643","18.36027","66.71162","0.01812","161.04199"
"1535.85600","2.46888","21.35394","63.38097","0.02133","187.30020"
"1543.85600","2.20277","17.66187","62.82154","0.01868","154.91620"
"1551.85600","2.39619","20.42418","61.76124","0.02061","179.14507"
"1559.85600","2.39613","20.21015","60.58257","0.02061","177.26775"
"1567.85600","2.39729","18.43884","59.79380","0.02062","161.73122"
"1575.85600","2.46921","19.10350","58.85931","0.02134","167.56104"
"1583.85600","2.50910","20.02540","57.73237","0.02173","175.64723"
"1591.85600","2.59032","20.67425","56.60432","0.02254","181.33847"
"1599.85600","2.60198","19.16212","55.84859","0.02266","168.07521"
"1607.85600","2.60533","18.81098","54.84065","0.02269","164.99530"
"1615.85600","2.69593","19.79780","53.88312","0.02360","173.65097"
"1623.85600","2.70004","20.14940","52.83786","0.02364","176.73486"
"1631.85600","2.73739","19.31431","52.16703","0.02401","169.41013"
"1639.85600","2.79873","19.27262","51.42419","0.02462","169.04442"
"1647.85600","2.86662","20.60916","49.94030","0.02530","180.76752"
"1655.85600","2.86652","19.21821","49.47019","0.02530","168.56718"
"1663.85600","2.87019","18.94233","48.18327","0.02533","166.14745"
"1671.85600","2.99986","20.66243","46.47131","0.02663","181.23479"
"1679.85600","2.99977","19.47403","45.39705","0.02662","170.81105"
"1687.85600","2.99988","18.88227","44.32647","0.02663","165.62064"
"1695.85600","3.00071","19.17503","43.63670","0.02663","168.18851"
"1703.85600","3.08080","20.47132","42.44942","0.02743","179.55855"
"1711.85600","3.08101","19.57169","41.20944","0.02743","171.66765"
"1719.85600","3.09826","18.72671","40.69034","0.02761","164.25620"
"1727.85600","3.15279","19.59990","39.55917","0.02815","171.91508"
"1735.85600","3.15264","19.91966","38.38795","0.02815","174.71980"
"1743.85600","3.15291","19.89994","37.18458","0.02815","174.54686"
"1751.85600","3.19330","19.05686","36.53085","0.02855","167.15196"
"1759.85600","3.19998","19.34218","35.60245","0.02862","169.65462"
"1767.85600","3.22231","20.13311","34.46585","0.02884","176.59201"
"1775.85600","3.24931","19.42808","33.62302","0.02911","170.40802"
"1783.85600","3.26590","19.00788","32.57272","0.02928","166.72232"
"1791.85600","3.27367","19.87853","31.31750","0.02935","174.35902"
"1799.85600","3.27334","20.01300","31.39887","0.02935","175.53848"
"1807.85600","3.27296","20.31890","31.24802","0.02935","178.22159"
"1815.85600","3.27287","19.96513","30.77938","0.02935","175.11865"
"1823.85600","3.27222","19.91637","30.82782","0.02934","174.69096"
"1831.85600","3.27124","19.51891","30.72409","0.02933","171.20468"
"1839.85600","3.26921","19.38413","30.42494","0.02931","170.02254"
"1847.85600","3.26285","19.17197","30.54145","0.02925","168.16167"
"1855.85600","3.26106","19.24044","30.79178","0.02923","168.76219"
"1863.85600","3.23124","19.00741","30.94032","0.02893","166.71828"
"1871.85600","3.23092","19.37528","31.84862","0.02893","169.94495"
"1879.85600","3.23079","19.61587","32.61498","0.02893","172.05519"
"1887.85600","3.20702","19.95796","33.22287","0.02869","175.05571"
"1895.85600","3.18833","19.50022","33.96976","0.02850","171.04077"
"1903.85600","3.18860","19.14749","34.78200","0.02851","167.94688"
"1911.85600","3.18849","19.87633","35.56657","0.02851","174.33971"
"1919.85600","3.18838","19.81087","36.33657","0.02850","173.76555"
"1927.85600","3.17486","20.04881","37.14817","0.02837","175.85255"
"1935.85600","3.13771","19.12261","37.97218","0.02800","167.72867"
"1943.85600","3.13655","19.54223","38.63234","0.02799","171.40930"
"1951.85600","3.13651","19.58364","39.39991","0.02799","171.77251"
"1959.85600","3.12239","19.36615","40.39732","0.02785","169.86484"
"1967.85600","3.08660","19.35026","41.13465","0.02749","169.72542"
"1975.85600","3.08486","19.29408","41.82998","0.02747","169.23273"
"1983.85600","3.08501","19.62294","42.58927","0.02747","172.11716"
"1991.85600","3.08499","19.66086","43.36966","0.02747","172.44980"
"1999.85600","3.08479","19.82374","44.05691","0.02747","173.87843"
"2007.85600","3.06987","19.93828","44.88734","0.02732","174.88310"
"2015.85600","3.02915","19.45549","45.86865","0.02692","170.64848"
"2023.85600","3.02545","19.82997","47.05064","0.02688","173.93307"
"2031.85600","2.98142","19.49043","48.19133","0.02644","170.95496"
"2039.85600","2.98133","19.83627","49.61240","0.02644","173.98834"
"2047.85600","2.93383","19.41957","51.07028","0.02597","170.33334"
"2055.85600","2.93195","19.79672","52.49597","0.02595","173.64143"
"2063.85600","2.88710","19.42204","53.88112","0.02550","170.35510"
"2071.85600","2.88709","19.78003","55.12360","0.02550","173.49506"
"2079.85600","2.87153","19.70100","56.40183","0.02535","172.80188"
"2087.85600","2.84151","19.65650","57.53214","0.02505","172.41159"
"2095.85600","2.79382","19.22880","58.71165","0.02457","168.66013"
"2103.85600","2.79386","19.56633","59.83727","0.02457","171.62064"
"2111.85600","2.79355","19.87270","60.98982","0.02457","174.30786"
"2119.85600","2.74518","19.61165","62.09325","0.02409","172.01817"
"2127.85600","2.70677","19.35488","63.20329","0.02370","169.76599"
"2135.85600","2.69292","19.59347","64.29107","0.02357","171.85867"
"2143.85600","2.68855","19.85950","65.33995","0.02352","174.19212"
"2151.85600","2.60836","19.26188","66.49641","0.02272","168.95026"
"2159.85600","2.60330","19.75322","67.64441","0.02267","173.25993"
"2167.85600","2.56069","19.59843","68.78814","0.02225","171.90218"
"2175.85600","2.50336","19.51087","69.97333","0.02168","171.13417"
"2183.85600","2.49076","19.90560","71.08482","0.02155","174.59647"
"2191.85600","2.40038","19.55562","72.11472","0.02065","171.52670"
"2199.85600","2.37463","19.65306","73.23143","0.02039","172.38136"
"2207.85600","2.29480","19.79591","74.37138","0.01960","173.63438"
"2215.85600","2.21812","19.58792","75.48705","0.01883","171.81000"
"2223.85600","2.14951","19.79334","76.64649","0.01815","173.61180"
"2231.85600","2.05773","19.56087","77.75938","0.01724","171.57274"
"2239.85600","1.98711","19.79449","78.88065","0.01653","173.62192"
"2247.85600","1.89971","19.74325","79.87695","0.01566","173.17242"
"2255.85600","1.77054","19.44951","80.94546","0.01437","170.59604"
"2263.85600","1.69070","19.67961","82.00063","0.01358","172.61421"
"2271.85600","1.56957","19.53696","83.08864","0.01237","171.36308"
"2279.85600","1.40855","19.55363","84.20689","0.01076","171.50926"
"2287.85600","1.33901","19.94504","85.34109","0.01007","174.94238"
"2295.85600","1.12679","19.44044","86.42439","0.00796","170.51648"
"2303.85600","0.90623","18.87328","87.43081","0.00576","165.54178"
"2311.85600","0.84688","19.87223","88.50408","0.00517","174.30374"
"2319.85600","0.67625","19.68200","89.68584","0.00347","172.63524"
"2327.85600","0.44974","19.65863","90.82095","0.00121","172.43022"
"2335.85600","0.23921","19.68125","91.91734","-0.00089","172.62865"
"2343.85600","-0.03567","19.44283","92.97765","-0.00363","170.53741"
"2351.85600","-0.26699","19.79669","94.01966","-0.00594","173.64120"
"2359.85600","-0.59516","19.60114","95.02188","-0.00921","171.92603"
"2367.85600","-0.94995","19.49642","96.11205","-0.01274","171.00749"
"2375.85600","-1.38732","19.48882","97.25332","-0.01710","170.94077"
"2383.85600","-1.72528","19.88293","98.31617","-0.02047","174.39764"
"2391.85600","-2.21430","19.74432","99.34565","-0.02535","173.18184"
"2399.85600","-2.63894","19.58668","100.44696","-0.02958","171.79916"
"2407.85600","-3.03203","19.75517","101.55465","-0.03350","173.27702"
"2415.85600","-3.43880","19.43300","102.56127","-0.03755","170.45119"
"2423.85600","-3.67267","19.82786","103.68716","-0.03988","173.91463"
"2431.85600","-4.00029","19.51470","104.79668","-0.04315","171.16779"
"2439.85600","-4.23719","19.66169","105.87446","-0.04551","172.45711"
"2447.85600","-4.52891","19.57457","106.98259","-0.04842","171.69293"
"2455.85600","-4.73001","19.50519","108.10120","-0.05042","171.08435"
"2463.85600","-4.88706","19.72766","109.16614","-0.05199","173.03571"
"2471.85600","-5.06920","19.60496","110.16244","-0.05380","171.95950"
"2479.85600","-5.21000","19.63921","111.17422","-0.05520","172.25989"
"2487.85600","-5.36075","19.75865","112.13583","-0.05671","173.30757"
"2495.85600","-5.54818","19.45746","113.25761","-0.05857","170.66576"
"2503.85600","-5.67773","19.64631","114.36710","-0.05987","172.32213"
"2511.85600","-5.83752","19.53223","115.42960","-0.06146","171.32158"
"2519.85600","-5.95598","19.55223","116.45895","-0.06264","171.49695"
"2527.85600","-6.08584","19.64199","117.60741","-0.06393","172.28433"
"2535.85600","-6.13566","19.90934","118.60904","-0.06443","174.62929"
"2543.85600","-6.25827","19.64386","119.66242","-0.06565","172.30072"
"2551.85600","-6.35577","19.69696","120.73229","-0.06662","172.76640"
"2559.85600","-6.50667","19.27330","121.84703","-0.06813","169.05043"
"2567.85600","-6.50670","19.94860","122.88895","-0.06813","174.97366"
"2575.85600","-6.60909","19.37118","123.87297","-0.06915","169.90897"
"2583.85600","-6.64885","19.66889","124.71114","-0.06955","172.52022"
"2591.85600","-6.65240","19.70093","125.36748","-0.06958","172.80128"
"2599.85600","-6.69327","19.12056","125.66501","-0.06999","167.71069"
"2607.85600","-6.69298","19.11592","125.69292","-0.06999","167.67004"
"2615.85600","-6.69208","19.14551","125.53905","-0.06998","167.92957"
"2623.85600","-6.63415","19.64644","125.23864","-0.06940","172.32332"
"2631.85600","-6.59004","20.14126","124.86842","-0.06896","176.66351"
"2639.85600","-6.59064","19.86325","124.43519","-0.06897","174.22496"
"2647.85600","-6.59096","19.49072","123.88566","-0.06897","170.95747"
"2655.85600","-6.59075","19.14141","123.14006","-0.06897","167.89355"
"2663.85600","-6.55549","19.01563","122.18147","-0.06861","166.79037"
"2671.85600","-6.43952","20.07782","121.11976","-0.06746","176.10704"
"2679.85600","-6.43967","19.43542","120.05809","-0.06746","170.47240"
"2687.85600","-6.43926","19.00737","118.96131","-0.06746","166.71790"
"2695.85600","-6.33022","19.94402","117.92735","-0.06637","174.93349"
"2703.85600","-6.32610","19.49636","116.84764","-0.06633","171.00694"
"2711.85600","-6.26841","19.69343","115.79325","-0.06575","172.73547"
"2719.85600","-6.23978","19.50329","114.74110","-0.06547","171.06775"
"2727.85600","-6.21302","19.34961","113.78166","-0.06520","169.71977"
"2735.85600","-6.12995","19.88604","112.82966","-0.06437","174.42490"
"2743.85600","-6.11848","19.50834","112.04916","-0.06426","171.11197"
"2751.85600","-6.06568","19.73472","111.17574","-0.06373","173.09767"
"2759.85600","-6.04106","19.48644","110.34119","-0.06349","170.91992"
"2767.85600","-5.90689","20.45979","109.56549","-0.06215","179.45744"
"2775.85600","-5.90752","19.94179","108.78046","-0.06216","174.91393"
"2783.85600","-5.90786","19.50025","108.00127","-0.06216","171.04106"
"2791.85600","-5.90755","19.20321","107.27451","-0.06216","168.43567"
"2799.85600","-5.89365","18.87171","106.58798","-0.06202","165.52802"
"2807.85600","-5.74383","19.80984","105.91026","-0.06052","173.75655"
"2815.85600","-5.74372","19.51687","105.22813","-0.06052","171.18683"
"2823.85600","-5.67713","19.70040","104.50935","-0.05986","172.79660"
"2831.85600","-5.63167","19.53510","103.86939","-0.05941","171.34673"
"2839.85600","-5.57715","19.73418","103.11776","-0.05886","173.09288"
"2847.85600","-5.52834","19.39418","102.35673","-0.05838","170.11070"
"2855.85600","-5.44489","19.72408","101.66978","-0.05755","173.00432"
"2863.85600","-5.40193","19.40233","100.91678","-0.05712","170.18221"
"2871.85600","-5.30755","19.56185","100.12415","-0.05618","171.58133"
"2879.85600","-5.21655","19.43801","99.25692","-0.05527","170.49518"
"2887.85600","-5.07154","19.75002","98.31887","-0.05382","173.23181"
"2895.85600","-4.97576","19.35487","97.41557","-0.05287","169.76585"
"2903.85600","-4.76835","19.67367","96.25652","-0.05080","172.56218"
"2911.85600","-4.54950","19.40254","95.14721","-0.04862","170.18401"
"2919.85600","-4.18229","19.90560","93.65267","-0.04496","174.59644"
"2927.85600","-3.90475","19.28700","92.29183","-0.04219","169.17059"
"2935.85600","-3.26239","20.01199","90.63337","-0.03579","175.52962"
"2943.85600","-2.74471","19.32510","89.01832","-0.03063","169.50478"
"2951.85600","-2.51995","19.07878","87.79494","-0.02839","167.34427"
"2959.85600","-1.66641","19.74769","86.32957","-0.01988","173.21143"
"2967.85600","-1.12858","19.42071","84.71204","-0.01452","170.34335"
"2975.85600","-0.86342","19.07407","83.36929","-0.01188","167.30296"
"2983.85600","-0.19805","19.83087","81.89587","-0.00525","173.94096"
"2991.85600","0.38703","19.48377","79.94537","0.00058","170.89650"
"2999.85600","0.74862","20.88553","78.18862","0.00419","183.19170"
"3007.85600","0.74855","19.08235","76.96732","0.00419","167.37553"
"3015.85600","0.81673","18.80728","75.94839","0.00487","164.96289"
"3023.85600","0.97112","19.60226","75.06161","0.00640","171.93579"
"3031.85600","0.97105","18.85684","74.49017","0.00640","165.39758"
"3039.85600","1.03077","18.92053","73.73827","0.00700","165.95621"
"3047.85600","1.36240","19.44382","72.36735","0.01030","170.54610"
"3055.85600","2.04786","20.09361","70.04733","0.01714","176.24557"
"3063.85600","2.19076","20.31151","67.01504","0.01856","178.15683"
"3071.85600","2.05795","17.75331","65.80399","0.01724","155.71822"
"3079.85600","2.19149","19.58881","64.86891","0.01857","171.81787"
"3087.85600","2.21371","20.28180","63.92078","0.01879","177.89616"
"3095.85600","2.21389","19.99123","62.94139","0.01879","175.34753"
"3103.85600","2.31061","18.90339","62.02856","0.01976","165.80582"
"3111.85600","2.36217","19.24524","61.21045","0.02027","168.80434"
"3119.85600","2.40931","19.69350","59.89401","0.02074","172.73607"
"3127.85600","2.49341","20.48355","58.75925","0.02158","179.66577"
"3135.85600","2.50657","19.63161","57.99624","0.02171","172.19328"
"3143.85600","2.57547","18.98165","57.14087","0.02240","166.49229"
"3151.85600","2.60373","19.31784","56.13658","0.02268","169.44112"
"3159.85600","2.65356","20.18041","55.17170","0.02317","177.00685"
"3167.85600","2.70909","19.86734","54.11156","0.02373","174.26088"
"3175.85600","2.76161","19.10163","53.15346","0.02425","167.54468"
"3183.85600","2.77130","19.21885","52.53622","0.02435","168.57285"
"3191.85600","2.81546","20.09714","51.21885","0.02479","176.27654"
"3199.85600","2.87048","19.60023","50.43116","0.02534","171.91797"
"3207.85600","2.87042","19.08758","49.62259","0.02534","167.42146"
"3215.85600","2.99349","20.50163","47.73135","0.02656","179.82439"
"3223.85600","3.00988","20.38118","46.54196","0.02673","178.76788"
"3231.85600","3.00971","19.01614","46.08685","0.02672","166.79480"
"3239.85600","3.00981","18.93755","45.31200","0.02673","166.10550"
"3247.85600","3.11460","20.74334","43.63417","0.02777","181.94446"
"3255.85600","3.12232","19.92263","42.70329","0.02785","174.74583"
"3263.85600","3.12193","19.07512","41.95196","0.02784","167.31215"
"3271.85600","3.12190","19.14264","40.96021","0.02784","167.90440"
"3279.85600","3.12254","19.72884","39.42074","0.02785","173.04608"
"3287.85600","3.19355","19.78856","38.73689","0.02856","173.56993"
"3295.85600","3.19485","19.05031","38.02343","0.02857","167.09454"
"3303.85600","3.23260","20.07117","36.50988","0.02895","176.04877"
"3311.85600","3.24029","20.24817","35.64210","0.02902","177.60121"
"3319.85600","3.24058","18.81921","34.58178","0.02903","165.06750"
"3327.85600","3.28060","19.63181","33.54411","0.02942","172.19501"
"3335.85600","3.28133","20.08639","32.47814","0.02943","176.18224"
"3343.85600","3.29024","19.55171","31.69350","0.02952","171.49245"
"3351.85600","3.29035","19.13616","31.32653","0.02952","167.84750"
"3359.85600","3.29026","19.31783","30.95181","0.02952","169.44099"
"3367.85600","3.29001","19.57249","31.40737","0.02952","171.67465"
"3375.85600","3.29002","19.73164","31.04414","0.02952","173.07066"
"3383.85600","3.29009","19.89565","30.55713","0.02952","174.50923"
"3391.85600","3.29010","20.17305","30.42670","0.02952","176.94229"
"3399.85600","3.29016","20.01762","30.44331","0.02952","175.57903"
"3407.85600","3.29025","20.07446","30.20033","0.02952","176.07758"
"3415.85600","3.29002","20.08482","31.06956","0.02952","176.16847"
"3423.85600","3.28924","19.95730","31.81173","0.02951","175.04997"
"3431.85600","3.26163","19.44161","32.64454","0.02923","170.52673"
"3439.85600","3.22916","18.97526","33.37670","0.02891","166.43623"
"3447.85600","3.22924","19.55759","34.00842","0.02891","171.54398"
"3455.85600","3.22921","20.03120","34.61296","0.02891","175.69812"
"3463.85600","3.22898","19.70826","35.61535","0.02891","172.86555"
"3471.85600","3.18013","19.35446","36.44198","0.02842","169.76231"
"3479.85600","3.18036","19.41711","37.10328","0.02842","170.31184"
"3487.85600","3.18034","19.92695","37.93405","0.02842","174.78372"
"3495.85600","3.18028","19.36910","38.84605","0.02842","169.89072"
"3503.85600","3.17633","19.51485","39.60300","0.02838","171.16911"
"3511.85600","3.11198","18.74647","40.43972","0.02774","164.42949"
"3519.85600","3.11240","19.36430","41.01075","0.02775","169.84862"
"3527.85600","3.11321","19.45379","41.73125","0.02776","170.63353"
"3535.85600","3.11330","19.59813","42.69315","0.02776","171.89954"
"3543.85600","3.11318","19.79798","43.56300","0.02776","173.65253"
"3551.85600","3.11288","19.86859","44.26494","0.02775","174.27182"
"3559.85600","3.11128","20.12910","44.99907","0.02774","176.55679"
"3567.85600","3.05879","19.60786","45.82688","0.02721","171.98492"
"3575.85600","3.04475","19.59470","46.86382","0.02707","171.86946"
"3583.85600","3.02777","19.69043","48.05220","0.02690","172.70918"
"3591.85600","2.98360","19.41910","49.35312","0.02646","170.32928"
"3599.85600","2.98358","19.77039","50.79559","0.02646","173.41051"
"3607.85600","2.94197","19.45314","52.22326","0.02605","170.62781"
"3615.85600","2.93178","19.70142","53.62722","0.02595","172.80559"
"3623.85600","2.88942","19.39432","54.89528","0.02553","170.11192"
"3631.85600","2.88935","19.71897","56.24318","0.02552","172.95949"
"3639.85600","2.87231","19.79287","57.49735","0.02535","173.60767"
"3647.85600","2.84358","19.61508","58.63713","0.02507","172.04822"
"3655.85600","2.80024","19.37688","59.72876","0.02464","169.95894"
"3663.85600","2.78981","19.46478","60.83839","0.02453","170.72993"
"3671.85600","2.78970","19.80263","61.95689","0.02453","173.69325"
"3679.85600","2.74108","19.51519","62.99198","0.02405","171.17206"
"3687.85600","2.70007","19.48298","64.09667","0.02364","170.88956"
"3695.85600","2.69814","19.87220","65.21847","0.02362","174.30351"
"3703.85600","2.65396","19.59782","66.39576","0.02318","171.89688"
"3711.85600","2.60843","19.54573","67.54218","0.02272","171.43999"
"3719.85600","2.58977","19.81034","68.70049","0.02254","173.76093"
"3727.85600","2.50509","19.29109","69.85448","0.02169","169.20644"
"3735.85600","2.50323","19.95723","70.93517","0.02168","175.04929"
"3743.85600","2.40264","19.29858","72.08616","0.02067","169.27214"
"3751.85600","2.38304","19.85652","73.21681","0.02048","174.16597"
"3759.85600","2.27126","19.19719","74.35486","0.01936","168.38283"
"3767.85600","2.24490","19.74897","75.48232","0.01910","173.22260"
"3775.85600","2.14716","19.60525","76.56506","0.01813","171.96204"
"3783.85600","2.07629","19.71157","77.64249","0.01742","172.89461"
"3791.85600","1.98017","19.62876","78.64035","0.01646","172.16827"
"3799.85600","1.89162","19.79935","79.70560","0.01558","173.66451"
"3807.85600","1.76789","19.52719","80.83177","0.01435","171.27739"
"3815.85600","1.71611","20.09854","81.96931","0.01383","176.28879"
"3823.85600","1.38319","18.56539","83.10828","0.01051","162.84120"
"3831.85600","1.38370","19.52988","84.17125","0.01052","171.30093"
"3839.85600","1.38346","20.45293","85.28123","0.01051","179.39720"
"3847.85600","1.06061","18.77509","86.33896","0.00730","164.68054"
"3855.85600","1.04426","20.12305","87.41248","0.00713","176.50374"
"3863.85600","0.71165","18.83018","88.48773","0.00382","165.16376"
"3871.85600","0.68168","19.87565","89.58172","0.00352","174.33380"
"3879.85600","0.45101","19.69508","90.67143","0.00122","172.74991"
"3887.85600","0.22985","19.58729","91.72691","-0.00098","171.80452"
"3895.85600","-0.06185","19.58798","92.84879","-0.00389","171.81053"
"3903.85600","-0.31173","19.61073","93.87091","-0.00638","172.01009"
"3911.85600","-0.59955","19.68166","94.92183","-0.00925","172.63228"
"3919.85600","-0.98127","19.40278","96.04725","-0.01306","170.18614"
"3927.85600","-1.22330","19.97933","97.11780","-0.01547","175.24319"
"3935.85600","-1.90582","19.25412","98.25486","-0.02227","168.88220"
"3943.85600","-2.21857","19.99357","99.34034","-0.02539","175.36809"
"3951.85600","-2.62536","19.64750","100.41177","-0.02944","172.33260"
"3959.85600","-3.00581","19.64828","101.42194","-0.03323","172.33945"
"3967.85600","-3.38940","19.33245","102.48245","-0.03706","169.56921"
"3975.85600","-3.61531","19.78946","103.55315","-0.03931","173.57776"
"3983.85600","-3.93174","19.61639","104.64096","-0.04246","172.05972"
"3991.85600","-4.22401","19.50335","105.69744","-0.04538","171.06824"
"3999.85600","-4.42832","19.63430","106.79523","-0.04741","172.21683"
"4007.85600","-4.67417","19.43320","107.88299","-0.04986","170.45291"
"4015.85600","-4.81301","19.76216","108.92439","-0.05125","173.33829"
"4023.85600","-4.98388","19.72216","110.04977","-0.05295","172.98747"
"4031.85600","-5.14016","19.63049","111.16702","-0.05451","172.18344"
"4039.85600","-5.33745","19.46913","112.21365","-0.05647","170.76807"
"4047.85600","-5.46817","19.55080","113.24596","-0.05778","171.48441"
"4055.85600","-5.58336","19.60863","114.30106","-0.05893","171.99165"
"4063.85600","-5.75702","19.52283","115.36801","-0.06066","171.23914"
"4071.85600","-5.83595","19.87535","116.33109","-0.06144","174.33112"
"4079.85600","-5.94581","19.72338","117.40872","-0.06254","172.99818"
"4087.85600","-6.11348","19.40464","118.43473","-0.06421","170.20242"
"4095.85600","-6.21011","19.38097","119.57988","-0.06517","169.99484"
"4103.85600","-6.30063","19.19621","120.59274","-0.06607","168.37424"
"4111.85600","-6.36412","19.65816","121.70043","-0.06671","172.42609"
"4119.85600","-6.45044","19.48298","122.84939","-0.06757","170.88962"
"4127.85600","-6.50497","19.54127","123.85349","-0.06811","171.40085"
"4135.85600","-6.55303","19.61792","124.77272","-0.06859","172.07314"
"4143.85600","-6.55481","19.85424","125.39745","-0.06861","174.14601"
"4151.85600","-6.59811","19.03210","125.73850","-0.06904","166.93483"
"4159.85600","-6.59781","19.07856","125.67290","-0.06904","167.34235"
"4167.85600","-6.59495","18.93752","125.46320","-0.06901","166.10522"
"4175.85600","-6.48747","20.27396","125.13432","-0.06794","177.82747"
"4183.85600","-6.48802","20.18279","124.74207","-0.06794","177.02777"
"4191.85600","-6.49124","19.93212","124.49652","-0.06797","174.82906"
"4199.85600","-6.50597","19.64658","124.18789","-0.06812","172.32451"
"4207.85600","-6.50625","19.55279","123.78419","-0.06812","171.50189"
"4215.85600","-6.50604","19.29319","123.42976","-0.06812","169.22488"
"4223.85600","-6.50512","19.13893","122.96655","-0.06811","167.87184"
"4231.85600","-6.44720","19.71556","122.47412","-0.06754","172.92953"
"4239.85600","-6.40841","20.15178","122.03579","-0.06715","176.75577"
"4247.85600","-6.40861","19.72900","121.56624","-0.06715","173.04744"
"4255.85600","-6.40867","19.64835","121.04025","-0.06715","172.34010"
"4263.85600","-6.40852","19.29515","120.53302","-0.06715","169.24205"
"4271.85600","-6.39904","19.20213","120.01029","-0.06706","168.42621"
"4279.85600","-6.32445","19.89703","119.55123","-0.06631","174.52130"
"4287.85600","-6.32454","19.64440","119.05199","-0.06631","172.30545"
"4295.85600","-6.32453","19.41592","118.54015","-0.06631","170.30141"
"4303.85600","-6.32430","19.24700","118.05251","-0.06631","168.81972"
"4311.85600","-6.25696","19.82221","117.59058","-0.06564","173.86504"
"4319.85600","-6.24564","19.74939","117.04697","-0.06553","173.22633"
"4327.85600","-6.24565","19.58593","116.51483","-0.06553","171.79254"
"4335.85600","-6.24509","19.35482","116.02163","-0.06552","169.76546"
"4343.85600","-6.20014","19.55954","115.56657","-0.06507","171.56113"
"4351.85600","-6.16875","19.70666","115.04310","-0.06476","172.85153"
"4359.85600","-6.15125","19.56877","114.58379","-0.06459","171.64206"
"4367.85600","-6.13824","19.41296","114.01624","-0.06446","170.27541"
"4375.85600","-6.11151","19.48501","113.42834","-0.06419","170.90736"
"4383.85600","-6.07525","19.70128","112.88041","-0.06383","172.80437"
"4391.85600","-6.05116","19.50591","112.36855","-0.06359","171.09073"
"4399.85600","-6.01023","19.79480","111.79284","-0.06318","173.62459"
"4407.85600","-6.00221","19.45388","111.25905","-0.06310","170.63432"
"4415.85600","-5.90148","20.38488","110.68311","-0.06210","178.80034"
"4423.85600","-5.84306","20.56784","110.15770","-0.06151","180.40511"
"4431.85600","-5.91665","19.43667","109.69587","-0.06225","170.48341"
"4439.85600","-5.91651","19.11642","109.16362","-0.06225","167.67436"
"4447.85600","-5.91595","18.88325","108.65447","-0.06224","165.62918"
"4455.85600","-5.82053","19.95591","108.10271","-0.06129","175.03777"
"4463.85600","-5.70933","20.33631","107.59495","-0.06018","178.37433"
"4471.85600","-5.73406","19.68160","107.10214","-0.06043","172.63173"
"4479.85600","-5.76331","19.20375","106.63374","-0.06072","168.44038"
"4487.85600","-5.76208","18.94677","106.12818","-0.06071","166.18633"
"4495.85600","-5.68011","19.75257","105.69806","-0.05989","173.25417"
"4503.85600","-5.64717","19.69480","105.26286","-0.05956","172.74751"
"4511.85600","-5.62839","19.54033","104.81064","-0.05937","171.39264"
"4519.85600","-5.62084","19.50707","104.40282","-0.05930","171.10086"
"4527.85600","-5.56004","19.71861","104.00273","-0.05869","172.95638"
"4535.85600","-5.55021","19.45297","103.55981","-0.05859","170.62633"
"4543.85600","-5.52728","19.50743","103.15173","-0.05837","171.10403"
"4551.85600","-5.47706","19.71532","102.74761","-0.05787","172.92747"
"4559.85600","-5.45509","19.67863","102.34817","-0.05765","172.60570"
"4567.85600","-5.43618","19.54140","102.03456","-0.05746","171.40195"
"4575.85600","-5.41013","19.51738","101.67767","-0.05720","171.19128"
"4583.85600","-5.34201","19.86430","101.26116","-0.05652","174.23425"
"4591.85600","-5.34198","19.43959","100.87524","-0.05652","170.50897"
"4599.85600","-5.33026","19.30284","100.50022","-0.05640","169.30951"
"4607.85600","-5.24518","19.73633","100.12673","-0.05555","173.11180"
"4615.85600","-5.24448","19.49470","99.78982","-0.05555","170.99234"
"4623.85600","-5.22129","19.47873","99.41596","-0.05532","170.85225"
"4631.85600","-5.13878","19.81587","98.99041","-0.05449","173.80943"
"4639.85600","-5.12486","19.59750","98.61823","-0.05436","171.89404"
"4647.85600","-5.04159","19.90632","98.22473","-0.05353","174.60280"
"4655.85600","-5.04030","19.50095","97.81762","-0.05351","171.04723"
"4663.85600","-4.97750","19.72766","97.40546","-0.05289","173.03568"
"4671.85600","-4.94574","19.39078","96.95778","-0.05257","170.08083"
"4679.85600","-4.87812","19.52740","96.47345","-0.05190","171.27914"
"4687.85600","-4.83847","19.38718","95.99837","-0.05150","170.04932"
"4695.85600","-4.74477","19.66765","95.51249","-0.05057","172.50934"
"4703.85600","-4.66106","19.95560","95.00875","-0.04973","175.03505"
"4711.85600","-4.59107","19.41261","94.51011","-0.04903","170.27234"
"4719.85600","-4.51059","19.63049","94.04314","-0.04823","172.18343"
"4727.85600","-4.36088","19.61458","93.42152","-0.04674","172.04385"
"4735.85600","-4.16407","19.55682","92.62961","-0.04478","171.53722"
"4743.85600","-3.97646","19.58489","91.75504","-0.04291","171.78343"
"4751.85600","-3.81571","19.39809","91.00553","-0.04131","170.14500"
"4759.85600","-3.47074","20.15323","90.06278","-0.03787","176.76852"
"4767.85600","-3.22551","19.45527","89.32893","-0.03542","170.64653"
"4775.85600","-3.02193","20.26519","88.52965","-0.03339","177.75047"
"4783.85600","-2.75589","18.99670","87.77805","-0.03074","166.62430"
"4791.85600","-2.39700","20.14656","86.87795","-0.02717","176.71001"
"4799.85600","-2.11302","19.75406","86.09745","-0.02434","173.26724"
"4807.85600","-1.93186","18.86805","85.42761","-0.02253","165.49590"
"4815.85600","-1.56120","20.20507","84.62234","-0.01884","177.22322"
"4823.85600","-1.36322","19.51918","83.78081","-0.01686","171.20709"
"4831.85600","-1.11323","18.60634","83.19683","-0.01437","163.20039"
"4839.85600","-0.69485","19.39635","82.42644","-0.01020","170.12975"
"4847.85600","-0.61058","19.74534","81.75278","-0.00936","173.19078"
"4855.85600","-0.48431","20.19026","81.22967","-0.00810","177.09331"
"4863.85600","-0.22999","20.16571","80.60852","-0.00557","176.87798"
"4871.85600","-0.19373","18.86745","80.07941","-0.00521","165.49065"
"4879.85600","-0.03319","19.25461","79.44738","-0.00361","168.88649"
"4887.85600","0.08091","19.64546","78.94469","-0.00247","172.31474"
"4895.85600","0.19218","20.11195","78.33553","-0.00136","176.40640"
"4903.85600","0.30197","20.40041","77.96201","-0.00026","178.93658"
"4911.85600","0.38406","19.12379","77.61200","0.00055","167.73901"
"4919.85600","0.47577","19.04199","77.12146","0.00147","167.02156"
"4927.85600","0.56342","19.46577","76.58356","0.00234","170.73865"
"4935.85600","0.65946","20.32004","76.03683","0.00330","178.23161"
"4943.85600","0.75849","19.42793","75.52657","0.00429","170.40669"
"4951.85600","0.78235","19.04848","75.20172","0.00452","167.07852"
"4959.85600","0.87598","19.92211","74.73999","0.00546","174.74129"
"4967.85600","1.20211","20.30314","73.81277","0.00871","178.08339"
"4975.85600","1.39902","19.96211","73.01237","0.01067","175.09215"
"4983.85600","1.32817","18.87311","72.31366","0.00996","165.54028"
"4991.85600","1.33335","19.13743","71.44218","0.01002","167.85872"
"4999.85600","1.46212","20.44236","70.92309","0.01130","179.30450"
"5007.85600","1.57881","20.38583","70.32977","0.01246","178.80865"
"5015.85600","1.61304","19.59123","69.74170","0.01280","171.83910"
"5023.85600","1.66086","18.68718","69.08374","0.01328","163.90941"
"5031.85600","1.82755","18.88969","68.06722","0.01494","165.68568"
"5039.85600","1.92994","19.13895","67.23713","0.01596","167.87201"
"5047.85600","1.92978","18.91383","66.83220","0.01596","165.89742"
"5055.85600","1.93013","18.65711","66.17724","0.01596","163.64571"
"5063.85600","1.99706","19.25435","65.78289","0.01663","168.88423"
"5071.85600","2.02380","19.06892","65.33502","0.01690","167.25772"
"5079.85600","2.07267","19.50937","64.67242","0.01738","171.12109"
"5087.85600","2.09667","19.48864","64.24519","0.01762","170.93918"
"5095.85600","2.12405","19.75113","63.73595","0.01790","173.24158"
"5103.85600","2.16657","20.15453","63.35115","0.01832","176.77985"
"5111.85600","2.19961","20.12944","62.93462","0.01865","176.55978"
"5119.85600","2.25177","20.58899","62.21347","0.01917","180.59067"
"5127.85600","2.28213","20.26831","61.67117","0.01947","177.77786"
"5135.85600","2.30629","20.02432","61.30470","0.01971","175.63780"
"5143.85600","2.31613","19.67168","61.02272","0.01981","172.54469"
"5151.85600","2.41582","20.16150","60.18905","0.02080","176.84103"
"5159.85600","2.41578","19.54943","59.79548","0.02080","171.47244"
"5167.85600","2.41581","19.01251","59.63963","0.02080","166.76300"
"5175.85600","2.42157","18.59824","59.23248","0.02086","163.12929"
"5183.85600","2.50535","19.18169","58.59659","0.02170","168.24693"
"5191.85600","2.50528","18.89005","58.07045","0.02170","165.68884"
"5199.85600","2.50537","18.92034","57.55074","0.02170","165.95456"
"5207.85600","2.53569","19.46879","57.16212","0.02200","170.76508"
"5215.85600","2.57894","19.77238","56.77691","0.02243","173.42796"
"5223.85600","2.57893","19.66770","56.36178","0.02243","172.50981"
"5231.85600","2.60633","19.67374","55.67033","0.02270","172.56279"
"5239.85600","2.65323","20.39405","55.29601","0.02317","178.88074"
"5247.85600","2.65324","20.20897","54.87123","0.02317","177.25743"
"5255.85600","2.65485","19.78666","54.43261","0.02319","173.55327"
"5263.85600","2.70935","20.11500","54.07473","0.02373","176.43320"
"5271.85600","2.71080","19.64657","53.45232","0.02374","172.32449"
"5279.85600","2.76708","19.81496","53.00290","0.02431","173.80148"
"5287.85600","2.76716","19.42737","52.40544","0.02431","170.40184"
"5295.85600","2.76721","19.05384","52.15289","0.02431","167.12547"
"5303.85600","2.79441","18.68577","51.71644","0.02458","163.89703"
"5311.85600","2.86255","19.34199","50.85532","0.02526","169.65291"
"5319.85600","2.86252","19.18691","50.12651","0.02526","168.29266"
"5327.85600","2.86450","19.00435","49.52765","0.02528","166.69142"
"5335.85600","2.89424","19.38976","48.99364","0.02557","170.07196"
"5343.85600","2.94187","19.94191","48.37105","0.02605","174.91493"
"5351.85600","2.94439","19.87324","47.79409","0.02607","174.31261"
"5359.85600","2.94435","19.74179","47.41521","0.02607","173.15962"
"5367.85600","2.94453","19.83785","46.88808","0.02607","174.00218"
"5375.85600","2.98331","20.10524","46.38465","0.02646","176.34758"
"5383.85600","2.99391","20.32106","45.73366","0.02657","178.24059"
"5391.85600","2.99593","19.78330","45.43871","0.02659","173.52377"
"5399.85600","3.04831","20.25098","44.83932","0.02711","177.62590"
"5407.85600","3.04815","19.90091","44.36303","0.02711","174.55531"
"5415.85600","3.04815","19.59951","43.78444","0.02711","171.91167"
"5423.85600","3.04830","19.48854","43.20581","0.02711","170.93832"
"5431.85600","3.08148","19.54075","42.76979","0.02744","171.39626"
"5439.85600","3.09120","19.33586","42.13042","0.02754","169.59912"
"5447.85600","3.09635","19.23456","41.61466","0.02759","168.71066"
"5455.85600","3.09679","19.13466","41.30800","0.02759","167.83443"
"5463.85600","3.15444","19.46735","40.72939","0.02817","170.75247"
"5471.85600","3.15562","19.48161","40.24788","0.02818","170.87758"
"5479.85600","3.15537","19.45067","39.57751","0.02818","170.60617"
"5487.85600","3.15530","19.44903","39.12799","0.02818","170.59181"
"5495.85600","3.15537","19.37436","38.61122","0.02818","169.93686"
"5503.85600","3.15556","19.38514","38.12429","0.02818","170.03139"
"5511.85600","3.16374","19.50653","37.45390","0.02826","171.09616"
"5519.85600","3.19256","20.01061","36.96175","0.02855","175.51750"
"5527.85600","3.19261","19.82700","36.53182","0.02855","173.90707"
"5535.85600","3.23517","20.47059","35.94726","0.02897","179.55212"
"5543.85600","3.23538","20.32670","35.37763","0.02897","178.29005"
"5551.85600","3.23521","20.01428","34.85627","0.02897","175.54970"
"5559.85600","3.23523","19.84559","34.28678","0.02897","174.07014"
"5567.85600","3.23532","19.51407","33.84085","0.02897","171.16226"
"5575.85600","3.23558","19.27799","33.33001","0.02898","169.09160"
"5583.85600","3.26505","19.31127","32.98843","0.02927","169.38347"
"5591.85600","3.28209","19.26107","32.24602","0.02944","168.94316"
"5599.85600","3.28193","19.38400","31.72232","0.02944","170.02135"
"5607.85600","3.28183","19.29648","31.17030","0.02944","169.25372"
"5615.85600","3.28170","19.32636","31.11848","0.02944","169.51585"
"5623.85600","3.28168","19.34543","30.76124","0.02943","169.68314"
"5631.85600","3.28157","19.60902","30.74729","0.02943","171.99509"
"5639.85600","3.28155","19.58697","30.47450","0.02943","171.80165"
"5647.85600","3.28149","19.73022","30.30837","0.02943","173.05821"
"5655.85600","3.28137","19.80999","30.23592","0.02943","173.75786"
"5663.85600","3.28133","19.87795","30.01465","0.02943","174.35394"
"5671.85600","3.28111","20.24566","30.14308","0.02943","177.57918"
"5679.85600","3.28028","20.11033","30.53414","0.02942","176.39221"
"5687.85600","3.26378","19.69483","31.09289","0.02926","172.74776"
"5695.85600","3.22392","19.09545","31.98810","0.02886","167.49048"
"5703.85600","3.22412","19.76788","32.56233","0.02886","173.38852"
"5711.85600","3.22424","19.25679","33.41450","0.02886","168.90561"
"5719.85600","3.22403","20.08459","34.12878","0.02886","176.16638"
"5727.85600","3.20085","19.66237","35.00101","0.02863","172.46309"
"5735.85600","3.17693","19.07102","35.82715","0.02839","167.27617"
"5743.85600","3.17708","19.33624","36.48932","0.02839","169.60246"
"5751.85600","3.17701","19.32806","37.34570","0.02839","169.53072"
"5759.85600","3.17671","20.01773","37.99955","0.02839","175.57996"
"5767.85600","3.15028","19.50297","38.56596","0.02813","171.06491"
"5775.85600","3.13998","19.58862","39.44511","0.02802","171.81616"
"5783.85600","3.13188","19.64931","40.06768","0.02794","172.34848"
"5791.85600","3.12756","19.75007","40.79163","0.02790","173.23228"
"5799.85600","3.08706","19.24282","41.53340","0.02750","168.78311"
"5807.85600","3.08719","19.58111","42.45962","0.02750","171.75031"
"5815.85600","3.08707","19.93348","43.58646","0.02750","174.84099"
"5823.85600","3.05484","19.68960","44.85316","0.02717","172.70184"
"5831.85600","3.02899","19.64577","46.17501","0.02692","172.31744"
"5839.85600","2.98802","19.29806","47.47874","0.02651","169.26762"
"5847.85600","2.98148","19.56517","48.88235","0.02644","171.61050"
"5855.85600","2.98132","19.89298","50.33298","0.02644","174.48576"
"5863.85600","2.93792","19.43737","51.68945","0.02601","170.48953"
"5867.70500","2.93719","19.67121","52.31298","0.02600","172.54056"