File: experimental/sma_database/results from second training/flexinol_isobaric_trained_150MPa.csv
Test : Start of hold value,"150.00000",MPa

Time,Extension,Load,Temperature: Chamber 3119-600 1 1,Tensile strain (Extension),Tensile stress
(s),(mm),(N),(C),(mm/mm),(MPa)
"0.00000","0.33016","0.76469","31.73093","0.00000","6.70723"
"7.70000","0.39362","1.11555","31.50289","0.00063","9.78471"
"15.40000","0.45774","1.54805","31.39466","0.00127","13.57825"
"23.10000","0.52191","2.18650","31.06577","0.00191","19.17825"
"30.80000","0.58612","3.10870","30.89877","0.00255","27.26708"
"38.50000","0.65029","4.03591","30.76961","0.00319","35.39990"
"46.20000","0.71446","4.72606","30.65658","0.00383","41.45334"
"53.90000","0.77865","5.54976","30.51988","0.00447","48.67819"
"61.60000","0.84285","5.93032","30.34312","0.00511","52.01619"
"69.30000","0.90701","6.19122","30.26356","0.00575","54.30453"
"77.00000","0.97122","6.46201","30.18621","0.00639","56.67978"
"84.70000","1.03540","6.84795","30.19713","0.00703","60.06488"
"92.40000","1.09957","7.38470","30.19236","0.00767","64.77281"
"100.10000","1.16378","8.12426","29.99792","0.00831","71.25974"
"107.80000","1.22799","8.82088","29.91018","0.00895","77.36987"
"115.50000","1.29199","9.59179","29.66060","0.00959","84.13174"
"123.20000","1.35627","9.87802","29.67359","0.01023","86.64236"
"130.90000","1.42033","9.99048","29.78420","0.01087","87.62872"
"138.60000","1.48447","10.33341","29.96640","0.01150","90.63668"
"146.30000","1.54858","11.35077","29.70332","0.01214","99.56016"
"154.00000","1.61286","12.02162","29.51908","0.01278","105.44431"
"161.70000","1.67687","12.61497","29.52563","0.01342","110.64868"
"169.40000","1.74112","12.64500","29.57817","0.01406","110.91212"
"177.10000","1.80520","12.99135","29.56224","0.01470","113.95000"
"184.80000","1.86947","13.82174","29.58782","0.01534","121.23357"
"192.50000","1.93352","14.56622","29.30536","0.01598","127.76353"
"200.20000","1.99778","15.02533","29.31111","0.01662","131.79054"
"207.90000","2.06192","15.12738","29.39031","0.01726","132.68561"
"215.60000","2.12615","15.78180","29.44444","0.01790","138.42566"
"223.30000","2.19028","16.78021","29.42956","0.01854","147.18301"
"230.88500","2.25396","17.15483","29.35126","0.01917","150.46886"
"238.58500","2.33596","17.37450","29.33164","0.01999","152.39566"
"246.28500","2.33545","17.50282","29.32880","0.01999","153.52118"
"253.98500","2.33469","17.61941","29.33092","0.01998","154.54378"
"261.68500","2.30307","16.83765","29.95207","0.01966","147.68683"
"269.38500","2.29201","16.87536","30.57180","0.01955","148.01753"
"277.08500","2.29042","17.20314","31.15342","0.01954","150.89261"
"284.78500","2.28877","17.32514","31.93993","0.01952","151.96266"
"292.48500","2.27133","17.07758","32.71376","0.01935","149.79131"
"300.18500","2.27116","17.05528","33.35371","0.01935","149.59564"
"307.88500","2.27103","17.17595","34.20358","0.01934","150.65407"
"315.58500","2.26977","17.25757","34.65879","0.01933","151.37003"
"323.28500","2.24641","16.92501","35.45219","0.01910","148.45303"
"330.98500","2.24404","16.95664","36.12952","0.01908","148.73048"
"338.68500","2.24402","17.11025","36.78517","0.01908","150.07780"
"346.38500","2.24388","17.24008","37.45396","0.01907","151.21660"
"354.08500","2.21391","16.98944","38.27433","0.01878","149.01817"
"361.78500","2.21389","17.21557","39.34846","0.01878","151.00162"
"369.48500","2.20275","17.12963","40.46973","0.01866","150.24783"
"377.18500","2.17159","16.92868","41.74252","0.01835","148.48528"
"384.88500","2.17142","17.21522","43.11805","0.01835","150.99854"
"392.58500","2.15870","17.11492","44.42907","0.01823","150.11877"
"400.28500","2.12387","16.80923","45.71726","0.01788","147.43755"
"407.98500","2.12399","17.06368","47.00452","0.01788","149.66937"
"415.68500","2.12400","17.13794","48.13670","0.01788","150.32072"
"423.38500","2.12383","17.25992","49.23676","0.01788","151.39064"
"431.08500","2.09985","17.07413","50.39652","0.01764","149.76102"
"438.78500","2.07929","16.96477","51.41078","0.01743","148.80182"
"446.48500","2.07913","17.14576","52.41365","0.01743","150.38933"
"454.18500","2.07210","17.18371","53.45920","0.01736","150.72217"
"461.88500","2.03961","16.87609","54.48596","0.01704","148.02397"
"469.58500","2.03063","16.96078","55.51136","0.01695","148.76682"
"477.28500","2.03062","17.11517","56.60526","0.01695","150.12097"
"484.98500","2.02682","17.36055","57.62543","0.01691","152.27327"
"492.68500","1.99734","17.05899","58.69486","0.01662","149.62820"
"500.38500","1.97829","17.07759","59.83685","0.01643","149.79138"
"508.08500","1.97197","17.18374","60.90728","0.01636","150.72241"
"515.78500","1.93553","16.89584","62.01046","0.01600","148.19719"
"523.48500","1.92868","17.07861","63.12584","0.01593","149.80026"
"531.18500","1.92861","17.31829","64.16226","0.01593","151.90262"
"538.88500","1.92505","17.49314","65.18189","0.01590","153.43626"
"546.58500","1.87207","17.08589","66.28738","0.01537","149.86417"
"554.28500","1.81255","16.58602","67.32504","0.01477","145.47972"
"561.98500","1.81272","16.93929","68.31341","0.01478","148.57831"
"569.68500","1.81273","17.22193","69.38387","0.01478","151.05736"
"577.38500","1.81258","17.55428","70.36842","0.01478","153.97250"
"585.08500","1.73966","16.92310","71.41531","0.01405","148.43629"
"592.78500","1.70736","17.08167","72.48532","0.01373","149.82715"
"600.48500","1.67846","17.26654","73.52688","0.01344","151.44868"
"608.18500","1.61871","17.15450","74.65603","0.01284","150.46594"
"615.88500","1.52608","16.67582","75.78514","0.01192","146.26733"
"623.58500","1.52052","17.36079","76.82652","0.01186","152.27536"
"631.28500","1.35840","16.27632","77.88161","0.01025","142.76326"
"638.98500","1.35139","17.14129","78.87543","0.01018","150.35008"
"646.68500","1.33921","17.57236","79.85179","0.01006","154.13112"
"654.38500","1.18091","16.84167","80.91518","0.00848","147.72202"
"662.08500","1.10183","17.13785","81.97169","0.00769","150.31990"
"669.78500","0.97856","16.79905","82.88029","0.00646","147.34819"
"677.48500","0.88978","17.43995","83.97379","0.00558","152.96970"
"685.18500","0.73545","17.11502","85.03542","0.00404","150.11967"
"692.88500","0.55820","16.80449","86.12701","0.00227","147.39598"
"700.58500","0.42260","17.20130","87.17140","0.00092","150.87648"
"708.28500","0.26013","17.09076","88.24121","-0.00070","149.90691"
"715.98500","0.11499","17.19506","89.20703","-0.00214","150.82170"
"723.68500","-0.11496","17.04741","90.19942","-0.00444","149.52669"
"731.38500","-0.35900","17.02375","91.32278","-0.00687","149.31909"
"739.08500","-0.63945","17.20300","92.30585","-0.00966","150.89137"
"746.78500","-0.93233","17.10191","93.22096","-0.01258","150.00464"
"754.48500","-1.30400","17.27164","94.32040","-0.01629","151.49338"
"762.18500","-1.71629","17.27530","95.36313","-0.02040","151.52556"
"769.88500","-2.33135","16.98536","96.37852","-0.02653","148.98242"
"777.58500","-2.71612","17.25368","97.47255","-0.03036","151.33586"
"785.28500","-3.16799","17.07341","98.44312","-0.03487","149.75467"
"792.98500","-3.57414","17.22118","99.39053","-0.03891","151.05086"
"800.68500","-3.87237","17.48410","100.56247","-0.04189","153.35693"
"808.38500","-4.35673","16.72039","101.64360","-0.04671","146.65826"
"816.08500","-4.52853","17.28594","102.63698","-0.04843","151.61887"
"823.78500","-4.78899","16.96381","103.60786","-0.05102","148.79333"
"831.48500","-4.98766","17.28574","104.62620","-0.05300","151.61705"
"839.18500","-5.24474","16.81021","105.74911","-0.05557","147.44611"
"846.88500","-5.41029","17.04512","106.73675","-0.05722","149.50658"
"854.58500","-5.58417","17.03342","107.74860","-0.05895","149.40390"
"862.28500","-5.76699","17.11280","108.73166","-0.06077","150.10019"
"869.98500","-5.94163","17.12526","109.81707","-0.06251","150.20950"
"877.68500","-6.05358","17.01696","110.81284","-0.06363","149.25955"
"885.38500","-6.15853","17.34155","111.80553","-0.06467","152.10664"
"893.08500","-6.35275","17.18239","112.81485","-0.06661","150.71059"
"900.78500","-6.50292","17.24782","113.82301","-0.06811","151.28448"
"908.48500","-6.65856","16.68657","115.03259","-0.06966","146.36166"
"916.18500","-6.80094","17.18411","116.03846","-0.07108","150.72566"
"923.88500","-6.83437","17.25967","117.02616","-0.07141","151.38843"
"931.58500","-6.94116","17.14009","118.11444","-0.07247","150.33960"
"939.28500","-7.03672","16.92281","119.11447","-0.07343","148.43376"
"946.98500","-7.09492","17.32054","120.11022","-0.07401","151.92230"
"954.68500","-7.22075","16.91078","121.09406","-0.07526","148.32820"
"962.38500","-7.23025","17.65971","122.16202","-0.07536","154.89728"
"970.08500","-7.42484","16.30239","123.13904","-0.07729","142.99188"
"977.78500","-7.42448","16.99691","123.99372","-0.07729","149.08366"
"985.48500","-7.42443","17.24686","124.76661","-0.07729","151.27606"
"993.18500","-7.42454","17.33519","125.22261","-0.07729","152.05083"
"1000.88500","-7.42474","17.38009","125.50597","-0.07729","152.44463"
"1008.58500","-7.42493","17.21998","125.51467","-0.07730","151.04030"
"1016.28500","-7.44199","16.83665","125.48508","-0.07747","147.67799"
"1023.98500","-7.46352","16.50453","125.14465","-0.07768","144.76491"
"1031.68500","-7.46224","16.34582","124.95116","-0.07767","143.37280"
"1039.38500","-7.36626","17.65931","124.58973","-0.07671","154.89378"
"1047.08500","-7.36653","17.33059","124.18356","-0.07671","152.01045"
"1054.78500","-7.36655","16.98139","123.49643","-0.07671","148.94757"
"1062.48500","-7.36623","16.58472","122.64742","-0.07671","145.46826"
"1070.18500","-7.26904","17.42971","121.58324","-0.07574","152.87988"
"1077.88500","-7.26903","16.89541","120.52504","-0.07574","148.19345"
"1085.58500","-7.23791","16.85555","119.45835","-0.07543","147.84381"
"1093.28500","-7.17306","17.24674","118.22596","-0.07479","151.27498"
"1100.98500","-7.17172","16.82974","117.09130","-0.07477","147.61745"
"1108.68500","-7.04817","17.86352","116.01021","-0.07354","156.68491"
"1116.38500","-7.04903","17.51874","114.94015","-0.07355","153.66078"
"1124.08500","-7.04969","17.10220","114.02039","-0.07356","150.00720"
"1131.78500","-7.04953","16.68956","113.16924","-0.07355","146.38786"
"1139.48500","-7.04840","16.37248","112.22392","-0.07354","143.60670"
"1147.18500","-6.92823","17.43401","111.41856","-0.07235","152.91762"
"1154.88500","-6.92326","16.96993","110.63660","-0.07230","148.84709"
"1162.58500","-6.89017","17.05660","109.76815","-0.07197","149.60728"
"1170.28500","-6.85305","16.99611","108.89067","-0.07160","149.07668"
"1177.98500","-6.82520","16.91538","108.17188","-0.07132","148.36856"
"1185.68500","-6.78629","16.87571","107.41434","-0.07093","148.02065"
"1193.38500","-6.69573","17.51808","106.65844","-0.07003","153.65500"
"1201.08500","-6.69579","17.21696","105.97977","-0.07003","151.01376"
"1208.78500","-6.69568","16.76456","105.25342","-0.07003","147.04572"
"1216.48500","-6.59757","17.42848","104.60758","-0.06905","152.86913"
"1224.18500","-6.59652","16.95256","103.87182","-0.06904","148.69472"
"1231.88500","-6.49655","17.55042","103.16128","-0.06804","153.93867"
"1239.58500","-6.49650","16.98566","102.44976","-0.06804","148.98503"
"1247.28500","-6.49447","16.81166","101.78999","-0.06802","147.45880"
"1254.98500","-6.33211","17.75345","101.08353","-0.06640","155.71947"
"1262.68500","-6.33122","17.14507","100.39980","-0.06639","150.38326"
"1270.38500","-6.33103","16.62980","99.72540","-0.06639","145.86368"
"1278.08500","-6.21316","17.47902","98.93578","-0.06522","153.31244"
"1285.78500","-6.19563","16.91734","98.22554","-0.06504","148.38577"
"1293.48500","-6.10071","17.10538","97.48809","-0.06410","150.03516"
"1301.18500","-6.00841","17.23805","96.64326","-0.06318","151.19878"
"1308.88500","-5.90993","16.99412","95.85335","-0.06220","149.05925"
"1316.58500","-5.81437","16.83052","94.89143","-0.06124","147.62424"
"1324.28500","-5.58260","17.11359","93.62129","-0.05893","150.10716"
"1331.98500","-5.43911","16.45280","92.48701","-0.05750","144.31120"
"1339.68500","-4.92943","17.35177","90.93565","-0.05242","152.19623"
"1347.38500","-4.38946","16.96021","89.02391","-0.04704","148.76180"
"1355.08500","-4.06561","16.32844","87.53157","-0.04381","143.22038"
"1362.78500","-3.35840","17.13988","85.96837","-0.03676","150.33768"
"1370.48500","-2.43394","18.91565","84.00085","-0.02755","165.91336"
"1378.18500","-2.22637","17.81036","82.76528","-0.02548","156.21863"
"1385.88500","-1.88414","17.58526","81.67476","-0.02207","154.24423"
"1393.58500","-1.31061","17.40260","80.24948","-0.01635","152.64206"
"1401.28500","-0.56472","17.22952","78.93717","-0.00892","151.12401"
"1408.98500","-0.14362","18.36427","77.47855","-0.00472","161.07707"
"1416.68500","0.12716","17.67357","75.99747","-0.00202","155.01880"
"1424.38500","0.33368","16.99071","74.83152","0.00003","149.02928"
"1432.08500","0.37173","16.93760","73.99507","0.00041","148.56349"
"1439.78500","0.47256","17.73920","73.09614","0.00142","155.59451"
"1447.48500","0.55641","17.35021","72.49864","0.00225","152.18259"
"1455.18500","0.66596","17.45499","71.70057","0.00335","153.10161"
"1462.88500","0.82528","18.30937","70.77037","0.00493","160.59558"
"1470.58500","1.56436","18.12189","68.92835","0.01230","158.95114"
"1478.28500","1.70728","18.05991","66.75596","0.01373","158.40747"
"1485.98500","1.62113","16.12350","64.38473","0.01287","141.42279"
"1493.68500","1.74482","18.10721","63.23722","0.01410","158.82237"
"1501.38500","1.74580","16.61141","62.54104","0.01411","145.70241"
"1509.08500","1.86459","16.76131","61.51519","0.01529","147.01721"
"1516.78500","1.88342","16.79235","60.68242","0.01548","147.28949"
"1524.48500","2.00447","18.27184","59.34401","0.01669","160.26640"
"1532.18500","2.03247","16.97411","58.18029","0.01697","148.88373"
"1539.88500","2.08305","16.37529","57.61745","0.01747","143.63132"
"1547.58500","2.14556","16.95537","56.72427","0.01809","148.71936"
"1555.28500","2.21469","17.98036","55.53247","0.01878","157.70975"
"1562.98500","2.21497","17.39569","54.86281","0.01879","152.58153"
"1570.68500","2.27256","16.50718","54.20565","0.01936","144.78815"
"1578.38500","2.31700","17.24456","53.07304","0.01980","151.25589"
"1586.08500","2.38210","18.31019","52.11678","0.02045","160.60275"
"1593.78500","2.39698","16.32573","51.30895","0.02060","143.19664"
"1601.48500","2.50275","17.29172","49.82755","0.02165","151.66951"
"1609.18500","2.51656","17.35265","48.46999","0.02179","152.20395"
"1616.88500","2.56656","18.05576","47.33199","0.02229","158.37106"
"1624.58500","2.57316","16.96533","46.58963","0.02236","148.80672"
"1632.28500","2.60431","16.32404","45.67263","0.02267","143.18184"
"1639.98500","2.62770","16.62418","44.81717","0.02290","145.81441"
"1647.68500","2.69175","17.61091","43.54344","0.02354","154.46924"
"1655.38500","2.69168","17.53870","42.99679","0.02354","153.83586"
"1663.08500","2.71854","16.74720","41.84523","0.02381","146.89343"
"1670.78500","2.77254","16.85344","40.76245","0.02434","147.82530"
"1678.48500","2.77241","16.85091","39.99474","0.02434","147.80309"
"1686.18500","2.77249","17.33101","38.94420","0.02434","152.01421"
"1693.88500","2.84328","17.83169","37.82449","0.02505","156.40572"
"1701.58500","2.85443","16.87078","37.07075","0.02516","147.97740"
"1709.28500","2.85426","16.81116","36.14405","0.02516","147.45448"
"1716.98500","2.85437","17.39433","34.96591","0.02516","152.56960"
"1724.68500","2.86875","17.25576","34.24847","0.02530","151.35414"
"1732.38500","2.91214","16.33017","33.46431","0.02573","143.23557"
"1740.08500","2.94521","17.40084","32.04409","0.02606","152.62665"
"1747.78500","2.94487","17.85805","31.26407","0.02606","156.63692"
"1755.48500","2.94390","17.96779","31.11337","0.02605","157.59949"
"1763.18500","2.94102","17.65102","31.21363","0.02602","154.82106"
"1770.88500","2.92302","16.80728","31.12371","0.02584","147.42043"
"1778.58500","2.90963","16.35043","30.83006","0.02571","143.41328"
"1786.28500","2.91000","16.24622","30.74725","0.02571","142.49924"
"1793.98500","2.91051","16.65130","30.59093","0.02572","146.05226"
"1801.68500","2.91258","17.05027","30.37180","0.02574","149.55170"
"1809.38500","2.94233","17.65362","30.45016","0.02604","154.84381"
"1817.08500","2.94158","17.98580","31.11560","0.02603","157.75743"
"1824.78500","2.93254","17.56420","31.78310","0.02594","154.05954"
"1832.48500","2.87591","16.71620","32.57587","0.02537","146.62152"
"1840.18500","2.87592","17.09181","33.26686","0.02537","149.91609"
"1847.88500","2.87589","17.61013","33.88465","0.02537","154.46240"
"1855.58500","2.87384","16.81065","34.76163","0.02535","147.44998"
"1863.28500","2.84022","17.39614","35.33995","0.02502","152.58540"
"1870.98500","2.83846","16.72431","36.31970","0.02500","146.69267"
"1878.68500","2.83842","17.13119","36.93893","0.02500","150.26149"
"1886.38500","2.83558","17.55246","37.55748","0.02497","153.95653"
"1894.08500","2.76685","16.76530","38.35349","0.02429","147.05222"
"1901.78500","2.76798","16.71163","39.20667","0.02430","146.58144"
"1909.48500","2.79682","17.18124","40.01329","0.02459","150.70053"
"1917.18500","2.79850","17.48292","40.81813","0.02460","153.34656"
"1924.88500","2.79816","17.54251","41.42384","0.02460","153.86929"
"1932.58500","2.79486","17.66212","42.07530","0.02457","154.91838"
"1940.28500","2.74576","17.04793","42.79137","0.02408","149.53117"
"1947.98500","2.73931","17.17843","43.56622","0.02401","150.67583"
"1955.68500","2.69283","16.70941","44.37091","0.02355","146.56197"
"1963.38500","2.69293","16.98122","45.27504","0.02355","148.94609"
"1971.08500","2.69297","17.34539","46.42152","0.02355","152.14034"
"1978.78500","2.69258","17.47151","47.58173","0.02355","153.24652"
"1986.48500","2.60899","16.57531","48.85888","0.02271","145.38574"
"1994.18500","2.60835","16.92206","50.21737","0.02271","148.42719"
"2001.88500","2.60838","17.35350","51.54356","0.02271","152.21147"
"2009.58500","2.59900","17.46126","52.85715","0.02261","153.15662"
"2017.28500","2.54592","16.91687","54.18815","0.02208","148.38168"
"2024.98500","2.54508","17.10873","55.36053","0.02208","150.06453"
"2032.68500","2.50099","16.81968","56.47957","0.02164","147.52919"
"2040.38500","2.50102","17.11865","57.61833","0.02164","150.15152"
"2048.08500","2.49654","17.29183","58.67773","0.02159","151.67050"
"2055.78500","2.44597","16.86865","59.67325","0.02109","147.95866"
"2063.48500","2.43571","17.08075","60.74088","0.02099","149.81905"
"2071.18500","2.40472","16.99178","61.76148","0.02068","149.03873"
"2078.88500","2.39840","17.29093","62.80104","0.02061","151.66258"
"2086.58500","2.35266","17.09308","63.95593","0.02016","149.92722"
"2094.28500","2.31144","16.94365","65.00983","0.01975","148.61658"
"2101.98500","2.30626","17.26806","66.09035","0.01970","151.46199"
"2109.68500","2.25588","17.06523","67.24467","0.01919","149.68292"
"2117.38500","2.21386","17.01109","68.30746","0.01877","149.20810"
"2125.08500","2.19647","17.30169","69.36772","0.01860","151.75694"
"2132.78500","2.10261","16.66218","70.50187","0.01767","146.14767"
"2140.48500","2.10262","17.51335","71.52908","0.01767","153.61349"
"2148.18500","2.02014","16.92118","72.65834","0.01684","148.41949"
"2155.88500","1.97299","17.14179","73.69974","0.01637","150.35446"
"2163.58500","1.90066","17.25169","74.70004","0.01565","151.31844"
"2171.28500","1.80553","16.94864","75.82302","0.01470","148.66026"
"2178.98500","1.72854","16.84814","76.89281","0.01394","147.77878"
"2186.68500","1.71258","17.78716","77.89969","0.01378","156.01518"
"2194.38500","1.39995","16.04603","79.01295","0.01066","140.74333"
"2202.08500","1.40298","16.99064","80.01582","0.01069","149.02872"
"2209.78500","1.40266","17.87004","81.10173","0.01069","156.74216"
"2217.48500","1.21132","16.87724","82.21851","0.00878","148.03401"
"2225.18500","1.15464","17.57694","83.16405","0.00822","154.17131"
"2232.88500","0.90116","16.65361","84.21319","0.00569","146.07251"
"2240.58500","0.76318","16.96073","85.30608","0.00432","148.76636"
"2248.28500","0.68059","17.27973","86.33509","0.00349","151.56435"
"2255.98500","0.46435","16.99495","87.30967","0.00134","149.06648"
"2263.68500","0.26023","17.04859","88.48604","-0.00070","149.53696"
"2271.38500","0.09118","17.21103","89.51128","-0.00238","150.96184"
"2279.08500","-0.17252","17.20187","90.50577","-0.00501","150.88148"
"2286.78500","-0.44662","17.07726","91.58192","-0.00774","149.78845"
"2294.48500","-0.70684","17.19328","92.51366","-0.01034","150.80615"
"2302.18500","-1.10264","17.07985","93.49343","-0.01428","149.81119"
"2309.88500","-1.41451","17.03949","94.59673","-0.01739","149.45714"
"2317.58500","-1.95933","16.93752","95.61764","-0.02282","148.56279"
"2325.28500","-2.44598","17.07134","96.67571","-0.02767","149.73653"
"2332.98500","-2.85247","17.19069","97.80101","-0.03172","150.78342"
"2340.68500","-3.31411","16.86931","98.79697","-0.03632","147.96446"
"2348.38500","-3.63630","17.44173","99.83790","-0.03953","152.98532"
"2356.08500","-3.91556","17.08605","100.91380","-0.04232","149.86560"
"2363.78500","-4.33894","16.80418","101.89162","-0.04654","147.39325"
"2371.48500","-4.53886","17.20100","102.89375","-0.04853","150.87379"
"2379.18500","-4.79180","17.16969","104.03043","-0.05105","150.59920"
"2386.88500","-4.97360","17.18432","104.99323","-0.05286","150.72749"
"2394.58500","-5.17332","16.96012","105.87820","-0.05485","148.76099"
"2402.28500","-5.34690","17.15300","106.91161","-0.05658","150.45279"
"2409.98500","-5.54658","17.03065","107.93375","-0.05857","149.37965"
"2417.68500","-5.71390","17.04637","109.00376","-0.06024","149.51752"
"2425.38500","-5.88535","17.12903","110.19485","-0.06195","150.24255"
"2433.08500","-6.07176","16.91481","111.25293","-0.06381","148.36362"
"2440.78500","-6.18674","17.27524","112.32092","-0.06495","151.52499"
"2448.48500","-6.33012","17.12175","113.41972","-0.06638","150.17871"
"2456.18500","-6.44486","17.23149","114.45672","-0.06753","151.14130"
"2463.88500","-6.48764","17.59573","115.29745","-0.06795","154.33607"
"2471.58500","-6.77374","15.91155","116.30589","-0.07081","139.56375"
"2479.28500","-6.79494","16.86346","117.25096","-0.07102","147.91319"
"2486.98500","-6.79497","17.52271","118.14686","-0.07102","153.69562"
"2494.68500","-6.88506","17.30034","119.29047","-0.07191","151.74519"
"2502.38500","-6.98326","17.26430","120.28806","-0.07289","151.42902"
"2510.08500","-7.07129","16.99277","121.29845","-0.07377","149.04741"
"2517.78500","-7.14010","17.07178","122.44506","-0.07446","149.74037"
"2525.48500","-7.18357","17.24005","123.47076","-0.07489","151.21632"
"2533.18500","-7.25148","16.93476","124.34443","-0.07557","148.53856"
"2540.88500","-7.27129","16.95776","125.04485","-0.07576","148.74026"
"2548.58500","-7.27122","17.09808","125.36420","-0.07576","149.97112"
"2556.28500","-7.27116","17.04325","125.55658","-0.07576","149.49011"
"2563.98500","-7.27110","17.03485","125.56085","-0.07576","149.41652"
"2571.68500","-7.27078","16.82475","125.30068","-0.07576","147.57364"
"2579.38500","-7.27007","16.74521","124.92661","-0.07575","146.87599"
"2587.08500","-7.22465","17.22639","124.64157","-0.07530","151.09656"
"2594.78500","-7.18069","17.66894","124.34789","-0.07486","154.97818"
"2602.48500","-7.18148","17.32257","123.81478","-0.07487","151.94017"
"2610.18500","-7.18179","16.91841","123.15875","-0.07487","148.39516"
"2617.88500","-7.18130","16.62104","122.28029","-0.07487","145.78688"
"2625.58500","-7.12622","16.97803","121.18833","-0.07432","148.91812"
"2633.28500","-7.06604","17.18160","120.17014","-0.07372","150.70366"
"2640.98500","-7.06578","16.79589","119.03608","-0.07372","147.32053"
"2648.68500","-6.98498","17.33629","117.92415","-0.07291","152.06052"
"2656.38500","-6.98492","16.76514","116.92648","-0.07291","147.05081"
"2664.08500","-6.92078","17.32791","115.92882","-0.07227","151.98698"
"2671.78500","-6.89153","17.17814","114.82562","-0.07198","150.67334"
"2679.48500","-6.89111","16.74800","113.88940","-0.07198","146.90045"
"2687.18500","-6.82068","17.27288","112.94741","-0.07127","151.50433"
"2694.88500","-6.81146","16.90988","112.04314","-0.07118","148.32030"
"2702.58500","-6.78585","16.96858","111.19395","-0.07093","148.83519"
"2710.28500","-6.69081","17.62150","110.38927","-0.06998","154.56209"
"2717.98500","-6.69092","17.13997","109.66764","-0.06998","150.33855"
"2725.68500","-6.69083","16.75949","108.92645","-0.06998","147.00121"
"2733.38500","-6.63028","17.20487","108.20109","-0.06938","150.90776"
"2741.08500","-6.57858","17.28352","107.50636","-0.06886","151.59760"
"2748.78500","-6.57857","16.91933","106.74583","-0.06886","148.40326"
"2756.48500","-6.52594","17.15034","106.05416","-0.06834","150.42949"
"2764.18500","-6.33605","18.40325","105.37428","-0.06644","161.41904"
"2771.88500","-6.44965","16.60992","104.71289","-0.06758","145.68935"
"2779.58500","-6.44933","16.34094","103.98254","-0.06757","143.33000"
"2787.28500","-6.44704","16.07459","103.26898","-0.06755","140.99380"
"2794.98500","-6.19721","18.15609","102.60973","-0.06506","159.25108"
"2802.68500","-6.19776","17.58881","101.91900","-0.06506","154.27534"
"2810.38500","-6.19859","17.14224","101.20142","-0.06507","150.35843"
"2818.08500","-6.19861","16.78235","100.50922","-0.06507","147.20172"
"2825.78500","-6.19813","16.22171","99.76430","-0.06507","142.28423"
"2833.48500","-6.09143","16.94481","98.90223","-0.06400","148.62669"
"2841.18500","-5.86200","17.72965","98.08596","-0.06172","155.51073"
"2848.88500","-5.86048","16.81052","97.32258","-0.06170","147.44885"
"2856.58500","-5.80015","16.65746","96.27549","-0.06110","146.10628"
"2864.28500","-5.55846","17.20271","95.11925","-0.05869","150.88885"
"2871.98500","-5.41077","16.95897","93.92125","-0.05722","148.75087"
"2879.68500","-5.17044","16.68241","92.63869","-0.05483","146.32510"
"2887.38500","-4.56859","17.85344","90.88404","-0.04883","156.59651"
"2895.08500","-4.20608","17.78384","89.13515","-0.04521","155.98604"
"2902.78500","-3.65780","17.29203","87.34978","-0.03975","151.67223"
"2910.48500","-3.27200","16.86398","86.02824","-0.03590","147.91769"
"2918.18500","-3.04957","16.43492","85.11471","-0.03369","144.15434"
"2925.88500","-2.60766","16.66675","83.76277","-0.02928","146.18777"
"2933.58500","-1.85908","18.09015","82.41434","-0.02182","158.67279"
"2941.28500","-1.46135","18.19393","81.05807","-0.01786","159.58301"
"2948.98500","-0.83392","18.15485","79.66026","-0.01160","159.24025"
"2956.68500","-0.61347","16.71889","78.63826","-0.00941","146.64508"
"2964.38500","-0.43613","16.72746","77.79150","-0.00764","146.72032"
"2972.08500","-0.24154","16.41076","76.86508","-0.00570","143.94241"
"2979.78500","0.08973","16.72685","75.68905","-0.00240","146.71495"
"2987.48500","0.87821","19.17707","73.71996","0.00546","168.20639"
"2995.18500","0.87814","16.71306","71.99898","0.00546","146.59395"
"3002.88500","1.26171","18.95397","70.25243","0.00928","166.24951"
"3010.58500","1.39240","15.74561","68.51408","0.01059","138.10825"
"3018.28500","1.50709","17.23844","66.92467","0.01173","151.20222"
"3025.98500","1.50706","17.56051","65.83031","0.01173","154.02718"
"3033.68500","1.55470","17.30468","64.97187","0.01220","151.78322"
"3041.38500","1.64965","15.29949","64.03890","0.01315","134.19522"
"3049.08500","1.74174","16.64555","63.13486","0.01407","146.00183"
"3056.78500","1.93353","18.81879","62.19869","0.01598","165.06381"
"3064.48500","1.93437","18.10197","60.98067","0.01599","158.77646"
"3072.18500","1.93575","15.99005","60.22983","0.01600","140.25229"
"3079.88500","2.04925","16.66558","59.38840","0.01713","146.17749"
"3087.58500","2.07963","17.12845","58.48382","0.01744","150.23746"
"3095.28500","2.17805","18.20405","57.38665","0.01842","159.67180"
"3102.98500","2.22356","17.25498","56.41304","0.01887","151.34726"
"3110.68500","2.22440","16.11021","55.54525","0.01888","141.30626"
"3118.38500","2.27269","17.07815","54.91335","0.01936","149.79628"
"3126.08500","2.31292","17.51006","54.02192","0.01976","153.58461"
"3133.78500","2.41199","17.21516","52.83107","0.02075","150.99802"
"3141.48500","2.41275","16.56189","52.09342","0.02076","145.26802"
"3149.18500","2.44276","17.24748","51.02276","0.02106","151.28149"
"3156.88500","2.55869","17.43240","49.61682","0.02221","152.90350"
"3164.58500","2.57866","16.28139","48.60760","0.02241","142.80775"
"3172.28500","2.60517","17.17127","47.44334","0.02268","150.61302"
"3179.98500","2.62728","17.50849","46.48396","0.02290","153.57089"
"3187.68500","2.67760","17.63261","45.56858","0.02340","154.65953"
"3195.38500","2.69433","16.13777","44.80016","0.02356","141.54802"
"3203.08500","2.72154","16.87584","43.67025","0.02383","148.02176"
"3210.78500","2.75003","17.57784","42.63993","0.02412","154.17914"
"3218.48500","2.78375","17.60468","41.58050","0.02445","154.41457"
"3226.18500","2.80235","16.33001","40.51184","0.02464","143.23413"
"3233.88500","2.81240","16.56577","39.89348","0.02474","145.30208"
"3241.58500","2.85383","17.61316","38.67035","0.02515","154.48897"
"3249.28500","2.85549","17.46595","37.67070","0.02517","153.19775"
"3256.98500","2.87226","16.26715","36.90654","0.02534","142.68277"
"3264.68500","2.89442","17.03986","35.91758","0.02556","149.46039"
"3272.38500","2.90130","17.44157","34.88470","0.02563","152.98395"
"3280.08500","2.96764","17.06671","33.87088","0.02629","149.69591"
"3287.78500","2.97783","17.09243","32.78615","0.02639","149.92155"
"3295.48500","2.97730","17.68266","31.98962","0.02638","155.09854"
"3303.18500","2.97664","17.84641","31.45285","0.02638","156.53482"
"3310.88500","2.97574","17.40961","31.21249","0.02637","152.70357"
"3318.58500","2.95561","16.68195","31.31613","0.02617","146.32114"
"3326.28500","2.94254","16.33363","31.19306","0.02604","143.26595"
"3333.98500","2.94302","16.41903","30.90237","0.02604","144.01501"
"3341.68500","2.94385","16.74966","30.61296","0.02605","146.91504"
"3349.38500","2.95796","17.30347","30.58994","0.02619","151.77260"
"3357.08500","2.97049","17.74741","30.39518","0.02632","155.66653"
"3364.78500","2.97080","17.67070","30.63263","0.02632","154.99362"
"3372.48500","2.97008","17.50207","31.53841","0.02631","153.51459"
"3380.18500","2.93380","16.67898","32.12294","0.02595","146.29503"
"3387.88500","2.88978","16.65940","32.92494","0.02551","146.12328"
"3395.58500","2.89035","17.20133","33.41692","0.02552","150.87669"
"3403.28500","2.89113","16.92768","34.21919","0.02553","148.47650"
"3410.98500","2.89117","17.14811","35.03246","0.02553","150.40988"
"3418.68500","2.89115","17.35395","35.66888","0.02553","152.21541"
"3426.38500","2.89069","17.81240","36.43082","0.02552","156.23656"
"3434.08500","2.88923","17.29666","37.33606","0.02551","151.71284"
"3441.78500","2.82735","16.86067","38.04317","0.02489","147.88867"
"3449.48500","2.82752","17.13595","38.75893","0.02489","150.30322"
"3457.18500","2.82759","17.27092","39.54165","0.02489","151.48714"
"3464.88500","2.82749","17.26404","40.33278","0.02489","151.42676"
"3472.58500","2.79473","17.10372","41.22314","0.02456","150.02054"
"3480.28500","2.78230","16.93513","41.70539","0.02444","148.54179"
"3487.98500","2.78237","17.13236","42.55316","0.02444","150.27174"
"3495.68500","2.78231","17.17884","43.28201","0.02444","150.67947"
"3503.38500","2.78206","17.43248","43.94320","0.02444","152.90416"
"3511.08500","2.74642","16.96359","44.70795","0.02408","148.79146"
"3518.78500","2.73716","17.13797","45.52293","0.02399","150.32097"
"3526.48500","2.69860","16.91566","46.59198","0.02361","148.37099"
"3534.18500","2.69801","17.14134","47.76055","0.02360","150.35056"
"3541.88500","2.68033","17.18378","49.02233","0.02342","150.72281"
"3549.58500","2.63512","16.97741","50.48026","0.02297","148.91261"
"3557.28500","2.63217","17.17573","51.81867","0.02294","150.65221"
"3564.98500","2.59297","17.06442","53.10152","0.02255","149.67583"
"3572.68500","2.58782","17.18454","54.44307","0.02250","150.72940"
"3580.38500","2.54682","16.98277","55.67383","0.02209","148.95969"
"3588.08500","2.54510","17.22253","56.82298","0.02208","151.06265"
"3595.78500","2.50377","16.81610","57.95447","0.02166","147.49779"
"3603.48500","2.50373","17.26531","58.96856","0.02166","151.43793"
"3611.18500","2.48233","17.14433","60.01835","0.02145","150.37671"
"3618.88500","2.45030","16.99678","61.12542","0.02113","149.08253"
"3626.58500","2.41271","16.94141","62.14707","0.02076","148.59692"
"3634.28500","2.40079","17.06894","63.19853","0.02064","149.71550"
"3641.98500","2.38646","17.33551","64.26177","0.02050","152.05362"
"3649.68500","2.31957","16.85902","65.32809","0.01983","147.87421"
"3657.38500","2.31933","17.27248","66.47820","0.01983","151.50078"
"3665.08500","2.27768","17.16154","67.53457","0.01941","150.52768"
"3672.78500","2.21285","16.91620","68.62511","0.01876","148.37575"
"3680.48500","2.19888","17.22997","69.67661","0.01863","151.12790"
"3688.18500","2.11085","16.78967","70.79748","0.01775","147.26591"
"3695.88500","2.10143","17.36682","71.88177","0.01765","152.32826"
"3703.58500","2.00444","17.01608","72.92644","0.01669","149.25183"
"3711.28500","1.94860","17.18058","74.07679","0.01613","150.69475"
"3718.98500","1.87927","17.17558","75.16820","0.01544","150.65083"
"3726.68500","1.67089","15.90734","76.20541","0.01336","139.52681"
"3734.38500","1.61845","16.59334","77.29385","0.01284","145.54388"
"3742.08500","1.61850","17.38841","78.29364","0.01284","152.51765"
"3749.78500","1.61808","18.18141","79.35911","0.01284","159.47319"
"3757.48500","1.22349","15.78975","80.44738","0.00890","138.49539"
"3765.18500","1.22381","16.83559","81.46227","0.00891","147.66873"
"3772.88500","1.22373","17.63218","82.55613","0.00891","154.65579"
"3780.58500","1.13134","17.59030","83.56342","0.00799","154.28847"
"3788.28500","0.80569","16.75708","84.57275","0.00474","146.98010"
"3795.98500","0.80547","17.68720","85.62301","0.00474","155.13837"
"3803.68500","0.56416","17.05207","86.65529","0.00233","149.56752"
"3811.38500","0.39969","17.21857","87.67874","0.00069","151.02789"
"3819.08500","0.15133","16.98199","88.74712","-0.00178","148.95285"
"3826.78500","-0.04976","17.00657","89.74162","-0.00379","149.16841"
"3834.48500","-0.29787","17.12494","90.75802","-0.00626","150.20673"
"3842.18500","-0.61282","17.04480","91.85918","-0.00940","149.50372"
"3849.88500","-0.93146","17.28417","92.88526","-0.01257","151.60332"
"3857.58500","-1.30163","17.32046","93.97886","-0.01626","151.92162"
"3865.28500","-1.68796","17.12011","95.08529","-0.02011","150.16428"
"3872.98500","-2.18316","16.92122","96.05739","-0.02505","148.41978"
"3880.68500","-2.65607","16.95202","97.06547","-0.02976","148.68994"
"3888.38500","-3.02278","17.03278","98.10050","-0.03342","149.39832"
"3896.08500","-3.46679","16.82012","99.13077","-0.03784","147.53305"
"3903.78500","-3.79859","16.95100","100.11064","-0.04115","148.68102"
"3911.48500","-4.10797","16.87021","101.28953","-0.04424","147.97235"
"3919.18500","-4.38682","16.91678","102.27091","-0.04701","148.38089"
"3926.88500","-4.61849","17.08061","103.27480","-0.04932","149.81787"
"3934.58500","-4.79734","17.28030","104.32572","-0.05111","151.56937"
"3942.28500","-5.05541","17.03525","105.36829","-0.05368","149.41995"
"3949.98500","-5.22961","16.90839","106.32451","-0.05541","148.30728"
"3957.68500","-5.38866","17.04896","107.48869","-0.05700","149.54025"
"3965.38500","-5.56981","17.15902","108.56669","-0.05881","150.50557"
"3973.08500","-5.73657","16.84160","109.52288","-0.06047","147.72147"
"3980.78500","-5.88892","16.99323","110.64620","-0.06199","149.05142"
"3988.48500","-6.02598","17.00056","111.56618","-0.06335","149.11569"
"3996.18500","-6.12013","17.52934","112.54039","-0.06429","153.75372"
"4003.88500","-6.26677","17.20371","113.60308","-0.06575","150.89760"
"4011.58500","-6.36128","17.26647","114.58690","-0.06669","151.44806"
"4019.28500","-6.50514","17.09454","115.53177","-0.06813","149.94006"
"4026.98500","-6.60459","16.96510","116.56107","-0.06912","148.80467"
"4034.68500","-6.61998","17.70226","117.69041","-0.06927","155.27043"
"4042.38500","-6.83989","16.24404","118.68576","-0.07146","142.48009"
"4050.08500","-6.88905","16.92864","119.80905","-0.07195","148.48486"
"4057.78500","-6.88954","17.62338","120.84315","-0.07196","154.57858"
"4065.48500","-7.00793","17.07429","121.87984","-0.07314","149.76244"
"4073.18500","-7.07796","16.85397","122.99164","-0.07384","147.82993"
"4080.88500","-7.11141","16.97597","123.79819","-0.07417","148.89999"
"4088.58500","-7.15108","17.03184","124.59389","-0.07457","149.39006"
"4096.28500","-7.17638","16.73061","125.24548","-0.07482","146.74791"
"4103.98500","-7.17609","16.81793","125.52419","-0.07482","147.51385"
"4111.68500","-7.17573","16.95594","125.60466","-0.07481","148.72438"
"4119.38500","-7.17509","16.65457","125.47878","-0.07481","146.08095"
"4127.08500","-7.12701","17.35055","125.13996","-0.07433","152.18558"
"4134.78500","-7.09155","17.87346","124.89333","-0.07397","156.77216"
"4142.48500","-7.09302","17.47445","124.51897","-0.07399","153.27234"
"4150.18500","-7.12658","16.77536","124.03609","-0.07432","147.14047"
"4157.88500","-7.12592","16.39299","123.52010","-0.07432","143.78662"
"4165.58500","-7.06486","16.97967","122.70008","-0.07371","148.93246"
"4173.28500","-7.01207","17.18885","121.87041","-0.07318","150.76727"
"4180.98500","-6.99664","16.97752","120.86687","-0.07303","148.91365"
"4188.68500","-6.92590","17.32514","119.70173","-0.07232","151.96265"
"4196.38500","-6.91711","17.10768","118.63816","-0.07223","150.05530"
"4204.08500","-6.88698","17.05470","117.68047","-0.07193","149.59055"
"4211.78500","-6.84758","17.08802","116.52518","-0.07154","149.88281"
"4219.48500","-6.81187","17.13499","115.53382","-0.07119","150.29486"
"4227.18500","-6.80066","16.79088","114.59554","-0.07107","147.27657"
"4234.88500","-6.70535","17.64021","113.60389","-0.07012","154.72624"
"4242.58500","-6.70282","17.19568","112.74106","-0.07010","150.82719"
"4250.28500","-6.70274","16.78017","111.91926","-0.07010","147.18259"
"4257.98500","-6.65588","16.97886","111.09604","-0.06963","148.92540"
"4265.68500","-6.59885","17.24512","110.33820","-0.06906","151.26076"
"4273.38500","-6.59876","16.74585","109.58720","-0.06906","146.88161"
"4281.08500","-6.49180","17.63859","108.75552","-0.06800","154.71204"
"4288.78500","-6.49195","17.27009","108.04008","-0.06800","151.47984"
"4296.48500","-6.49194","16.90098","107.38520","-0.06800","148.24228"
"4304.18500","-6.49152","16.50437","106.61376","-0.06799","144.76350"
"4311.88500","-6.22969","18.69789","105.90146","-0.06538","164.00336"
"4319.58500","-6.37923","16.26107","105.27071","-0.06687","142.62950"
"4327.28500","-6.37475","16.17579","104.59025","-0.06683","141.88150"
"4334.98500","-6.23635","17.42867","103.94467","-0.06545","152.87071"
"4342.68500","-6.23638","17.03827","103.26861","-0.06545","149.44647"
"4350.38500","-6.23623","16.70100","102.51410","-0.06545","146.48824"
"4358.08500","-6.16108","17.20716","101.76775","-0.06470","150.92787"
"4365.78500","-6.09516","17.06225","101.10047","-0.06404","149.65680"
"4373.48500","-6.01429","17.23755","100.28094","-0.06324","151.19437"
"4381.18500","-5.95266","17.28563","99.49458","-0.06262","151.61613"
"4388.88500","-5.79986","17.58455","98.74535","-0.06110","154.23798"
"4396.58500","-5.79992","16.93157","97.84602","-0.06110","148.51060"
"4404.28500","-5.72436","16.90050","96.99832","-0.06035","148.23805"
"4411.98500","-5.51682","16.91519","95.90901","-0.05828","148.36691"
"4419.68500","-5.34143","17.10276","94.58984","-0.05653","150.01212"
"4427.38500","-5.05317","17.15260","93.24840","-0.05366","150.44926"
"4435.08500","-4.87018","16.73966","91.82861","-0.05183","146.82730"
"4442.78500","-4.30628","17.64135","90.08588","-0.04621","154.73625"
"4450.48500","-4.15916","16.96353","88.69479","-0.04475","148.79091"
"4458.18500","-3.43458","17.65483","87.34019","-0.03752","154.85443"
"4465.88500","-3.13597","16.73059","86.05952","-0.03455","146.74770"
"4473.58500","-2.61632","17.07199","84.62207","-0.02937","149.74223"
"4481.28500","-2.32551","16.51015","83.48013","-0.02647","144.81421"
"4488.98500","-1.81026","17.55180","82.23151","-0.02133","153.95073"
"4496.68500","-1.38799","16.89520","80.99541","-0.01713","148.19159"
"4504.38500","-1.03534","16.63190","80.03883","-0.01361","145.88216"
"4512.08500","-0.45083","16.38737","78.46268","-0.00778","143.73729"
"4519.78500","0.84231","17.80761","75.94849","0.00510","156.19450"
"4527.48500","0.86918","18.03690","74.15802","0.00537","158.20567"
"4535.18500","0.67408","15.46193","73.83327","0.00343","135.62003"
"4542.88500","1.01421","16.50913","72.83517","0.00682","144.80525"
"4550.58500","1.18834","15.70062","70.82344","0.00855","137.71367"
"4558.28500","1.51183","18.88077","68.58492","0.01178","165.60742"
"4565.98500","1.51356","18.69043","67.37072","0.01179","163.93797"
"4573.68500","1.51346","17.14808","66.35759","0.01179","150.40964"
"4581.38500","1.51356","16.04330","65.58137","0.01179","140.71938"
"4589.08500","1.51402","15.43225","64.97422","0.01180","135.35970"
"4596.78500","1.91415","19.43314","63.68354","0.01579","170.45241"
"4604.48500","1.90946","18.53071","62.75548","0.01574","162.53697"
"4612.18500","1.86740","16.40516","61.88523","0.01532","143.89337"
"4619.88500","1.87303","14.97097","61.02923","0.01538","131.31374"
"4627.58500","2.03196","17.04841","59.91833","0.01696","149.53543"
"4635.28500","2.07307","17.70081","59.00071","0.01737","155.25774"
"4642.98500","2.12928","17.89417","58.06261","0.01793","156.95372"
"4650.68500","2.21190","16.72535","57.06102","0.01876","146.70177"
"4658.38500","2.21984","16.15590","56.16504","0.01883","141.70699"
"4666.08500","2.26861","17.05693","55.63524","0.01932","149.61015"
"4673.78500","2.30243","17.76806","54.63022","0.01966","155.84761"
"4681.48500","2.41397","17.68381","53.51679","0.02077","155.10866"
"4689.18500","2.41682","16.35159","52.58805","0.02080","143.42349"
"4696.88500","2.45205","17.44194","51.78925","0.02115","152.98714"
"4704.58500","2.48532","17.79297","50.96038","0.02148","156.06615"
"4712.28500","2.59202","16.77629","49.59047","0.02254","147.14857"
"4719.98500","2.60359","17.14993","48.12355","0.02266","150.42586"
"4727.68500","2.60496","17.34271","47.19238","0.02267","152.11679"
"4735.38500","2.68808","17.76038","46.18998","0.02350","155.78029"
"4743.08500","2.69817","16.47857","45.11629","0.02360","144.53723"
"4750.78500","2.69919","16.54443","44.49217","0.02361","145.11493"
"4758.48500","2.83849","18.51793","42.98801","0.02500","162.42491"
"4766.18500","2.83718","18.31156","41.98209","0.02499","160.61478"
"4773.88500","2.77092","16.02013","41.21280","0.02433","140.51611"
"4781.58500","2.77191","15.88675","40.50565","0.02434","139.34625"
"4789.28500","2.85600","17.51295","39.26516","0.02518","153.60997"
"4796.98500","2.88029","17.79101","38.44750","0.02542","156.04893"
"4804.68500","2.88059","16.38067","37.40810","0.02542","143.67854"
"4812.38500","2.88581","16.43121","36.71120","0.02547","144.12180"
"4820.08500","2.93540","17.76243","35.51650","0.02597","155.79823"
"4827.78500","2.95676","17.39090","34.34868","0.02618","152.53949"
"4835.48500","2.95675","16.38564","33.42814","0.02618","143.72215"
"4843.18500","2.95670","16.99509","32.73394","0.02618","149.06775"
"4850.88500","2.97451","17.85246","31.78641","0.02636","156.58789"
"4858.58500","2.98295","17.09000","31.52825","0.02644","149.90022"
"4866.28500","2.98278","16.74973","31.55772","0.02644","146.91565"
"4873.98500","2.98261","16.98311","31.17473","0.02644","148.96269"
"4881.68500","2.98243","17.41612","31.16532","0.02644","152.76068"
"4889.38500","2.98238","17.62645","30.56519","0.02643","154.60556"
"4897.08500","2.98224","17.84315","30.45151","0.02643","156.50626"
"4904.78500","2.98197","17.39126","30.71026","0.02643","152.54263"
"4912.48500","2.98169","17.09776","30.65330","0.02643","149.96832"
"4920.18500","2.97609","17.03335","31.00853","0.02637","149.40335"
"4927.88500","2.93247","16.62620","31.77049","0.02594","145.83211"
"4935.58500","2.93255","17.10239","32.39137","0.02594","150.00890"
"4943.28500","2.93262","17.41674","32.96134","0.02594","152.76616"
"4950.98500","2.93260","17.02581","33.72166","0.02594","149.33717"
"4958.68500","2.91020","16.97552","34.41816","0.02572","148.89604"
"4966.38500","2.88758","17.07286","35.14619","0.02549","149.74991"
"4974.08500","2.88754","16.91480","36.15831","0.02549","148.36349"
"4981.78500","2.88752","17.18623","36.66545","0.02549","150.74428"
"4989.48500","2.88263","17.65592","37.31675","0.02544","154.86398"
"4997.18500","2.85117","17.32993","38.26851","0.02513","152.00470"
"5004.88500","2.84708","17.46742","39.14436","0.02509","153.21065"
"5012.58500","2.84021","17.50696","39.88079","0.02502","153.55746"
"5020.28500","2.80053","16.87994","40.62533","0.02462","148.05769"
"5027.98500","2.80091","16.62695","41.53227","0.02463","145.83867"
"5035.68500","2.80104","17.10588","42.13409","0.02463","150.03954"
"5043.38500","2.80095","17.28262","42.99857","0.02463","151.58975"
"5051.08500","2.80069","17.36946","43.63223","0.02462","152.35144"
"5058.78500","2.79383","17.46209","44.27396","0.02456","153.16389"
"5066.48500","2.74796","17.02576","45.05708","0.02410","149.33675"
"5074.18500","2.74745","17.23252","45.94295","0.02409","151.15027"
"5081.88500","2.69668","16.74487","47.01523","0.02359","146.87297"
"5089.58500","2.69211","16.99397","48.28535","0.02354","149.05792"
"5097.28500","2.69192","17.31128","49.50864","0.02354","151.84114"
"5104.98500","2.63631","16.82735","50.86650","0.02299","147.59644"
"5112.68500","2.61241","16.91642","52.30784","0.02275","148.37769"
"5120.38500","2.61064","17.11435","53.59060","0.02273","150.11375"
"5128.08500","2.58488","17.10975","54.83020","0.02247","150.07343"
"5135.78500","2.55381","16.90987","56.10631","0.02216","148.32025"
"5143.48500","2.55128","17.24297","57.23864","0.02214","151.24196"
"5151.18500","2.50292","16.90273","58.34105","0.02166","148.25760"
"5158.88500","2.50294","17.12130","59.43487","0.02166","150.17474"
"5166.58500","2.49524","17.29558","60.41877","0.02158","151.70341"
"5174.28500","2.44745","17.08748","61.45356","0.02110","149.87810"
"5181.98500","2.41657","16.83751","62.55014","0.02080","147.68559"
"5189.68500","2.40753","17.13609","63.59157","0.02071","150.30446"
"5197.38500","2.36242","16.96144","64.63962","0.02026","148.77261"
"5205.08500","2.34249","17.22260","65.75425","0.02006","151.06328"
"5212.78500","2.30287","17.19977","66.82073","0.01966","150.86304"
"5220.48500","2.26082","17.05566","67.89434","0.01924","149.59901"
"5228.18500","2.21401","17.15538","69.08408","0.01878","150.47369"
"5235.88500","2.19222","17.34202","70.13422","0.01856","152.11075"
"5243.58500","2.10125","17.01135","71.21300","0.01765","149.21037"
"5251.28500","2.09765","17.59122","72.35168","0.01762","154.29657"
"5258.98500","1.99482","17.04526","73.38876","0.01659","149.50778"
"5266.68500","1.91574","17.00275","74.44273","0.01580","149.13496"
"5274.38500","1.83190","17.07830","75.50468","0.01497","149.79762"
"5282.08500","1.76924","17.30528","76.54775","0.01434","151.78848"
"5289.78500","1.66926","17.15597","77.58247","0.01335","150.47888"
"5297.48500","1.56540","16.90297","78.62717","0.01231","148.25974"
"5305.18500","1.35042","16.40332","79.65955","0.01017","143.87720"
"5312.88500","1.35051","17.21212","80.67023","0.01017","150.97137"
"5320.58500","1.35017","18.10141","81.78107","0.01017","158.77150"
"5328.28500","1.04992","16.33222","82.83344","0.00717","143.25357"
"5335.98500","0.91034","16.99354","83.84757","0.00578","149.05411"
"5343.68500","0.86054","17.57553","84.93174","0.00529","154.15894"
"5351.38500","0.61740","16.98349","85.94722","0.00286","148.96602"
"5359.08500","0.50603","17.42135","86.94555","0.00175","152.80655"
"5366.78500","0.29884","17.28438","88.09465","-0.00031","151.60518"
"5374.48500","0.04229","17.05705","89.13101","-0.00287","149.61118"
"5382.18500","-0.17589","17.13424","90.18501","-0.00504","150.28824"
"5389.88500","-0.46696","17.13508","91.34756","-0.00795","150.29561"
"5397.58500","-0.75090","17.27392","92.33046","-0.01078","151.51340"
"5405.28500","-1.12065","16.96013","93.25195","-0.01446","148.76106"
"5412.98500","-1.38554","17.19800","94.33307","-0.01710","150.84753"
"5420.68500","-2.01517","16.82837","95.33270","-0.02338","147.60536"
"5428.38500","-2.39311","17.22349","96.35133","-0.02714","151.07108"
"5436.08500","-2.76525","17.29160","97.42664","-0.03085","151.66853"
"5443.78500","-3.18031","17.04092","98.43280","-0.03499","149.46968"
"5451.48500","-3.60286","17.15139","99.41892","-0.03920","150.43871"
"5459.18500","-3.97321","16.67683","100.58892","-0.04289","146.27625"
"5466.88500","-4.21482","17.18718","101.57526","-0.04530","150.75259"
"5474.58500","-4.46396","16.99934","102.60500","-0.04778","149.10500"
"5482.28500","-4.66417","16.97911","103.67585","-0.04978","148.92758"
"5489.98500","-4.84015","17.21056","104.71782","-0.05153","150.95766"
"5497.68500","-5.05728","17.32215","105.71056","-0.05370","151.93646"
"5505.38500","-5.27976","17.02347","106.83811","-0.05591","149.31668"
"5513.08500","-5.37688","17.23710","107.78933","-0.05688","151.19043"
"5520.78500","-5.58427","17.04355","108.75700","-0.05895","149.49280"
"5528.48500","-5.74979","17.15589","109.88828","-0.06060","150.47810"
"5536.18500","-5.87212","17.03277","110.83802","-0.06182","149.39821"
"5543.88500","-6.01303","17.09592","111.74849","-0.06322","149.95212"
"5551.58500","-6.16364","16.89724","112.83794","-0.06472","148.20943"
"5559.28500","-6.22469","17.38166","113.81102","-0.06533","152.45839"
"5566.98500","-6.32932","17.45098","114.80412","-0.06638","153.06642"
"5574.68500","-6.47899","16.99895","115.97625","-0.06787","149.10162"
"5582.38500","-6.55205","17.37615","117.09496","-0.06860","152.41013"
"5590.08500","-6.65028","17.23547","118.15027","-0.06957","151.17618"
"5597.78500","-6.74108","17.06986","119.18562","-0.07048","149.72354"
"5604.35500","-6.88768","16.41788","120.05760","-0.07194","144.00488"